Workbook

Sheet Vejledning
C2: Gratis skabelon fra Prowi
B4: Salgsbudget
B5: Fra omsætningsmål til sælgere, kvoter og provisionsomkostning
B7: Regnearket regner baglæns fra jeres omsætningsmål: hvor meget pipeline og hvor mange handler der skal til, hvor mange sælgere I skal have, hvordan kvoterne fordeles pr. sælger og måned, og hvad salgslønnen koster ved 80, 100 og 120 % målopfyldelse. Det indeholder eksempeldata for 10 sælgere, så du kan se, hvordan det virker.
B9: Trin for trin
B10: 1. Forudsætninger | C10: Skriv omsætningsmål, ordrestørrelse, win rate, salgscyklus, kvote, opstartsperiode, sælgerafgang, løn og sæsonfordeling. Det er de eneste tal, regnearket bygger på, ud over sælgerlisten.
B11: 2. Kapacitet | C11: Viser nødvendig pipeline, antal handler og salgsmuligheder, og hvor mange sælgere I skal have, når opstart og afgang er regnet med. Her skal du ikke skrive noget.
B12: 3. Kvotefordeling | C12: Skriv sælgerne ind (op til 20) med startmåned, og om de er nye. Arket fordeler årskvoten på måneder efter sæsonfordelingen og nedsætter kvoten i opstartsperioden.
B13: 4. OTE og provision | C13: Viser OTE, pay mix og provisionssats (variabel løn ÷ kvote) og provisionen pr. sælger ved 80, 100 og 120 % målopfyldelse. Målopfyldelserne kan ændres.
B14: 5. Overblik | C14: Samler budgettet: sælgere, kvote, pipeline, salgslønomkostninger og omkostning i % af omsætningen (cost of sales) for de tre scenarier og pr. måned.
B16: Farver
B17: Lavendel felt, lilla tekst | C17: Her skriver du. Alt andet er formler.
B18: Gråt felt | C18: Beregnet automatisk. Ret ikke i formlerne, medmindre du ved, hvad du gør.
B19: Lyseblåt felt | C19: Resultater og totaler.
B21: Sådan regner arket
B22: Handler og pipeline | C22: Handler = omsætningsmål ÷ ordrestørrelse. Salgsmuligheder = handler ÷ win rate. Nødvendig pipeline = omsætningsmål ÷ win rate, og pipeline coverage = pipeline ÷ mål.
B23: Kapacitet pr. sælger | C23: Årskvote × planlagt målopfyldelse. Fuldt produktive sælgere (FTE) = omsætningsmål ÷ kapacitet pr. sælger.
B24: Opstart og afgang | C24: En ny sælger mister opstartsmåneder × (1 − produktivitet i opstart) ÷ 12 af et års kapacitet. En sælger, der stopper, koster rekrutteringstid plus en ny opstart. Antal sælgere = (FTE − sælgere ved start × tab pr. ny) ÷ (1 − afgang × tab pr. afgang − tab pr. ny). Nye sælgere antages at starte ved årets begyndelse.
B25: Kvote pr. måned | C25: Årskvote × månedens andel af sæsonfordelingen. Før startmåneden er kvoten 0, og i opstartsperioden ganges den med produktiviteten i opstart. Afgang er ikke med i kvoteplanen, fordi I ikke ved, hvem der stopper.
B26: Provisionssats | C26: Variabel løn ved 100 % ÷ sælgerens årskvote. Over 100 % ganges satsen med acceleratorfaktoren. Sæt faktoren til 1, hvis I ikke bruger accelerator.
B27: Cost of sales | C27: Grundløn + provision + øvrige lønomkostninger ÷ omsætning i scenariet. Omsætning = kvote i alt × målopfyldelse.
B28: Pipeline pr. måned | C28: Pipeline, der skal skabes i en måned = kvoten i måneden salgscyklussen senere ÷ win rate. For de sidste måneder bruges årets sæsonfordeling for næste år.
B30: Godt at vide
B31: • | C31: Alle tal i arket er eksempler. Brug jeres egne tal fra CRM og regnskab, fx win rate og ordrestørrelse for de seneste 12 måneder.
B32: • | C32: Budgettet er en model, ikke en garanti. Brug det til at teste, hvad der sker, hvis win rate falder, eller en ansættelse bliver forsinket.
B33: • | C33: Løn er uden feriepenge, pension og andre tillæg, medmindre I lægger dem i 'Øvrige lønomkostninger'.
B34: • | C34: Ingen makroer. Alle beregninger er almindelige formler, som virker i Excel, Google Sheets, Numbers og LibreOffice.
B37: prowi.io · Gratis skabelon fra Prowi

Sheet Forudsætninger
B2: Forudsætninger
B3: Skriv kun i de lavendel felter. Alle andre ark regner ud fra tallene her og sælgerlisten i Kvotefordeling.
B5: Mål og salgsproces
B6: År | C6: 2026 | E6: Budgetåret.
B7: Omsætningsmål, nysalg (kr.) | C7: 24000000 | E7: Den omsætning, sælgerne skal lukke i året.
B8: Gennemsnitlig ordrestørrelse (kr.) | C8: 150000 | E8: Gennemsnitlig værdi af en vundet handel. Brug jeres egne tal fra CRM.
B9: Win rate | C9: 0.25 | E9: Andel af kvalificerede salgsmuligheder, der bliver vundet.
B10: Salgscyklus (måneder) | C10: 3 | E10: Tid fra kvalificeret salgsmulighed til underskrift.
B12: Sælgere
B13: Sælgere ved årets start | C13: 7 | E13: Fuldt oplærte sælgere, der er ansat 1. januar.
B14: Årskvote pr. fuldt produktiv sælger (kr.) | C14: 3000000 | E14: Standardkvote. Kan ændres pr. sælger i Kvotefordeling.
B15: Planlagt gennemsnitlig målopfyldelse | C15: 0.9 | E15: Den målopfyldelse, I budgetterer med. Sjældent 100 % for hele teamet.
B16: Opstartsperiode, ramp (måneder) | C16: 4 | E16: Måneder, før en ny sælger er fuldt produktiv.
B17: Produktivitet i opstartsperioden | C17: 0.5 | E17: Gennemsnitlig andel af fuld kvote i opstartsperioden.
B18: Årlig sælgerafgang | C18: 0.15 | E18: Andel af sælgerne, der forventes at stoppe i løbet af året.
B19: Rekrutteringstid ved afgang (måneder) | C19: 2 | E19: Måneder, en stilling står tom, før en ny sælger starter.
B21: Løn og provision (standardplan)
B22: Grundløn pr. måned (kr.) | C22: 42000 | E22: Fast løn pr. sælger.
B23: Variabel løn ved 100 %, pr. år (kr.) | C23: 216000 | E23: Provision ved præcis 100 % af årskvoten.
B24: Accelerator over 100 % (faktor) | C24: 1.5 | E24: Satsen over kvoten = provisionssats × faktor. Skriv 1, hvis I ikke bruger accelerator.
B25: Øvrige lønomkostninger (% af løn) | C25: 0.1 | E25: Eksempel. Fx pension, ATP, forsikring og feriepenge. Brug jeres egne tal.
B27: Sæsonfordeling | E27: Vægt pr. måned. Vægtene behøver ikke summe til 100; arket regner andelene ud.
B28: Måned | C28: Vægt | D28: Andel
B29: Januar | C29: 7 | D29: =IF(SUM($C$29:$C$40)=0,1/12,C29/SUM($C$29:$C$40)) -> 0.07
B30: Februar | C30: 8 | D30: =IF(SUM($C$29:$C$40)=0,1/12,C30/SUM($C$29:$C$40)) -> 0.08
B31: Marts | C31: 9 | D31: =IF(SUM($C$29:$C$40)=0,1/12,C31/SUM($C$29:$C$40)) -> 0.09
B32: April | C32: 8 | D32: =IF(SUM($C$29:$C$40)=0,1/12,C32/SUM($C$29:$C$40)) -> 0.08
B33: Maj | C33: 9 | D33: =IF(SUM($C$29:$C$40)=0,1/12,C33/SUM($C$29:$C$40)) -> 0.09 | E33: Eksempel: lavere i juli (ferie) og højere i årets sidste måneder.
B34: Juni | C34: 9 | D34: =IF(SUM($C$29:$C$40)=0,1/12,C34/SUM($C$29:$C$40)) -> 0.09
B35: Juli | C35: 4 | D35: =IF(SUM($C$29:$C$40)=0,1/12,C35/SUM($C$29:$C$40)) -> 0.04
B36: August | C36: 7 | D36: =IF(SUM($C$29:$C$40)=0,1/12,C36/SUM($C$29:$C$40)) -> 0.07
B37: September | C37: 9 | D37: =IF(SUM($C$29:$C$40)=0,1/12,C37/SUM($C$29:$C$40)) -> 0.09
B38: Oktober | C38: 9 | D38: =IF(SUM($C$29:$C$40)=0,1/12,C38/SUM($C$29:$C$40)) -> 0.09
B39: November | C39: 10 | D39: =IF(SUM($C$29:$C$40)=0,1/12,C39/SUM($C$29:$C$40)) -> 0.1
B40: December | C40: 11 | D40: =IF(SUM($C$29:$C$40)=0,1/12,C40/SUM($C$29:$C$40)) -> 0.11
B41: I alt | C41: =SUM(C29:C40) -> 100 | D41: =SUM(D29:D40) -> 1

Sheet Kapacitet
B2: Kapacitet: pipeline og antal sælgere
B3: Alt på dette ark er formler. Ret forudsætningerne i Forudsætninger.
B4: Pipeline og aktivitet
B5: Omsætningsmål (kr.) | C5: =Forudsætninger!$C$7 -> 24000000 | E5: Fra Forudsætninger.
B6: Handler, der skal vindes | C6: =IFERROR(C5/Forudsætninger!$C$8,0) -> 160 | E6: Omsætningsmål ÷ gennemsnitlig ordrestørrelse.
B7: Kvalificerede salgsmuligheder i året | C7: =IFERROR(C6/Forudsætninger!$C$9,0) -> 640 | E7: Handler ÷ win rate.
B8: Nødvendig pipeline (kr.) | C8: =IFERROR(C5/Forudsætninger!$C$9,0) -> 96000000 | E8: Omsætningsmål ÷ win rate.
B9: Pipeline coverage | C9: =IFERROR(C8/C5,0) -> 4 | E9: Pipeline ÷ omsætningsmål. Svarer til 1 ÷ win rate.
B10: Salgsmuligheder pr. måned (gennemsnit) | C10: =C7/12 -> 53.333333 | E10: Se fordelingen pr. måned i Overblik.
B11: Pipeline skabes ca. så mange måneder før lukning | C11: =Forudsætninger!$C$10 -> 3 | E11: Salgscyklussen fra Forudsætninger.
B13: Sælgerkapacitet
B14: Kapacitet pr. fuldt produktiv sælger (kr.) | C14: =Forudsætninger!$C$14*Forudsætninger!$C$15 -> 2700000 | E14: Årskvote × planlagt målopfyldelse.
B15: Fuldt produktive sælgere (FTE), der skal til | C15: =IFERROR(C5/C14,0) -> 8.8888889 | E15: Omsætningsmål ÷ kapacitet pr. sælger.
B16: Tab pr. ny sælger (andel af et års kapacitet) | C16: =Forudsætninger!$C$16*(1-Forudsætninger!$C$17)/12 -> 0.16666667 | E16: Opstartsmåneder × (1 − produktivitet i opstart) ÷ 12.
B17: Tab pr. sælger, der stopper (andel af et år) | C17: =(Forudsætninger!$C$19+Forudsætninger!$C$16*(1-Forudsætninger!$C$17))/12 -> 0.33333333 | E17: (Rekrutteringstid + opstartstab i måneder) ÷ 12.
B18: Antal sælgere, I skal have (beregnet) | C18: =IFERROR(IF((C15-Forudsætninger!$C$13*C16)/(1-Forudsætninger!$C$18*C17-C16)>Forudsætninger!$C$13,(C15-Forudsætninger!$C$13*C16)/(1-Forudsætninger!$C$18*C17-C16),C15/(1-Forudsætninger!$C$18*C17)),0) -> 9.858156 | E18: Inklusive tab ved opstart og afgang. Nye sælgere antages at starte ved årets begyndelse.
B19: Antal sælgere, I skal have (rundet op) | C19: =ROUNDUP(C18,0) -> 10 | E19: Det antal stillinger, budgettet kræver i gennemsnit over året.
B20: Sælgere ved årets start | C20: =Forudsætninger!$C$13 -> 7 | E20: Fra Forudsætninger.
B21: Nye sælgere til vækst | C21: =MAX(0,C19-C20) -> 3 | E21: Skal helst starte tidligt på året.
B22: Forventede afgange i året | C22: =C19*Forudsætninger!$C$18 -> 1.5 | E22: Antal sælgere × årlig afgang. Hver afgang kræver en genansættelse.
B23: Rekrutteringer i alt i året | C23: =C21+C22 -> 4.5 | E23: Nye sælgere + genansættelser.
B25: Sammenligning med kvoteplanen
B26: Sælgere i Kvotefordeling | C26: =COUNTA(Kvotefordeling!$B$7:$B$26) -> 10 | E26: Antal navne på sælgerlisten.
B27: Forskel: sælgere i planen − sælgere, I skal have | C27: =C26-C19 -> 0 | E27: Negativt tal: planen har for få sælgere.

Sheet Kvotefordeling
B2: Kvotefordeling pr. sælger og måned
B3: Skriv sælgerne i de lavendel kolonner B-E. Kvoten fordeles efter sæsonfordelingen og nedsættes i opstartsperioden for nye sælgere.
B4: Individuel årskvote er valgfri. Tom = standardkvoten fra Forudsætninger. Startmåned 1 = januar.
B6: Sælger | C6: Startmåned (1-12) | D6: Ny sælger med opstart? | E6: Individuel årskvote (valgfri) | F6: Årskvote, anvendt | G6: Jan | H6: Feb | I6: Mar | J6: Apr | K6: Maj | L6: Jun | M6: Jul | N6: Aug | O6: Sep | P6: Okt | Q6: Nov | R6: Dec | S6: Kvote i året
B7: Anna Holm | C7: 1 | D7: Nej | F7: =IF($B7="","",IF(N($E7)>0,$E7,Forudsætninger!$C$14)) -> 3000000 | G7: =IF($B7="","",$F7*INDEX(Forudsætninger!$D$29:$D$40,1)*IF(1<IF(N($C7)<1,1,$C7),0,IF(AND($D7="Ja",1<IF(N($C7)<1,1,$C7)+Forudsætninger!$C$16),Forudsætninger!$C$17,1))) -> 210000 | H7: =IF($B7="","",$F7*INDEX(Forudsætninger!$D$29:$D$40,2)*IF(2<IF(N($C7)<1,1,$C7),0,IF(AND($D7="Ja",2<IF(N($C7)<1,1,$C7)+Forudsætninger!$C$16),Forudsætninger!$C$17,1))) -> 240000 | I7: =IF($B7="","",$F7*INDEX(Forudsætninger!$D$29:$D$40,3)*IF(3<IF(N($C7)<1,1,$C7),0,IF(AND($D7="Ja",3<IF(N($C7)<1,1,$C7)+Forudsætninger!$C$16),Forudsætninger!$C$17,1))) -> 270000 | J7: =IF($B7="","",$F7*INDEX(Forudsætninger!$D$29:$D$40,4)*IF(4<IF(N($C7)<1,1,$C7),0,IF(AND($D7="Ja",4<IF(N($C7)<1,1,$C7)+Forudsætninger!$C$16),Forudsætninger!$C$17,1))) -> 240000 | K7: =IF($B7="","",$F7*INDEX(Forudsætninger!$D$29:$D$40,5)*IF(5<IF(N($C7)<1,1,$C7),0,IF(AND($D7="Ja",5<IF(N($C7)<1,1,$C7)+Forudsætninger!$C$16),Forudsætninger!$C$17,1))) -> 270000 | L7: =IF($B7="","",$F7*INDEX(Forudsætninger!$D$29:$D$40,6)*IF(6<IF(N($C7)<1,1,$C7),0,IF(AND($D7="Ja",6<IF(N($C7)<1,1,$C7)+Forudsætninger!$C$16),Forudsætninger!$C$17,1))) -> 270000 | M7: =IF($B7="","",$F7*INDEX(Forudsætninger!$D$29:$D$40,7)*IF(7<IF(N($C7)<1,1,$C7),0,IF(AND($D7="Ja",7<IF(N($C7)<1,1,$C7)+Forudsætninger!$C$16),Forudsætninger!$C$17,1))) -> 120000 | N7: =IF($B7="","",$F7*INDEX(Forudsætninger!$D$29:$D$40,8)*IF(8<IF(N($C7)<1,1,$C7),0,IF(AND($D7="Ja",8<IF(N($C7)<1,1,$C7)+Forudsætninger!$C$16),Forudsætninger!$C$17,1))) -> 210000 | O7: =IF($B7="","",$F7*INDEX(Forudsætninger!$D$29:$D$40,9)*IF(9<IF(N($C7)<1,1,$C7),0,IF(AND($D7="Ja",9<IF(N($C7)<1,1,$C7)+Forudsætninger!$C$16),Forudsætninger!$C$17,1))) -> 270000 | P7: =IF($B7="","",$F7*INDEX(Forudsætninger!$D$29:$D$40,10)*IF(10<IF(N($C7)<1,1,$C7),0,IF(AND($D7="Ja",10<IF(N($C7)<1,1,$C7)+Forudsætninger!$C$16),Forudsætninger!$C$17,1))) -> 270000 | Q7: =IF($B7="","",$F7*INDEX(Forudsætninger!$D$29:$D$40,11)*IF(11<IF(N($C7)<1,1,$C7),0,IF(AND($D7="Ja",11<IF(N($C7)<1,1,$C7)+Forudsætninger!$C$16),Forudsætninger!$C$17,1))) -> 300000 | R7: =IF($B7="","",$F7*INDEX(Forudsætninger!$D$29:$D$40,12)*IF(12<IF(N($C7)<1,1,$C7),0,IF(AND($D7="Ja",12<IF(N($C7)<1,1,$C7)+Forudsætninger!$C$16),Forudsætninger!$C$17,1))) -> 330000 | S7: =IF($B7="","",SUM(G7:R7)) -> 3000000
B8: Bo Jensen | C8: 1 | D8: Nej | F8: =IF($B8="","",IF(N($E8)>0,$E8,Forudsætninger!$C$14)) -> 3000000 | G8: =IF($B8="","",$F8*INDEX(Forudsætninger!$D$29:$D$40,1)*IF(1<IF(N($C8)<1,1,$C8),0,IF(AND($D8="Ja",1<IF(N($C8)<1,1,$C8)+Forudsætninger!$C$16),Forudsætninger!$C$17,1))) -> 210000 | H8: =IF($B8="","",$F8*INDEX(Forudsætninger!$D$29:$D$40,2)*IF(2<IF(N($C8)<1,1,$C8),0,IF(AND($D8="Ja",2<IF(N($C8)<1,1,$C8)+Forudsætninger!$C$16),Forudsætninger!$C$17,1))) -> 240000 | I8: =IF($B8="","",$F8*INDEX(Forudsætninger!$D$29:$D$40,3)*IF(3<IF(N($C8)<1,1,$C8),0,IF(AND($D8="Ja",3<IF(N($C8)<1,1,$C8)+Forudsætninger!$C$16),Forudsætninger!$C$17,1))) -> 270000 | J8: =IF($B8="","",$F8*INDEX(Forudsætninger!$D$29:$D$40,4)*IF(4<IF(N($C8)<1,1,$C8),0,IF(AND($D8="Ja",4<IF(N($C8)<1,1,$C8)+Forudsætninger!$C$16),Forudsætninger!$C$17,1))) -> 240000 | K8: =IF($B8="","",$F8*INDEX(Forudsætninger!$D$29:$D$40,5)*IF(5<IF(N($C8)<1,1,$C8),0,IF(AND($D8="Ja",5<IF(N($C8)<1,1,$C8)+Forudsætninger!$C$16),Forudsætninger!$C$17,1))) -> 270000 | L8: =IF($B8="","",$F8*INDEX(Forudsætninger!$D$29:$D$40,6)*IF(6<IF(N($C8)<1,1,$C8),0,IF(AND($D8="Ja",6<IF(N($C8)<1,1,$C8)+Forudsætninger!$C$16),Forudsætninger!$C$17,1))) -> 270000 | M8: =IF($B8="","",$F8*INDEX(Forudsætninger!$D$29:$D$40,7)*IF(7<IF(N($C8)<1,1,$C8),0,IF(AND($D8="Ja",7<IF(N($C8)<1,1,$C8)+Forudsætninger!$C$16),Forudsætninger!$C$17,1))) -> 120000 | N8: =IF($B8="","",$F8*INDEX(Forudsætninger!$D$29:$D$40,8)*IF(8<IF(N($C8)<1,1,$C8),0,IF(AND($D8="Ja",8<IF(N($C8)<1,1,$C8)+Forudsætninger!$C$16),Forudsætninger!$C$17,1))) -> 210000 | O8: =IF($B8="","",$F8*INDEX(Forudsætninger!$D$29:$D$40,9)*IF(9<IF(N($C8)<1,1,$C8),0,IF(AND($D8="Ja",9<IF(N($C8)<1,1,$C8)+Forudsætninger!$C$16),Forudsætninger!$C$17,1))) -> 270000 | P8: =IF($B8="","",$F8*INDEX(Forudsætninger!$D$29:$D$40,10)*IF(10<IF(N($C8)<1,1,$C8),0,IF(AND($D8="Ja",10<IF(N($C8)<1,1,$C8)+Forudsætninger!$C$16),Forudsætninger!$C$17,1))) -> 270000 | Q8: =IF($B8="","",$F8*INDEX(Forudsætninger!$D$29:$D$40,11)*IF(11<IF(N($C8)<1,1,$C8),0,IF(AND($D8="Ja",11<IF(N($C8)<1,1,$C8)+Forudsætninger!$C$16),Forudsætninger!$C$17,1))) -> 300000 | R8: =IF($B8="","",$F8*INDEX(Forudsætninger!$D$29:$D$40,12)*IF(12<IF(N($C8)<1,1,$C8),0,IF(AND($D8="Ja",12<IF(N($C8)<1,1,$C8)+Forudsætninger!$C$16),Forudsætninger!$C$17,1))) -> 330000 | S8: =IF($B8="","",SUM(G8:R8)) -> 3000000
B9: Camilla Nørgaard | C9: 1 | D9: Nej | F9: =IF($B9="","",IF(N($E9)>0,$E9,Forudsætninger!$C$14)) -> 3000000 | G9: =IF($B9="","",$F9*INDEX(Forudsætninger!$D$29:$D$40,1)*IF(1<IF(N($C9)<1,1,$C9),0,IF(AND($D9="Ja",1<IF(N($C9)<1,1,$C9)+Forudsætninger!$C$16),Forudsætninger!$C$17,1))) -> 210000 | H9: =IF($B9="","",$F9*INDEX(Forudsætninger!$D$29:$D$40,2)*IF(2<IF(N($C9)<1,1,$C9),0,IF(AND($D9="Ja",2<IF(N($C9)<1,1,$C9)+Forudsætninger!$C$16),Forudsætninger!$C$17,1))) -> 240000 | I9: =IF($B9="","",$F9*INDEX(Forudsætninger!$D$29:$D$40,3)*IF(3<IF(N($C9)<1,1,$C9),0,IF(AND($D9="Ja",3<IF(N($C9)<1,1,$C9)+Forudsætninger!$C$16),Forudsætninger!$C$17,1))) -> 270000 | J9: =IF($B9="","",$F9*INDEX(Forudsætninger!$D$29:$D$40,4)*IF(4<IF(N($C9)<1,1,$C9),0,IF(AND($D9="Ja",4<IF(N($C9)<1,1,$C9)+Forudsætninger!$C$16),Forudsætninger!$C$17,1))) -> 240000 | K9: =IF($B9="","",$F9*INDEX(Forudsætninger!$D$29:$D$40,5)*IF(5<IF(N($C9)<1,1,$C9),0,IF(AND($D9="Ja",5<IF(N($C9)<1,1,$C9)+Forudsætninger!$C$16),Forudsætninger!$C$17,1))) -> 270000 | L9: =IF($B9="","",$F9*INDEX(Forudsætninger!$D$29:$D$40,6)*IF(6<IF(N($C9)<1,1,$C9),0,IF(AND($D9="Ja",6<IF(N($C9)<1,1,$C9)+Forudsætninger!$C$16),Forudsætninger!$C$17,1))) -> 270000 | M9: =IF($B9="","",$F9*INDEX(Forudsætninger!$D$29:$D$40,7)*IF(7<IF(N($C9)<1,1,$C9),0,IF(AND($D9="Ja",7<IF(N($C9)<1,1,$C9)+Forudsætninger!$C$16),Forudsætninger!$C$17,1))) -> 120000 | N9: =IF($B9="","",$F9*INDEX(Forudsætninger!$D$29:$D$40,8)*IF(8<IF(N($C9)<1,1,$C9),0,IF(AND($D9="Ja",8<IF(N($C9)<1,1,$C9)+Forudsætninger!$C$16),Forudsætninger!$C$17,1))) -> 210000 | O9: =IF($B9="","",$F9*INDEX(Forudsætninger!$D$29:$D$40,9)*IF(9<IF(N($C9)<1,1,$C9),0,IF(AND($D9="Ja",9<IF(N($C9)<1,1,$C9)+Forudsætninger!$C$16),Forudsætninger!$C$17,1))) -> 270000 | P9: =IF($B9="","",$F9*INDEX(Forudsætninger!$D$29:$D$40,10)*IF(10<IF(N($C9)<1,1,$C9),0,IF(AND($D9="Ja",10<IF(N($C9)<1,1,$C9)+Forudsætninger!$C$16),Forudsætninger!$C$17,1))) -> 270000 | Q9: =IF($B9="","",$F9*INDEX(Forudsætninger!$D$29:$D$40,11)*IF(11<IF(N($C9)<1,1,$C9),0,IF(AND($D9="Ja",11<IF(N($C9)<1,1,$C9)+Forudsætninger!$C$16),Forudsætninger!$C$17,1))) -> 300000 | R9: =IF($B9="","",$F9*INDEX(Forudsætninger!$D$29:$D$40,12)*IF(12<IF(N($C9)<1,1,$C9),0,IF(AND($D9="Ja",12<IF(N($C9)<1,1,$C9)+Forudsætninger!$C$16),Forudsætninger!$C$17,1))) -> 330000 | S9: =IF($B9="","",SUM(G9:R9)) -> 3000000
B10: Dennis Lund | C10: 1 | D10: Nej | F10: =IF($B10="","",IF(N($E10)>0,$E10,Forudsætninger!$C$14)) -> 3000000 | G10: =IF($B10="","",$F10*INDEX(Forudsætninger!$D$29:$D$40,1)*IF(1<IF(N($C10)<1,1,$C10),0,IF(AND($D10="Ja",1<IF(N($C10)<1,1,$C10)+Forudsætninger!$C$16),Forudsætninger!$C$17,1))) -> 210000 | H10: =IF($B10="","",$F10*INDEX(Forudsætninger!$D$29:$D$40,2)*IF(2<IF(N($C10)<1,1,$C10),0,IF(AND($D10="Ja",2<IF(N($C10)<1,1,$C10)+Forudsætninger!$C$16),Forudsætninger!$C$17,1))) -> 240000 | I10: =IF($B10="","",$F10*INDEX(Forudsætninger!$D$29:$D$40,3)*IF(3<IF(N($C10)<1,1,$C10),0,IF(AND($D10="Ja",3<IF(N($C10)<1,1,$C10)+Forudsætninger!$C$16),Forudsætninger!$C$17,1))) -> 270000 | J10: =IF($B10="","",$F10*INDEX(Forudsætninger!$D$29:$D$40,4)*IF(4<IF(N($C10)<1,1,$C10),0,IF(AND($D10="Ja",4<IF(N($C10)<1,1,$C10)+Forudsætninger!$C$16),Forudsætninger!$C$17,1))) -> 240000 | K10: =IF($B10="","",$F10*INDEX(Forudsætninger!$D$29:$D$40,5)*IF(5<IF(N($C10)<1,1,$C10),0,IF(AND($D10="Ja",5<IF(N($C10)<1,1,$C10)+Forudsætninger!$C$16),Forudsætninger!$C$17,1))) -> 270000 | L10: =IF($B10="","",$F10*INDEX(Forudsætninger!$D$29:$D$40,6)*IF(6<IF(N($C10)<1,1,$C10),0,IF(AND($D10="Ja",6<IF(N($C10)<1,1,$C10)+Forudsætninger!$C$16),Forudsætninger!$C$17,1))) -> 270000 | M10: =IF($B10="","",$F10*INDEX(Forudsætninger!$D$29:$D$40,7)*IF(7<IF(N($C10)<1,1,$C10),0,IF(AND($D10="Ja",7<IF(N($C10)<1,1,$C10)+Forudsætninger!$C$16),Forudsætninger!$C$17,1))) -> 120000 | N10: =IF($B10="","",$F10*INDEX(Forudsætninger!$D$29:$D$40,8)*IF(8<IF(N($C10)<1,1,$C10),0,IF(AND($D10="Ja",8<IF(N($C10)<1,1,$C10)+Forudsætninger!$C$16),Forudsætninger!$C$17,1))) -> 210000 | O10: =IF($B10="","",$F10*INDEX(Forudsætninger!$D$29:$D$40,9)*IF(9<IF(N($C10)<1,1,$C10),0,IF(AND($D10="Ja",9<IF(N($C10)<1,1,$C10)+Forudsætninger!$C$16),Forudsætninger!$C$17,1))) -> 270000 | P10: =IF($B10="","",$F10*INDEX(Forudsætninger!$D$29:$D$40,10)*IF(10<IF(N($C10)<1,1,$C10),0,IF(AND($D10="Ja",10<IF(N($C10)<1,1,$C10)+Forudsætninger!$C$16),Forudsætninger!$C$17,1))) -> 270000 | Q10: =IF($B10="","",$F10*INDEX(Forudsætninger!$D$29:$D$40,11)*IF(11<IF(N($C10)<1,1,$C10),0,IF(AND($D10="Ja",11<IF(N($C10)<1,1,$C10)+Forudsætninger!$C$16),Forudsætninger!$C$17,1))) -> 300000 | R10: =IF($B10="","",$F10*INDEX(Forudsætninger!$D$29:$D$40,12)*IF(12<IF(N($C10)<1,1,$C10),0,IF(AND($D10="Ja",12<IF(N($C10)<1,1,$C10)+Forudsætninger!$C$16),Forudsætninger!$C$17,1))) -> 330000 | S10: =IF($B10="","",SUM(G10:R10)) -> 3000000
B11: Emma Krogh | C11: 1 | D11: Nej | F11: =IF($B11="","",IF(N($E11)>0,$E11,Forudsætninger!$C$14)) -> 3000000 | G11: =IF($B11="","",$F11*INDEX(Forudsætninger!$D$29:$D$40,1)*IF(1<IF(N($C11)<1,1,$C11),0,IF(AND($D11="Ja",1<IF(N($C11)<1,1,$C11)+Forudsætninger!$C$16),Forudsætninger!$C$17,1))) -> 210000 | H11: =IF($B11="","",$F11*INDEX(Forudsætninger!$D$29:$D$40,2)*IF(2<IF(N($C11)<1,1,$C11),0,IF(AND($D11="Ja",2<IF(N($C11)<1,1,$C11)+Forudsætninger!$C$16),Forudsætninger!$C$17,1))) -> 240000 | I11: =IF($B11="","",$F11*INDEX(Forudsætninger!$D$29:$D$40,3)*IF(3<IF(N($C11)<1,1,$C11),0,IF(AND($D11="Ja",3<IF(N($C11)<1,1,$C11)+Forudsætninger!$C$16),Forudsætninger!$C$17,1))) -> 270000 | J11: =IF($B11="","",$F11*INDEX(Forudsætninger!$D$29:$D$40,4)*IF(4<IF(N($C11)<1,1,$C11),0,IF(AND($D11="Ja",4<IF(N($C11)<1,1,$C11)+Forudsætninger!$C$16),Forudsætninger!$C$17,1))) -> 240000 | K11: =IF($B11="","",$F11*INDEX(Forudsætninger!$D$29:$D$40,5)*IF(5<IF(N($C11)<1,1,$C11),0,IF(AND($D11="Ja",5<IF(N($C11)<1,1,$C11)+Forudsætninger!$C$16),Forudsætninger!$C$17,1))) -> 270000 | L11: =IF($B11="","",$F11*INDEX(Forudsætninger!$D$29:$D$40,6)*IF(6<IF(N($C11)<1,1,$C11),0,IF(AND($D11="Ja",6<IF(N($C11)<1,1,$C11)+Forudsætninger!$C$16),Forudsætninger!$C$17,1))) -> 270000 | M11: =IF($B11="","",$F11*INDEX(Forudsætninger!$D$29:$D$40,7)*IF(7<IF(N($C11)<1,1,$C11),0,IF(AND($D11="Ja",7<IF(N($C11)<1,1,$C11)+Forudsætninger!$C$16),Forudsætninger!$C$17,1))) -> 120000 | N11: =IF($B11="","",$F11*INDEX(Forudsætninger!$D$29:$D$40,8)*IF(8<IF(N($C11)<1,1,$C11),0,IF(AND($D11="Ja",8<IF(N($C11)<1,1,$C11)+Forudsætninger!$C$16),Forudsætninger!$C$17,1))) -> 210000 | O11: =IF($B11="","",$F11*INDEX(Forudsætninger!$D$29:$D$40,9)*IF(9<IF(N($C11)<1,1,$C11),0,IF(AND($D11="Ja",9<IF(N($C11)<1,1,$C11)+Forudsætninger!$C$16),Forudsætninger!$C$17,1))) -> 270000 | P11: =IF($B11="","",$F11*INDEX(Forudsætninger!$D$29:$D$40,10)*IF(10<IF(N($C11)<1,1,$C11),0,IF(AND($D11="Ja",10<IF(N($C11)<1,1,$C11)+Forudsætninger!$C$16),Forudsætninger!$C$17,1))) -> 270000 | Q11: =IF($B11="","",$F11*INDEX(Forudsætninger!$D$29:$D$40,11)*IF(11<IF(N($C11)<1,1,$C11),0,IF(AND($D11="Ja",11<IF(N($C11)<1,1,$C11)+Forudsætninger!$C$16),Forudsætninger!$C$17,1))) -> 300000 | R11: =IF($B11="","",$F11*INDEX(Forudsætninger!$D$29:$D$40,12)*IF(12<IF(N($C11)<1,1,$C11),0,IF(AND($D11="Ja",12<IF(N($C11)<1,1,$C11)+Forudsætninger!$C$16),Forudsætninger!$C$17,1))) -> 330000 | S11: =IF($B11="","",SUM(G11:R11)) -> 3000000
B12: Frederik Sand | C12: 1 | D12: Nej | F12: =IF($B12="","",IF(N($E12)>0,$E12,Forudsætninger!$C$14)) -> 3000000 | G12: =IF($B12="","",$F12*INDEX(Forudsætninger!$D$29:$D$40,1)*IF(1<IF(N($C12)<1,1,$C12),0,IF(AND($D12="Ja",1<IF(N($C12)<1,1,$C12)+Forudsætninger!$C$16),Forudsætninger!$C$17,1))) -> 210000 | H12: =IF($B12="","",$F12*INDEX(Forudsætninger!$D$29:$D$40,2)*IF(2<IF(N($C12)<1,1,$C12),0,IF(AND($D12="Ja",2<IF(N($C12)<1,1,$C12)+Forudsætninger!$C$16),Forudsætninger!$C$17,1))) -> 240000 | I12: =IF($B12="","",$F12*INDEX(Forudsætninger!$D$29:$D$40,3)*IF(3<IF(N($C12)<1,1,$C12),0,IF(AND($D12="Ja",3<IF(N($C12)<1,1,$C12)+Forudsætninger!$C$16),Forudsætninger!$C$17,1))) -> 270000 | J12: =IF($B12="","",$F12*INDEX(Forudsætninger!$D$29:$D$40,4)*IF(4<IF(N($C12)<1,1,$C12),0,IF(AND($D12="Ja",4<IF(N($C12)<1,1,$C12)+Forudsætninger!$C$16),Forudsætninger!$C$17,1))) -> 240000 | K12: =IF($B12="","",$F12*INDEX(Forudsætninger!$D$29:$D$40,5)*IF(5<IF(N($C12)<1,1,$C12),0,IF(AND($D12="Ja",5<IF(N($C12)<1,1,$C12)+Forudsætninger!$C$16),Forudsætninger!$C$17,1))) -> 270000 | L12: =IF($B12="","",$F12*INDEX(Forudsætninger!$D$29:$D$40,6)*IF(6<IF(N($C12)<1,1,$C12),0,IF(AND($D12="Ja",6<IF(N($C12)<1,1,$C12)+Forudsætninger!$C$16),Forudsætninger!$C$17,1))) -> 270000 | M12: =IF($B12="","",$F12*INDEX(Forudsætninger!$D$29:$D$40,7)*IF(7<IF(N($C12)<1,1,$C12),0,IF(AND($D12="Ja",7<IF(N($C12)<1,1,$C12)+Forudsætninger!$C$16),Forudsætninger!$C$17,1))) -> 120000 | N12: =IF($B12="","",$F12*INDEX(Forudsætninger!$D$29:$D$40,8)*IF(8<IF(N($C12)<1,1,$C12),0,IF(AND($D12="Ja",8<IF(N($C12)<1,1,$C12)+Forudsætninger!$C$16),Forudsætninger!$C$17,1))) -> 210000 | O12: =IF($B12="","",$F12*INDEX(Forudsætninger!$D$29:$D$40,9)*IF(9<IF(N($C12)<1,1,$C12),0,IF(AND($D12="Ja",9<IF(N($C12)<1,1,$C12)+Forudsætninger!$C$16),Forudsætninger!$C$17,1))) -> 270000 | P12: =IF($B12="","",$F12*INDEX(Forudsætninger!$D$29:$D$40,10)*IF(10<IF(N($C12)<1,1,$C12),0,IF(AND($D12="Ja",10<IF(N($C12)<1,1,$C12)+Forudsætninger!$C$16),Forudsætninger!$C$17,1))) -> 270000 | Q12: =IF($B12="","",$F12*INDEX(Forudsætninger!$D$29:$D$40,11)*IF(11<IF(N($C12)<1,1,$C12),0,IF(AND($D12="Ja",11<IF(N($C12)<1,1,$C12)+Forudsætninger!$C$16),Forudsætninger!$C$17,1))) -> 300000 | R12: =IF($B12="","",$F12*INDEX(Forudsætninger!$D$29:$D$40,12)*IF(12<IF(N($C12)<1,1,$C12),0,IF(AND($D12="Ja",12<IF(N($C12)<1,1,$C12)+Forudsætninger!$C$16),Forudsætninger!$C$17,1))) -> 330000 | S12: =IF($B12="","",SUM(G12:R12)) -> 3000000
B13: Gitte Mølgaard | C13: 1 | D13: Nej | F13: =IF($B13="","",IF(N($E13)>0,$E13,Forudsætninger!$C$14)) -> 3000000 | G13: =IF($B13="","",$F13*INDEX(Forudsætninger!$D$29:$D$40,1)*IF(1<IF(N($C13)<1,1,$C13),0,IF(AND($D13="Ja",1<IF(N($C13)<1,1,$C13)+Forudsætninger!$C$16),Forudsætninger!$C$17,1))) -> 210000 | H13: =IF($B13="","",$F13*INDEX(Forudsætninger!$D$29:$D$40,2)*IF(2<IF(N($C13)<1,1,$C13),0,IF(AND($D13="Ja",2<IF(N($C13)<1,1,$C13)+Forudsætninger!$C$16),Forudsætninger!$C$17,1))) -> 240000 | I13: =IF($B13="","",$F13*INDEX(Forudsætninger!$D$29:$D$40,3)*IF(3<IF(N($C13)<1,1,$C13),0,IF(AND($D13="Ja",3<IF(N($C13)<1,1,$C13)+Forudsætninger!$C$16),Forudsætninger!$C$17,1))) -> 270000 | J13: =IF($B13="","",$F13*INDEX(Forudsætninger!$D$29:$D$40,4)*IF(4<IF(N($C13)<1,1,$C13),0,IF(AND($D13="Ja",4<IF(N($C13)<1,1,$C13)+Forudsætninger!$C$16),Forudsætninger!$C$17,1))) -> 240000 | K13: =IF($B13="","",$F13*INDEX(Forudsætninger!$D$29:$D$40,5)*IF(5<IF(N($C13)<1,1,$C13),0,IF(AND($D13="Ja",5<IF(N($C13)<1,1,$C13)+Forudsætninger!$C$16),Forudsætninger!$C$17,1))) -> 270000 | L13: =IF($B13="","",$F13*INDEX(Forudsætninger!$D$29:$D$40,6)*IF(6<IF(N($C13)<1,1,$C13),0,IF(AND($D13="Ja",6<IF(N($C13)<1,1,$C13)+Forudsætninger!$C$16),Forudsætninger!$C$17,1))) -> 270000 | M13: =IF($B13="","",$F13*INDEX(Forudsætninger!$D$29:$D$40,7)*IF(7<IF(N($C13)<1,1,$C13),0,IF(AND($D13="Ja",7<IF(N($C13)<1,1,$C13)+Forudsætninger!$C$16),Forudsætninger!$C$17,1))) -> 120000 | N13: =IF($B13="","",$F13*INDEX(Forudsætninger!$D$29:$D$40,8)*IF(8<IF(N($C13)<1,1,$C13),0,IF(AND($D13="Ja",8<IF(N($C13)<1,1,$C13)+Forudsætninger!$C$16),Forudsætninger!$C$17,1))) -> 210000 | O13: =IF($B13="","",$F13*INDEX(Forudsætninger!$D$29:$D$40,9)*IF(9<IF(N($C13)<1,1,$C13),0,IF(AND($D13="Ja",9<IF(N($C13)<1,1,$C13)+Forudsætninger!$C$16),Forudsætninger!$C$17,1))) -> 270000 | P13: =IF($B13="","",$F13*INDEX(Forudsætninger!$D$29:$D$40,10)*IF(10<IF(N($C13)<1,1,$C13),0,IF(AND($D13="Ja",10<IF(N($C13)<1,1,$C13)+Forudsætninger!$C$16),Forudsætninger!$C$17,1))) -> 270000 | Q13: =IF($B13="","",$F13*INDEX(Forudsætninger!$D$29:$D$40,11)*IF(11<IF(N($C13)<1,1,$C13),0,IF(AND($D13="Ja",11<IF(N($C13)<1,1,$C13)+Forudsætninger!$C$16),Forudsætninger!$C$17,1))) -> 300000 | R13: =IF($B13="","",$F13*INDEX(Forudsætninger!$D$29:$D$40,12)*IF(12<IF(N($C13)<1,1,$C13),0,IF(AND($D13="Ja",12<IF(N($C13)<1,1,$C13)+Forudsætninger!$C$16),Forudsætninger!$C$17,1))) -> 330000 | S13: =IF($B13="","",SUM(G13:R13)) -> 3000000
B14: Ny sælger 1 | C14: 1 | D14: Ja | F14: =IF($B14="","",IF(N($E14)>0,$E14,Forudsætninger!$C$14)) -> 3000000 | G14: =IF($B14="","",$F14*INDEX(Forudsætninger!$D$29:$D$40,1)*IF(1<IF(N($C14)<1,1,$C14),0,IF(AND($D14="Ja",1<IF(N($C14)<1,1,$C14)+Forudsætninger!$C$16),Forudsætninger!$C$17,1))) -> 105000 | H14: =IF($B14="","",$F14*INDEX(Forudsætninger!$D$29:$D$40,2)*IF(2<IF(N($C14)<1,1,$C14),0,IF(AND($D14="Ja",2<IF(N($C14)<1,1,$C14)+Forudsætninger!$C$16),Forudsætninger!$C$17,1))) -> 120000 | I14: =IF($B14="","",$F14*INDEX(Forudsætninger!$D$29:$D$40,3)*IF(3<IF(N($C14)<1,1,$C14),0,IF(AND($D14="Ja",3<IF(N($C14)<1,1,$C14)+Forudsætninger!$C$16),Forudsætninger!$C$17,1))) -> 135000 | J14: =IF($B14="","",$F14*INDEX(Forudsætninger!$D$29:$D$40,4)*IF(4<IF(N($C14)<1,1,$C14),0,IF(AND($D14="Ja",4<IF(N($C14)<1,1,$C14)+Forudsætninger!$C$16),Forudsætninger!$C$17,1))) -> 120000 | K14: =IF($B14="","",$F14*INDEX(Forudsætninger!$D$29:$D$40,5)*IF(5<IF(N($C14)<1,1,$C14),0,IF(AND($D14="Ja",5<IF(N($C14)<1,1,$C14)+Forudsætninger!$C$16),Forudsætninger!$C$17,1))) -> 270000 | L14: =IF($B14="","",$F14*INDEX(Forudsætninger!$D$29:$D$40,6)*IF(6<IF(N($C14)<1,1,$C14),0,IF(AND($D14="Ja",6<IF(N($C14)<1,1,$C14)+Forudsætninger!$C$16),Forudsætninger!$C$17,1))) -> 270000 | M14: =IF($B14="","",$F14*INDEX(Forudsætninger!$D$29:$D$40,7)*IF(7<IF(N($C14)<1,1,$C14),0,IF(AND($D14="Ja",7<IF(N($C14)<1,1,$C14)+Forudsætninger!$C$16),Forudsætninger!$C$17,1))) -> 120000 | N14: =IF($B14="","",$F14*INDEX(Forudsætninger!$D$29:$D$40,8)*IF(8<IF(N($C14)<1,1,$C14),0,IF(AND($D14="Ja",8<IF(N($C14)<1,1,$C14)+Forudsætninger!$C$16),Forudsætninger!$C$17,1))) -> 210000 | O14: =IF($B14="","",$F14*INDEX(Forudsætninger!$D$29:$D$40,9)*IF(9<IF(N($C14)<1,1,$C14),0,IF(AND($D14="Ja",9<IF(N($C14)<1,1,$C14)+Forudsætninger!$C$16),Forudsætninger!$C$17,1))) -> 270000 | P14: =IF($B14="","",$F14*INDEX(Forudsætninger!$D$29:$D$40,10)*IF(10<IF(N($C14)<1,1,$C14),0,IF(AND($D14="Ja",10<IF(N($C14)<1,1,$C14)+Forudsætninger!$C$16),Forudsætninger!$C$17,1))) -> 270000 | Q14: =IF($B14="","",$F14*INDEX(Forudsætninger!$D$29:$D$40,11)*IF(11<IF(N($C14)<1,1,$C14),0,IF(AND($D14="Ja",11<IF(N($C14)<1,1,$C14)+Forudsætninger!$C$16),Forudsætninger!$C$17,1))) -> 300000 | R14: =IF($B14="","",$F14*INDEX(Forudsætninger!$D$29:$D$40,12)*IF(12<IF(N($C14)<1,1,$C14),0,IF(AND($D14="Ja",12<IF(N($C14)<1,1,$C14)+Forudsætninger!$C$16),Forudsætninger!$C$17,1))) -> 330000 | S14: =IF($B14="","",SUM(G14:R14)) -> 2520000
B15: Ny sælger 2 | C15: 2 | D15: Ja | F15: =IF($B15="","",IF(N($E15)>0,$E15,Forudsætninger!$C$14)) -> 3000000 | G15: =IF($B15="","",$F15*INDEX(Forudsætninger!$D$29:$D$40,1)*IF(1<IF(N($C15)<1,1,$C15),0,IF(AND($D15="Ja",1<IF(N($C15)<1,1,$C15)+Forudsætninger!$C$16),Forudsætninger!$C$17,1))) -> 0 | H15: =IF($B15="","",$F15*INDEX(Forudsætninger!$D$29:$D$40,2)*IF(2<IF(N($C15)<1,1,$C15),0,IF(AND($D15="Ja",2<IF(N($C15)<1,1,$C15)+Forudsætninger!$C$16),Forudsætninger!$C$17,1))) -> 120000 | I15: =IF($B15="","",$F15*INDEX(Forudsætninger!$D$29:$D$40,3)*IF(3<IF(N($C15)<1,1,$C15),0,IF(AND($D15="Ja",3<IF(N($C15)<1,1,$C15)+Forudsætninger!$C$16),Forudsætninger!$C$17,1))) -> 135000 | J15: =IF($B15="","",$F15*INDEX(Forudsætninger!$D$29:$D$40,4)*IF(4<IF(N($C15)<1,1,$C15),0,IF(AND($D15="Ja",4<IF(N($C15)<1,1,$C15)+Forudsætninger!$C$16),Forudsætninger!$C$17,1))) -> 120000 | K15: =IF($B15="","",$F15*INDEX(Forudsætninger!$D$29:$D$40,5)*IF(5<IF(N($C15)<1,1,$C15),0,IF(AND($D15="Ja",5<IF(N($C15)<1,1,$C15)+Forudsætninger!$C$16),Forudsætninger!$C$17,1))) -> 135000 | L15: =IF($B15="","",$F15*INDEX(Forudsætninger!$D$29:$D$40,6)*IF(6<IF(N($C15)<1,1,$C15),0,IF(AND($D15="Ja",6<IF(N($C15)<1,1,$C15)+Forudsætninger!$C$16),Forudsætninger!$C$17,1))) -> 270000 | M15: =IF($B15="","",$F15*INDEX(Forudsætninger!$D$29:$D$40,7)*IF(7<IF(N($C15)<1,1,$C15),0,IF(AND($D15="Ja",7<IF(N($C15)<1,1,$C15)+Forudsætninger!$C$16),Forudsætninger!$C$17,1))) -> 120000 | N15: =IF($B15="","",$F15*INDEX(Forudsætninger!$D$29:$D$40,8)*IF(8<IF(N($C15)<1,1,$C15),0,IF(AND($D15="Ja",8<IF(N($C15)<1,1,$C15)+Forudsætninger!$C$16),Forudsætninger!$C$17,1))) -> 210000 | O15: =IF($B15="","",$F15*INDEX(Forudsætninger!$D$29:$D$40,9)*IF(9<IF(N($C15)<1,1,$C15),0,IF(AND($D15="Ja",9<IF(N($C15)<1,1,$C15)+Forudsætninger!$C$16),Forudsætninger!$C$17,1))) -> 270000 | P15: =IF($B15="","",$F15*INDEX(Forudsætninger!$D$29:$D$40,10)*IF(10<IF(N($C15)<1,1,$C15),0,IF(AND($D15="Ja",10<IF(N($C15)<1,1,$C15)+Forudsætninger!$C$16),Forudsætninger!$C$17,1))) -> 270000 | Q15: =IF($B15="","",$F15*INDEX(Forudsætninger!$D$29:$D$40,11)*IF(11<IF(N($C15)<1,1,$C15),0,IF(AND($D15="Ja",11<IF(N($C15)<1,1,$C15)+Forudsætninger!$C$16),Forudsætninger!$C$17,1))) -> 300000 | R15: =IF($B15="","",$F15*INDEX(Forudsætninger!$D$29:$D$40,12)*IF(12<IF(N($C15)<1,1,$C15),0,IF(AND($D15="Ja",12<IF(N($C15)<1,1,$C15)+Forudsætninger!$C$16),Forudsætninger!$C$17,1))) -> 330000 | S15: =IF($B15="","",SUM(G15:R15)) -> 2280000
B16: Ny sælger 3 | C16: 4 | D16: Ja | F16: =IF($B16="","",IF(N($E16)>0,$E16,Forudsætninger!$C$14)) -> 3000000 | G16: =IF($B16="","",$F16*INDEX(Forudsætninger!$D$29:$D$40,1)*IF(1<IF(N($C16)<1,1,$C16),0,IF(AND($D16="Ja",1<IF(N($C16)<1,1,$C16)+Forudsætninger!$C$16),Forudsætninger!$C$17,1))) -> 0 | H16: =IF($B16="","",$F16*INDEX(Forudsætninger!$D$29:$D$40,2)*IF(2<IF(N($C16)<1,1,$C16),0,IF(AND($D16="Ja",2<IF(N($C16)<1,1,$C16)+Forudsætninger!$C$16),Forudsætninger!$C$17,1))) -> 0 | I16: =IF($B16="","",$F16*INDEX(Forudsætninger!$D$29:$D$40,3)*IF(3<IF(N($C16)<1,1,$C16),0,IF(AND($D16="Ja",3<IF(N($C16)<1,1,$C16)+Forudsætninger!$C$16),Forudsætninger!$C$17,1))) -> 0 | J16: =IF($B16="","",$F16*INDEX(Forudsætninger!$D$29:$D$40,4)*IF(4<IF(N($C16)<1,1,$C16),0,IF(AND($D16="Ja",4<IF(N($C16)<1,1,$C16)+Forudsætninger!$C$16),Forudsætninger!$C$17,1))) -> 120000 | K16: =IF($B16="","",$F16*INDEX(Forudsætninger!$D$29:$D$40,5)*IF(5<IF(N($C16)<1,1,$C16),0,IF(AND($D16="Ja",5<IF(N($C16)<1,1,$C16)+Forudsætninger!$C$16),Forudsætninger!$C$17,1))) -> 135000 | L16: =IF($B16="","",$F16*INDEX(Forudsætninger!$D$29:$D$40,6)*IF(6<IF(N($C16)<1,1,$C16),0,IF(AND($D16="Ja",6<IF(N($C16)<1,1,$C16)+Forudsætninger!$C$16),Forudsætninger!$C$17,1))) -> 135000 | M16: =IF($B16="","",$F16*INDEX(Forudsætninger!$D$29:$D$40,7)*IF(7<IF(N($C16)<1,1,$C16),0,IF(AND($D16="Ja",7<IF(N($C16)<1,1,$C16)+Forudsætninger!$C$16),Forudsætninger!$C$17,1))) -> 60000 | N16: =IF($B16="","",$F16*INDEX(Forudsætninger!$D$29:$D$40,8)*IF(8<IF(N($C16)<1,1,$C16),0,IF(AND($D16="Ja",8<IF(N($C16)<1,1,$C16)+Forudsætninger!$C$16),Forudsætninger!$C$17,1))) -> 210000 | O16: =IF($B16="","",$F16*INDEX(Forudsætninger!$D$29:$D$40,9)*IF(9<IF(N($C16)<1,1,$C16),0,IF(AND($D16="Ja",9<IF(N($C16)<1,1,$C16)+Forudsætninger!$C$16),Forudsætninger!$C$17,1))) -> 270000 | P16: =IF($B16="","",$F16*INDEX(Forudsætninger!$D$29:$D$40,10)*IF(10<IF(N($C16)<1,1,$C16),0,IF(AND($D16="Ja",10<IF(N($C16)<1,1,$C16)+Forudsætninger!$C$16),Forudsætninger!$C$17,1))) -> 270000 | Q16: =IF($B16="","",$F16*INDEX(Forudsætninger!$D$29:$D$40,11)*IF(11<IF(N($C16)<1,1,$C16),0,IF(AND($D16="Ja",11<IF(N($C16)<1,1,$C16)+Forudsætninger!$C$16),Forudsætninger!$C$17,1))) -> 300000 | R16: =IF($B16="","",$F16*INDEX(Forudsætninger!$D$29:$D$40,12)*IF(12<IF(N($C16)<1,1,$C16),0,IF(AND($D16="Ja",12<IF(N($C16)<1,1,$C16)+Forudsætninger!$C$16),Forudsætninger!$C$17,1))) -> 330000 | S16: =IF($B16="","",SUM(G16:R16)) -> 1830000
F17: =IF($B17="","",IF(N($E17)>0,$E17,Forudsætninger!$C$14)) | G17: =IF($B17="","",$F17*INDEX(Forudsætninger!$D$29:$D$40,1)*IF(1<IF(N($C17)<1,1,$C17),0,IF(AND($D17="Ja",1<IF(N($C17)<1,1,$C17)+Forudsætninger!$C$16),Forudsætninger!$C$17,1))) | H17: =IF($B17="","",$F17*INDEX(Forudsætninger!$D$29:$D$40,2)*IF(2<IF(N($C17)<1,1,$C17),0,IF(AND($D17="Ja",2<IF(N($C17)<1,1,$C17)+Forudsætninger!$C$16),Forudsætninger!$C$17,1))) | I17: =IF($B17="","",$F17*INDEX(Forudsætninger!$D$29:$D$40,3)*IF(3<IF(N($C17)<1,1,$C17),0,IF(AND($D17="Ja",3<IF(N($C17)<1,1,$C17)+Forudsætninger!$C$16),Forudsætninger!$C$17,1))) | J17: =IF($B17="","",$F17*INDEX(Forudsætninger!$D$29:$D$40,4)*IF(4<IF(N($C17)<1,1,$C17),0,IF(AND($D17="Ja",4<IF(N($C17)<1,1,$C17)+Forudsætninger!$C$16),Forudsætninger!$C$17,1))) | K17: =IF($B17="","",$F17*INDEX(Forudsætninger!$D$29:$D$40,5)*IF(5<IF(N($C17)<1,1,$C17),0,IF(AND($D17="Ja",5<IF(N($C17)<1,1,$C17)+Forudsætninger!$C$16),Forudsætninger!$C$17,1))) | L17: =IF($B17="","",$F17*INDEX(Forudsætninger!$D$29:$D$40,6)*IF(6<IF(N($C17)<1,1,$C17),0,IF(AND($D17="Ja",6<IF(N($C17)<1,1,$C17)+Forudsætninger!$C$16),Forudsætninger!$C$17,1))) | M17: =IF($B17="","",$F17*INDEX(Forudsætninger!$D$29:$D$40,7)*IF(7<IF(N($C17)<1,1,$C17),0,IF(AND($D17="Ja",7<IF(N($C17)<1,1,$C17)+Forudsætninger!$C$16),Forudsætninger!$C$17,1))) | N17: =IF($B17="","",$F17*INDEX(Forudsætninger!$D$29:$D$40,8)*IF(8<IF(N($C17)<1,1,$C17),0,IF(AND($D17="Ja",8<IF(N($C17)<1,1,$C17)+Forudsætninger!$C$16),Forudsætninger!$C$17,1))) | O17: =IF($B17="","",$F17*INDEX(Forudsætninger!$D$29:$D$40,9)*IF(9<IF(N($C17)<1,1,$C17),0,IF(AND($D17="Ja",9<IF(N($C17)<1,1,$C17)+Forudsætninger!$C$16),Forudsætninger!$C$17,1))) | P17: =IF($B17="","",$F17*INDEX(Forudsætninger!$D$29:$D$40,10)*IF(10<IF(N($C17)<1,1,$C17),0,IF(AND($D17="Ja",10<IF(N($C17)<1,1,$C17)+Forudsætninger!$C$16),Forudsætninger!$C$17,1))) | Q17: =IF($B17="","",$F17*INDEX(Forudsætninger!$D$29:$D$40,11)*IF(11<IF(N($C17)<1,1,$C17),0,IF(AND($D17="Ja",11<IF(N($C17)<1,1,$C17)+Forudsætninger!$C$16),Forudsætninger!$C$17,1))) | R17: =IF($B17="","",$F17*INDEX(Forudsætninger!$D$29:$D$40,12)*IF(12<IF(N($C17)<1,1,$C17),0,IF(AND($D17="Ja",12<IF(N($C17)<1,1,$C17)+Forudsætninger!$C$16),Forudsætninger!$C$17,1))) | S17: =IF($B17="","",SUM(G17:R17))
F18: =IF($B18="","",IF(N($E18)>0,$E18,Forudsætninger!$C$14)) | G18: =IF($B18="","",$F18*INDEX(Forudsætninger!$D$29:$D$40,1)*IF(1<IF(N($C18)<1,1,$C18),0,IF(AND($D18="Ja",1<IF(N($C18)<1,1,$C18)+Forudsætninger!$C$16),Forudsætninger!$C$17,1))) | H18: =IF($B18="","",$F18*INDEX(Forudsætninger!$D$29:$D$40,2)*IF(2<IF(N($C18)<1,1,$C18),0,IF(AND($D18="Ja",2<IF(N($C18)<1,1,$C18)+Forudsætninger!$C$16),Forudsætninger!$C$17,1))) | I18: =IF($B18="","",$F18*INDEX(Forudsætninger!$D$29:$D$40,3)*IF(3<IF(N($C18)<1,1,$C18),0,IF(AND($D18="Ja",3<IF(N($C18)<1,1,$C18)+Forudsætninger!$C$16),Forudsætninger!$C$17,1))) | J18: =IF($B18="","",$F18*INDEX(Forudsætninger!$D$29:$D$40,4)*IF(4<IF(N($C18)<1,1,$C18),0,IF(AND($D18="Ja",4<IF(N($C18)<1,1,$C18)+Forudsætninger!$C$16),Forudsætninger!$C$17,1))) | K18: =IF($B18="","",$F18*INDEX(Forudsætninger!$D$29:$D$40,5)*IF(5<IF(N($C18)<1,1,$C18),0,IF(AND($D18="Ja",5<IF(N($C18)<1,1,$C18)+Forudsætninger!$C$16),Forudsætninger!$C$17,1))) | L18: =IF($B18="","",$F18*INDEX(Forudsætninger!$D$29:$D$40,6)*IF(6<IF(N($C18)<1,1,$C18),0,IF(AND($D18="Ja",6<IF(N($C18)<1,1,$C18)+Forudsætninger!$C$16),Forudsætninger!$C$17,1))) | M18: =IF($B18="","",$F18*INDEX(Forudsætninger!$D$29:$D$40,7)*IF(7<IF(N($C18)<1,1,$C18),0,IF(AND($D18="Ja",7<IF(N($C18)<1,1,$C18)+Forudsætninger!$C$16),Forudsætninger!$C$17,1))) | N18: =IF($B18="","",$F18*INDEX(Forudsætninger!$D$29:$D$40,8)*IF(8<IF(N($C18)<1,1,$C18),0,IF(AND($D18="Ja",8<IF(N($C18)<1,1,$C18)+Forudsætninger!$C$16),Forudsætninger!$C$17,1))) | O18: =IF($B18="","",$F18*INDEX(Forudsætninger!$D$29:$D$40,9)*IF(9<IF(N($C18)<1,1,$C18),0,IF(AND($D18="Ja",9<IF(N($C18)<1,1,$C18)+Forudsætninger!$C$16),Forudsætninger!$C$17,1))) | P18: =IF($B18="","",$F18*INDEX(Forudsætninger!$D$29:$D$40,10)*IF(10<IF(N($C18)<1,1,$C18),0,IF(AND($D18="Ja",10<IF(N($C18)<1,1,$C18)+Forudsætninger!$C$16),Forudsætninger!$C$17,1))) | Q18: =IF($B18="","",$F18*INDEX(Forudsætninger!$D$29:$D$40,11)*IF(11<IF(N($C18)<1,1,$C18),0,IF(AND($D18="Ja",11<IF(N($C18)<1,1,$C18)+Forudsætninger!$C$16),Forudsætninger!$C$17,1))) | R18: =IF($B18="","",$F18*INDEX(Forudsætninger!$D$29:$D$40,12)*IF(12<IF(N($C18)<1,1,$C18),0,IF(AND($D18="Ja",12<IF(N($C18)<1,1,$C18)+Forudsætninger!$C$16),Forudsætninger!$C$17,1))) | S18: =IF($B18="","",SUM(G18:R18))
F19: =IF($B19="","",IF(N($E19)>0,$E19,Forudsætninger!$C$14)) | G19: =IF($B19="","",$F19*INDEX(Forudsætninger!$D$29:$D$40,1)*IF(1<IF(N($C19)<1,1,$C19),0,IF(AND($D19="Ja",1<IF(N($C19)<1,1,$C19)+Forudsætninger!$C$16),Forudsætninger!$C$17,1))) | H19: =IF($B19="","",$F19*INDEX(Forudsætninger!$D$29:$D$40,2)*IF(2<IF(N($C19)<1,1,$C19),0,IF(AND($D19="Ja",2<IF(N($C19)<1,1,$C19)+Forudsætninger!$C$16),Forudsætninger!$C$17,1))) | I19: =IF($B19="","",$F19*INDEX(Forudsætninger!$D$29:$D$40,3)*IF(3<IF(N($C19)<1,1,$C19),0,IF(AND($D19="Ja",3<IF(N($C19)<1,1,$C19)+Forudsætninger!$C$16),Forudsætninger!$C$17,1))) | J19: =IF($B19="","",$F19*INDEX(Forudsætninger!$D$29:$D$40,4)*IF(4<IF(N($C19)<1,1,$C19),0,IF(AND($D19="Ja",4<IF(N($C19)<1,1,$C19)+Forudsætninger!$C$16),Forudsætninger!$C$17,1))) | K19: =IF($B19="","",$F19*INDEX(Forudsætninger!$D$29:$D$40,5)*IF(5<IF(N($C19)<1,1,$C19),0,IF(AND($D19="Ja",5<IF(N($C19)<1,1,$C19)+Forudsætninger!$C$16),Forudsætninger!$C$17,1))) | L19: =IF($B19="","",$F19*INDEX(Forudsætninger!$D$29:$D$40,6)*IF(6<IF(N($C19)<1,1,$C19),0,IF(AND($D19="Ja",6<IF(N($C19)<1,1,$C19)+Forudsætninger!$C$16),Forudsætninger!$C$17,1))) | M19: =IF($B19="","",$F19*INDEX(Forudsætninger!$D$29:$D$40,7)*IF(7<IF(N($C19)<1,1,$C19),0,IF(AND($D19="Ja",7<IF(N($C19)<1,1,$C19)+Forudsætninger!$C$16),Forudsætninger!$C$17,1))) | N19: =IF($B19="","",$F19*INDEX(Forudsætninger!$D$29:$D$40,8)*IF(8<IF(N($C19)<1,1,$C19),0,IF(AND($D19="Ja",8<IF(N($C19)<1,1,$C19)+Forudsætninger!$C$16),Forudsætninger!$C$17,1))) | O19: =IF($B19="","",$F19*INDEX(Forudsætninger!$D$29:$D$40,9)*IF(9<IF(N($C19)<1,1,$C19),0,IF(AND($D19="Ja",9<IF(N($C19)<1,1,$C19)+Forudsætninger!$C$16),Forudsætninger!$C$17,1))) | P19: =IF($B19="","",$F19*INDEX(Forudsætninger!$D$29:$D$40,10)*IF(10<IF(N($C19)<1,1,$C19),0,IF(AND($D19="Ja",10<IF(N($C19)<1,1,$C19)+Forudsætninger!$C$16),Forudsætninger!$C$17,1))) | Q19: =IF($B19="","",$F19*INDEX(Forudsætninger!$D$29:$D$40,11)*IF(11<IF(N($C19)<1,1,$C19),0,IF(AND($D19="Ja",11<IF(N($C19)<1,1,$C19)+Forudsætninger!$C$16),Forudsætninger!$C$17,1))) | R19: =IF($B19="","",$F19*INDEX(Forudsætninger!$D$29:$D$40,12)*IF(12<IF(N($C19)<1,1,$C19),0,IF(AND($D19="Ja",12<IF(N($C19)<1,1,$C19)+Forudsætninger!$C$16),Forudsætninger!$C$17,1))) | S19: =IF($B19="","",SUM(G19:R19))
F20: =IF($B20="","",IF(N($E20)>0,$E20,Forudsætninger!$C$14)) | G20: =IF($B20="","",$F20*INDEX(Forudsætninger!$D$29:$D$40,1)*IF(1<IF(N($C20)<1,1,$C20),0,IF(AND($D20="Ja",1<IF(N($C20)<1,1,$C20)+Forudsætninger!$C$16),Forudsætninger!$C$17,1))) | H20: =IF($B20="","",$F20*INDEX(Forudsætninger!$D$29:$D$40,2)*IF(2<IF(N($C20)<1,1,$C20),0,IF(AND($D20="Ja",2<IF(N($C20)<1,1,$C20)+Forudsætninger!$C$16),Forudsætninger!$C$17,1))) | I20: =IF($B20="","",$F20*INDEX(Forudsætninger!$D$29:$D$40,3)*IF(3<IF(N($C20)<1,1,$C20),0,IF(AND($D20="Ja",3<IF(N($C20)<1,1,$C20)+Forudsætninger!$C$16),Forudsætninger!$C$17,1))) | J20: =IF($B20="","",$F20*INDEX(Forudsætninger!$D$29:$D$40,4)*IF(4<IF(N($C20)<1,1,$C20),0,IF(AND($D20="Ja",4<IF(N($C20)<1,1,$C20)+Forudsætninger!$C$16),Forudsætninger!$C$17,1))) | K20: =IF($B20="","",$F20*INDEX(Forudsætninger!$D$29:$D$40,5)*IF(5<IF(N($C20)<1,1,$C20),0,IF(AND($D20="Ja",5<IF(N($C20)<1,1,$C20)+Forudsætninger!$C$16),Forudsætninger!$C$17,1))) | L20: =IF($B20="","",$F20*INDEX(Forudsætninger!$D$29:$D$40,6)*IF(6<IF(N($C20)<1,1,$C20),0,IF(AND($D20="Ja",6<IF(N($C20)<1,1,$C20)+Forudsætninger!$C$16),Forudsætninger!$C$17,1))) | M20: =IF($B20="","",$F20*INDEX(Forudsætninger!$D$29:$D$40,7)*IF(7<IF(N($C20)<1,1,$C20),0,IF(AND($D20="Ja",7<IF(N($C20)<1,1,$C20)+Forudsætninger!$C$16),Forudsætninger!$C$17,1))) | N20: =IF($B20="","",$F20*INDEX(Forudsætninger!$D$29:$D$40,8)*IF(8<IF(N($C20)<1,1,$C20),0,IF(AND($D20="Ja",8<IF(N($C20)<1,1,$C20)+Forudsætninger!$C$16),Forudsætninger!$C$17,1))) | O20: =IF($B20="","",$F20*INDEX(Forudsætninger!$D$29:$D$40,9)*IF(9<IF(N($C20)<1,1,$C20),0,IF(AND($D20="Ja",9<IF(N($C20)<1,1,$C20)+Forudsætninger!$C$16),Forudsætninger!$C$17,1))) | P20: =IF($B20="","",$F20*INDEX(Forudsætninger!$D$29:$D$40,10)*IF(10<IF(N($C20)<1,1,$C20),0,IF(AND($D20="Ja",10<IF(N($C20)<1,1,$C20)+Forudsætninger!$C$16),Forudsætninger!$C$17,1))) | Q20: =IF($B20="","",$F20*INDEX(Forudsætninger!$D$29:$D$40,11)*IF(11<IF(N($C20)<1,1,$C20),0,IF(AND($D20="Ja",11<IF(N($C20)<1,1,$C20)+Forudsætninger!$C$16),Forudsætninger!$C$17,1))) | R20: =IF($B20="","",$F20*INDEX(Forudsætninger!$D$29:$D$40,12)*IF(12<IF(N($C20)<1,1,$C20),0,IF(AND($D20="Ja",12<IF(N($C20)<1,1,$C20)+Forudsætninger!$C$16),Forudsætninger!$C$17,1))) | S20: =IF($B20="","",SUM(G20:R20))
F21: =IF($B21="","",IF(N($E21)>0,$E21,Forudsætninger!$C$14)) | G21: =IF($B21="","",$F21*INDEX(Forudsætninger!$D$29:$D$40,1)*IF(1<IF(N($C21)<1,1,$C21),0,IF(AND($D21="Ja",1<IF(N($C21)<1,1,$C21)+Forudsætninger!$C$16),Forudsætninger!$C$17,1))) | H21: =IF($B21="","",$F21*INDEX(Forudsætninger!$D$29:$D$40,2)*IF(2<IF(N($C21)<1,1,$C21),0,IF(AND($D21="Ja",2<IF(N($C21)<1,1,$C21)+Forudsætninger!$C$16),Forudsætninger!$C$17,1))) | I21: =IF($B21="","",$F21*INDEX(Forudsætninger!$D$29:$D$40,3)*IF(3<IF(N($C21)<1,1,$C21),0,IF(AND($D21="Ja",3<IF(N($C21)<1,1,$C21)+Forudsætninger!$C$16),Forudsætninger!$C$17,1))) | J21: =IF($B21="","",$F21*INDEX(Forudsætninger!$D$29:$D$40,4)*IF(4<IF(N($C21)<1,1,$C21),0,IF(AND($D21="Ja",4<IF(N($C21)<1,1,$C21)+Forudsætninger!$C$16),Forudsætninger!$C$17,1))) | K21: =IF($B21="","",$F21*INDEX(Forudsætninger!$D$29:$D$40,5)*IF(5<IF(N($C21)<1,1,$C21),0,IF(AND($D21="Ja",5<IF(N($C21)<1,1,$C21)+Forudsætninger!$C$16),Forudsætninger!$C$17,1))) | L21: =IF($B21="","",$F21*INDEX(Forudsætninger!$D$29:$D$40,6)*IF(6<IF(N($C21)<1,1,$C21),0,IF(AND($D21="Ja",6<IF(N($C21)<1,1,$C21)+Forudsætninger!$C$16),Forudsætninger!$C$17,1))) | M21: =IF($B21="","",$F21*INDEX(Forudsætninger!$D$29:$D$40,7)*IF(7<IF(N($C21)<1,1,$C21),0,IF(AND($D21="Ja",7<IF(N($C21)<1,1,$C21)+Forudsætninger!$C$16),Forudsætninger!$C$17,1))) | N21: =IF($B21="","",$F21*INDEX(Forudsætninger!$D$29:$D$40,8)*IF(8<IF(N($C21)<1,1,$C21),0,IF(AND($D21="Ja",8<IF(N($C21)<1,1,$C21)+Forudsætninger!$C$16),Forudsætninger!$C$17,1))) | O21: =IF($B21="","",$F21*INDEX(Forudsætninger!$D$29:$D$40,9)*IF(9<IF(N($C21)<1,1,$C21),0,IF(AND($D21="Ja",9<IF(N($C21)<1,1,$C21)+Forudsætninger!$C$16),Forudsætninger!$C$17,1))) | P21: =IF($B21="","",$F21*INDEX(Forudsætninger!$D$29:$D$40,10)*IF(10<IF(N($C21)<1,1,$C21),0,IF(AND($D21="Ja",10<IF(N($C21)<1,1,$C21)+Forudsætninger!$C$16),Forudsætninger!$C$17,1))) | Q21: =IF($B21="","",$F21*INDEX(Forudsætninger!$D$29:$D$40,11)*IF(11<IF(N($C21)<1,1,$C21),0,IF(AND($D21="Ja",11<IF(N($C21)<1,1,$C21)+Forudsætninger!$C$16),Forudsætninger!$C$17,1))) | R21: =IF($B21="","",$F21*INDEX(Forudsætninger!$D$29:$D$40,12)*IF(12<IF(N($C21)<1,1,$C21),0,IF(AND($D21="Ja",12<IF(N($C21)<1,1,$C21)+Forudsætninger!$C$16),Forudsætninger!$C$17,1))) | S21: =IF($B21="","",SUM(G21:R21))
F22: =IF($B22="","",IF(N($E22)>0,$E22,Forudsætninger!$C$14)) | G22: =IF($B22="","",$F22*INDEX(Forudsætninger!$D$29:$D$40,1)*IF(1<IF(N($C22)<1,1,$C22),0,IF(AND($D22="Ja",1<IF(N($C22)<1,1,$C22)+Forudsætninger!$C$16),Forudsætninger!$C$17,1))) | H22: =IF($B22="","",$F22*INDEX(Forudsætninger!$D$29:$D$40,2)*IF(2<IF(N($C22)<1,1,$C22),0,IF(AND($D22="Ja",2<IF(N($C22)<1,1,$C22)+Forudsætninger!$C$16),Forudsætninger!$C$17,1))) | I22: =IF($B22="","",$F22*INDEX(Forudsætninger!$D$29:$D$40,3)*IF(3<IF(N($C22)<1,1,$C22),0,IF(AND($D22="Ja",3<IF(N($C22)<1,1,$C22)+Forudsætninger!$C$16),Forudsætninger!$C$17,1))) | J22: =IF($B22="","",$F22*INDEX(Forudsætninger!$D$29:$D$40,4)*IF(4<IF(N($C22)<1,1,$C22),0,IF(AND($D22="Ja",4<IF(N($C22)<1,1,$C22)+Forudsætninger!$C$16),Forudsætninger!$C$17,1))) | K22: =IF($B22="","",$F22*INDEX(Forudsætninger!$D$29:$D$40,5)*IF(5<IF(N($C22)<1,1,$C22),0,IF(AND($D22="Ja",5<IF(N($C22)<1,1,$C22)+Forudsætninger!$C$16),Forudsætninger!$C$17,1))) | L22: =IF($B22="","",$F22*INDEX(Forudsætninger!$D$29:$D$40,6)*IF(6<IF(N($C22)<1,1,$C22),0,IF(AND($D22="Ja",6<IF(N($C22)<1,1,$C22)+Forudsætninger!$C$16),Forudsætninger!$C$17,1))) | M22: =IF($B22="","",$F22*INDEX(Forudsætninger!$D$29:$D$40,7)*IF(7<IF(N($C22)<1,1,$C22),0,IF(AND($D22="Ja",7<IF(N($C22)<1,1,$C22)+Forudsætninger!$C$16),Forudsætninger!$C$17,1))) | N22: =IF($B22="","",$F22*INDEX(Forudsætninger!$D$29:$D$40,8)*IF(8<IF(N($C22)<1,1,$C22),0,IF(AND($D22="Ja",8<IF(N($C22)<1,1,$C22)+Forudsætninger!$C$16),Forudsætninger!$C$17,1))) | O22: =IF($B22="","",$F22*INDEX(Forudsætninger!$D$29:$D$40,9)*IF(9<IF(N($C22)<1,1,$C22),0,IF(AND($D22="Ja",9<IF(N($C22)<1,1,$C22)+Forudsætninger!$C$16),Forudsætninger!$C$17,1))) | P22: =IF($B22="","",$F22*INDEX(Forudsætninger!$D$29:$D$40,10)*IF(10<IF(N($C22)<1,1,$C22),0,IF(AND($D22="Ja",10<IF(N($C22)<1,1,$C22)+Forudsætninger!$C$16),Forudsætninger!$C$17,1))) | Q22: =IF($B22="","",$F22*INDEX(Forudsætninger!$D$29:$D$40,11)*IF(11<IF(N($C22)<1,1,$C22),0,IF(AND($D22="Ja",11<IF(N($C22)<1,1,$C22)+Forudsætninger!$C$16),Forudsætninger!$C$17,1))) | R22: =IF($B22="","",$F22*INDEX(Forudsætninger!$D$29:$D$40,12)*IF(12<IF(N($C22)<1,1,$C22),0,IF(AND($D22="Ja",12<IF(N($C22)<1,1,$C22)+Forudsætninger!$C$16),Forudsætninger!$C$17,1))) | S22: =IF($B22="","",SUM(G22:R22))
F23: =IF($B23="","",IF(N($E23)>0,$E23,Forudsætninger!$C$14)) | G23: =IF($B23="","",$F23*INDEX(Forudsætninger!$D$29:$D$40,1)*IF(1<IF(N($C23)<1,1,$C23),0,IF(AND($D23="Ja",1<IF(N($C23)<1,1,$C23)+Forudsætninger!$C$16),Forudsætninger!$C$17,1))) | H23: =IF($B23="","",$F23*INDEX(Forudsætninger!$D$29:$D$40,2)*IF(2<IF(N($C23)<1,1,$C23),0,IF(AND($D23="Ja",2<IF(N($C23)<1,1,$C23)+Forudsætninger!$C$16),Forudsætninger!$C$17,1))) | I23: =IF($B23="","",$F23*INDEX(Forudsætninger!$D$29:$D$40,3)*IF(3<IF(N($C23)<1,1,$C23),0,IF(AND($D23="Ja",3<IF(N($C23)<1,1,$C23)+Forudsætninger!$C$16),Forudsætninger!$C$17,1))) | J23: =IF($B23="","",$F23*INDEX(Forudsætninger!$D$29:$D$40,4)*IF(4<IF(N($C23)<1,1,$C23),0,IF(AND($D23="Ja",4<IF(N($C23)<1,1,$C23)+Forudsætninger!$C$16),Forudsætninger!$C$17,1))) | K23: =IF($B23="","",$F23*INDEX(Forudsætninger!$D$29:$D$40,5)*IF(5<IF(N($C23)<1,1,$C23),0,IF(AND($D23="Ja",5<IF(N($C23)<1,1,$C23)+Forudsætninger!$C$16),Forudsætninger!$C$17,1))) | L23: =IF($B23="","",$F23*INDEX(Forudsætninger!$D$29:$D$40,6)*IF(6<IF(N($C23)<1,1,$C23),0,IF(AND($D23="Ja",6<IF(N($C23)<1,1,$C23)+Forudsætninger!$C$16),Forudsætninger!$C$17,1))) | M23: =IF($B23="","",$F23*INDEX(Forudsætninger!$D$29:$D$40,7)*IF(7<IF(N($C23)<1,1,$C23),0,IF(AND($D23="Ja",7<IF(N($C23)<1,1,$C23)+Forudsætninger!$C$16),Forudsætninger!$C$17,1))) | N23: =IF($B23="","",$F23*INDEX(Forudsætninger!$D$29:$D$40,8)*IF(8<IF(N($C23)<1,1,$C23),0,IF(AND($D23="Ja",8<IF(N($C23)<1,1,$C23)+Forudsætninger!$C$16),Forudsætninger!$C$17,1))) | O23: =IF($B23="","",$F23*INDEX(Forudsætninger!$D$29:$D$40,9)*IF(9<IF(N($C23)<1,1,$C23),0,IF(AND($D23="Ja",9<IF(N($C23)<1,1,$C23)+Forudsætninger!$C$16),Forudsætninger!$C$17,1))) | P23: =IF($B23="","",$F23*INDEX(Forudsætninger!$D$29:$D$40,10)*IF(10<IF(N($C23)<1,1,$C23),0,IF(AND($D23="Ja",10<IF(N($C23)<1,1,$C23)+Forudsætninger!$C$16),Forudsætninger!$C$17,1))) | Q23: =IF($B23="","",$F23*INDEX(Forudsætninger!$D$29:$D$40,11)*IF(11<IF(N($C23)<1,1,$C23),0,IF(AND($D23="Ja",11<IF(N($C23)<1,1,$C23)+Forudsætninger!$C$16),Forudsætninger!$C$17,1))) | R23: =IF($B23="","",$F23*INDEX(Forudsætninger!$D$29:$D$40,12)*IF(12<IF(N($C23)<1,1,$C23),0,IF(AND($D23="Ja",12<IF(N($C23)<1,1,$C23)+Forudsætninger!$C$16),Forudsætninger!$C$17,1))) | S23: =IF($B23="","",SUM(G23:R23))
F24: =IF($B24="","",IF(N($E24)>0,$E24,Forudsætninger!$C$14)) | G24: =IF($B24="","",$F24*INDEX(Forudsætninger!$D$29:$D$40,1)*IF(1<IF(N($C24)<1,1,$C24),0,IF(AND($D24="Ja",1<IF(N($C24)<1,1,$C24)+Forudsætninger!$C$16),Forudsætninger!$C$17,1))) | H24: =IF($B24="","",$F24*INDEX(Forudsætninger!$D$29:$D$40,2)*IF(2<IF(N($C24)<1,1,$C24),0,IF(AND($D24="Ja",2<IF(N($C24)<1,1,$C24)+Forudsætninger!$C$16),Forudsætninger!$C$17,1))) | I24: =IF($B24="","",$F24*INDEX(Forudsætninger!$D$29:$D$40,3)*IF(3<IF(N($C24)<1,1,$C24),0,IF(AND($D24="Ja",3<IF(N($C24)<1,1,$C24)+Forudsætninger!$C$16),Forudsætninger!$C$17,1))) | J24: =IF($B24="","",$F24*INDEX(Forudsætninger!$D$29:$D$40,4)*IF(4<IF(N($C24)<1,1,$C24),0,IF(AND($D24="Ja",4<IF(N($C24)<1,1,$C24)+Forudsætninger!$C$16),Forudsætninger!$C$17,1))) | K24: =IF($B24="","",$F24*INDEX(Forudsætninger!$D$29:$D$40,5)*IF(5<IF(N($C24)<1,1,$C24),0,IF(AND($D24="Ja",5<IF(N($C24)<1,1,$C24)+Forudsætninger!$C$16),Forudsætninger!$C$17,1))) | L24: =IF($B24="","",$F24*INDEX(Forudsætninger!$D$29:$D$40,6)*IF(6<IF(N($C24)<1,1,$C24),0,IF(AND($D24="Ja",6<IF(N($C24)<1,1,$C24)+Forudsætninger!$C$16),Forudsætninger!$C$17,1))) | M24: =IF($B24="","",$F24*INDEX(Forudsætninger!$D$29:$D$40,7)*IF(7<IF(N($C24)<1,1,$C24),0,IF(AND($D24="Ja",7<IF(N($C24)<1,1,$C24)+Forudsætninger!$C$16),Forudsætninger!$C$17,1))) | N24: =IF($B24="","",$F24*INDEX(Forudsætninger!$D$29:$D$40,8)*IF(8<IF(N($C24)<1,1,$C24),0,IF(AND($D24="Ja",8<IF(N($C24)<1,1,$C24)+Forudsætninger!$C$16),Forudsætninger!$C$17,1))) | O24: =IF($B24="","",$F24*INDEX(Forudsætninger!$D$29:$D$40,9)*IF(9<IF(N($C24)<1,1,$C24),0,IF(AND($D24="Ja",9<IF(N($C24)<1,1,$C24)+Forudsætninger!$C$16),Forudsætninger!$C$17,1))) | P24: =IF($B24="","",$F24*INDEX(Forudsætninger!$D$29:$D$40,10)*IF(10<IF(N($C24)<1,1,$C24),0,IF(AND($D24="Ja",10<IF(N($C24)<1,1,$C24)+Forudsætninger!$C$16),Forudsætninger!$C$17,1))) | Q24: =IF($B24="","",$F24*INDEX(Forudsætninger!$D$29:$D$40,11)*IF(11<IF(N($C24)<1,1,$C24),0,IF(AND($D24="Ja",11<IF(N($C24)<1,1,$C24)+Forudsætninger!$C$16),Forudsætninger!$C$17,1))) | R24: =IF($B24="","",$F24*INDEX(Forudsætninger!$D$29:$D$40,12)*IF(12<IF(N($C24)<1,1,$C24),0,IF(AND($D24="Ja",12<IF(N($C24)<1,1,$C24)+Forudsætninger!$C$16),Forudsætninger!$C$17,1))) | S24: =IF($B24="","",SUM(G24:R24))
F25: =IF($B25="","",IF(N($E25)>0,$E25,Forudsætninger!$C$14)) | G25: =IF($B25="","",$F25*INDEX(Forudsætninger!$D$29:$D$40,1)*IF(1<IF(N($C25)<1,1,$C25),0,IF(AND($D25="Ja",1<IF(N($C25)<1,1,$C25)+Forudsætninger!$C$16),Forudsætninger!$C$17,1))) | H25: =IF($B25="","",$F25*INDEX(Forudsætninger!$D$29:$D$40,2)*IF(2<IF(N($C25)<1,1,$C25),0,IF(AND($D25="Ja",2<IF(N($C25)<1,1,$C25)+Forudsætninger!$C$16),Forudsætninger!$C$17,1))) | I25: =IF($B25="","",$F25*INDEX(Forudsætninger!$D$29:$D$40,3)*IF(3<IF(N($C25)<1,1,$C25),0,IF(AND($D25="Ja",3<IF(N($C25)<1,1,$C25)+Forudsætninger!$C$16),Forudsætninger!$C$17,1))) | J25: =IF($B25="","",$F25*INDEX(Forudsætninger!$D$29:$D$40,4)*IF(4<IF(N($C25)<1,1,$C25),0,IF(AND($D25="Ja",4<IF(N($C25)<1,1,$C25)+Forudsætninger!$C$16),Forudsætninger!$C$17,1))) | K25: =IF($B25="","",$F25*INDEX(Forudsætninger!$D$29:$D$40,5)*IF(5<IF(N($C25)<1,1,$C25),0,IF(AND($D25="Ja",5<IF(N($C25)<1,1,$C25)+Forudsætninger!$C$16),Forudsætninger!$C$17,1))) | L25: =IF($B25="","",$F25*INDEX(Forudsætninger!$D$29:$D$40,6)*IF(6<IF(N($C25)<1,1,$C25),0,IF(AND($D25="Ja",6<IF(N($C25)<1,1,$C25)+Forudsætninger!$C$16),Forudsætninger!$C$17,1))) | M25: =IF($B25="","",$F25*INDEX(Forudsætninger!$D$29:$D$40,7)*IF(7<IF(N($C25)<1,1,$C25),0,IF(AND($D25="Ja",7<IF(N($C25)<1,1,$C25)+Forudsætninger!$C$16),Forudsætninger!$C$17,1))) | N25: =IF($B25="","",$F25*INDEX(Forudsætninger!$D$29:$D$40,8)*IF(8<IF(N($C25)<1,1,$C25),0,IF(AND($D25="Ja",8<IF(N($C25)<1,1,$C25)+Forudsætninger!$C$16),Forudsætninger!$C$17,1))) | O25: =IF($B25="","",$F25*INDEX(Forudsætninger!$D$29:$D$40,9)*IF(9<IF(N($C25)<1,1,$C25),0,IF(AND($D25="Ja",9<IF(N($C25)<1,1,$C25)+Forudsætninger!$C$16),Forudsætninger!$C$17,1))) | P25: =IF($B25="","",$F25*INDEX(Forudsætninger!$D$29:$D$40,10)*IF(10<IF(N($C25)<1,1,$C25),0,IF(AND($D25="Ja",10<IF(N($C25)<1,1,$C25)+Forudsætninger!$C$16),Forudsætninger!$C$17,1))) | Q25: =IF($B25="","",$F25*INDEX(Forudsætninger!$D$29:$D$40,11)*IF(11<IF(N($C25)<1,1,$C25),0,IF(AND($D25="Ja",11<IF(N($C25)<1,1,$C25)+Forudsætninger!$C$16),Forudsætninger!$C$17,1))) | R25: =IF($B25="","",$F25*INDEX(Forudsætninger!$D$29:$D$40,12)*IF(12<IF(N($C25)<1,1,$C25),0,IF(AND($D25="Ja",12<IF(N($C25)<1,1,$C25)+Forudsætninger!$C$16),Forudsætninger!$C$17,1))) | S25: =IF($B25="","",SUM(G25:R25))
F26: =IF($B26="","",IF(N($E26)>0,$E26,Forudsætninger!$C$14)) | G26: =IF($B26="","",$F26*INDEX(Forudsætninger!$D$29:$D$40,1)*IF(1<IF(N($C26)<1,1,$C26),0,IF(AND($D26="Ja",1<IF(N($C26)<1,1,$C26)+Forudsætninger!$C$16),Forudsætninger!$C$17,1))) | H26: =IF($B26="","",$F26*INDEX(Forudsætninger!$D$29:$D$40,2)*IF(2<IF(N($C26)<1,1,$C26),0,IF(AND($D26="Ja",2<IF(N($C26)<1,1,$C26)+Forudsætninger!$C$16),Forudsætninger!$C$17,1))) | I26: =IF($B26="","",$F26*INDEX(Forudsætninger!$D$29:$D$40,3)*IF(3<IF(N($C26)<1,1,$C26),0,IF(AND($D26="Ja",3<IF(N($C26)<1,1,$C26)+Forudsætninger!$C$16),Forudsætninger!$C$17,1))) | J26: =IF($B26="","",$F26*INDEX(Forudsætninger!$D$29:$D$40,4)*IF(4<IF(N($C26)<1,1,$C26),0,IF(AND($D26="Ja",4<IF(N($C26)<1,1,$C26)+Forudsætninger!$C$16),Forudsætninger!$C$17,1))) | K26: =IF($B26="","",$F26*INDEX(Forudsætninger!$D$29:$D$40,5)*IF(5<IF(N($C26)<1,1,$C26),0,IF(AND($D26="Ja",5<IF(N($C26)<1,1,$C26)+Forudsætninger!$C$16),Forudsætninger!$C$17,1))) | L26: =IF($B26="","",$F26*INDEX(Forudsætninger!$D$29:$D$40,6)*IF(6<IF(N($C26)<1,1,$C26),0,IF(AND($D26="Ja",6<IF(N($C26)<1,1,$C26)+Forudsætninger!$C$16),Forudsætninger!$C$17,1))) | M26: =IF($B26="","",$F26*INDEX(Forudsætninger!$D$29:$D$40,7)*IF(7<IF(N($C26)<1,1,$C26),0,IF(AND($D26="Ja",7<IF(N($C26)<1,1,$C26)+Forudsætninger!$C$16),Forudsætninger!$C$17,1))) | N26: =IF($B26="","",$F26*INDEX(Forudsætninger!$D$29:$D$40,8)*IF(8<IF(N($C26)<1,1,$C26),0,IF(AND($D26="Ja",8<IF(N($C26)<1,1,$C26)+Forudsætninger!$C$16),Forudsætninger!$C$17,1))) | O26: =IF($B26="","",$F26*INDEX(Forudsætninger!$D$29:$D$40,9)*IF(9<IF(N($C26)<1,1,$C26),0,IF(AND($D26="Ja",9<IF(N($C26)<1,1,$C26)+Forudsætninger!$C$16),Forudsætninger!$C$17,1))) | P26: =IF($B26="","",$F26*INDEX(Forudsætninger!$D$29:$D$40,10)*IF(10<IF(N($C26)<1,1,$C26),0,IF(AND($D26="Ja",10<IF(N($C26)<1,1,$C26)+Forudsætninger!$C$16),Forudsætninger!$C$17,1))) | Q26: =IF($B26="","",$F26*INDEX(Forudsætninger!$D$29:$D$40,11)*IF(11<IF(N($C26)<1,1,$C26),0,IF(AND($D26="Ja",11<IF(N($C26)<1,1,$C26)+Forudsætninger!$C$16),Forudsætninger!$C$17,1))) | R26: =IF($B26="","",$F26*INDEX(Forudsætninger!$D$29:$D$40,12)*IF(12<IF(N($C26)<1,1,$C26),0,IF(AND($D26="Ja",12<IF(N($C26)<1,1,$C26)+Forudsætninger!$C$16),Forudsætninger!$C$17,1))) | S26: =IF($B26="","",SUM(G26:R26))
B27: Kvote i alt | G27: =SUM(G7:G26) -> 1575000 | H27: =SUM(H7:H26) -> 1920000 | I27: =SUM(I7:I26) -> 2160000 | J27: =SUM(J7:J26) -> 2040000 | K27: =SUM(K7:K26) -> 2430000 | L27: =SUM(L7:L26) -> 2565000 | M27: =SUM(M7:M26) -> 1140000 | N27: =SUM(N7:N26) -> 2100000 | ... S27: =SUM(S7:S26) -> 27630000
B28: Omsætningsmål fordelt efter sæson | G28: =Forudsætninger!$C$7*INDEX(Forudsætninger!$D$29:$D$40,1) -> 1680000 | H28: =Forudsætninger!$C$7*INDEX(Forudsætninger!$D$29:$D$40,2) -> 1920000 | I28: =Forudsætninger!$C$7*INDEX(Forudsætninger!$D$29:$D$40,3) -> 2160000 | J28: =Forudsætninger!$C$7*INDEX(Forudsætninger!$D$29:$D$40,4) -> 1920000 | K28: =Forudsætninger!$C$7*INDEX(Forudsætninger!$D$29:$D$40,5) -> 2160000 | L28: =Forudsætninger!$C$7*INDEX(Forudsætninger!$D$29:$D$40,6) -> 2160000 | M28: =Forudsætninger!$C$7*INDEX(Forudsætninger!$D$29:$D$40,7) -> 960000 | N28: =Forudsætninger!$C$7*INDEX(Forudsætninger!$D$29:$D$40,8) -> 1680000 | O28: =Forudsætninger!$C$7*INDEX(Forudsætninger!$D$29:$D$40,9) -> 2160000 | P28: =Forudsætninger!$C$7*INDEX(Forudsætninger!$D$29:$D$40,10) -> 2160000 | Q28: =Forudsætninger!$C$7*INDEX(Forudsætninger!$D$29:$D$40,11) -> 2400000 | R28: =Forudsætninger!$C$7*INDEX(Forudsætninger!$D$29:$D$40,12) -> 2640000 | S28: =SUM(G28:R28) -> 24000000
B29: Kvote i % af omsætningsmål | G29: =IFERROR(G27/G28,0) -> 0.9375 | H29: =IFERROR(H27/H28,0) -> 1 | I29: =IFERROR(I27/I28,0) -> 1 | J29: =IFERROR(J27/J28,0) -> 1.0625 | K29: =IFERROR(K27/K28,0) -> 1.125 | L29: =IFERROR(L27/L28,0) -> 1.1875 | M29: =IFERROR(M27/M28,0) -> 1.1875 | N29: =IFERROR(N27/N28,0) -> 1.25 | ... S29: =IFERROR(S27/S28,0) -> 1.15125
B31: Kvote over 100 % af omsætningsmålet er en buffer mod afgang, forsinkede ansættelser og sælgere, der ikke når målet.

Sheet OTE og provision
B2: OTE og provision
B3: Standardplanen fra Forudsætninger. Målopfyldelserne i række 15 kan ændres.
B4: Standardplan pr. fuldt produktiv sælger
B5: Grundløn pr. år (kr.) | C5: =Forudsætninger!$C$22*12 -> 504000
B6: Variabel løn ved 100 % (kr.) | C6: =Forudsætninger!$C$23 -> 216000
B7: OTE, on-target earnings (kr.) | C7: =C5+C6 -> 720000 | D7: OTE = grundløn + variabel løn ved 100 %.
B8: Pay mix, fast andel | C8: =IFERROR(C5/C7,0) -> 0.7
B9: Pay mix, variabel andel | C9: =IFERROR(C6/C7,0) -> 0.3
B10: Provisionssats (variabel ÷ kvote) | C10: =IFERROR(C6/Forudsætninger!$C$14,0) -> 0.072 | D10: Sats = variabel løn ved 100 % ÷ årskvote.
B11: Sats over 100 % (med accelerator) | C11: =C10*Forudsætninger!$C$24 -> 0.108
B13: Provision for en fuldt produktiv sælger
C14: Scenarie 1 | D14: Scenarie 2 | E14: Scenarie 3
B15: Målopfyldelse | C15: 0.8 | D15: 1 | E15: 1.2
B16: Salg (kr.) | C16: =Forudsætninger!$C$14*C15 -> 2400000 | D16: =Forudsætninger!$C$14*D15 -> 3000000 | E16: =Forudsætninger!$C$14*E15 -> 3600000
B17: Provision (kr.) | C17: =Forudsætninger!$C$14*MIN(C15,1)*$C$10+Forudsætninger!$C$14*MAX(0,C15-1)*$C$11 -> 172800 | D17: =Forudsætninger!$C$14*MIN(D15,1)*$C$10+Forudsætninger!$C$14*MAX(0,D15-1)*$C$11 -> 216000 | E17: =Forudsætninger!$C$14*MIN(E15,1)*$C$10+Forudsætninger!$C$14*MAX(0,E15-1)*$C$11 -> 280800
