Workbook

Sheet Vejledning
C2: Gratis skabelon fra Prowi
B4: OTE og pay mix
B5: Grundløn, variabel løn, provisionssats og løn ved forskellig målopfyldelse
B7: Skabelonen regner salgslønnen ud for op til 8 roller: grundløn og variabel løn ud fra OTE og pay mix, provisionssatsen (variabel løn ÷ kvote), hvad sælgeren tjener ved 50, 75, 100, 125 og 150 % målopfyldelse med og uden accelerator, og hvad det koster virksomheden. Der er eksempeltal for fire roller. Tallene er eksempler, ikke markedsdata.
B9: Trin for trin
B10: 1. Roller | C10: En række pr. rolle: antal sælgere, OTE pr. år, fast andel (pay mix), årskvote, acceleratorfaktor og eventuelt loft. Skriv også jeres øvrige lønomkostninger i procent.
B11: 2. Udbetaling | C11: Vælg fem niveauer for målopfyldelse øverst. Arket viser for hver rolle salg, provision med og uden accelerator, samlet løn og lønomkostning.
B12: 3. Overblik | C12: Rollerne side om side ved 100 % og hele teamets salgsløn ved de fem niveauer.
B14: Farver
B15: Lavendel felt, lilla tekst | C15: Her skriver du. Alt andet er formler.
B16: Gråt felt | C16: Beregnet automatisk. Ret ikke i formlerne, medmindre du ved, hvad du gør.
B17: Lyseblåt felt | C17: Resultater og totaler.
B19: Sådan regner arket
B20: Grundløn og variabel løn | C20: Grundløn = OTE × fast andel. Variabel løn ved 100 % = OTE − grundløn.
B21: Provisionssats | C21: Variabel løn ved 100 % ÷ årskvote. Så tjener sælgeren præcis den variable løn, når kvoten nås.
B22: Accelerator | C22: Over 100 % ganges satsen med acceleratorfaktoren, men kun på salget over kvoten. Faktor 1 eller tom = ingen accelerator.
B23: Loft | C23: Provisionen er højst loftet × variabel løn ved 100 %. Fx 150 % betyder, at provisionen højst er 1,5 gange den variable løn. Tomt felt = intet loft.
B24: Acceleratoreffekt | C24: Provision med accelerator minus provision med samme sats hele vejen. Viser, hvad acceleratoren koster ved hvert niveau.
B25: Lønomkostning | C25: Samlet løn × (1 + øvrige lønomkostninger). Lønomkostning i % af salg er det, salgslønnen koster pr. solgt krone.
B27: Godt at vide
B28: • | C28: Alle tal er eksempler. Brug jeres egne lønniveauer, kvoter og omkostningsprocenter.
B29: • | C29: Øvrige lønomkostninger er et eksempel på fx pension, ATP, forsikring og feriepenge. Få det rigtige tal fra jeres lønsystem eller revisor.
B30: • | C30: Arket regner på årsbasis. Betaler I provision pr. måned eller kvartal, kan resultatet afvige, hvis salget svinger, fordi accelerator og loft så gælder pr. periode.
B31: • | C31: Ingen makroer. Alle beregninger er almindelige formler, som virker i Excel, Google Sheets, Numbers og LibreOffice.
B34: prowi.io · Gratis skabelon fra Prowi

Sheet Roller
B2: Roller
B3: Skriv kun i de lavendel felter. En række pr. rolle.
B5: Generelt
B6: Virksomhed | C6: Eksempel ApS
B7: Øvrige lønomkostninger (% af løn) | C7: 0.1 | E7: Eksempel. Fx pension, ATP, forsikring og feriepenge. Brug jeres eget tal.
B10: Rolle | C10: Antal | D10: OTE pr. år | E10: Fast andel (pay mix) | F10: Årskvote | G10: Accelerator-faktor over 100 % | H10: Loft (% af variabel, valgfri) | I10: Grundløn pr. år | J10: Grundløn pr. måned | K10: Variabel løn ved 100 % | L10: Provisions-sats | M10: Sats over kvote | N10: Kvote ÷ OTE | O10: Lønomkostning ved 100 % | P10: Omkostning i % af kvote | Q10: Team: omkostning ved 100 %
B11: Inside sales | C11: 4 | D11: 540000 | E11: 0.75 | F11: 2700000 | G11: 1.5 | I11: =IF($B11="","",N(D11)*N(E11)) -> 405000 | J11: =IF($B11="","",I11/12) -> 33750 | K11: =IF($B11="","",N(D11)-I11) -> 135000 | L11: =IF($B11="","",IFERROR(K11/F11,0)) -> 0.05 | M11: =IF($B11="","",L11*IF(N(G11)=0,1,G11)) -> 0.075 | N11: =IF($B11="","",IFERROR(N(F11)/D11,0)) -> 5 | O11: =IF($B11="","",N(D11)*(1+Roller!$C$7)) -> 594000 | P11: =IF($B11="","",IFERROR(O11/F11,0)) -> 0.22 | Q11: =IF($B11="","",O11*N(C11)) -> 2376000
B12: Account executive | C12: 5 | D12: 720000 | E12: 0.6 | F12: 3600000 | G12: 1.5 | H12: 2 | I12: =IF($B12="","",N(D12)*N(E12)) -> 432000 | J12: =IF($B12="","",I12/12) -> 36000 | K12: =IF($B12="","",N(D12)-I12) -> 288000 | L12: =IF($B12="","",IFERROR(K12/F12,0)) -> 0.08 | M12: =IF($B12="","",L12*IF(N(G12)=0,1,G12)) -> 0.12 | N12: =IF($B12="","",IFERROR(N(F12)/D12,0)) -> 5 | O12: =IF($B12="","",N(D12)*(1+Roller!$C$7)) -> 792000 | P12: =IF($B12="","",IFERROR(O12/F12,0)) -> 0.22 | Q12: =IF($B12="","",O12*N(C12)) -> 3960000
B13: Key account manager | C13: 2 | D13: 840000 | E13: 0.7 | F13: 6300000 | G13: 1.25 | H13: 1.5 | I13: =IF($B13="","",N(D13)*N(E13)) -> 588000 | J13: =IF($B13="","",I13/12) -> 49000 | K13: =IF($B13="","",N(D13)-I13) -> 252000 | L13: =IF($B13="","",IFERROR(K13/F13,0)) -> 0.04 | M13: =IF($B13="","",L13*IF(N(G13)=0,1,G13)) -> 0.05 | N13: =IF($B13="","",IFERROR(N(F13)/D13,0)) -> 7.5 | O13: =IF($B13="","",N(D13)*(1+Roller!$C$7)) -> 924000 | P13: =IF($B13="","",IFERROR(O13/F13,0)) -> 0.14666667 | Q13: =IF($B13="","",O13*N(C13)) -> 1848000
B14: Udesælger | C14: 3 | D14: 660000 | E14: 0.65 | F14: 3300000 | G14: 1.5 | I14: =IF($B14="","",N(D14)*N(E14)) -> 429000 | J14: =IF($B14="","",I14/12) -> 35750 | K14: =IF($B14="","",N(D14)-I14) -> 231000 | L14: =IF($B14="","",IFERROR(K14/F14,0)) -> 0.07 | M14: =IF($B14="","",L14*IF(N(G14)=0,1,G14)) -> 0.105 | N14: =IF($B14="","",IFERROR(N(F14)/D14,0)) -> 5 | O14: =IF($B14="","",N(D14)*(1+Roller!$C$7)) -> 726000 | P14: =IF($B14="","",IFERROR(O14/F14,0)) -> 0.22 | Q14: =IF($B14="","",O14*N(C14)) -> 2178000
I15: =IF($B15="","",N(D15)*N(E15)) | J15: =IF($B15="","",I15/12) | K15: =IF($B15="","",N(D15)-I15) | L15: =IF($B15="","",IFERROR(K15/F15,0)) | M15: =IF($B15="","",L15*IF(N(G15)=0,1,G15)) | N15: =IF($B15="","",IFERROR(N(F15)/D15,0)) | O15: =IF($B15="","",N(D15)*(1+Roller!$C$7)) | P15: =IF($B15="","",IFERROR(O15/F15,0)) | Q15: =IF($B15="","",O15*N(C15))
I16: =IF($B16="","",N(D16)*N(E16)) | J16: =IF($B16="","",I16/12) | K16: =IF($B16="","",N(D16)-I16) | L16: =IF($B16="","",IFERROR(K16/F16,0)) | M16: =IF($B16="","",L16*IF(N(G16)=0,1,G16)) | N16: =IF($B16="","",IFERROR(N(F16)/D16,0)) | O16: =IF($B16="","",N(D16)*(1+Roller!$C$7)) | P16: =IF($B16="","",IFERROR(O16/F16,0)) | Q16: =IF($B16="","",O16*N(C16))
I17: =IF($B17="","",N(D17)*N(E17)) | J17: =IF($B17="","",I17/12) | K17: =IF($B17="","",N(D17)-I17) | L17: =IF($B17="","",IFERROR(K17/F17,0)) | M17: =IF($B17="","",L17*IF(N(G17)=0,1,G17)) | N17: =IF($B17="","",IFERROR(N(F17)/D17,0)) | O17: =IF($B17="","",N(D17)*(1+Roller!$C$7)) | P17: =IF($B17="","",IFERROR(O17/F17,0)) | Q17: =IF($B17="","",O17*N(C17))
I18: =IF($B18="","",N(D18)*N(E18)) | J18: =IF($B18="","",I18/12) | K18: =IF($B18="","",N(D18)-I18) | L18: =IF($B18="","",IFERROR(K18/F18,0)) | M18: =IF($B18="","",L18*IF(N(G18)=0,1,G18)) | N18: =IF($B18="","",IFERROR(N(F18)/D18,0)) | O18: =IF($B18="","",N(D18)*(1+Roller!$C$7)) | P18: =IF($B18="","",IFERROR(O18/F18,0)) | Q18: =IF($B18="","",O18*N(C18))
B19: I alt | C19: =SUM(C11:C18) -> 14 | Q19: =SUM(Q11:Q18) -> 10362000
B21: Fast andel 70 % betyder pay mix 70/30: 70 % af OTE er grundløn og 30 % er variabel løn ved 100 % målopfyldelse.
B22: Kvote ÷ OTE viser, hvor mange gange OTE sælgeren skal sælge for. Loft 150 % = provisionen er højst 1,5 × variabel løn ved 100 %.

Sheet Udbetaling
B2: Udbetaling ved forskellig målopfyldelse
B3: Skriv fem niveauer for målopfyldelse i række 5. Resten er formler for hver rolle fra Roller.
B5: Målopfyldelse | C5: 0.5 | D5: 0.75 | E5: 1 | F5: 1.25 | G5: 1.5
B8: =IF(Roller!$B$11="","",Roller!$B$11) -> Inside sales | C8: =IF($B8="","",C$5) -> 0.5 | D8: =IF($B8="","",D$5) -> 0.75 | E8: =IF($B8="","",E$5) -> 1 | F8: =IF($B8="","",F$5) -> 1.25 | G8: =IF($B8="","",G$5) -> 1.5
B9: Målopfyldelse | C9: =IF($B$8="","",C$5) -> 0.5 | D9: =IF($B$8="","",D$5) -> 0.75 | E9: =IF($B$8="","",E$5) -> 1 | F9: =IF($B$8="","",F$5) -> 1.25 | G9: =IF($B$8="","",G$5) -> 1.5
B10: Salg | C10: =IF($B$8="","",N(Roller!$F$11)*C$9) -> 1350000 | D10: =IF($B$8="","",N(Roller!$F$11)*D$9) -> 2025000 | E10: =IF($B$8="","",N(Roller!$F$11)*E$9) -> 2700000 | F10: =IF($B$8="","",N(Roller!$F$11)*F$9) -> 3375000 | G10: =IF($B$8="","",N(Roller!$F$11)*G$9) -> 4050000
B11: Provision uden accelerator | C11: =IF($B$8="","",IF(Roller!$H$11="",N(Roller!$F$11)*C$9*Roller!$L$11,MIN(N(Roller!$F$11)*C$9*Roller!$L$11,Roller!$K$11*Roller!$H$11))) -> 67500 | D11: =IF($B$8="","",IF(Roller!$H$11="",N(Roller!$F$11)*D$9*Roller!$L$11,MIN(N(Roller!$F$11)*D$9*Roller!$L$11,Roller!$K$11*Roller!$H$11))) -> 101250 | E11: =IF($B$8="","",IF(Roller!$H$11="",N(Roller!$F$11)*E$9*Roller!$L$11,MIN(N(Roller!$F$11)*E$9*Roller!$L$11,Roller!$K$11*Roller!$H$11))) -> 135000 | F11: =IF($B$8="","",IF(Roller!$H$11="",N(Roller!$F$11)*F$9*Roller!$L$11,MIN(N(Roller!$F$11)*F$9*Roller!$L$11,Roller!$K$11*Roller!$H$11))) -> 168750 | G11: =IF($B$8="","",IF(Roller!$H$11="",N(Roller!$F$11)*G$9*Roller!$L$11,MIN(N(Roller!$F$11)*G$9*Roller!$L$11,Roller!$K$11*Roller!$H$11))) -> 202500
B12: Provision med accelerator | C12: =IF($B$8="","",IF(Roller!$H$11="",N(Roller!$F$11)*MIN(C$9,1)*Roller!$L$11+N(Roller!$F$11)*MAX(0,C$9-1)*Roller!$M$11,MIN(N(Roller!$F$11)*MIN(C$9,1)*Roller!$L$11+N(Roller!$F$11)*MAX(0,C$9-1)*Roller!$M$11,Roller!$K$11*Roller!$H$11))) -> 67500 | D12: =IF($B$8="","",IF(Roller!$H$11="",N(Roller!$F$11)*MIN(D$9,1)*Roller!$L$11+N(Roller!$F$11)*MAX(0,D$9-1)*Roller!$M$11,MIN(N(Roller!$F$11)*MIN(D$9,1)*Roller!$L$11+N(Roller!$F$11)*MAX(0,D$9-1)*Roller!$M$11,Roller!$K$11*Roller!$H$11))) -> 101250 | E12: =IF($B$8="","",IF(Roller!$H$11="",N(Roller!$F$11)*MIN(E$9,1)*Roller!$L$11+N(Roller!$F$11)*MAX(0,E$9-1)*Roller!$M$11,MIN(N(Roller!$F$11)*MIN(E$9,1)*Roller!$L$11+N(Roller!$F$11)*MAX(0,E$9-1)*Roller!$M$11,Roller!$K$11*Roller!$H$11))) -> 135000 | F12: =IF($B$8="","",IF(Roller!$H$11="",N(Roller!$F$11)*MIN(F$9,1)*Roller!$L$11+N(Roller!$F$11)*MAX(0,F$9-1)*Roller!$M$11,MIN(N(Roller!$F$11)*MIN(F$9,1)*Roller!$L$11+N(Roller!$F$11)*MAX(0,F$9-1)*Roller!$M$11,Roller!$K$11*Roller!$H$11))) -> 185625 | G12: =IF($B$8="","",IF(Roller!$H$11="",N(Roller!$F$11)*MIN(G$9,1)*Roller!$L$11+N(Roller!$F$11)*MAX(0,G$9-1)*Roller!$M$11,MIN(N(Roller!$F$11)*MIN(G$9,1)*Roller!$L$11+N(Roller!$F$11)*MAX(0,G$9-1)*Roller!$M$11,Roller!$K$11*Roller!$H$11))) -> 236250
B13: Acceleratoreffekt | C13: =IF($B$8="","",C12-C11) -> 0 | D13: =IF($B$8="","",D12-D11) -> 0 | E13: =IF($B$8="","",E12-E11) -> 0 | F13: =IF($B$8="","",F12-F11) -> 16875 | G13: =IF($B$8="","",G12-G11) -> 33750
B14: Samlet løn (grundløn + provision) | C14: =IF($B$8="","",Roller!$I$11+C12) -> 472500 | D14: =IF($B$8="","",Roller!$I$11+D12) -> 506250 | E14: =IF($B$8="","",Roller!$I$11+E12) -> 540000 | F14: =IF($B$8="","",Roller!$I$11+F12) -> 590625 | G14: =IF($B$8="","",Roller!$I$11+G12) -> 641250
B15: Samlet løn i % af OTE | C15: =IF($B$8="","",IFERROR(C14/Roller!$D$11,0)) -> 0.875 | D15: =IF($B$8="","",IFERROR(D14/Roller!$D$11,0)) -> 0.9375 | E15: =IF($B$8="","",IFERROR(E14/Roller!$D$11,0)) -> 1 | F15: =IF($B$8="","",IFERROR(F14/Roller!$D$11,0)) -> 1.09375 | G15: =IF($B$8="","",IFERROR(G14/Roller!$D$11,0)) -> 1.1875
B16: Provision i % af variabel løn ved 100 % | C16: =IF($B$8="","",IFERROR(C12/Roller!$K$11,0)) -> 0.5 | D16: =IF($B$8="","",IFERROR(D12/Roller!$K$11,0)) -> 0.75 | E16: =IF($B$8="","",IFERROR(E12/Roller!$K$11,0)) -> 1 | F16: =IF($B$8="","",IFERROR(F12/Roller!$K$11,0)) -> 1.375 | G16: =IF($B$8="","",IFERROR(G12/Roller!$K$11,0)) -> 1.75
B17: Lønomkostning for virksomheden | C17: =IF($B$8="","",C14*(1+Roller!$C$7)) -> 519750 | D17: =IF($B$8="","",D14*(1+Roller!$C$7)) -> 556875 | E17: =IF($B$8="","",E14*(1+Roller!$C$7)) -> 594000 | F17: =IF($B$8="","",F14*(1+Roller!$C$7)) -> 649687.5 | G17: =IF($B$8="","",G14*(1+Roller!$C$7)) -> 705375
B18: Lønomkostning i % af salg | C18: =IF($B$8="","",IFERROR(C17/C10,0)) -> 0.385 | D18: =IF($B$8="","",IFERROR(D17/D10,0)) -> 0.275 | E18: =IF($B$8="","",IFERROR(E17/E10,0)) -> 0.22 | F18: =IF($B$8="","",IFERROR(F17/F10,0)) -> 0.1925 | G18: =IF($B$8="","",IFERROR(G17/G10,0)) -> 0.17416667
B19: Team: lønomkostning (× antal sælgere) | C19: =IF($B$8="","",C17*N(Roller!$C$11)) -> 2079000 | D19: =IF($B$8="","",D17*N(Roller!$C$11)) -> 2227500 | E19: =IF($B$8="","",E17*N(Roller!$C$11)) -> 2376000 | F19: =IF($B$8="","",F17*N(Roller!$C$11)) -> 2598750 | G19: =IF($B$8="","",G17*N(Roller!$C$11)) -> 2821500
B21: =IF(Roller!$B$12="","",Roller!$B$12) -> Account executive | C21: =IF($B21="","",C$5) -> 0.5 | D21: =IF($B21="","",D$5) -> 0.75 | E21: =IF($B21="","",E$5) -> 1 | F21: =IF($B21="","",F$5) -> 1.25 | G21: =IF($B21="","",G$5) -> 1.5
B22: Målopfyldelse | C22: =IF($B$21="","",C$5) -> 0.5 | D22: =IF($B$21="","",D$5) -> 0.75 | E22: =IF($B$21="","",E$5) -> 1 | F22: =IF($B$21="","",F$5) -> 1.25 | G22: =IF($B$21="","",G$5) -> 1.5
B23: Salg | C23: =IF($B$21="","",N(Roller!$F$12)*C$22) -> 1800000 | D23: =IF($B$21="","",N(Roller!$F$12)*D$22) -> 2700000 | E23: =IF($B$21="","",N(Roller!$F$12)*E$22) -> 3600000 | F23: =IF($B$21="","",N(Roller!$F$12)*F$22) -> 4500000 | G23: =IF($B$21="","",N(Roller!$F$12)*G$22) -> 5400000
B24: Provision uden accelerator | C24: =IF($B$21="","",IF(Roller!$H$12="",N(Roller!$F$12)*C$22*Roller!$L$12,MIN(N(Roller!$F$12)*C$22*Roller!$L$12,Roller!$K$12*Roller!$H$12))) -> 144000 | D24: =IF($B$21="","",IF(Roller!$H$12="",N(Roller!$F$12)*D$22*Roller!$L$12,MIN(N(Roller!$F$12)*D$22*Roller!$L$12,Roller!$K$12*Roller!$H$12))) -> 216000 | E24: =IF($B$21="","",IF(Roller!$H$12="",N(Roller!$F$12)*E$22*Roller!$L$12,MIN(N(Roller!$F$12)*E$22*Roller!$L$12,Roller!$K$12*Roller!$H$12))) -> 288000 | F24: =IF($B$21="","",IF(Roller!$H$12="",N(Roller!$F$12)*F$22*Roller!$L$12,MIN(N(Roller!$F$12)*F$22*Roller!$L$12,Roller!$K$12*Roller!$H$12))) -> 360000 | G24: =IF($B$21="","",IF(Roller!$H$12="",N(Roller!$F$12)*G$22*Roller!$L$12,MIN(N(Roller!$F$12)*G$22*Roller!$L$12,Roller!$K$12*Roller!$H$12))) -> 432000
B25: Provision med accelerator | C25: =IF($B$21="","",IF(Roller!$H$12="",N(Roller!$F$12)*MIN(C$22,1)*Roller!$L$12+N(Roller!$F$12)*MAX(0,C$22-1)*Roller!$M$12,MIN(N(Roller!$F$12)*MIN(C$22,1)*Roller!$L$12+N(Roller!$F$12)*MAX(0,C$22-1)*Roller!$M$12,Roller!$K$12*Roller!$H$12))) -> 144000 | D25: =IF($B$21="","",IF(Roller!$H$12="",N(Roller!$F$12)*MIN(D$22,1)*Roller!$L$12+N(Roller!$F$12)*MAX(0,D$22-1)*Roller!$M$12,MIN(N(Roller!$F$12)*MIN(D$22,1)*Roller!$L$12+N(Roller!$F$12)*MAX(0,D$22-1)*Roller!$M$12,Roller!$K$12*Roller!$H$12))) -> 216000 | E25: =IF($B$21="","",IF(Roller!$H$12="",N(Roller!$F$12)*MIN(E$22,1)*Roller!$L$12+N(Roller!$F$12)*MAX(0,E$22-1)*Roller!$M$12,MIN(N(Roller!$F$12)*MIN(E$22,1)*Roller!$L$12+N(Roller!$F$12)*MAX(0,E$22-1)*Roller!$M$12,Roller!$K$12*Roller!$H$12))) -> 288000 | F25: =IF($B$21="","",IF(Roller!$H$12="",N(Roller!$F$12)*MIN(F$22,1)*Roller!$L$12+N(Roller!$F$12)*MAX(0,F$22-1)*Roller!$M$12,MIN(N(Roller!$F$12)*MIN(F$22,1)*Roller!$L$12+N(Roller!$F$12)*MAX(0,F$22-1)*Roller!$M$12,Roller!$K$12*Roller!$H$12))) -> 396000 | G25: =IF($B$21="","",IF(Roller!$H$12="",N(Roller!$F$12)*MIN(G$22,1)*Roller!$L$12+N(Roller!$F$12)*MAX(0,G$22-1)*Roller!$M$12,MIN(N(Roller!$F$12)*MIN(G$22,1)*Roller!$L$12+N(Roller!$F$12)*MAX(0,G$22-1)*Roller!$M$12,Roller!$K$12*Roller!$H$12))) -> 504000
B26: Acceleratoreffekt | C26: =IF($B$21="","",C25-C24) -> 0 | D26: =IF($B$21="","",D25-D24) -> 0 | E26: =IF($B$21="","",E25-E24) -> 0 | F26: =IF($B$21="","",F25-F24) -> 36000 | G26: =IF($B$21="","",G25-G24) -> 72000
B27: Samlet løn (grundløn + provision) | C27: =IF($B$21="","",Roller!$I$12+C25) -> 576000 | D27: =IF($B$21="","",Roller!$I$12+D25) -> 648000 | E27: =IF($B$21="","",Roller!$I$12+E25) -> 720000 | F27: =IF($B$21="","",Roller!$I$12+F25) -> 828000 | G27: =IF($B$21="","",Roller!$I$12+G25) -> 936000
B28: Samlet løn i % af OTE | C28: =IF($B$21="","",IFERROR(C27/Roller!$D$12,0)) -> 0.8 | D28: =IF($B$21="","",IFERROR(D27/Roller!$D$12,0)) -> 0.9 | E28: =IF($B$21="","",IFERROR(E27/Roller!$D$12,0)) -> 1 | F28: =IF($B$21="","",IFERROR(F27/Roller!$D$12,0)) -> 1.15 | G28: =IF($B$21="","",IFERROR(G27/Roller!$D$12,0)) -> 1.3
B29: Provision i % af variabel løn ved 100 % | C29: =IF($B$21="","",IFERROR(C25/Roller!$K$12,0)) -> 0.5 | D29: =IF($B$21="","",IFERROR(D25/Roller!$K$12,0)) -> 0.75 | E29: =IF($B$21="","",IFERROR(E25/Roller!$K$12,0)) -> 1 | F29: =IF($B$21="","",IFERROR(F25/Roller!$K$12,0)) -> 1.375 | G29: =IF($B$21="","",IFERROR(G25/Roller!$K$12,0)) -> 1.75
B30: Lønomkostning for virksomheden | C30: =IF($B$21="","",C27*(1+Roller!$C$7)) -> 633600 | D30: =IF($B$21="","",D27*(1+Roller!$C$7)) -> 712800 | E30: =IF($B$21="","",E27*(1+Roller!$C$7)) -> 792000 | F30: =IF($B$21="","",F27*(1+Roller!$C$7)) -> 910800 | G30: =IF($B$21="","",G27*(1+Roller!$C$7)) -> 1029600
B31: Lønomkostning i % af salg | C31: =IF($B$21="","",IFERROR(C30/C23,0)) -> 0.352 | D31: =IF($B$21="","",IFERROR(D30/D23,0)) -> 0.264 | E31: =IF($B$21="","",IFERROR(E30/E23,0)) -> 0.22 | F31: =IF($B$21="","",IFERROR(F30/F23,0)) -> 0.2024 | G31: =IF($B$21="","",IFERROR(G30/G23,0)) -> 0.19066667
B32: Team: lønomkostning (× antal sælgere) | C32: =IF($B$21="","",C30*N(Roller!$C$12)) -> 3168000 | D32: =IF($B$21="","",D30*N(Roller!$C$12)) -> 3564000 | E32: =IF($B$21="","",E30*N(Roller!$C$12)) -> 3960000 | F32: =IF($B$21="","",F30*N(Roller!$C$12)) -> 4554000 | G32: =IF($B$21="","",G30*N(Roller!$C$12)) -> 5148000
B34: =IF(Roller!$B$13="","",Roller!$B$13) -> Key account manager | C34: =IF($B34="","",C$5) -> 0.5 | D34: =IF($B34="","",D$5) -> 0.75 | E34: =IF($B34="","",E$5) -> 1 | F34: =IF($B34="","",F$5) -> 1.25 | G34: =IF($B34="","",G$5) -> 1.5
B35: Målopfyldelse | C35: =IF($B$34="","",C$5) -> 0.5 | D35: =IF($B$34="","",D$5) -> 0.75 | E35: =IF($B$34="","",E$5) -> 1 | F35: =IF($B$34="","",F$5) -> 1.25 | G35: =IF($B$34="","",G$5) -> 1.5
B36: Salg | C36: =IF($B$34="","",N(Roller!$F$13)*C$35) -> 3150000 | D36: =IF($B$34="","",N(Roller!$F$13)*D$35) -> 4725000 | E36: =IF($B$34="","",N(Roller!$F$13)*E$35) -> 6300000 | F36: =IF($B$34="","",N(Roller!$F$13)*F$35) -> 7875000 | G36: =IF($B$34="","",N(Roller!$F$13)*G$35) -> 9450000
B37: Provision uden accelerator | C37: =IF($B$34="","",IF(Roller!$H$13="",N(Roller!$F$13)*C$35*Roller!$L$13,MIN(N(Roller!$F$13)*C$35*Roller!$L$13,Roller!$K$13*Roller!$H$13))) -> 126000 | D37: =IF($B$34="","",IF(Roller!$H$13="",N(Roller!$F$13)*D$35*Roller!$L$13,MIN(N(Roller!$F$13)*D$35*Roller!$L$13,Roller!$K$13*Roller!$H$13))) -> 189000 | E37: =IF($B$34="","",IF(Roller!$H$13="",N(Roller!$F$13)*E$35*Roller!$L$13,MIN(N(Roller!$F$13)*E$35*Roller!$L$13,Roller!$K$13*Roller!$H$13))) -> 252000 | F37: =IF($B$34="","",IF(Roller!$H$13="",N(Roller!$F$13)*F$35*Roller!$L$13,MIN(N(Roller!$F$13)*F$35*Roller!$L$13,Roller!$K$13*Roller!$H$13))) -> 315000 | G37: =IF($B$34="","",IF(Roller!$H$13="",N(Roller!$F$13)*G$35*Roller!$L$13,MIN(N(Roller!$F$13)*G$35*Roller!$L$13,Roller!$K$13*Roller!$H$13))) -> 378000
B38: Provision med accelerator | C38: =IF($B$34="","",IF(Roller!$H$13="",N(Roller!$F$13)*MIN(C$35,1)*Roller!$L$13+N(Roller!$F$13)*MAX(0,C$35-1)*Roller!$M$13,MIN(N(Roller!$F$13)*MIN(C$35,1)*Roller!$L$13+N(Roller!$F$13)*MAX(0,C$35-1)*Roller!$M$13,Roller!$K$13*Roller!$H$13))) -> 126000 | D38: =IF($B$34="","",IF(Roller!$H$13="",N(Roller!$F$13)*MIN(D$35,1)*Roller!$L$13+N(Roller!$F$13)*MAX(0,D$35-1)*Roller!$M$13,MIN(N(Roller!$F$13)*MIN(D$35,1)*Roller!$L$13+N(Roller!$F$13)*MAX(0,D$35-1)*Roller!$M$13,Roller!$K$13*Roller!$H$13))) -> 189000 | E38: =IF($B$34="","",IF(Roller!$H$13="",N(Roller!$F$13)*MIN(E$35,1)*Roller!$L$13+N(Roller!$F$13)*MAX(0,E$35-1)*Roller!$M$13,MIN(N(Roller!$F$13)*MIN(E$35,1)*Roller!$L$13+N(Roller!$F$13)*MAX(0,E$35-1)*Roller!$M$13,Roller!$K$13*Roller!$H$13))) -> 252000 | F38: =IF($B$34="","",IF(Roller!$H$13="",N(Roller!$F$13)*MIN(F$35,1)*Roller!$L$13+N(Roller!$F$13)*MAX(0,F$35-1)*Roller!$M$13,MIN(N(Roller!$F$13)*MIN(F$35,1)*Roller!$L$13+N(Roller!$F$13)*MAX(0,F$35-1)*Roller!$M$13,Roller!$K$13*Roller!$H$13))) -> 330750 | G38: =IF($B$34="","",IF(Roller!$H$13="",N(Roller!$F$13)*MIN(G$35,1)*Roller!$L$13+N(Roller!$F$13)*MAX(0,G$35-1)*Roller!$M$13,MIN(N(Roller!$F$13)*MIN(G$35,1)*Roller!$L$13+N(Roller!$F$13)*MAX(0,G$35-1)*Roller!$M$13,Roller!$K$13*Roller!$H$13))) -> 378000
B39: Acceleratoreffekt | C39: =IF($B$34="","",C38-C37) -> 0 | D39: =IF($B$34="","",D38-D37) -> 0 | E39: =IF($B$34="","",E38-E37) -> 0 | F39: =IF($B$34="","",F38-F37) -> 15750 | G39: =IF($B$34="","",G38-G37) -> 0
B40: Samlet løn (grundløn + provision) | C40: =IF($B$34="","",Roller!$I$13+C38) -> 714000 | D40: =IF($B$34="","",Roller!$I$13+D38) -> 777000 | E40: =IF($B$34="","",Roller!$I$13+E38) -> 840000 | F40: =IF($B$34="","",Roller!$I$13+F38) -> 918750 | G40: =IF($B$34="","",Roller!$I$13+G38) -> 966000
B41: Samlet løn i % af OTE | C41: =IF($B$34="","",IFERROR(C40/Roller!$D$13,0)) -> 0.85 | D41: =IF($B$34="","",IFERROR(D40/Roller!$D$13,0)) -> 0.925 | E41: =IF($B$34="","",IFERROR(E40/Roller!$D$13,0)) -> 1 | F41: =IF($B$34="","",IFERROR(F40/Roller!$D$13,0)) -> 1.09375 | G41: =IF($B$34="","",IFERROR(G40/Roller!$D$13,0)) -> 1.15
B42: Provision i % af variabel løn ved 100 % | C42: =IF($B$34="","",IFERROR(C38/Roller!$K$13,0)) -> 0.5 | D42: =IF($B$34="","",IFERROR(D38/Roller!$K$13,0)) -> 0.75 | E42: =IF($B$34="","",IFERROR(E38/Roller!$K$13,0)) -> 1 | F42: =IF($B$34="","",IFERROR(F38/Roller!$K$13,0)) -> 1.3125 | G42: =IF($B$34="","",IFERROR(G38/Roller!$K$13,0)) -> 1.5
B43: Lønomkostning for virksomheden | C43: =IF($B$34="","",C40*(1+Roller!$C$7)) -> 785400 | D43: =IF($B$34="","",D40*(1+Roller!$C$7)) -> 854700 | E43: =IF($B$34="","",E40*(1+Roller!$C$7)) -> 924000 | F43: =IF($B$34="","",F40*(1+Roller!$C$7)) -> 1010625 | G43: =IF($B$34="","",G40*(1+Roller!$C$7)) -> 1062600
B44: Lønomkostning i % af salg | C44: =IF($B$34="","",IFERROR(C43/C36,0)) -> 0.24933333 | D44: =IF($B$34="","",IFERROR(D43/D36,0)) -> 0.18088889 | E44: =IF($B$34="","",IFERROR(E43/E36,0)) -> 0.14666667 | F44: =IF($B$34="","",IFERROR(F43/F36,0)) -> 0.12833333 | G44: =IF($B$34="","",IFERROR(G43/G36,0)) -> 0.11244444
B45: Team: lønomkostning (× antal sælgere) | C45: =IF($B$34="","",C43*N(Roller!$C$13)) -> 1570800 | D45: =IF($B$34="","",D43*N(Roller!$C$13)) -> 1709400 | E45: =IF($B$34="","",E43*N(Roller!$C$13)) -> 1848000 | F45: =IF($B$34="","",F43*N(Roller!$C$13)) -> 2021250 | G45: =IF($B$34="","",G43*N(Roller!$C$13)) -> 2125200
B47: =IF(Roller!$B$14="","",Roller!$B$14) -> Udesælger | C47: =IF($B47="","",C$5) -> 0.5 | D47: =IF($B47="","",D$5) -> 0.75 | E47: =IF($B47="","",E$5) -> 1 | F47: =IF($B47="","",F$5) -> 1.25 | G47: =IF($B47="","",G$5) -> 1.5
...

Sheet Overblik
J1: prowi.io
B2: OTE og pay mix
B3: =Roller!$C$6 -> Eksempel ApS
B5: Roller ved 100 % målopfyldelse
B6: Rolle | C6: Antal | D6: OTE | E6: Grundløn | F6: Variabel løn | G6: Pay mix (fast) | H6: Provisionssats | I6: Sats over kvote | J6: Kvote ÷ OTE
B7: =IF(Roller!$B$11="","",Roller!$B$11) -> Inside sales | C7: =IF($B7="","",Roller!$C$11) -> 4 | D7: =IF($B7="","",Roller!$D$11) -> 540000 | E7: =IF($B7="","",Roller!$I$11) -> 405000 | F7: =IF($B7="","",Roller!$K$11) -> 135000 | G7: =IF($B7="","",Roller!$E$11) -> 0.75 | H7: =IF($B7="","",Roller!$L$11) -> 0.05 | I7: =IF($B7="","",Roller!$M$11) -> 0.075 | J7: =IF($B7="","",Roller!$N$11) -> 5
B8: =IF(Roller!$B$12="","",Roller!$B$12) -> Account executive | C8: =IF($B8="","",Roller!$C$12) -> 5 | D8: =IF($B8="","",Roller!$D$12) -> 720000 | E8: =IF($B8="","",Roller!$I$12) -> 432000 | F8: =IF($B8="","",Roller!$K$12) -> 288000 | G8: =IF($B8="","",Roller!$E$12) -> 0.6 | H8: =IF($B8="","",Roller!$L$12) -> 0.08 | I8: =IF($B8="","",Roller!$M$12) -> 0.12 | J8: =IF($B8="","",Roller!$N$12) -> 5
B9: =IF(Roller!$B$13="","",Roller!$B$13) -> Key account manager | C9: =IF($B9="","",Roller!$C$13) -> 2 | D9: =IF($B9="","",Roller!$D$13) -> 840000 | E9: =IF($B9="","",Roller!$I$13) -> 588000 | F9: =IF($B9="","",Roller!$K$13) -> 252000 | G9: =IF($B9="","",Roller!$E$13) -> 0.7 | H9: =IF($B9="","",Roller!$L$13) -> 0.04 | I9: =IF($B9="","",Roller!$M$13) -> 0.05 | J9: =IF($B9="","",Roller!$N$13) -> 7.5
B10: =IF(Roller!$B$14="","",Roller!$B$14) -> Udesælger | C10: =IF($B10="","",Roller!$C$14) -> 3 | D10: =IF($B10="","",Roller!$D$14) -> 660000 | E10: =IF($B10="","",Roller!$I$14) -> 429000 | F10: =IF($B10="","",Roller!$K$14) -> 231000 | G10: =IF($B10="","",Roller!$E$14) -> 0.65 | H10: =IF($B10="","",Roller!$L$14) -> 0.07 | I10: =IF($B10="","",Roller!$M$14) -> 0.105 | J10: =IF($B10="","",Roller!$N$14) -> 5
B11: =IF(Roller!$B$15="","",Roller!$B$15) | C11: =IF($B11="","",Roller!$C$15) | D11: =IF($B11="","",Roller!$D$15) | E11: =IF($B11="","",Roller!$I$15) | F11: =IF($B11="","",Roller!$K$15) | G11: =IF($B11="","",Roller!$E$15) | H11: =IF($B11="","",Roller!$L$15) | I11: =IF($B11="","",Roller!$M$15) | J11: =IF($B11="","",Roller!$N$15)
B12: =IF(Roller!$B$16="","",Roller!$B$16) | C12: =IF($B12="","",Roller!$C$16) | D12: =IF($B12="","",Roller!$D$16) | E12: =IF($B12="","",Roller!$I$16) | F12: =IF($B12="","",Roller!$K$16) | G12: =IF($B12="","",Roller!$E$16) | H12: =IF($B12="","",Roller!$L$16) | I12: =IF($B12="","",Roller!$M$16) | J12: =IF($B12="","",Roller!$N$16)
B13: =IF(Roller!$B$17="","",Roller!$B$17) | C13: =IF($B13="","",Roller!$C$17) | D13: =IF($B13="","",Roller!$D$17) | E13: =IF($B13="","",Roller!$I$17) | F13: =IF($B13="","",Roller!$K$17) | G13: =IF($B13="","",Roller!$E$17) | H13: =IF($B13="","",Roller!$L$17) | I13: =IF($B13="","",Roller!$M$17) | J13: =IF($B13="","",Roller!$N$17)
B14: =IF(Roller!$B$18="","",Roller!$B$18) | C14: =IF($B14="","",Roller!$C$18) | D14: =IF($B14="","",Roller!$D$18) | E14: =IF($B14="","",Roller!$I$18) | F14: =IF($B14="","",Roller!$K$18) | G14: =IF($B14="","",Roller!$E$18) | H14: =IF($B14="","",Roller!$L$18) | I14: =IF($B14="","",Roller!$M$18) | J14: =IF($B14="","",Roller!$N$18)
B17: Hele teamet ved de fem niveauer
C18: Niveau 1 | D18: Niveau 2 | E18: Niveau 3 | F18: Niveau 4 | G18: Niveau 5
B19: Målopfyldelse | C19: =Udbetaling!C$5 -> 0.5 | D19: =Udbetaling!D$5 -> 0.75 | E19: =Udbetaling!E$5 -> 1 | F19: =Udbetaling!F$5 -> 1.25 | G19: =Udbetaling!G$5 -> 1.5
B20: Salg | C20: =N(Udbetaling!C10)*N(Roller!$C$11)+N(Udbetaling!C23)*N(Roller!$C$12)+N(Udbetaling!C36)*N(Roller!$C$13)+N(Udbetaling!C49)*N(Roller!$C$14)+N(Udbetaling!C62)*N(Roller!$C$15)+N(Udbetaling!C75)*N(Roller!$C$16)+N(Udbetaling!C88)*N(Roller!$C$17)+N(Udbetaling!C101)*N(Roller!$C$18) -> 25650000 | D20: =N(Udbetaling!D10)*N(Roller!$C$11)+N(Udbetaling!D23)*N(Roller!$C$12)+N(Udbetaling!D36)*N(Roller!$C$13)+N(Udbetaling!D49)*N(Roller!$C$14)+N(Udbetaling!D62)*N(Roller!$C$15)+N(Udbetaling!D75)*N(Roller!$C$16)+N(Udbetaling!D88)*N(Roller!$C$17)+N(Udbetaling!D101)*N(Roller!$C$18) -> 38475000 | E20: =N(Udbetaling!E10)*N(Roller!$C$11)+N(Udbetaling!E23)*N(Roller!$C$12)+N(Udbetaling!E36)*N(Roller!$C$13)+N(Udbetaling!E49)*N(Roller!$C$14)+N(Udbetaling!E62)*N(Roller!$C$15)+N(Udbetaling!E75)*N(Roller!$C$16)+N(Udbetaling!E88)*N(Roller!$C$17)+N(Udbetaling!E101)*N(Roller!$C$18) -> 51300000 | F20: =N(Udbetaling!F10)*N(Roller!$C$11)+N(Udbetaling!F23)*N(Roller!$C$12)+N(Udbetaling!F36)*N(Roller!$C$13)+N(Udbetaling!F49)*N(Roller!$C$14)+N(Udbetaling!F62)*N(Roller!$C$15)+N(Udbetaling!F75)*N(Roller!$C$16)+N(Udbetaling!F88)*N(Roller!$C$17)+N(Udbetaling!F101)*N(Roller!$C$18) -> 64125000 | G20: =N(Udbetaling!G10)*N(Roller!$C$11)+N(Udbetaling!G23)*N(Roller!$C$12)+N(Udbetaling!G36)*N(Roller!$C$13)+N(Udbetaling!G49)*N(Roller!$C$14)+N(Udbetaling!G62)*N(Roller!$C$15)+N(Udbetaling!G75)*N(Roller!$C$16)+N(Udbetaling!G88)*N(Roller!$C$17)+N(Udbetaling!G101)*N(Roller!$C$18) -> 76950000
B21: Grundløn | C21: =N(Roller!$I$11)*N(Roller!$C$11)+N(Roller!$I$12)*N(Roller!$C$12)+N(Roller!$I$13)*N(Roller!$C$13)+N(Roller!$I$14)*N(Roller!$C$14)+N(Roller!$I$15)*N(Roller!$C$15)+N(Roller!$I$16)*N(Roller!$C$16)+N(Roller!$I$17)*N(Roller!$C$17)+N(Roller!$I$18)*N(Roller!$C$18) -> 6243000 | D21: =N(Roller!$I$11)*N(Roller!$C$11)+N(Roller!$I$12)*N(Roller!$C$12)+N(Roller!$I$13)*N(Roller!$C$13)+N(Roller!$I$14)*N(Roller!$C$14)+N(Roller!$I$15)*N(Roller!$C$15)+N(Roller!$I$16)*N(Roller!$C$16)+N(Roller!$I$17)*N(Roller!$C$17)+N(Roller!$I$18)*N(Roller!$C$18) -> 6243000 | E21: =N(Roller!$I$11)*N(Roller!$C$11)+N(Roller!$I$12)*N(Roller!$C$12)+N(Roller!$I$13)*N(Roller!$C$13)+N(Roller!$I$14)*N(Roller!$C$14)+N(Roller!$I$15)*N(Roller!$C$15)+N(Roller!$I$16)*N(Roller!$C$16)+N(Roller!$I$17)*N(Roller!$C$17)+N(Roller!$I$18)*N(Roller!$C$18) -> 6243000 | F21: =N(Roller!$I$11)*N(Roller!$C$11)+N(Roller!$I$12)*N(Roller!$C$12)+N(Roller!$I$13)*N(Roller!$C$13)+N(Roller!$I$14)*N(Roller!$C$14)+N(Roller!$I$15)*N(Roller!$C$15)+N(Roller!$I$16)*N(Roller!$C$16)+N(Roller!$I$17)*N(Roller!$C$17)+N(Roller!$I$18)*N(Roller!$C$18) -> 6243000 | G21: =N(Roller!$I$11)*N(Roller!$C$11)+N(Roller!$I$12)*N(Roller!$C$12)+N(Roller!$I$13)*N(Roller!$C$13)+N(Roller!$I$14)*N(Roller!$C$14)+N(Roller!$I$15)*N(Roller!$C$15)+N(Roller!$I$16)*N(Roller!$C$16)+N(Roller!$I$17)*N(Roller!$C$17)+N(Roller!$I$18)*N(Roller!$C$18) -> 6243000
B22: Provision | C22: =N(Udbetaling!C12)*N(Roller!$C$11)+N(Udbetaling!C25)*N(Roller!$C$12)+N(Udbetaling!C38)*N(Roller!$C$13)+N(Udbetaling!C51)*N(Roller!$C$14)+N(Udbetaling!C64)*N(Roller!$C$15)+N(Udbetaling!C77)*N(Roller!$C$16)+N(Udbetaling!C90)*N(Roller!$C$17)+N(Udbetaling!C103)*N(Roller!$C$18) -> 1588500 | D22: =N(Udbetaling!D12)*N(Roller!$C$11)+N(Udbetaling!D25)*N(Roller!$C$12)+N(Udbetaling!D38)*N(Roller!$C$13)+N(Udbetaling!D51)*N(Roller!$C$14)+N(Udbetaling!D64)*N(Roller!$C$15)+N(Udbetaling!D77)*N(Roller!$C$16)+N(Udbetaling!D90)*N(Roller!$C$17)+N(Udbetaling!D103)*N(Roller!$C$18) -> 2382750 | E22: =N(Udbetaling!E12)*N(Roller!$C$11)+N(Udbetaling!E25)*N(Roller!$C$12)+N(Udbetaling!E38)*N(Roller!$C$13)+N(Udbetaling!E51)*N(Roller!$C$14)+N(Udbetaling!E64)*N(Roller!$C$15)+N(Udbetaling!E77)*N(Roller!$C$16)+N(Udbetaling!E90)*N(Roller!$C$17)+N(Udbetaling!E103)*N(Roller!$C$18) -> 3177000 | F22: =N(Udbetaling!F12)*N(Roller!$C$11)+N(Udbetaling!F25)*N(Roller!$C$12)+N(Udbetaling!F38)*N(Roller!$C$13)+N(Udbetaling!F51)*N(Roller!$C$14)+N(Udbetaling!F64)*N(Roller!$C$15)+N(Udbetaling!F77)*N(Roller!$C$16)+N(Udbetaling!F90)*N(Roller!$C$17)+N(Udbetaling!F103)*N(Roller!$C$18) -> 4336875 | G22: =N(Udbetaling!G12)*N(Roller!$C$11)+N(Udbetaling!G25)*N(Roller!$C$12)+N(Udbetaling!G38)*N(Roller!$C$13)+N(Udbetaling!G51)*N(Roller!$C$14)+N(Udbetaling!G64)*N(Roller!$C$15)+N(Udbetaling!G77)*N(Roller!$C$16)+N(Udbetaling!G90)*N(Roller!$C$17)+N(Udbetaling!G103)*N(Roller!$C$18) -> 5433750
B23: Heraf acceleratoreffekt | C23: =N(Udbetaling!C13)*N(Roller!$C$11)+N(Udbetaling!C26)*N(Roller!$C$12)+N(Udbetaling!C39)*N(Roller!$C$13)+N(Udbetaling!C52)*N(Roller!$C$14)+N(Udbetaling!C65)*N(Roller!$C$15)+N(Udbetaling!C78)*N(Roller!$C$16)+N(Udbetaling!C91)*N(Roller!$C$17)+N(Udbetaling!C104)*N(Roller!$C$18) -> 0 | D23: =N(Udbetaling!D13)*N(Roller!$C$11)+N(Udbetaling!D26)*N(Roller!$C$12)+N(Udbetaling!D39)*N(Roller!$C$13)+N(Udbetaling!D52)*N(Roller!$C$14)+N(Udbetaling!D65)*N(Roller!$C$15)+N(Udbetaling!D78)*N(Roller!$C$16)+N(Udbetaling!D91)*N(Roller!$C$17)+N(Udbetaling!D104)*N(Roller!$C$18) -> 0 | E23: =N(Udbetaling!E13)*N(Roller!$C$11)+N(Udbetaling!E26)*N(Roller!$C$12)+N(Udbetaling!E39)*N(Roller!$C$13)+N(Udbetaling!E52)*N(Roller!$C$14)+N(Udbetaling!E65)*N(Roller!$C$15)+N(Udbetaling!E78)*N(Roller!$C$16)+N(Udbetaling!E91)*N(Roller!$C$17)+N(Udbetaling!E104)*N(Roller!$C$18) -> 0 | F23: =N(Udbetaling!F13)*N(Roller!$C$11)+N(Udbetaling!F26)*N(Roller!$C$12)+N(Udbetaling!F39)*N(Roller!$C$13)+N(Udbetaling!F52)*N(Roller!$C$14)+N(Udbetaling!F65)*N(Roller!$C$15)+N(Udbetaling!F78)*N(Roller!$C$16)+N(Udbetaling!F91)*N(Roller!$C$17)+N(Udbetaling!F104)*N(Roller!$C$18) -> 365625 | G23: =N(Udbetaling!G13)*N(Roller!$C$11)+N(Udbetaling!G26)*N(Roller!$C$12)+N(Udbetaling!G39)*N(Roller!$C$13)+N(Udbetaling!G52)*N(Roller!$C$14)+N(Udbetaling!G65)*N(Roller!$C$15)+N(Udbetaling!G78)*N(Roller!$C$16)+N(Udbetaling!G91)*N(Roller!$C$17)+N(Udbetaling!G104)*N(Roller!$C$18) -> 668250
B24: Samlet løn | C24: =N(Udbetaling!C14)*N(Roller!$C$11)+N(Udbetaling!C27)*N(Roller!$C$12)+N(Udbetaling!C40)*N(Roller!$C$13)+N(Udbetaling!C53)*N(Roller!$C$14)+N(Udbetaling!C66)*N(Roller!$C$15)+N(Udbetaling!C79)*N(Roller!$C$16)+N(Udbetaling!C92)*N(Roller!$C$17)+N(Udbetaling!C105)*N(Roller!$C$18) -> 7831500 | D24: =N(Udbetaling!D14)*N(Roller!$C$11)+N(Udbetaling!D27)*N(Roller!$C$12)+N(Udbetaling!D40)*N(Roller!$C$13)+N(Udbetaling!D53)*N(Roller!$C$14)+N(Udbetaling!D66)*N(Roller!$C$15)+N(Udbetaling!D79)*N(Roller!$C$16)+N(Udbetaling!D92)*N(Roller!$C$17)+N(Udbetaling!D105)*N(Roller!$C$18) -> 8625750 | E24: =N(Udbetaling!E14)*N(Roller!$C$11)+N(Udbetaling!E27)*N(Roller!$C$12)+N(Udbetaling!E40)*N(Roller!$C$13)+N(Udbetaling!E53)*N(Roller!$C$14)+N(Udbetaling!E66)*N(Roller!$C$15)+N(Udbetaling!E79)*N(Roller!$C$16)+N(Udbetaling!E92)*N(Roller!$C$17)+N(Udbetaling!E105)*N(Roller!$C$18) -> 9420000 | F24: =N(Udbetaling!F14)*N(Roller!$C$11)+N(Udbetaling!F27)*N(Roller!$C$12)+N(Udbetaling!F40)*N(Roller!$C$13)+N(Udbetaling!F53)*N(Roller!$C$14)+N(Udbetaling!F66)*N(Roller!$C$15)+N(Udbetaling!F79)*N(Roller!$C$16)+N(Udbetaling!F92)*N(Roller!$C$17)+N(Udbetaling!F105)*N(Roller!$C$18) -> 10579875 | G24: =N(Udbetaling!G14)*N(Roller!$C$11)+N(Udbetaling!G27)*N(Roller!$C$12)+N(Udbetaling!G40)*N(Roller!$C$13)+N(Udbetaling!G53)*N(Roller!$C$14)+N(Udbetaling!G66)*N(Roller!$C$15)+N(Udbetaling!G79)*N(Roller!$C$16)+N(Udbetaling!G92)*N(Roller!$C$17)+N(Udbetaling!G105)*N(Roller!$C$18) -> 11676750
B25: Lønomkostning for virksomheden | C25: =N(Udbetaling!C17)*N(Roller!$C$11)+N(Udbetaling!C30)*N(Roller!$C$12)+N(Udbetaling!C43)*N(Roller!$C$13)+N(Udbetaling!C56)*N(Roller!$C$14)+N(Udbetaling!C69)*N(Roller!$C$15)+N(Udbetaling!C82)*N(Roller!$C$16)+N(Udbetaling!C95)*N(Roller!$C$17)+N(Udbetaling!C108)*N(Roller!$C$18) -> 8614650 | D25: =N(Udbetaling!D17)*N(Roller!$C$11)+N(Udbetaling!D30)*N(Roller!$C$12)+N(Udbetaling!D43)*N(Roller!$C$13)+N(Udbetaling!D56)*N(Roller!$C$14)+N(Udbetaling!D69)*N(Roller!$C$15)+N(Udbetaling!D82)*N(Roller!$C$16)+N(Udbetaling!D95)*N(Roller!$C$17)+N(Udbetaling!D108)*N(Roller!$C$18) -> 9488325 | E25: =N(Udbetaling!E17)*N(Roller!$C$11)+N(Udbetaling!E30)*N(Roller!$C$12)+N(Udbetaling!E43)*N(Roller!$C$13)+N(Udbetaling!E56)*N(Roller!$C$14)+N(Udbetaling!E69)*N(Roller!$C$15)+N(Udbetaling!E82)*N(Roller!$C$16)+N(Udbetaling!E95)*N(Roller!$C$17)+N(Udbetaling!E108)*N(Roller!$C$18) -> 10362000 | F25: =N(Udbetaling!F17)*N(Roller!$C$11)+N(Udbetaling!F30)*N(Roller!$C$12)+N(Udbetaling!F43)*N(Roller!$C$13)+N(Udbetaling!F56)*N(Roller!$C$14)+N(Udbetaling!F69)*N(Roller!$C$15)+N(Udbetaling!F82)*N(Roller!$C$16)+N(Udbetaling!F95)*N(Roller!$C$17)+N(Udbetaling!F108)*N(Roller!$C$18) -> 11637862 | G25: =N(Udbetaling!G17)*N(Roller!$C$11)+N(Udbetaling!G30)*N(Roller!$C$12)+N(Udbetaling!G43)*N(Roller!$C$13)+N(Udbetaling!G56)*N(Roller!$C$14)+N(Udbetaling!G69)*N(Roller!$C$15)+N(Udbetaling!G82)*N(Roller!$C$16)+N(Udbetaling!G95)*N(Roller!$C$17)+N(Udbetaling!G108)*N(Roller!$C$18) -> 12844425
B26: Lønomkostning i % af salg | C26: =IFERROR(C25/C20,0) -> 0.3358538 | D26: =IFERROR(D25/D20,0) -> 0.24661014 | E26: =IFERROR(E25/E20,0) -> 0.2019883 | F26: =IFERROR(F25/F20,0) -> 0.18148713 | G26: =IFERROR(G25/G20,0) -> 0.1669191
B27: Provision i % af salg | C27: =IFERROR(C22/C20,0) -> 0.061929825 | D27: =IFERROR(D22/D20,0) -> 0.061929825 | E27: =IFERROR(E22/E20,0) -> 0.061929825 | F27: =IFERROR(F22/F20,0) -> 0.067631579 | G27: =IFERROR(G22/G20,0) -> 0.070614035
B28: Alle sælgere i en rolle antages at nå samme målopfyldelse. Grundlønnen er den samme på alle niveauer.
B30: prowi.io · Gratis skabelon fra Prowi
