Workbook

Sheet Instructions
C2: Free template from Prowi
B4: Commission template
B5: How to use the workbook
B7: The workbook calculates commission per rep per month from your sales, and produces a payroll file and a statement you can give the rep. It contains example data for 3 reps and 20 deals, so you can see how it works before you enter your own numbers. Amounts are plain numbers in your currency; the example uses DKK.
B9: Step by step
B10: 1. Settings | C10: Pick the year and the payroll month. Enter the reps (up to 10) and choose model, basis, quota, rates and any cap for each. The pay code for the payroll file also goes here.
B11: 2. Sales | C11: One row per deal: date, rep, customer, deal ID, amount, gross margin (only needed if commission is paid on margin), status and clawback. The grey columns on the right are calculated.
B12: 3. Calculation | C12: Shows for each rep and month: sales, attainment, commission under the model, accelerator amount, cap, clawbacks and final commission. You do not type anything here.
B13: 4. Payroll | C13: One line per rep for the payroll month with pay code and amount. Enter it or import it into your payroll system.
B14: 5. Statement | C14: Pick a rep and a month in the lavender cells. The sheet is set up to print on one A4 page and can be sent to the rep as a PDF.
B15: 6. New month | C15: Add the month's deals in Sales, change the payroll month in Settings, check Calculation, and send the payroll file and statements. Save a copy of the file each month so you can document what was paid.
B17: Colours
B18: Lavender cell, purple text | C18: This is where you type. Everything else is formulas.
B19: Grey cell | C19: Calculated automatically. Leave the formulas alone unless you know what you are changing.
B20: Light blue cell | C20: Final commission and totals.
B22: How the workbook calculates
B23: Flat rate | C23: Commission = basis × rate. Example: 6% of revenue.
B24: Tiered | C24: Three tiers, calculated marginally: each unit of currency earns the rate of the tier it falls in. Tier 1 runs from 0 to limit 1, tier 2 from limit 1 to limit 2, and tier 3 is everything above limit 2. The limits apply per month.
B25: Accelerator | C25: A base rate up to the monthly quota and a higher accelerator rate on everything above quota. The accelerator amount is shown in its own column.
B26: Basis | C26: Choose per rep whether commission is paid on revenue (Amount) or gross margin. Quota and tier limits are entered in the same basis.
B27: Attainment | C27: Basis in the month divided by the monthly quota.
B28: Cap | C28: Maximum commission per month (before clawbacks). An empty cell means no cap.
B29: Status and clawback | C29: Won: the deal counts in the month it was sold. Cancelled + Clawback = No: the deal was cancelled before commission was paid and does not count. Cancelled + Clawback = Yes: commission was paid, so the deal stays in its original month, and the commission is deducted in the month given in Cancelled date.
B30: Clawback amount | C30: The basis of the cancelled deal × the rep's effective commission rate in the month the deal originally counted in. If the deal was from an earlier year, the rep's flat rate/base rate or tier 1 rate is used.
B31: Offsetting | C31: Clawbacks are only offset against later commission. If a clawback is larger than the month's commission, the rest carries to the next month, so commission never turns negative in the workbook.
B32: Effective rate | C32: Final commission before clawbacks divided by the basis. Used for clawbacks and to split commission per deal on the statement.
B34: Good to know
B35: • | C35: The workbook covers one calendar year and up to 10 reps and 300 deals. Use a new copy each year.
B36: • | C36: The calculation is a starting point. Check that it matches your commission agreement before you pay. Special rules for holiday, sickness, splits and draws are not included.
B37: • | C37: The pay code differs between payroll systems. Find it in your payroll system or ask your payroll provider.
B38: • | C38: No macros. Every calculation is an ordinary formula that works in Excel, Google Sheets, Numbers and LibreOffice.
B41: prowi.io · Free template from Prowi

Sheet Settings
B2: Settings
B4: Year | C4: 2026 | D4: The calendar year the workbook covers.
B5: Payroll month | C5: March | D5: The month the payroll file is made for. The statement uses the same month unless you pick another.
B6: Payroll month no. | C6: =MATCH(C5,Settings!$Q$12:$Q$23,0) -> 3 | D6: Calculated automatically.
B7: Pay code for commission | D7: The pay code comes from your payroll system (for example Danløn, Dataløn, Lessor or Zenegy). Enter it here and it appears in the payroll file.
B8: Company | C8: Example ApS | D8: Shown on the statement.
B10: Reps and commission model (one row per rep) | Q10: Lists (used by formulas and drop-downs)
B11: Rep | C11: Employee no. | D11: Model | E11: Basis | F11: Monthly quota | G11: Flat rate / base rate | H11: Tier 1 up to | I11: Tier 1 rate | J11: Tier 2 up to | K11: Tier 2 rate | L11: Tier 3 rate (above tier 2) | M11: Accelerator rate above quota | N11: Cap per month | Q11: Months | R11: Models | S11: Basis | T11: Status | U11: Yes/No
B12: Anna Holm | C12: 101 | D12: Flat rate | E12: Revenue | F12: 250000 | G12: 0.06 | Q12: January | R12: Flat rate | S12: Revenue | T12: Won | U12: Yes
B13: Bo Jensen | C13: 102 | D13: Tiered | E13: Revenue | F13: 300000 | H13: 150000 | I13: 0.04 | J13: 300000 | K13: 0.07 | L13: 0.1 | N13: 25000 | Q13: February | R13: Tiered | S13: Gross margin | T13: Cancelled | U13: No
B14: Camilla Nørgaard | C14: 103 | D14: Accelerator | E14: Gross margin | F14: 120000 | G14: 0.15 | M14: 0.25 | N14: 35000 | Q14: March | R14: Accelerator
Q15: April
Q16: May
Q17: June
Q18: July
Q19: August
Q20: September
Q21: October
Q22: November
B23: Which fields does each model use? | Q23: December
B24: Flat rate | C24: Flat rate / base rate. Quota is only used to show attainment.
B25: Tiered | C25: Tier 1 up to, tier 1 rate, tier 2 up to, tier 2 rate and tier 3 rate. The limits are per month, in the same basis as the commission.
B26: Accelerator | C26: Monthly quota, flat rate / base rate (up to quota) and accelerator rate (above quota).
B27: All models | C27: The cap is optional. Enter rates as percentages, for example 6%. Quota and limits are amounts.

Sheet Sales
A1: Sales: one row per deal
A2: Type in the lavender columns A-I. The grey columns J-O are calculated. Only fill in Cancelled date for a clawback (Status = Cancelled and Clawback = Yes).
A4: Date | B4: Rep | C4: Customer | D4: Deal ID | E4: Amount | F4: Gross margin | G4: Status | H4: Clawback | I4: Cancelled date | J4: Month | K4: Counts in sales | L4: Basis | M4: Clawback month | N4: Effective rate | O4: Clawback amount | P4: Stmt match | Q4: Stmt no. | R4: Stmt clawback match | S4: Stmt clawback no.
A5: 46028 | B5: Anna Holm | C5: Nordlys ApS | D5: D-1001 | E5: 85000 | F5: 34000 | G5: Won | H5: No | J5: =IF(OR($A5="",$B5=""),"",IF(YEAR($A5)=Settings!$C$4,MONTH($A5),"")) -> 1 | K5: =IF($A5="","",IF(OR($J5="",$B5=""),0,IF(OR($G5="Won",$H5="Yes"),1,0))) -> 1 | L5: =IF($B5="","",IFERROR(IF(INDEX(Settings!$E$12:$E$21,MATCH($B5,Settings!$B$12:$B$21,0))="Gross margin",N($F5),N($E5)),"")) -> 85000 | M5: =IF(AND($G5="Cancelled",$H5="Yes",$I5<>""),IF(YEAR($I5)=Settings!$C$4,MONTH($I5),""),"") | N5: =IF($M5="","",IFERROR(IF($J5="",IF(INDEX(Settings!$D$12:$D$21,MATCH($B5,Settings!$B$12:$B$21,0))="Tiered",INDEX(Settings!$I$12:$I$21,MATCH($B5,Settings!$B$12:$B$21,0)),INDEX(Settings!$G$12:$G$21,MATCH($B5,Settings!$B$12:$B$21,0))),INDEX(Calculation!$U$6:$U$125,(MATCH($B5,Settings!$B$12:$B$21,0)-1)*12+$J5)),0)) | O5: =IF($M5="",0,N($L5)*N($N5)) -> 0 | P5: =IF(AND($B5<>"",$B5=Statement!$C$6,$J5=Statement!$C$8,$K5=1),1,0) -> 0 | Q5: =IF($P5=1,SUM($P$5:$P5),"") | R5: =IF(AND($B5<>"",$B5=Statement!$C$6,$M5=Statement!$C$8),1,0) -> 0 | S5: =IF($R5=1,SUM($R$5:$R5),"")
A6: 46036 | B6: Bo Jensen | C6: Fjordtech A/S | D6: D-1002 | E6: 120000 | F6: 42000 | G6: Won | H6: No | J6: =IF(OR($A6="",$B6=""),"",IF(YEAR($A6)=Settings!$C$4,MONTH($A6),"")) -> 1 | K6: =IF($A6="","",IF(OR($J6="",$B6=""),0,IF(OR($G6="Won",$H6="Yes"),1,0))) -> 1 | L6: =IF($B6="","",IFERROR(IF(INDEX(Settings!$E$12:$E$21,MATCH($B6,Settings!$B$12:$B$21,0))="Gross margin",N($F6),N($E6)),"")) -> 120000 | M6: =IF(AND($G6="Cancelled",$H6="Yes",$I6<>""),IF(YEAR($I6)=Settings!$C$4,MONTH($I6),""),"") | N6: =IF($M6="","",IFERROR(IF($J6="",IF(INDEX(Settings!$D$12:$D$21,MATCH($B6,Settings!$B$12:$B$21,0))="Tiered",INDEX(Settings!$I$12:$I$21,MATCH($B6,Settings!$B$12:$B$21,0)),INDEX(Settings!$G$12:$G$21,MATCH($B6,Settings!$B$12:$B$21,0))),INDEX(Calculation!$U$6:$U$125,(MATCH($B6,Settings!$B$12:$B$21,0)-1)*12+$J6)),0)) | O6: =IF($M6="",0,N($L6)*N($N6)) -> 0 | P6: =IF(AND($B6<>"",$B6=Statement!$C$6,$J6=Statement!$C$8,$K6=1),1,0) -> 0 | Q6: =IF($P6=1,SUM($P$5:$P6),"") | R6: =IF(AND($B6<>"",$B6=Statement!$C$6,$M6=Statement!$C$8),1,0) -> 0 | S6: =IF($R6=1,SUM($R$5:$R6),"")
A7: 46042 | B7: Camilla Nørgaard | C7: Grønvang Engros | D7: D-1003 | E7: 210000 | F7: 63000 | G7: Won | H7: No | J7: =IF(OR($A7="",$B7=""),"",IF(YEAR($A7)=Settings!$C$4,MONTH($A7),"")) -> 1 | K7: =IF($A7="","",IF(OR($J7="",$B7=""),0,IF(OR($G7="Won",$H7="Yes"),1,0))) -> 1 | L7: =IF($B7="","",IFERROR(IF(INDEX(Settings!$E$12:$E$21,MATCH($B7,Settings!$B$12:$B$21,0))="Gross margin",N($F7),N($E7)),"")) -> 63000 | M7: =IF(AND($G7="Cancelled",$H7="Yes",$I7<>""),IF(YEAR($I7)=Settings!$C$4,MONTH($I7),""),"") | N7: =IF($M7="","",IFERROR(IF($J7="",IF(INDEX(Settings!$D$12:$D$21,MATCH($B7,Settings!$B$12:$B$21,0))="Tiered",INDEX(Settings!$I$12:$I$21,MATCH($B7,Settings!$B$12:$B$21,0)),INDEX(Settings!$G$12:$G$21,MATCH($B7,Settings!$B$12:$B$21,0))),INDEX(Calculation!$U$6:$U$125,(MATCH($B7,Settings!$B$12:$B$21,0)-1)*12+$J7)),0)) | O7: =IF($M7="",0,N($L7)*N($N7)) -> 0 | P7: =IF(AND($B7<>"",$B7=Statement!$C$6,$J7=Statement!$C$8,$K7=1),1,0) -> 0 | Q7: =IF($P7=1,SUM($P$5:$P7),"") | R7: =IF(AND($B7<>"",$B7=Statement!$C$6,$M7=Statement!$C$8),1,0) -> 0 | S7: =IF($R7=1,SUM($R$5:$R7),"")
A8: 46044 | B8: Anna Holm | C8: Kystlinjen ApS | D8: D-1004 | E8: 60000 | F8: 21000 | G8: Cancelled | H8: Yes | I8: 46093 | J8: =IF(OR($A8="",$B8=""),"",IF(YEAR($A8)=Settings!$C$4,MONTH($A8),"")) -> 1 | K8: =IF($A8="","",IF(OR($J8="",$B8=""),0,IF(OR($G8="Won",$H8="Yes"),1,0))) -> 1 | L8: =IF($B8="","",IFERROR(IF(INDEX(Settings!$E$12:$E$21,MATCH($B8,Settings!$B$12:$B$21,0))="Gross margin",N($F8),N($E8)),"")) -> 60000 | M8: =IF(AND($G8="Cancelled",$H8="Yes",$I8<>""),IF(YEAR($I8)=Settings!$C$4,MONTH($I8),""),"") -> 3 | N8: =IF($M8="","",IFERROR(IF($J8="",IF(INDEX(Settings!$D$12:$D$21,MATCH($B8,Settings!$B$12:$B$21,0))="Tiered",INDEX(Settings!$I$12:$I$21,MATCH($B8,Settings!$B$12:$B$21,0)),INDEX(Settings!$G$12:$G$21,MATCH($B8,Settings!$B$12:$B$21,0))),INDEX(Calculation!$U$6:$U$125,(MATCH($B8,Settings!$B$12:$B$21,0)-1)*12+$J8)),0)) -> 0.06 | O8: =IF($M8="",0,N($L8)*N($N8)) -> 3600 | P8: =IF(AND($B8<>"",$B8=Statement!$C$6,$J8=Statement!$C$8,$K8=1),1,0) -> 0 | Q8: =IF($P8=1,SUM($P$5:$P8),"") | R8: =IF(AND($B8<>"",$B8=Statement!$C$6,$M8=Statement!$C$8),1,0) -> 1 | S8: =IF($R8=1,SUM($R$5:$R8),"") -> 1
A9: 46050 | B9: Bo Jensen | C9: Hede Logistik ApS | D9: D-1005 | E9: 95000 | F9: 30400 | G9: Won | H9: No | J9: =IF(OR($A9="",$B9=""),"",IF(YEAR($A9)=Settings!$C$4,MONTH($A9),"")) -> 1 | K9: =IF($A9="","",IF(OR($J9="",$B9=""),0,IF(OR($G9="Won",$H9="Yes"),1,0))) -> 1 | L9: =IF($B9="","",IFERROR(IF(INDEX(Settings!$E$12:$E$21,MATCH($B9,Settings!$B$12:$B$21,0))="Gross margin",N($F9),N($E9)),"")) -> 95000 | M9: =IF(AND($G9="Cancelled",$H9="Yes",$I9<>""),IF(YEAR($I9)=Settings!$C$4,MONTH($I9),""),"") | N9: =IF($M9="","",IFERROR(IF($J9="",IF(INDEX(Settings!$D$12:$D$21,MATCH($B9,Settings!$B$12:$B$21,0))="Tiered",INDEX(Settings!$I$12:$I$21,MATCH($B9,Settings!$B$12:$B$21,0)),INDEX(Settings!$G$12:$G$21,MATCH($B9,Settings!$B$12:$B$21,0))),INDEX(Calculation!$U$6:$U$125,(MATCH($B9,Settings!$B$12:$B$21,0)-1)*12+$J9)),0)) | O9: =IF($M9="",0,N($L9)*N($N9)) -> 0 | P9: =IF(AND($B9<>"",$B9=Statement!$C$6,$J9=Statement!$C$8,$K9=1),1,0) -> 0 | Q9: =IF($P9=1,SUM($P$5:$P9),"") | R9: =IF(AND($B9<>"",$B9=Statement!$C$6,$M9=Statement!$C$8),1,0) -> 0 | S9: =IF($R9=1,SUM($R$5:$R9),"")
A10: 46052 | B10: Camilla Nørgaard | C10: Bakke & Søn A/S | D10: D-1006 | E10: 90000 | F10: 31500 | G10: Won | H10: No | J10: =IF(OR($A10="",$B10=""),"",IF(YEAR($A10)=Settings!$C$4,MONTH($A10),"")) -> 1 | K10: =IF($A10="","",IF(OR($J10="",$B10=""),0,IF(OR($G10="Won",$H10="Yes"),1,0))) -> 1 | L10: =IF($B10="","",IFERROR(IF(INDEX(Settings!$E$12:$E$21,MATCH($B10,Settings!$B$12:$B$21,0))="Gross margin",N($F10),N($E10)),"")) -> 31500 | M10: =IF(AND($G10="Cancelled",$H10="Yes",$I10<>""),IF(YEAR($I10)=Settings!$C$4,MONTH($I10),""),"") | N10: =IF($M10="","",IFERROR(IF($J10="",IF(INDEX(Settings!$D$12:$D$21,MATCH($B10,Settings!$B$12:$B$21,0))="Tiered",INDEX(Settings!$I$12:$I$21,MATCH($B10,Settings!$B$12:$B$21,0)),INDEX(Settings!$G$12:$G$21,MATCH($B10,Settings!$B$12:$B$21,0))),INDEX(Calculation!$U$6:$U$125,(MATCH($B10,Settings!$B$12:$B$21,0)-1)*12+$J10)),0)) | O10: =IF($M10="",0,N($L10)*N($N10)) -> 0 | P10: =IF(AND($B10<>"",$B10=Statement!$C$6,$J10=Statement!$C$8,$K10=1),1,0) -> 0 | Q10: =IF($P10=1,SUM($P$5:$P10),"") | R10: =IF(AND($B10<>"",$B10=Statement!$C$6,$M10=Statement!$C$8),1,0) -> 0 | S10: =IF($R10=1,SUM($R$5:$R10),"")
A11: 46057 | B11: Anna Holm | C11: Søndergaard Revision | D11: D-1007 | E11: 110000 | F11: 49500 | G11: Won | H11: No | J11: =IF(OR($A11="",$B11=""),"",IF(YEAR($A11)=Settings!$C$4,MONTH($A11),"")) -> 2 | K11: =IF($A11="","",IF(OR($J11="",$B11=""),0,IF(OR($G11="Won",$H11="Yes"),1,0))) -> 1 | L11: =IF($B11="","",IFERROR(IF(INDEX(Settings!$E$12:$E$21,MATCH($B11,Settings!$B$12:$B$21,0))="Gross margin",N($F11),N($E11)),"")) -> 110000 | M11: =IF(AND($G11="Cancelled",$H11="Yes",$I11<>""),IF(YEAR($I11)=Settings!$C$4,MONTH($I11),""),"") | N11: =IF($M11="","",IFERROR(IF($J11="",IF(INDEX(Settings!$D$12:$D$21,MATCH($B11,Settings!$B$12:$B$21,0))="Tiered",INDEX(Settings!$I$12:$I$21,MATCH($B11,Settings!$B$12:$B$21,0)),INDEX(Settings!$G$12:$G$21,MATCH($B11,Settings!$B$12:$B$21,0))),INDEX(Calculation!$U$6:$U$125,(MATCH($B11,Settings!$B$12:$B$21,0)-1)*12+$J11)),0)) | O11: =IF($M11="",0,N($L11)*N($N11)) -> 0 | P11: =IF(AND($B11<>"",$B11=Statement!$C$6,$J11=Statement!$C$8,$K11=1),1,0) -> 0 | Q11: =IF($P11=1,SUM($P$5:$P11),"") | R11: =IF(AND($B11<>"",$B11=Statement!$C$6,$M11=Statement!$C$8),1,0) -> 0 | S11: =IF($R11=1,SUM($R$5:$R11),"")
A12: 46064 | B12: Bo Jensen | C12: Vestkyst Byg A/S | D12: D-1008 | E12: 175000 | F12: 52500 | G12: Won | H12: No | J12: =IF(OR($A12="",$B12=""),"",IF(YEAR($A12)=Settings!$C$4,MONTH($A12),"")) -> 2 | K12: =IF($A12="","",IF(OR($J12="",$B12=""),0,IF(OR($G12="Won",$H12="Yes"),1,0))) -> 1 | L12: =IF($B12="","",IFERROR(IF(INDEX(Settings!$E$12:$E$21,MATCH($B12,Settings!$B$12:$B$21,0))="Gross margin",N($F12),N($E12)),"")) -> 175000 | M12: =IF(AND($G12="Cancelled",$H12="Yes",$I12<>""),IF(YEAR($I12)=Settings!$C$4,MONTH($I12),""),"") | N12: =IF($M12="","",IFERROR(IF($J12="",IF(INDEX(Settings!$D$12:$D$21,MATCH($B12,Settings!$B$12:$B$21,0))="Tiered",INDEX(Settings!$I$12:$I$21,MATCH($B12,Settings!$B$12:$B$21,0)),INDEX(Settings!$G$12:$G$21,MATCH($B12,Settings!$B$12:$B$21,0))),INDEX(Calculation!$U$6:$U$125,(MATCH($B12,Settings!$B$12:$B$21,0)-1)*12+$J12)),0)) | O12: =IF($M12="",0,N($L12)*N($N12)) -> 0 | P12: =IF(AND($B12<>"",$B12=Statement!$C$6,$J12=Statement!$C$8,$K12=1),1,0) -> 0 | Q12: =IF($P12=1,SUM($P$5:$P12),"") | R12: =IF(AND($B12<>"",$B12=Statement!$C$6,$M12=Statement!$C$8),1,0) -> 0 | S12: =IF($R12=1,SUM($R$5:$R12),"")
A13: 46070 | B13: Camilla Nørgaard | C13: Lindholm Foods ApS | D13: D-1009 | E13: 260000 | F13: 78000 | G13: Won | H13: No | J13: =IF(OR($A13="",$B13=""),"",IF(YEAR($A13)=Settings!$C$4,MONTH($A13),"")) -> 2 | K13: =IF($A13="","",IF(OR($J13="",$B13=""),0,IF(OR($G13="Won",$H13="Yes"),1,0))) -> 1 | L13: =IF($B13="","",IFERROR(IF(INDEX(Settings!$E$12:$E$21,MATCH($B13,Settings!$B$12:$B$21,0))="Gross margin",N($F13),N($E13)),"")) -> 78000 | M13: =IF(AND($G13="Cancelled",$H13="Yes",$I13<>""),IF(YEAR($I13)=Settings!$C$4,MONTH($I13),""),"") | N13: =IF($M13="","",IFERROR(IF($J13="",IF(INDEX(Settings!$D$12:$D$21,MATCH($B13,Settings!$B$12:$B$21,0))="Tiered",INDEX(Settings!$I$12:$I$21,MATCH($B13,Settings!$B$12:$B$21,0)),INDEX(Settings!$G$12:$G$21,MATCH($B13,Settings!$B$12:$B$21,0))),INDEX(Calculation!$U$6:$U$125,(MATCH($B13,Settings!$B$12:$B$21,0)-1)*12+$J13)),0)) | O13: =IF($M13="",0,N($L13)*N($N13)) -> 0 | P13: =IF(AND($B13<>"",$B13=Statement!$C$6,$J13=Statement!$C$8,$K13=1),1,0) -> 0 | Q13: =IF($P13=1,SUM($P$5:$P13),"") | R13: =IF(AND($B13<>"",$B13=Statement!$C$6,$M13=Statement!$C$8),1,0) -> 0 | S13: =IF($R13=1,SUM($R$5:$R13),"")
A14: 46072 | B14: Anna Holm | C14: Østergade Optik | D14: D-1010 | E14: 45000 | F14: 18000 | G14: Won | H14: No | J14: =IF(OR($A14="",$B14=""),"",IF(YEAR($A14)=Settings!$C$4,MONTH($A14),"")) -> 2 | K14: =IF($A14="","",IF(OR($J14="",$B14=""),0,IF(OR($G14="Won",$H14="Yes"),1,0))) -> 1 | L14: =IF($B14="","",IFERROR(IF(INDEX(Settings!$E$12:$E$21,MATCH($B14,Settings!$B$12:$B$21,0))="Gross margin",N($F14),N($E14)),"")) -> 45000 | M14: =IF(AND($G14="Cancelled",$H14="Yes",$I14<>""),IF(YEAR($I14)=Settings!$C$4,MONTH($I14),""),"") | N14: =IF($M14="","",IFERROR(IF($J14="",IF(INDEX(Settings!$D$12:$D$21,MATCH($B14,Settings!$B$12:$B$21,0))="Tiered",INDEX(Settings!$I$12:$I$21,MATCH($B14,Settings!$B$12:$B$21,0)),INDEX(Settings!$G$12:$G$21,MATCH($B14,Settings!$B$12:$B$21,0))),INDEX(Calculation!$U$6:$U$125,(MATCH($B14,Settings!$B$12:$B$21,0)-1)*12+$J14)),0)) | O14: =IF($M14="",0,N($L14)*N($N14)) -> 0 | P14: =IF(AND($B14<>"",$B14=Statement!$C$6,$J14=Statement!$C$8,$K14=1),1,0) -> 0 | Q14: =IF($P14=1,SUM($P$5:$P14),"") | R14: =IF(AND($B14<>"",$B14=Statement!$C$6,$M14=Statement!$C$8),1,0) -> 0 | S14: =IF($R14=1,SUM($R$5:$R14),"")
A15: 46077 | B15: Bo Jensen | C15: Mølleparken Ejendomme | D15: D-1011 | E15: 140000 | F15: 46200 | G15: Won | H15: No | J15: =IF(OR($A15="",$B15=""),"",IF(YEAR($A15)=Settings!$C$4,MONTH($A15),"")) -> 2 | K15: =IF($A15="","",IF(OR($J15="",$B15=""),0,IF(OR($G15="Won",$H15="Yes"),1,0))) -> 1 | L15: =IF($B15="","",IFERROR(IF(INDEX(Settings!$E$12:$E$21,MATCH($B15,Settings!$B$12:$B$21,0))="Gross margin",N($F15),N($E15)),"")) -> 140000 | M15: =IF(AND($G15="Cancelled",$H15="Yes",$I15<>""),IF(YEAR($I15)=Settings!$C$4,MONTH($I15),""),"") | N15: =IF($M15="","",IFERROR(IF($J15="",IF(INDEX(Settings!$D$12:$D$21,MATCH($B15,Settings!$B$12:$B$21,0))="Tiered",INDEX(Settings!$I$12:$I$21,MATCH($B15,Settings!$B$12:$B$21,0)),INDEX(Settings!$G$12:$G$21,MATCH($B15,Settings!$B$12:$B$21,0))),INDEX(Calculation!$U$6:$U$125,(MATCH($B15,Settings!$B$12:$B$21,0)-1)*12+$J15)),0)) | O15: =IF($M15="",0,N($L15)*N($N15)) -> 0 | P15: =IF(AND($B15<>"",$B15=Statement!$C$6,$J15=Statement!$C$8,$K15=1),1,0) -> 0 | Q15: =IF($P15=1,SUM($P$5:$P15),"") | R15: =IF(AND($B15<>"",$B15=Statement!$C$6,$M15=Statement!$C$8),1,0) -> 0 | S15: =IF($R15=1,SUM($R$5:$R15),"")
A16: 46079 | B16: Camilla Nørgaard | C16: Havnens Fisk ApS | D16: D-1012 | E16: 70000 | F16: 22400 | G16: Won | H16: No | J16: =IF(OR($A16="",$B16=""),"",IF(YEAR($A16)=Settings!$C$4,MONTH($A16),"")) -> 2 | K16: =IF($A16="","",IF(OR($J16="",$B16=""),0,IF(OR($G16="Won",$H16="Yes"),1,0))) -> 1 | L16: =IF($B16="","",IFERROR(IF(INDEX(Settings!$E$12:$E$21,MATCH($B16,Settings!$B$12:$B$21,0))="Gross margin",N($F16),N($E16)),"")) -> 22400 | M16: =IF(AND($G16="Cancelled",$H16="Yes",$I16<>""),IF(YEAR($I16)=Settings!$C$4,MONTH($I16),""),"") | N16: =IF($M16="","",IFERROR(IF($J16="",IF(INDEX(Settings!$D$12:$D$21,MATCH($B16,Settings!$B$12:$B$21,0))="Tiered",INDEX(Settings!$I$12:$I$21,MATCH($B16,Settings!$B$12:$B$21,0)),INDEX(Settings!$G$12:$G$21,MATCH($B16,Settings!$B$12:$B$21,0))),INDEX(Calculation!$U$6:$U$125,(MATCH($B16,Settings!$B$12:$B$21,0)-1)*12+$J16)),0)) | O16: =IF($M16="",0,N($L16)*N($N16)) -> 0 | P16: =IF(AND($B16<>"",$B16=Statement!$C$6,$J16=Statement!$C$8,$K16=1),1,0) -> 0 | Q16: =IF($P16=1,SUM($P$5:$P16),"") | R16: =IF(AND($B16<>"",$B16=Statement!$C$6,$M16=Statement!$C$8),1,0) -> 0 | S16: =IF($R16=1,SUM($R$5:$R16),"")
A17: 46084 | B17: Anna Holm | C17: Birkely Tandklinik | D17: D-1013 | E17: 130000 | F17: 58500 | G17: Won | H17: No | J17: =IF(OR($A17="",$B17=""),"",IF(YEAR($A17)=Settings!$C$4,MONTH($A17),"")) -> 3 | K17: =IF($A17="","",IF(OR($J17="",$B17=""),0,IF(OR($G17="Won",$H17="Yes"),1,0))) -> 1 | L17: =IF($B17="","",IFERROR(IF(INDEX(Settings!$E$12:$E$21,MATCH($B17,Settings!$B$12:$B$21,0))="Gross margin",N($F17),N($E17)),"")) -> 130000 | M17: =IF(AND($G17="Cancelled",$H17="Yes",$I17<>""),IF(YEAR($I17)=Settings!$C$4,MONTH($I17),""),"") | N17: =IF($M17="","",IFERROR(IF($J17="",IF(INDEX(Settings!$D$12:$D$21,MATCH($B17,Settings!$B$12:$B$21,0))="Tiered",INDEX(Settings!$I$12:$I$21,MATCH($B17,Settings!$B$12:$B$21,0)),INDEX(Settings!$G$12:$G$21,MATCH($B17,Settings!$B$12:$B$21,0))),INDEX(Calculation!$U$6:$U$125,(MATCH($B17,Settings!$B$12:$B$21,0)-1)*12+$J17)),0)) | O17: =IF($M17="",0,N($L17)*N($N17)) -> 0 | P17: =IF(AND($B17<>"",$B17=Statement!$C$6,$J17=Statement!$C$8,$K17=1),1,0) -> 1 | Q17: =IF($P17=1,SUM($P$5:$P17),"") -> 1 | R17: =IF(AND($B17<>"",$B17=Statement!$C$6,$M17=Statement!$C$8),1,0) -> 0 | S17: =IF($R17=1,SUM($R$5:$R17),"")
A18: 46090 | B18: Bo Jensen | C18: Skovgaard Maskiner A/S | D18: D-1014 | E18: 230000 | F18: 69000 | G18: Won | H18: No | J18: =IF(OR($A18="",$B18=""),"",IF(YEAR($A18)=Settings!$C$4,MONTH($A18),"")) -> 3 | K18: =IF($A18="","",IF(OR($J18="",$B18=""),0,IF(OR($G18="Won",$H18="Yes"),1,0))) -> 1 | L18: =IF($B18="","",IFERROR(IF(INDEX(Settings!$E$12:$E$21,MATCH($B18,Settings!$B$12:$B$21,0))="Gross margin",N($F18),N($E18)),"")) -> 230000 | M18: =IF(AND($G18="Cancelled",$H18="Yes",$I18<>""),IF(YEAR($I18)=Settings!$C$4,MONTH($I18),""),"") | N18: =IF($M18="","",IFERROR(IF($J18="",IF(INDEX(Settings!$D$12:$D$21,MATCH($B18,Settings!$B$12:$B$21,0))="Tiered",INDEX(Settings!$I$12:$I$21,MATCH($B18,Settings!$B$12:$B$21,0)),INDEX(Settings!$G$12:$G$21,MATCH($B18,Settings!$B$12:$B$21,0))),INDEX(Calculation!$U$6:$U$125,(MATCH($B18,Settings!$B$12:$B$21,0)-1)*12+$J18)),0)) | O18: =IF($M18="",0,N($L18)*N($N18)) -> 0 | P18: =IF(AND($B18<>"",$B18=Statement!$C$6,$J18=Statement!$C$8,$K18=1),1,0) -> 0 | Q18: =IF($P18=1,SUM($P$5:$P18),"") | R18: =IF(AND($B18<>"",$B18=Statement!$C$6,$M18=Statement!$C$8),1,0) -> 0 | S18: =IF($R18=1,SUM($R$5:$R18),"")
A19: 46093 | B19: Camilla Nørgaard | C19: Nordhavn Kaffe | D19: D-1015 | E19: 180000 | F19: 61200 | G19: Won | H19: No | J19: =IF(OR($A19="",$B19=""),"",IF(YEAR($A19)=Settings!$C$4,MONTH($A19),"")) -> 3 | K19: =IF($A19="","",IF(OR($J19="",$B19=""),0,IF(OR($G19="Won",$H19="Yes"),1,0))) -> 1 | L19: =IF($B19="","",IFERROR(IF(INDEX(Settings!$E$12:$E$21,MATCH($B19,Settings!$B$12:$B$21,0))="Gross margin",N($F19),N($E19)),"")) -> 61200 | M19: =IF(AND($G19="Cancelled",$H19="Yes",$I19<>""),IF(YEAR($I19)=Settings!$C$4,MONTH($I19),""),"") | N19: =IF($M19="","",IFERROR(IF($J19="",IF(INDEX(Settings!$D$12:$D$21,MATCH($B19,Settings!$B$12:$B$21,0))="Tiered",INDEX(Settings!$I$12:$I$21,MATCH($B19,Settings!$B$12:$B$21,0)),INDEX(Settings!$G$12:$G$21,MATCH($B19,Settings!$B$12:$B$21,0))),INDEX(Calculation!$U$6:$U$125,(MATCH($B19,Settings!$B$12:$B$21,0)-1)*12+$J19)),0)) | O19: =IF($M19="",0,N($L19)*N($N19)) -> 0 | P19: =IF(AND($B19<>"",$B19=Statement!$C$6,$J19=Statement!$C$8,$K19=1),1,0) -> 0 | Q19: =IF($P19=1,SUM($P$5:$P19),"") | R19: =IF(AND($B19<>"",$B19=Statement!$C$6,$M19=Statement!$C$8),1,0) -> 0 | S19: =IF($R19=1,SUM($R$5:$R19),"")
A20: 46097 | B20: Anna Holm | C20: Rosenhøj Boliger | D20: D-1016 | E20: 75000 | F20: 30000 | G20: Cancelled | H20: No | J20: =IF(OR($A20="",$B20=""),"",IF(YEAR($A20)=Settings!$C$4,MONTH($A20),"")) -> 3 | K20: =IF($A20="","",IF(OR($J20="",$B20=""),0,IF(OR($G20="Won",$H20="Yes"),1,0))) -> 0 | L20: =IF($B20="","",IFERROR(IF(INDEX(Settings!$E$12:$E$21,MATCH($B20,Settings!$B$12:$B$21,0))="Gross margin",N($F20),N($E20)),"")) -> 75000 | M20: =IF(AND($G20="Cancelled",$H20="Yes",$I20<>""),IF(YEAR($I20)=Settings!$C$4,MONTH($I20),""),"") | N20: =IF($M20="","",IFERROR(IF($J20="",IF(INDEX(Settings!$D$12:$D$21,MATCH($B20,Settings!$B$12:$B$21,0))="Tiered",INDEX(Settings!$I$12:$I$21,MATCH($B20,Settings!$B$12:$B$21,0)),INDEX(Settings!$G$12:$G$21,MATCH($B20,Settings!$B$12:$B$21,0))),INDEX(Calculation!$U$6:$U$125,(MATCH($B20,Settings!$B$12:$B$21,0)-1)*12+$J20)),0)) | O20: =IF($M20="",0,N($L20)*N($N20)) -> 0 | P20: =IF(AND($B20<>"",$B20=Statement!$C$6,$J20=Statement!$C$8,$K20=1),1,0) -> 0 | Q20: =IF($P20=1,SUM($P$5:$P20),"") | R20: =IF(AND($B20<>"",$B20=Statement!$C$6,$M20=Statement!$C$8),1,0) -> 0 | S20: =IF($R20=1,SUM($R$5:$R20),"")
... A24: 46111 | B24: Camilla Nørgaard | C24: Dalgaard Transport | D24: D-1020 | E24: 120000 | F24: 48400 | G24: Won | H24: No | J24: =IF(OR($A24="",$B24=""),"",IF(YEAR($A24)=Settings!$C$4,MONTH($A24),"")) -> 3 | K24: =IF($A24="","",IF(OR($J24="",$B24=""),0,IF(OR($G24="Won",$H24="Yes"),1,0))) -> 1 | L24: =IF($B24="","",IFERROR(IF(INDEX(Settings!$E$12:$E$21,MATCH($B24,Settings!$B$12:$B$21,0))="Gross margin",N($F24),N($E24)),"")) -> 48400 | M24: =IF(AND($G24="Cancelled",$H24="Yes",$I24<>""),IF(YEAR($I24)=Settings!$C$4,MONTH($I24),""),"") | N24: =IF($M24="","",IFERROR(IF($J24="",IF(INDEX(Settings!$D$12:$D$21,MATCH($B24,Settings!$B$12:$B$21,0))="Tiered",INDEX(Settings!$I$12:$I$21,MATCH($B24,Settings!$B$12:$B$21,0)),INDEX(Settings!$G$12:$G$21,MATCH($B24,Settings!$B$12:$B$21,0))),INDEX(Calculation!$U$6:$U$125,(MATCH($B24,Settings!$B$12:$B$21,0)-1)*12+$J24)),0)) | O24: =IF($M24="",0,N($L24)*N($N24)) -> 0 | P24: =IF(AND($B24<>"",$B24=Statement!$C$6,$J24=Statement!$C$8,$K24=1),1,0) -> 0 | Q24: =IF($P24=1,SUM($P$5:$P24),"") | R24: =IF(AND($B24<>"",$B24=Statement!$C$6,$M24=Statement!$C$8),1,0) -> 0 | S24: =IF($R24=1,SUM($R$5:$R24),"")
J25: =IF(OR($A25="",$B25=""),"",IF(YEAR($A25)=Settings!$C$4,MONTH($A25),"")) | K25: =IF($A25="","",IF(OR($J25="",$B25=""),0,IF(OR($G25="Won",$H25="Yes"),1,0))) | L25: =IF($B25="","",IFERROR(IF(INDEX(Settings!$E$12:$E$21,MATCH($B25,Settings!$B$12:$B$21,0))="Gross margin",N($F25),N($E25)),"")) | M25: =IF(AND($G25="Cancelled",$H25="Yes",$I25<>""),IF(YEAR($I25)=Settings!$C$4,MONTH($I25),""),"") | N25: =IF($M25="","",IFERROR(IF($J25="",IF(INDEX(Settings!$D$12:$D$21,MATCH($B25,Settings!$B$12:$B$21,0))="Tiered",INDEX(Settings!$I$12:$I$21,MATCH($B25,Settings!$B$12:$B$21,0)),INDEX(Settings!$G$12:$G$21,MATCH($B25,Settings!$B$12:$B$21,0))),INDEX(Calculation!$U$6:$U$125,(MATCH($B25,Settings!$B$12:$B$21,0)-1)*12+$J25)),0)) | O25: =IF($M25="",0,N($L25)*N($N25)) -> 0 | P25: =IF(AND($B25<>"",$B25=Statement!$C$6,$J25=Statement!$C$8,$K25=1),1,0) -> 0 | Q25: =IF($P25=1,SUM($P$5:$P25),"") | R25: =IF(AND($B25<>"",$B25=Statement!$C$6,$M25=Statement!$C$8),1,0) -> 0 | S25: =IF($R25=1,SUM($R$5:$R25),"")
J26: =IF(OR($A26="",$B26=""),"",IF(YEAR($A26)=Settings!$C$4,MONTH($A26),"")) | K26: =IF($A26="","",IF(OR($J26="",$B26=""),0,IF(OR($G26="Won",$H26="Yes"),1,0))) | L26: =IF($B26="","",IFERROR(IF(INDEX(Settings!$E$12:$E$21,MATCH($B26,Settings!$B$12:$B$21,0))="Gross margin",N($F26),N($E26)),"")) | M26: =IF(AND($G26="Cancelled",$H26="Yes",$I26<>""),IF(YEAR($I26)=Settings!$C$4,MONTH($I26),""),"") | N26: =IF($M26="","",IFERROR(IF($J26="",IF(INDEX(Settings!$D$12:$D$21,MATCH($B26,Settings!$B$12:$B$21,0))="Tiered",INDEX(Settings!$I$12:$I$21,MATCH($B26,Settings!$B$12:$B$21,0)),INDEX(Settings!$G$12:$G$21,MATCH($B26,Settings!$B$12:$B$21,0))),INDEX(Calculation!$U$6:$U$125,(MATCH($B26,Settings!$B$12:$B$21,0)-1)*12+$J26)),0)) | O26: =IF($M26="",0,N($L26)*N($N26)) -> 0 | P26: =IF(AND($B26<>"",$B26=Statement!$C$6,$J26=Statement!$C$8,$K26=1),1,0) -> 0 | Q26: =IF($P26=1,SUM($P$5:$P26),"") | R26: =IF(AND($B26<>"",$B26=Statement!$C$6,$M26=Statement!$C$8),1,0) -> 0 | S26: =IF($R26=1,SUM($R$5:$R26),"")
J27: =IF(OR($A27="",$B27=""),"",IF(YEAR($A27)=Settings!$C$4,MONTH($A27),"")) | K27: =IF($A27="","",IF(OR($J27="",$B27=""),0,IF(OR($G27="Won",$H27="Yes"),1,0))) | L27: =IF($B27="","",IFERROR(IF(INDEX(Settings!$E$12:$E$21,MATCH($B27,Settings!$B$12:$B$21,0))="Gross margin",N($F27),N($E27)),"")) | M27: =IF(AND($G27="Cancelled",$H27="Yes",$I27<>""),IF(YEAR($I27)=Settings!$C$4,MONTH($I27),""),"") | N27: =IF($M27="","",IFERROR(IF($J27="",IF(INDEX(Settings!$D$12:$D$21,MATCH($B27,Settings!$B$12:$B$21,0))="Tiered",INDEX(Settings!$I$12:$I$21,MATCH($B27,Settings!$B$12:$B$21,0)),INDEX(Settings!$G$12:$G$21,MATCH($B27,Settings!$B$12:$B$21,0))),INDEX(Calculation!$U$6:$U$125,(MATCH($B27,Settings!$B$12:$B$21,0)-1)*12+$J27)),0)) | O27: =IF($M27="",0,N($L27)*N($N27)) -> 0 | P27: =IF(AND($B27<>"",$B27=Statement!$C$6,$J27=Statement!$C$8,$K27=1),1,0) -> 0 | Q27: =IF($P27=1,SUM($P$5:$P27),"") | R27: =IF(AND($B27<>"",$B27=Statement!$C$6,$M27=Statement!$C$8),1,0) -> 0 | S27: =IF($R27=1,SUM($R$5:$R27),"")
J28: =IF(OR($A28="",$B28=""),"",IF(YEAR($A28)=Settings!$C$4,MONTH($A28),"")) | K28: =IF($A28="","",IF(OR($J28="",$B28=""),0,IF(OR($G28="Won",$H28="Yes"),1,0))) | L28: =IF($B28="","",IFERROR(IF(INDEX(Settings!$E$12:$E$21,MATCH($B28,Settings!$B$12:$B$21,0))="Gross margin",N($F28),N($E28)),"")) | M28: =IF(AND($G28="Cancelled",$H28="Yes",$I28<>""),IF(YEAR($I28)=Settings!$C$4,MONTH($I28),""),"") | N28: =IF($M28="","",IFERROR(IF($J28="",IF(INDEX(Settings!$D$12:$D$21,MATCH($B28,Settings!$B$12:$B$21,0))="Tiered",INDEX(Settings!$I$12:$I$21,MATCH($B28,Settings!$B$12:$B$21,0)),INDEX(Settings!$G$12:$G$21,MATCH($B28,Settings!$B$12:$B$21,0))),INDEX(Calculation!$U$6:$U$125,(MATCH($B28,Settings!$B$12:$B$21,0)-1)*12+$J28)),0)) | O28: =IF($M28="",0,N($L28)*N($N28)) -> 0 | P28: =IF(AND($B28<>"",$B28=Statement!$C$6,$J28=Statement!$C$8,$K28=1),1,0) -> 0 | Q28: =IF($P28=1,SUM($P$5:$P28),"") | R28: =IF(AND($B28<>"",$B28=Statement!$C$6,$M28=Statement!$C$8),1,0) -> 0 | S28: =IF($R28=1,SUM($R$5:$R28),"")
J29: =IF(OR($A29="",$B29=""),"",IF(YEAR($A29)=Settings!$C$4,MONTH($A29),"")) | K29: =IF($A29="","",IF(OR($J29="",$B29=""),0,IF(OR($G29="Won",$H29="Yes"),1,0))) | L29: =IF($B29="","",IFERROR(IF(INDEX(Settings!$E$12:$E$21,MATCH($B29,Settings!$B$12:$B$21,0))="Gross margin",N($F29),N($E29)),"")) | M29: =IF(AND($G29="Cancelled",$H29="Yes",$I29<>""),IF(YEAR($I29)=Settings!$C$4,MONTH($I29),""),"") | N29: =IF($M29="","",IFERROR(IF($J29="",IF(INDEX(Settings!$D$12:$D$21,MATCH($B29,Settings!$B$12:$B$21,0))="Tiered",INDEX(Settings!$I$12:$I$21,MATCH($B29,Settings!$B$12:$B$21,0)),INDEX(Settings!$G$12:$G$21,MATCH($B29,Settings!$B$12:$B$21,0))),INDEX(Calculation!$U$6:$U$125,(MATCH($B29,Settings!$B$12:$B$21,0)-1)*12+$J29)),0)) | O29: =IF($M29="",0,N($L29)*N($N29)) -> 0 | P29: =IF(AND($B29<>"",$B29=Statement!$C$6,$J29=Statement!$C$8,$K29=1),1,0) -> 0 | Q29: =IF($P29=1,SUM($P$5:$P29),"") | R29: =IF(AND($B29<>"",$B29=Statement!$C$6,$M29=Statement!$C$8),1,0) -> 0 | S29: =IF($R29=1,SUM($R$5:$R29),"")
J30: =IF(OR($A30="",$B30=""),"",IF(YEAR($A30)=Settings!$C$4,MONTH($A30),"")) | K30: =IF($A30="","",IF(OR($J30="",$B30=""),0,IF(OR($G30="Won",$H30="Yes"),1,0))) | L30: =IF($B30="","",IFERROR(IF(INDEX(Settings!$E$12:$E$21,MATCH($B30,Settings!$B$12:$B$21,0))="Gross margin",N($F30),N($E30)),"")) | M30: =IF(AND($G30="Cancelled",$H30="Yes",$I30<>""),IF(YEAR($I30)=Settings!$C$4,MONTH($I30),""),"") | N30: =IF($M30="","",IFERROR(IF($J30="",IF(INDEX(Settings!$D$12:$D$21,MATCH($B30,Settings!$B$12:$B$21,0))="Tiered",INDEX(Settings!$I$12:$I$21,MATCH($B30,Settings!$B$12:$B$21,0)),INDEX(Settings!$G$12:$G$21,MATCH($B30,Settings!$B$12:$B$21,0))),INDEX(Calculation!$U$6:$U$125,(MATCH($B30,Settings!$B$12:$B$21,0)-1)*12+$J30)),0)) | O30: =IF($M30="",0,N($L30)*N($N30)) -> 0 | P30: =IF(AND($B30<>"",$B30=Statement!$C$6,$J30=Statement!$C$8,$K30=1),1,0) -> 0 | Q30: =IF($P30=1,SUM($P$5:$P30),"") | R30: =IF(AND($B30<>"",$B30=Statement!$C$6,$M30=Statement!$C$8),1,0) -> 0 | S30: =IF($R30=1,SUM($R$5:$R30),"")
J31: =IF(OR($A31="",$B31=""),"",IF(YEAR($A31)=Settings!$C$4,MONTH($A31),"")) | K31: =IF($A31="","",IF(OR($J31="",$B31=""),0,IF(OR($G31="Won",$H31="Yes"),1,0))) | L31: =IF($B31="","",IFERROR(IF(INDEX(Settings!$E$12:$E$21,MATCH($B31,Settings!$B$12:$B$21,0))="Gross margin",N($F31),N($E31)),"")) | M31: =IF(AND($G31="Cancelled",$H31="Yes",$I31<>""),IF(YEAR($I31)=Settings!$C$4,MONTH($I31),""),"") | N31: =IF($M31="","",IFERROR(IF($J31="",IF(INDEX(Settings!$D$12:$D$21,MATCH($B31,Settings!$B$12:$B$21,0))="Tiered",INDEX(Settings!$I$12:$I$21,MATCH($B31,Settings!$B$12:$B$21,0)),INDEX(Settings!$G$12:$G$21,MATCH($B31,Settings!$B$12:$B$21,0))),INDEX(Calculation!$U$6:$U$125,(MATCH($B31,Settings!$B$12:$B$21,0)-1)*12+$J31)),0)) | O31: =IF($M31="",0,N($L31)*N($N31)) -> 0 | P31: =IF(AND($B31<>"",$B31=Statement!$C$6,$J31=Statement!$C$8,$K31=1),1,0) -> 0 | Q31: =IF($P31=1,SUM($P$5:$P31),"") | R31: =IF(AND($B31<>"",$B31=Statement!$C$6,$M31=Statement!$C$8),1,0) -> 0 | S31: =IF($R31=1,SUM($R$5:$R31),"")
J32: =IF(OR($A32="",$B32=""),"",IF(YEAR($A32)=Settings!$C$4,MONTH($A32),"")) | K32: =IF($A32="","",IF(OR($J32="",$B32=""),0,IF(OR($G32="Won",$H32="Yes"),1,0))) | L32: =IF($B32="","",IFERROR(IF(INDEX(Settings!$E$12:$E$21,MATCH($B32,Settings!$B$12:$B$21,0))="Gross margin",N($F32),N($E32)),"")) | M32: =IF(AND($G32="Cancelled",$H32="Yes",$I32<>""),IF(YEAR($I32)=Settings!$C$4,MONTH($I32),""),"") | N32: =IF($M32="","",IFERROR(IF($J32="",IF(INDEX(Settings!$D$12:$D$21,MATCH($B32,Settings!$B$12:$B$21,0))="Tiered",INDEX(Settings!$I$12:$I$21,MATCH($B32,Settings!$B$12:$B$21,0)),INDEX(Settings!$G$12:$G$21,MATCH($B32,Settings!$B$12:$B$21,0))),INDEX(Calculation!$U$6:$U$125,(MATCH($B32,Settings!$B$12:$B$21,0)-1)*12+$J32)),0)) | O32: =IF($M32="",0,N($L32)*N($N32)) -> 0 | P32: =IF(AND($B32<>"",$B32=Statement!$C$6,$J32=Statement!$C$8,$K32=1),1,0) -> 0 | Q32: =IF($P32=1,SUM($P$5:$P32),"") | R32: =IF(AND($B32<>"",$B32=Statement!$C$6,$M32=Statement!$C$8),1,0) -> 0 | S32: =IF($R32=1,SUM($R$5:$R32),"")
J33: =IF(OR($A33="",$B33=""),"",IF(YEAR($A33)=Settings!$C$4,MONTH($A33),"")) | K33: =IF($A33="","",IF(OR($J33="",$B33=""),0,IF(OR($G33="Won",$H33="Yes"),1,0))) | L33: =IF($B33="","",IFERROR(IF(INDEX(Settings!$E$12:$E$21,MATCH($B33,Settings!$B$12:$B$21,0))="Gross margin",N($F33),N($E33)),"")) | M33: =IF(AND($G33="Cancelled",$H33="Yes",$I33<>""),IF(YEAR($I33)=Settings!$C$4,MONTH($I33),""),"") | N33: =IF($M33="","",IFERROR(IF($J33="",IF(INDEX(Settings!$D$12:$D$21,MATCH($B33,Settings!$B$12:$B$21,0))="Tiered",INDEX(Settings!$I$12:$I$21,MATCH($B33,Settings!$B$12:$B$21,0)),INDEX(Settings!$G$12:$G$21,MATCH($B33,Settings!$B$12:$B$21,0))),INDEX(Calculation!$U$6:$U$125,(MATCH($B33,Settings!$B$12:$B$21,0)-1)*12+$J33)),0)) | O33: =IF($M33="",0,N($L33)*N($N33)) -> 0 | P33: =IF(AND($B33<>"",$B33=Statement!$C$6,$J33=Statement!$C$8,$K33=1),1,0) -> 0 | Q33: =IF($P33=1,SUM($P$5:$P33),"") | R33: =IF(AND($B33<>"",$B33=Statement!$C$6,$M33=Statement!$C$8),1,0) -> 0 | S33: =IF($R33=1,SUM($R$5:$R33),"")
J34: =IF(OR($A34="",$B34=""),"",IF(YEAR($A34)=Settings!$C$4,MONTH($A34),"")) | K34: =IF($A34="","",IF(OR($J34="",$B34=""),0,IF(OR($G34="Won",$H34="Yes"),1,0))) | L34: =IF($B34="","",IFERROR(IF(INDEX(Settings!$E$12:$E$21,MATCH($B34,Settings!$B$12:$B$21,0))="Gross margin",N($F34),N($E34)),"")) | M34: =IF(AND($G34="Cancelled",$H34="Yes",$I34<>""),IF(YEAR($I34)=Settings!$C$4,MONTH($I34),""),"") | N34: =IF($M34="","",IFERROR(IF($J34="",IF(INDEX(Settings!$D$12:$D$21,MATCH($B34,Settings!$B$12:$B$21,0))="Tiered",INDEX(Settings!$I$12:$I$21,MATCH($B34,Settings!$B$12:$B$21,0)),INDEX(Settings!$G$12:$G$21,MATCH($B34,Settings!$B$12:$B$21,0))),INDEX(Calculation!$U$6:$U$125,(MATCH($B34,Settings!$B$12:$B$21,0)-1)*12+$J34)),0)) | O34: =IF($M34="",0,N($L34)*N($N34)) -> 0 | P34: =IF(AND($B34<>"",$B34=Statement!$C$6,$J34=Statement!$C$8,$K34=1),1,0) -> 0 | Q34: =IF($P34=1,SUM($P$5:$P34),"") | R34: =IF(AND($B34<>"",$B34=Statement!$C$6,$M34=Statement!$C$8),1,0) -> 0 | S34: =IF($R34=1,SUM($R$5:$R34),"")
J35: =IF(OR($A35="",$B35=""),"",IF(YEAR($A35)=Settings!$C$4,MONTH($A35),"")) | K35: =IF($A35="","",IF(OR($J35="",$B35=""),0,IF(OR($G35="Won",$H35="Yes"),1,0))) | L35: =IF($B35="","",IFERROR(IF(INDEX(Settings!$E$12:$E$21,MATCH($B35,Settings!$B$12:$B$21,0))="Gross margin",N($F35),N($E35)),"")) | M35: =IF(AND($G35="Cancelled",$H35="Yes",$I35<>""),IF(YEAR($I35)=Settings!$C$4,MONTH($I35),""),"") | N35: =IF($M35="","",IFERROR(IF($J35="",IF(INDEX(Settings!$D$12:$D$21,MATCH($B35,Settings!$B$12:$B$21,0))="Tiered",INDEX(Settings!$I$12:$I$21,MATCH($B35,Settings!$B$12:$B$21,0)),INDEX(Settings!$G$12:$G$21,MATCH($B35,Settings!$B$12:$B$21,0))),INDEX(Calculation!$U$6:$U$125,(MATCH($B35,Settings!$B$12:$B$21,0)-1)*12+$J35)),0)) | O35: =IF($M35="",0,N($L35)*N($N35)) -> 0 | P35: =IF(AND($B35<>"",$B35=Statement!$C$6,$J35=Statement!$C$8,$K35=1),1,0) -> 0 | Q35: =IF($P35=1,SUM($P$5:$P35),"") | R35: =IF(AND($B35<>"",$B35=Statement!$C$6,$M35=Statement!$C$8),1,0) -> 0 | S35: =IF($R35=1,SUM($R$5:$R35),"")
J36: =IF(OR($A36="",$B36=""),"",IF(YEAR($A36)=Settings!$C$4,MONTH($A36),"")) | K36: =IF($A36="","",IF(OR($J36="",$B36=""),0,IF(OR($G36="Won",$H36="Yes"),1,0))) | L36: =IF($B36="","",IFERROR(IF(INDEX(Settings!$E$12:$E$21,MATCH($B36,Settings!$B$12:$B$21,0))="Gross margin",N($F36),N($E36)),"")) | M36: =IF(AND($G36="Cancelled",$H36="Yes",$I36<>""),IF(YEAR($I36)=Settings!$C$4,MONTH($I36),""),"") | N36: =IF($M36="","",IFERROR(IF($J36="",IF(INDEX(Settings!$D$12:$D$21,MATCH($B36,Settings!$B$12:$B$21,0))="Tiered",INDEX(Settings!$I$12:$I$21,MATCH($B36,Settings!$B$12:$B$21,0)),INDEX(Settings!$G$12:$G$21,MATCH($B36,Settings!$B$12:$B$21,0))),INDEX(Calculation!$U$6:$U$125,(MATCH($B36,Settings!$B$12:$B$21,0)-1)*12+$J36)),0)) | O36: =IF($M36="",0,N($L36)*N($N36)) -> 0 | P36: =IF(AND($B36<>"",$B36=Statement!$C$6,$J36=Statement!$C$8,$K36=1),1,0) -> 0 | Q36: =IF($P36=1,SUM($P$5:$P36),"") | R36: =IF(AND($B36<>"",$B36=Statement!$C$6,$M36=Statement!$C$8),1,0) -> 0 | S36: =IF($R36=1,SUM($R$5:$R36),"")
... J304: =IF(OR($A304="",$B304=""),"",IF(YEAR($A304)=Settings!$C$4,MONTH($A304),"")) | K304: =IF($A304="","",IF(OR($J304="",$B304=""),0,IF(OR($G304="Won",$H304="Yes"),1,0))) | L304: =IF($B304="","",IFERROR(IF(INDEX(Settings!$E$12:$E$21,MATCH($B304,Settings!$B$12:$B$21,0))="Gross margin",N($F304),N($E304)),"")) | M304: =IF(AND($G304="Cancelled",$H304="Yes",$I304<>""),IF(YEAR($I304)=Settings!$C$4,MONTH($I304),""),"") | N304: =IF($M304="","",IFERROR(IF($J304="",IF(INDEX(Settings!$D$12:$D$21,MATCH($B304,Settings!$B$12:$B$21,0))="Tiered",INDEX(Settings!$I$12:$I$21,MATCH($B304,Settings!$B$12:$B$21,0)),INDEX(Settings!$G$12:$G$21,MATCH($B304,Settings!$B$12:$B$21,0))),INDEX(Calculation!$U$6:$U$125,(MATCH($B304,Settings!$B$12:$B$21,0)-1)*12+$J304)),0)) | O304: =IF($M304="",0,N($L304)*N($N304)) -> 0 | P304: =IF(AND($B304<>"",$B304=Statement!$C$6,$J304=Statement!$C$8,$K304=1),1,0) -> 0 | Q304: =IF($P304=1,SUM($P$5:$P304),"") | R304: =IF(AND($B304<>"",$B304=Statement!$C$6,$M304=Statement!$C$8),1,0) -> 0 | S304: =IF($R304=1,SUM($R$5:$R304),"")

Sheet Calculation
A1: Calculation per rep per month
A2: Everything on this sheet is formulas. Empty rep rows in Settings give empty rows here. Use the filter in the header to see one rep or one month.
A3: Order: commission under the model → cap → clawback offset → final commission.
A5: Rep | B5: Month no. | C5: Month | D5: Model | E5: Sales, revenue | F5: Basis | G5: Quota | H5: Attainment | I5: Commission flat rate | J5: Commission tiered | K5: Commission base up to quota | L5: Accelerator amount above quota | M5: Commission before cap | N5: Cap | O5: Commission after cap | P5: Clawback in month | Q5: Clawback carried in | R5: Clawback offset | S5: Clawback to next month | T5: Final commission | U5: Effective rate
A6: =IF(Settings!$B$12="","",Settings!$B$12) -> Anna Holm | B6: =IF($A6="","",1) -> 1 | C6: =IF($A6="","",INDEX(Settings!$Q$12:$Q$23,$B6)) -> January | D6: =IF($A6="","",Settings!$D$12) -> Flat rate | E6: =IF($A6="","",SUMIFS(Sales!$E$5:$E$304,Sales!$B$5:$B$304,$A6,Sales!$J$5:$J$304,$B6,Sales!$K$5:$K$304,1)) -> 145000 | F6: =IF($A6="","",SUMIFS(Sales!$L$5:$L$304,Sales!$B$5:$B$304,$A6,Sales!$J$5:$J$304,$B6,Sales!$K$5:$K$304,1)) -> 145000 | G6: =IF($A6="","",N(Settings!$F$12)) -> 250000 | H6: =IF(OR($A6="",N(G6)=0),"",F6/G6) -> 0.58 | I6: =IF($A6="","",IF($D6="Flat rate",F6*N(Settings!$G$12),0)) -> 8700 | J6: =IF($A6="","",IF($D6="Tiered",MIN(F6,N(Settings!$H$12))*N(Settings!$I$12)+MAX(0,MIN(F6,N(Settings!$J$12))-N(Settings!$H$12))*N(Settings!$K$12)+MAX(0,F6-N(Settings!$J$12))*N(Settings!$L$12),0)) -> 0 | K6: =IF($A6="","",IF($D6="Accelerator",MIN(F6,G6)*N(Settings!$G$12),0)) -> 0 | L6: =IF($A6="","",IF($D6="Accelerator",MAX(0,F6-G6)*N(Settings!$M$12),0)) -> 0 | M6: =IF($A6="","",I6+J6+K6+L6) -> 8700 | N6: =IF(OR($A6="",Settings!$N$12=""),"",Settings!$N$12) | O6: =IF($A6="","",IF(N6="",M6,MIN(M6,N6))) -> 8700 | P6: =IF($A6="","",SUMIFS(Sales!$O$5:$O$304,Sales!$B$5:$B$304,$A6,Sales!$M$5:$M$304,$B6)) -> 0 | Q6: =IF($A6="","",0) -> 0 | R6: =IF($A6="","",MIN(O6,P6+Q6)) -> 0 | S6: =IF($A6="","",P6+Q6-R6) -> 0 | T6: =IF($A6="","",O6-R6) -> 8700 | U6: =IF($A6="","",IF(N(F6)=0,0,O6/F6)) -> 0.06
A7: =IF(Settings!$B$12="","",Settings!$B$12) -> Anna Holm | B7: =IF($A7="","",2) -> 2 | C7: =IF($A7="","",INDEX(Settings!$Q$12:$Q$23,$B7)) -> February | D7: =IF($A7="","",Settings!$D$12) -> Flat rate | E7: =IF($A7="","",SUMIFS(Sales!$E$5:$E$304,Sales!$B$5:$B$304,$A7,Sales!$J$5:$J$304,$B7,Sales!$K$5:$K$304,1)) -> 155000 | F7: =IF($A7="","",SUMIFS(Sales!$L$5:$L$304,Sales!$B$5:$B$304,$A7,Sales!$J$5:$J$304,$B7,Sales!$K$5:$K$304,1)) -> 155000 | G7: =IF($A7="","",N(Settings!$F$12)) -> 250000 | H7: =IF(OR($A7="",N(G7)=0),"",F7/G7) -> 0.62 | I7: =IF($A7="","",IF($D7="Flat rate",F7*N(Settings!$G$12),0)) -> 9300 | J7: =IF($A7="","",IF($D7="Tiered",MIN(F7,N(Settings!$H$12))*N(Settings!$I$12)+MAX(0,MIN(F7,N(Settings!$J$12))-N(Settings!$H$12))*N(Settings!$K$12)+MAX(0,F7-N(Settings!$J$12))*N(Settings!$L$12),0)) -> 0 | K7: =IF($A7="","",IF($D7="Accelerator",MIN(F7,G7)*N(Settings!$G$12),0)) -> 0 | L7: =IF($A7="","",IF($D7="Accelerator",MAX(0,F7-G7)*N(Settings!$M$12),0)) -> 0 | M7: =IF($A7="","",I7+J7+K7+L7) -> 9300 | N7: =IF(OR($A7="",Settings!$N$12=""),"",Settings!$N$12) | O7: =IF($A7="","",IF(N7="",M7,MIN(M7,N7))) -> 9300 | P7: =IF($A7="","",SUMIFS(Sales!$O$5:$O$304,Sales!$B$5:$B$304,$A7,Sales!$M$5:$M$304,$B7)) -> 0 | Q7: =IF($A7="","",S6) -> 0 | R7: =IF($A7="","",MIN(O7,P7+Q7)) -> 0 | S7: =IF($A7="","",P7+Q7-R7) -> 0 | T7: =IF($A7="","",O7-R7) -> 9300 | U7: =IF($A7="","",IF(N(F7)=0,0,O7/F7)) -> 0.06
A8: =IF(Settings!$B$12="","",Settings!$B$12) -> Anna Holm | B8: =IF($A8="","",3) -> 3 | C8: =IF($A8="","",INDEX(Settings!$Q$12:$Q$23,$B8)) -> March | D8: =IF($A8="","",Settings!$D$12) -> Flat rate | E8: =IF($A8="","",SUMIFS(Sales!$E$5:$E$304,Sales!$B$5:$B$304,$A8,Sales!$J$5:$J$304,$B8,Sales!$K$5:$K$304,1)) -> 225000 | F8: =IF($A8="","",SUMIFS(Sales!$L$5:$L$304,Sales!$B$5:$B$304,$A8,Sales!$J$5:$J$304,$B8,Sales!$K$5:$K$304,1)) -> 225000 | G8: =IF($A8="","",N(Settings!$F$12)) -> 250000 | H8: =IF(OR($A8="",N(G8)=0),"",F8/G8) -> 0.9 | I8: =IF($A8="","",IF($D8="Flat rate",F8*N(Settings!$G$12),0)) -> 13500 | J8: =IF($A8="","",IF($D8="Tiered",MIN(F8,N(Settings!$H$12))*N(Settings!$I$12)+MAX(0,MIN(F8,N(Settings!$J$12))-N(Settings!$H$12))*N(Settings!$K$12)+MAX(0,F8-N(Settings!$J$12))*N(Settings!$L$12),0)) -> 0 | K8: =IF($A8="","",IF($D8="Accelerator",MIN(F8,G8)*N(Settings!$G$12),0)) -> 0 | L8: =IF($A8="","",IF($D8="Accelerator",MAX(0,F8-G8)*N(Settings!$M$12),0)) -> 0 | M8: =IF($A8="","",I8+J8+K8+L8) -> 13500 | N8: =IF(OR($A8="",Settings!$N$12=""),"",Settings!$N$12) | O8: =IF($A8="","",IF(N8="",M8,MIN(M8,N8))) -> 13500 | P8: =IF($A8="","",SUMIFS(Sales!$O$5:$O$304,Sales!$B$5:$B$304,$A8,Sales!$M$5:$M$304,$B8)) -> 3600 | Q8: =IF($A8="","",S7) -> 0 | R8: =IF($A8="","",MIN(O8,P8+Q8)) -> 3600 | S8: =IF($A8="","",P8+Q8-R8) -> 0 | T8: =IF($A8="","",O8-R8) -> 9900 | U8: =IF($A8="","",IF(N(F8)=0,0,O8/F8)) -> 0.06
A9: =IF(Settings!$B$12="","",Settings!$B$12) -> Anna Holm | B9: =IF($A9="","",4) -> 4 | C9: =IF($A9="","",INDEX(Settings!$Q$12:$Q$23,$B9)) -> April | D9: =IF($A9="","",Settings!$D$12) -> Flat rate | E9: =IF($A9="","",SUMIFS(Sales!$E$5:$E$304,Sales!$B$5:$B$304,$A9,Sales!$J$5:$J$304,$B9,Sales!$K$5:$K$304,1)) -> 0 | F9: =IF($A9="","",SUMIFS(Sales!$L$5:$L$304,Sales!$B$5:$B$304,$A9,Sales!$J$5:$J$304,$B9,Sales!$K$5:$K$304,1)) -> 0 | G9: =IF($A9="","",N(Settings!$F$12)) -> 250000 | H9: =IF(OR($A9="",N(G9)=0),"",F9/G9) -> 0 | I9: =IF($A9="","",IF($D9="Flat rate",F9*N(Settings!$G$12),0)) -> 0 | J9: =IF($A9="","",IF($D9="Tiered",MIN(F9,N(Settings!$H$12))*N(Settings!$I$12)+MAX(0,MIN(F9,N(Settings!$J$12))-N(Settings!$H$12))*N(Settings!$K$12)+MAX(0,F9-N(Settings!$J$12))*N(Settings!$L$12),0)) -> 0 | K9: =IF($A9="","",IF($D9="Accelerator",MIN(F9,G9)*N(Settings!$G$12),0)) -> 0 | L9: =IF($A9="","",IF($D9="Accelerator",MAX(0,F9-G9)*N(Settings!$M$12),0)) -> 0 | M9: =IF($A9="","",I9+J9+K9+L9) -> 0 | N9: =IF(OR($A9="",Settings!$N$12=""),"",Settings!$N$12) | O9: =IF($A9="","",IF(N9="",M9,MIN(M9,N9))) -> 0 | P9: =IF($A9="","",SUMIFS(Sales!$O$5:$O$304,Sales!$B$5:$B$304,$A9,Sales!$M$5:$M$304,$B9)) -> 0 | Q9: =IF($A9="","",S8) -> 0 | R9: =IF($A9="","",MIN(O9,P9+Q9)) -> 0 | S9: =IF($A9="","",P9+Q9-R9) -> 0 | T9: =IF($A9="","",O9-R9) -> 0 | U9: =IF($A9="","",IF(N(F9)=0,0,O9/F9)) -> 0
A10: =IF(Settings!$B$12="","",Settings!$B$12) -> Anna Holm | B10: =IF($A10="","",5) -> 5 | C10: =IF($A10="","",INDEX(Settings!$Q$12:$Q$23,$B10)) -> May | D10: =IF($A10="","",Settings!$D$12) -> Flat rate | E10: =IF($A10="","",SUMIFS(Sales!$E$5:$E$304,Sales!$B$5:$B$304,$A10,Sales!$J$5:$J$304,$B10,Sales!$K$5:$K$304,1)) -> 0 | F10: =IF($A10="","",SUMIFS(Sales!$L$5:$L$304,Sales!$B$5:$B$304,$A10,Sales!$J$5:$J$304,$B10,Sales!$K$5:$K$304,1)) -> 0 | G10: =IF($A10="","",N(Settings!$F$12)) -> 250000 | H10: =IF(OR($A10="",N(G10)=0),"",F10/G10) -> 0 | I10: =IF($A10="","",IF($D10="Flat rate",F10*N(Settings!$G$12),0)) -> 0 | J10: =IF($A10="","",IF($D10="Tiered",MIN(F10,N(Settings!$H$12))*N(Settings!$I$12)+MAX(0,MIN(F10,N(Settings!$J$12))-N(Settings!$H$12))*N(Settings!$K$12)+MAX(0,F10-N(Settings!$J$12))*N(Settings!$L$12),0)) -> 0 | K10: =IF($A10="","",IF($D10="Accelerator",MIN(F10,G10)*N(Settings!$G$12),0)) -> 0 | L10: =IF($A10="","",IF($D10="Accelerator",MAX(0,F10-G10)*N(Settings!$M$12),0)) -> 0 | M10: =IF($A10="","",I10+J10+K10+L10) -> 0 | N10: =IF(OR($A10="",Settings!$N$12=""),"",Settings!$N$12) | O10: =IF($A10="","",IF(N10="",M10,MIN(M10,N10))) -> 0 | P10: =IF($A10="","",SUMIFS(Sales!$O$5:$O$304,Sales!$B$5:$B$304,$A10,Sales!$M$5:$M$304,$B10)) -> 0 | Q10: =IF($A10="","",S9) -> 0 | R10: =IF($A10="","",MIN(O10,P10+Q10)) -> 0 | S10: =IF($A10="","",P10+Q10-R10) -> 0 | T10: =IF($A10="","",O10-R10) -> 0 | U10: =IF($A10="","",IF(N(F10)=0,0,O10/F10)) -> 0
A11: =IF(Settings!$B$12="","",Settings!$B$12) -> Anna Holm | B11: =IF($A11="","",6) -> 6 | C11: =IF($A11="","",INDEX(Settings!$Q$12:$Q$23,$B11)) -> June | D11: =IF($A11="","",Settings!$D$12) -> Flat rate | E11: =IF($A11="","",SUMIFS(Sales!$E$5:$E$304,Sales!$B$5:$B$304,$A11,Sales!$J$5:$J$304,$B11,Sales!$K$5:$K$304,1)) -> 0 | F11: =IF($A11="","",SUMIFS(Sales!$L$5:$L$304,Sales!$B$5:$B$304,$A11,Sales!$J$5:$J$304,$B11,Sales!$K$5:$K$304,1)) -> 0 | G11: =IF($A11="","",N(Settings!$F$12)) -> 250000 | H11: =IF(OR($A11="",N(G11)=0),"",F11/G11) -> 0 | I11: =IF($A11="","",IF($D11="Flat rate",F11*N(Settings!$G$12),0)) -> 0 | J11: =IF($A11="","",IF($D11="Tiered",MIN(F11,N(Settings!$H$12))*N(Settings!$I$12)+MAX(0,MIN(F11,N(Settings!$J$12))-N(Settings!$H$12))*N(Settings!$K$12)+MAX(0,F11-N(Settings!$J$12))*N(Settings!$L$12),0)) -> 0 | K11: =IF($A11="","",IF($D11="Accelerator",MIN(F11,G11)*N(Settings!$G$12),0)) -> 0 | L11: =IF($A11="","",IF($D11="Accelerator",MAX(0,F11-G11)*N(Settings!$M$12),0)) -> 0 | M11: =IF($A11="","",I11+J11+K11+L11) -> 0 | N11: =IF(OR($A11="",Settings!$N$12=""),"",Settings!$N$12) | O11: =IF($A11="","",IF(N11="",M11,MIN(M11,N11))) -> 0 | P11: =IF($A11="","",SUMIFS(Sales!$O$5:$O$304,Sales!$B$5:$B$304,$A11,Sales!$M$5:$M$304,$B11)) -> 0 | Q11: =IF($A11="","",S10) -> 0 | R11: =IF($A11="","",MIN(O11,P11+Q11)) -> 0 | S11: =IF($A11="","",P11+Q11-R11) -> 0 | T11: =IF($A11="","",O11-R11) -> 0 | U11: =IF($A11="","",IF(N(F11)=0,0,O11/F11)) -> 0
A12: =IF(Settings!$B$12="","",Settings!$B$12) -> Anna Holm | B12: =IF($A12="","",7) -> 7 | C12: =IF($A12="","",INDEX(Settings!$Q$12:$Q$23,$B12)) -> July | D12: =IF($A12="","",Settings!$D$12) -> Flat rate | E12: =IF($A12="","",SUMIFS(Sales!$E$5:$E$304,Sales!$B$5:$B$304,$A12,Sales!$J$5:$J$304,$B12,Sales!$K$5:$K$304,1)) -> 0 | F12: =IF($A12="","",SUMIFS(Sales!$L$5:$L$304,Sales!$B$5:$B$304,$A12,Sales!$J$5:$J$304,$B12,Sales!$K$5:$K$304,1)) -> 0 | G12: =IF($A12="","",N(Settings!$F$12)) -> 250000 | H12: =IF(OR($A12="",N(G12)=0),"",F12/G12) -> 0 | I12: =IF($A12="","",IF($D12="Flat rate",F12*N(Settings!$G$12),0)) -> 0 | J12: =IF($A12="","",IF($D12="Tiered",MIN(F12,N(Settings!$H$12))*N(Settings!$I$12)+MAX(0,MIN(F12,N(Settings!$J$12))-N(Settings!$H$12))*N(Settings!$K$12)+MAX(0,F12-N(Settings!$J$12))*N(Settings!$L$12),0)) -> 0 | K12: =IF($A12="","",IF($D12="Accelerator",MIN(F12,G12)*N(Settings!$G$12),0)) -> 0 | L12: =IF($A12="","",IF($D12="Accelerator",MAX(0,F12-G12)*N(Settings!$M$12),0)) -> 0 | M12: =IF($A12="","",I12+J12+K12+L12) -> 0 | N12: =IF(OR($A12="",Settings!$N$12=""),"",Settings!$N$12) | O12: =IF($A12="","",IF(N12="",M12,MIN(M12,N12))) -> 0 | P12: =IF($A12="","",SUMIFS(Sales!$O$5:$O$304,Sales!$B$5:$B$304,$A12,Sales!$M$5:$M$304,$B12)) -> 0 | Q12: =IF($A12="","",S11) -> 0 | R12: =IF($A12="","",MIN(O12,P12+Q12)) -> 0 | S12: =IF($A12="","",P12+Q12-R12) -> 0 | T12: =IF($A12="","",O12-R12) -> 0 | U12: =IF($A12="","",IF(N(F12)=0,0,O12/F12)) -> 0
A13: =IF(Settings!$B$12="","",Settings!$B$12) -> Anna Holm | B13: =IF($A13="","",8) -> 8 | C13: =IF($A13="","",INDEX(Settings!$Q$12:$Q$23,$B13)) -> August | D13: =IF($A13="","",Settings!$D$12) -> Flat rate | E13: =IF($A13="","",SUMIFS(Sales!$E$5:$E$304,Sales!$B$5:$B$304,$A13,Sales!$J$5:$J$304,$B13,Sales!$K$5:$K$304,1)) -> 0 | F13: =IF($A13="","",SUMIFS(Sales!$L$5:$L$304,Sales!$B$5:$B$304,$A13,Sales!$J$5:$J$304,$B13,Sales!$K$5:$K$304,1)) -> 0 | G13: =IF($A13="","",N(Settings!$F$12)) -> 250000 | H13: =IF(OR($A13="",N(G13)=0),"",F13/G13) -> 0 | I13: =IF($A13="","",IF($D13="Flat rate",F13*N(Settings!$G$12),0)) -> 0 | J13: =IF($A13="","",IF($D13="Tiered",MIN(F13,N(Settings!$H$12))*N(Settings!$I$12)+MAX(0,MIN(F13,N(Settings!$J$12))-N(Settings!$H$12))*N(Settings!$K$12)+MAX(0,F13-N(Settings!$J$12))*N(Settings!$L$12),0)) -> 0 | K13: =IF($A13="","",IF($D13="Accelerator",MIN(F13,G13)*N(Settings!$G$12),0)) -> 0 | L13: =IF($A13="","",IF($D13="Accelerator",MAX(0,F13-G13)*N(Settings!$M$12),0)) -> 0 | M13: =IF($A13="","",I13+J13+K13+L13) -> 0 | N13: =IF(OR($A13="",Settings!$N$12=""),"",Settings!$N$12) | O13: =IF($A13="","",IF(N13="",M13,MIN(M13,N13))) -> 0 | P13: =IF($A13="","",SUMIFS(Sales!$O$5:$O$304,Sales!$B$5:$B$304,$A13,Sales!$M$5:$M$304,$B13)) -> 0 | Q13: =IF($A13="","",S12) -> 0 | R13: =IF($A13="","",MIN(O13,P13+Q13)) -> 0 | S13: =IF($A13="","",P13+Q13-R13) -> 0 | T13: =IF($A13="","",O13-R13) -> 0 | U13: =IF($A13="","",IF(N(F13)=0,0,O13/F13)) -> 0
A14: =IF(Settings!$B$12="","",Settings!$B$12) -> Anna Holm | B14: =IF($A14="","",9) -> 9 | C14: =IF($A14="","",INDEX(Settings!$Q$12:$Q$23,$B14)) -> September | D14: =IF($A14="","",Settings!$D$12) -> Flat rate | E14: =IF($A14="","",SUMIFS(Sales!$E$5:$E$304,Sales!$B$5:$B$304,$A14,Sales!$J$5:$J$304,$B14,Sales!$K$5:$K$304,1)) -> 0 | F14: =IF($A14="","",SUMIFS(Sales!$L$5:$L$304,Sales!$B$5:$B$304,$A14,Sales!$J$5:$J$304,$B14,Sales!$K$5:$K$304,1)) -> 0 | G14: =IF($A14="","",N(Settings!$F$12)) -> 250000 | H14: =IF(OR($A14="",N(G14)=0),"",F14/G14) -> 0 | I14: =IF($A14="","",IF($D14="Flat rate",F14*N(Settings!$G$12),0)) -> 0 | J14: =IF($A14="","",IF($D14="Tiered",MIN(F14,N(Settings!$H$12))*N(Settings!$I$12)+MAX(0,MIN(F14,N(Settings!$J$12))-N(Settings!$H$12))*N(Settings!$K$12)+MAX(0,F14-N(Settings!$J$12))*N(Settings!$L$12),0)) -> 0 | K14: =IF($A14="","",IF($D14="Accelerator",MIN(F14,G14)*N(Settings!$G$12),0)) -> 0 | L14: =IF($A14="","",IF($D14="Accelerator",MAX(0,F14-G14)*N(Settings!$M$12),0)) -> 0 | M14: =IF($A14="","",I14+J14+K14+L14) -> 0 | N14: =IF(OR($A14="",Settings!$N$12=""),"",Settings!$N$12) | O14: =IF($A14="","",IF(N14="",M14,MIN(M14,N14))) -> 0 | P14: =IF($A14="","",SUMIFS(Sales!$O$5:$O$304,Sales!$B$5:$B$304,$A14,Sales!$M$5:$M$304,$B14)) -> 0 | Q14: =IF($A14="","",S13) -> 0 | R14: =IF($A14="","",MIN(O14,P14+Q14)) -> 0 | S14: =IF($A14="","",P14+Q14-R14) -> 0 | T14: =IF($A14="","",O14-R14) -> 0 | U14: =IF($A14="","",IF(N(F14)=0,0,O14/F14)) -> 0
A15: =IF(Settings!$B$12="","",Settings!$B$12) -> Anna Holm | B15: =IF($A15="","",10) -> 10 | C15: =IF($A15="","",INDEX(Settings!$Q$12:$Q$23,$B15)) -> October | D15: =IF($A15="","",Settings!$D$12) -> Flat rate | E15: =IF($A15="","",SUMIFS(Sales!$E$5:$E$304,Sales!$B$5:$B$304,$A15,Sales!$J$5:$J$304,$B15,Sales!$K$5:$K$304,1)) -> 0 | F15: =IF($A15="","",SUMIFS(Sales!$L$5:$L$304,Sales!$B$5:$B$304,$A15,Sales!$J$5:$J$304,$B15,Sales!$K$5:$K$304,1)) -> 0 | G15: =IF($A15="","",N(Settings!$F$12)) -> 250000 | H15: =IF(OR($A15="",N(G15)=0),"",F15/G15) -> 0 | I15: =IF($A15="","",IF($D15="Flat rate",F15*N(Settings!$G$12),0)) -> 0 | J15: =IF($A15="","",IF($D15="Tiered",MIN(F15,N(Settings!$H$12))*N(Settings!$I$12)+MAX(0,MIN(F15,N(Settings!$J$12))-N(Settings!$H$12))*N(Settings!$K$12)+MAX(0,F15-N(Settings!$J$12))*N(Settings!$L$12),0)) -> 0 | K15: =IF($A15="","",IF($D15="Accelerator",MIN(F15,G15)*N(Settings!$G$12),0)) -> 0 | L15: =IF($A15="","",IF($D15="Accelerator",MAX(0,F15-G15)*N(Settings!$M$12),0)) -> 0 | M15: =IF($A15="","",I15+J15+K15+L15) -> 0 | N15: =IF(OR($A15="",Settings!$N$12=""),"",Settings!$N$12) | O15: =IF($A15="","",IF(N15="",M15,MIN(M15,N15))) -> 0 | P15: =IF($A15="","",SUMIFS(Sales!$O$5:$O$304,Sales!$B$5:$B$304,$A15,Sales!$M$5:$M$304,$B15)) -> 0 | Q15: =IF($A15="","",S14) -> 0 | R15: =IF($A15="","",MIN(O15,P15+Q15)) -> 0 | S15: =IF($A15="","",P15+Q15-R15) -> 0 | T15: =IF($A15="","",O15-R15) -> 0 | U15: =IF($A15="","",IF(N(F15)=0,0,O15/F15)) -> 0
A16: =IF(Settings!$B$12="","",Settings!$B$12) -> Anna Holm | B16: =IF($A16="","",11) -> 11 | C16: =IF($A16="","",INDEX(Settings!$Q$12:$Q$23,$B16)) -> November | D16: =IF($A16="","",Settings!$D$12) -> Flat rate | E16: =IF($A16="","",SUMIFS(Sales!$E$5:$E$304,Sales!$B$5:$B$304,$A16,Sales!$J$5:$J$304,$B16,Sales!$K$5:$K$304,1)) -> 0 | F16: =IF($A16="","",SUMIFS(Sales!$L$5:$L$304,Sales!$B$5:$B$304,$A16,Sales!$J$5:$J$304,$B16,Sales!$K$5:$K$304,1)) -> 0 | G16: =IF($A16="","",N(Settings!$F$12)) -> 250000 | H16: =IF(OR($A16="",N(G16)=0),"",F16/G16) -> 0 | I16: =IF($A16="","",IF($D16="Flat rate",F16*N(Settings!$G$12),0)) -> 0 | J16: =IF($A16="","",IF($D16="Tiered",MIN(F16,N(Settings!$H$12))*N(Settings!$I$12)+MAX(0,MIN(F16,N(Settings!$J$12))-N(Settings!$H$12))*N(Settings!$K$12)+MAX(0,F16-N(Settings!$J$12))*N(Settings!$L$12),0)) -> 0 | K16: =IF($A16="","",IF($D16="Accelerator",MIN(F16,G16)*N(Settings!$G$12),0)) -> 0 | L16: =IF($A16="","",IF($D16="Accelerator",MAX(0,F16-G16)*N(Settings!$M$12),0)) -> 0 | M16: =IF($A16="","",I16+J16+K16+L16) -> 0 | N16: =IF(OR($A16="",Settings!$N$12=""),"",Settings!$N$12) | O16: =IF($A16="","",IF(N16="",M16,MIN(M16,N16))) -> 0 | P16: =IF($A16="","",SUMIFS(Sales!$O$5:$O$304,Sales!$B$5:$B$304,$A16,Sales!$M$5:$M$304,$B16)) -> 0 | Q16: =IF($A16="","",S15) -> 0 | R16: =IF($A16="","",MIN(O16,P16+Q16)) -> 0 | S16: =IF($A16="","",P16+Q16-R16) -> 0 | T16: =IF($A16="","",O16-R16) -> 0 | U16: =IF($A16="","",IF(N(F16)=0,0,O16/F16)) -> 0
A17: =IF(Settings!$B$12="","",Settings!$B$12) -> Anna Holm | B17: =IF($A17="","",12) -> 12 | C17: =IF($A17="","",INDEX(Settings!$Q$12:$Q$23,$B17)) -> December | D17: =IF($A17="","",Settings!$D$12) -> Flat rate | E17: =IF($A17="","",SUMIFS(Sales!$E$5:$E$304,Sales!$B$5:$B$304,$A17,Sales!$J$5:$J$304,$B17,Sales!$K$5:$K$304,1)) -> 0 | F17: =IF($A17="","",SUMIFS(Sales!$L$5:$L$304,Sales!$B$5:$B$304,$A17,Sales!$J$5:$J$304,$B17,Sales!$K$5:$K$304,1)) -> 0 | G17: =IF($A17="","",N(Settings!$F$12)) -> 250000 | H17: =IF(OR($A17="",N(G17)=0),"",F17/G17) -> 0 | I17: =IF($A17="","",IF($D17="Flat rate",F17*N(Settings!$G$12),0)) -> 0 | J17: =IF($A17="","",IF($D17="Tiered",MIN(F17,N(Settings!$H$12))*N(Settings!$I$12)+MAX(0,MIN(F17,N(Settings!$J$12))-N(Settings!$H$12))*N(Settings!$K$12)+MAX(0,F17-N(Settings!$J$12))*N(Settings!$L$12),0)) -> 0 | K17: =IF($A17="","",IF($D17="Accelerator",MIN(F17,G17)*N(Settings!$G$12),0)) -> 0 | L17: =IF($A17="","",IF($D17="Accelerator",MAX(0,F17-G17)*N(Settings!$M$12),0)) -> 0 | M17: =IF($A17="","",I17+J17+K17+L17) -> 0 | N17: =IF(OR($A17="",Settings!$N$12=""),"",Settings!$N$12) | O17: =IF($A17="","",IF(N17="",M17,MIN(M17,N17))) -> 0 | P17: =IF($A17="","",SUMIFS(Sales!$O$5:$O$304,Sales!$B$5:$B$304,$A17,Sales!$M$5:$M$304,$B17)) -> 0 | Q17: =IF($A17="","",S16) -> 0 | R17: =IF($A17="","",MIN(O17,P17+Q17)) -> 0 | S17: =IF($A17="","",P17+Q17-R17) -> 0 | T17: =IF($A17="","",O17-R17) -> 0 | U17: =IF($A17="","",IF(N(F17)=0,0,O17/F17)) -> 0
A18: =IF(Settings!$B$13="","",Settings!$B$13) -> Bo Jensen | B18: =IF($A18="","",1) -> 1 | C18: =IF($A18="","",INDEX(Settings!$Q$12:$Q$23,$B18)) -> January | D18: =IF($A18="","",Settings!$D$13) -> Tiered | E18: =IF($A18="","",SUMIFS(Sales!$E$5:$E$304,Sales!$B$5:$B$304,$A18,Sales!$J$5:$J$304,$B18,Sales!$K$5:$K$304,1)) -> 215000 | F18: =IF($A18="","",SUMIFS(Sales!$L$5:$L$304,Sales!$B$5:$B$304,$A18,Sales!$J$5:$J$304,$B18,Sales!$K$5:$K$304,1)) -> 215000 | G18: =IF($A18="","",N(Settings!$F$13)) -> 300000 | H18: =IF(OR($A18="",N(G18)=0),"",F18/G18) -> 0.71666667 | I18: =IF($A18="","",IF($D18="Flat rate",F18*N(Settings!$G$13),0)) -> 0 | J18: =IF($A18="","",IF($D18="Tiered",MIN(F18,N(Settings!$H$13))*N(Settings!$I$13)+MAX(0,MIN(F18,N(Settings!$J$13))-N(Settings!$H$13))*N(Settings!$K$13)+MAX(0,F18-N(Settings!$J$13))*N(Settings!$L$13),0)) -> 10550 | K18: =IF($A18="","",IF($D18="Accelerator",MIN(F18,G18)*N(Settings!$G$13),0)) -> 0 | L18: =IF($A18="","",IF($D18="Accelerator",MAX(0,F18-G18)*N(Settings!$M$13),0)) -> 0 | M18: =IF($A18="","",I18+J18+K18+L18) -> 10550 | N18: =IF(OR($A18="",Settings!$N$13=""),"",Settings!$N$13) -> 25000 | O18: =IF($A18="","",IF(N18="",M18,MIN(M18,N18))) -> 10550 | P18: =IF($A18="","",SUMIFS(Sales!$O$5:$O$304,Sales!$B$5:$B$304,$A18,Sales!$M$5:$M$304,$B18)) -> 0 | Q18: =IF($A18="","",0) -> 0 | R18: =IF($A18="","",MIN(O18,P18+Q18)) -> 0 | S18: =IF($A18="","",P18+Q18-R18) -> 0 | T18: =IF($A18="","",O18-R18) -> 10550 | U18: =IF($A18="","",IF(N(F18)=0,0,O18/F18)) -> 0.049069767
A19: =IF(Settings!$B$13="","",Settings!$B$13) -> Bo Jensen | B19: =IF($A19="","",2) -> 2 | C19: =IF($A19="","",INDEX(Settings!$Q$12:$Q$23,$B19)) -> February | D19: =IF($A19="","",Settings!$D$13) -> Tiered | E19: =IF($A19="","",SUMIFS(Sales!$E$5:$E$304,Sales!$B$5:$B$304,$A19,Sales!$J$5:$J$304,$B19,Sales!$K$5:$K$304,1)) -> 315000 | F19: =IF($A19="","",SUMIFS(Sales!$L$5:$L$304,Sales!$B$5:$B$304,$A19,Sales!$J$5:$J$304,$B19,Sales!$K$5:$K$304,1)) -> 315000 | G19: =IF($A19="","",N(Settings!$F$13)) -> 300000 | H19: =IF(OR($A19="",N(G19)=0),"",F19/G19) -> 1.05 | I19: =IF($A19="","",IF($D19="Flat rate",F19*N(Settings!$G$13),0)) -> 0 | J19: =IF($A19="","",IF($D19="Tiered",MIN(F19,N(Settings!$H$13))*N(Settings!$I$13)+MAX(0,MIN(F19,N(Settings!$J$13))-N(Settings!$H$13))*N(Settings!$K$13)+MAX(0,F19-N(Settings!$J$13))*N(Settings!$L$13),0)) -> 18000 | K19: =IF($A19="","",IF($D19="Accelerator",MIN(F19,G19)*N(Settings!$G$13),0)) -> 0 | L19: =IF($A19="","",IF($D19="Accelerator",MAX(0,F19-G19)*N(Settings!$M$13),0)) -> 0 | M19: =IF($A19="","",I19+J19+K19+L19) -> 18000 | N19: =IF(OR($A19="",Settings!$N$13=""),"",Settings!$N$13) -> 25000 | O19: =IF($A19="","",IF(N19="",M19,MIN(M19,N19))) -> 18000 | P19: =IF($A19="","",SUMIFS(Sales!$O$5:$O$304,Sales!$B$5:$B$304,$A19,Sales!$M$5:$M$304,$B19)) -> 0 | Q19: =IF($A19="","",S18) -> 0 | R19: =IF($A19="","",MIN(O19,P19+Q19)) -> 0 | S19: =IF($A19="","",P19+Q19-R19) -> 0 | T19: =IF($A19="","",O19-R19) -> 18000 | U19: =IF($A19="","",IF(N(F19)=0,0,O19/F19)) -> 0.057142857
