Workbook

Sheet Instructions
C2: Free template from Prowi
B4: Commission statement
B5: One statement per rep per month, ready for approval and payroll
B7: The template brings together everything that goes into a rep's commission for a month: the deals with amount, rate and commission, corrections and clawbacks from earlier months, draws and the balance carried forward. The rep confirms, the manager and finance approve, and the payroll sheet lists the amounts with employee number and pay code. It contains example data for three reps for January to March 2026.
B9: Step by step
B10: 1. Settings | C10: Enter company, year and pay code. Add the reps with employee number, manager, default rate and any draw.
B11: 2. Deals | C11: One row per deal with rep, date, customer, deal ID and amount. Leave the rate empty to use the rep's default rate, or enter the rate for the tier the deal falls in.
B12: 3. Adjustments | C12: Clawbacks and adjustments to deals from earlier months. Pick the month the adjustment is settled in.
B13: 4. Statement | C13: Pick a rep and a month. The statement shows deals, adjustments, draw, balance and the amount payable. Save or print as PDF.
B14: 5. Approvals | C14: One row per rep per month: the rep confirms, the manager approves, finance approves. The dates appear on the statement.
B15: 6. Payroll | C15: Pick the payroll month. The sheet shows employee number, pay code, description and amount per rep, and whether finance has approved.
B17: Colours
B18: Lavender cell, purple text | C18: This is where you type. Everything else is formulas.
B19: Grey cell | C19: Calculated automatically. Leave the formulas alone unless you know what you are changing.
B20: Light blue cell | C20: Results and totals.
B22: How the workbook calculates
B23: Commission per deal | C23: Amount × rate. Empty rate = the rep's default rate from Settings.
B24: Adjustments | C24: Basis × rate. A clawback is deducted (enter the basis as a positive number). An adjustment is added or deducted according to the sign of the basis.
B25: Statement lines A-H | C25: A deals + B adjustments = C commission for the period. C − D draw + E balance from last month = F result. G payable = F, but never below 0. H is the balance carried to next month.
B26: Recoverable draw | C26: The rep receives the draw every month. If commission is lower than the draw, the difference carries forward as a negative balance and is recovered from later commission.
B27: Non-recoverable draw | C27: The rep keeps the draw even if commission is lower. Only negative commission (for example after a large clawback) carries forward.
B28: Payroll | C28: The amount is G payable for the selected month. The draw is not included because it is paid separately. A line is approved when finance has a date in Approvals.
B30: Good to know
B31: • | C31: All names and numbers are examples. Delete the example data in Deals, Adjustments and Approvals before you use the workbook.
B32: • | C32: Use one file per year. Enter any negative balance from last year in Settings, column K.
B33: • | C33: The pay code is the code your payroll system uses for commission. It comes from your payroll system or provider.
B34: • | C34: The statement has room for 25 deals and 10 adjustments per rep per month. If there are more, a warning appears.
B35: • | C35: No macros. Every calculation is an ordinary formula that works in Excel, Google Sheets, Numbers and LibreOffice.
B38: prowi.io · Free template from Prowi

Sheet Settings
B2: Settings
B3: Only type in the lavender cells.
B5: General
B6: Company | C6: Example ApS | D6: Shown at the top of the statement.
B7: Year | C7: 2026 | D7: The year this file covers. Deals dated in another year are ignored.
B8: Pay code for commission | D8: The code from your payroll system. Empty = 'Enter pay code' on the payroll sheet.
B9: Currency | C9: DKK | D9: Shown on the statement and payroll sheet. Amounts are plain numbers.
B11: Reps
B12: Employee no. | C12: Name | D12: Team | E12: Manager | F12: Default rate | G12: Draw per month | H12: Draw from month | I12: Draw to month | J12: Draw recoverable | K12: Opening balance (negative) | L12: Note | N12: Months (helper list)
B13: 101 | C13: Anna Holm | D13: North | E13: Mette Lund | F13: 0.08 | G13: 10000 | H13: January | I13: March | J13: Yes | L13: Started in January, draw while ramping | N13: January
B14: 102 | C14: Bo Jensen | D14: North | E14: Mette Lund | F14: 0.06 | N14: February
B15: 103 | C15: Camilla Nørgaard | D15: South | E15: Kasper Dahl | F15: 0.1 | G15: 15000 | H15: January | I15: March | J15: No | L15: Guarantee for the first three months | N15: March
N16: April
N17: May
N18: June
N19: July
N20: August
N21: September
N22: October
N23: November
N24: December
B29: Draw recoverable: Yes = the draw is recovered from later commission. No = a guarantee the rep keeps. Empty = Yes.
B30: Draw from/to: empty from-month = January, empty to-month = December. The default rate is used when a deal has no rate.

Sheet Deals
A2: Deals
A3: One row per deal. Empty rate = the rep's default rate. Columns J and K are helper columns.
A5: Rep | B5: Date | C5: Customer | D5: Deal ID | E5: Amount (basis) | F5: Tier (optional) | G5: Rate (empty = default) | H5: Rate used | I5: Commission | J5: Month no. | K5: Line on statement
A6: Anna Holm | B6: 46037 | C6: Fjordtech ApS | D6: D-1001 | E6: 50000 | H6: =IF(OR(A6="",E6=""),"",IF(G6="",IFERROR(INDEX(Settings!$F$13:$F$27,MATCH(A6,Settings!$C$13:$C$27,0)),0),G6)) -> 0.08 | I6: =IF(H6="","",ROUND(E6*H6,2)) -> 4000 | J6: =IF(OR(A6="",B6=""),"",IF(YEAR(B6)=Settings!$C$7,MONTH(B6),"")) -> 1 | K6: =IF(AND(A6<>"",A6=Statement!$C$6,J6=Statement!$K$7),COUNTIFS(A$6:A6,Statement!$C$6,J$6:J6,Statement!$K$7),"")
A7: Bo Jensen | B7: 46034 | C7: Østerby Maskiner | D7: D-1002 | E7: 180000 | H7: =IF(OR(A7="",E7=""),"",IF(G7="",IFERROR(INDEX(Settings!$F$13:$F$27,MATCH(A7,Settings!$C$13:$C$27,0)),0),G7)) -> 0.06 | I7: =IF(H7="","",ROUND(E7*H7,2)) -> 10800 | J7: =IF(OR(A7="",B7=""),"",IF(YEAR(B7)=Settings!$C$7,MONTH(B7),"")) -> 1 | K7: =IF(AND(A7<>"",A7=Statement!$C$6,J7=Statement!$K$7),COUNTIFS(A$6:A7,Statement!$C$6,J$6:J7,Statement!$K$7),"")
A8: Anna Holm | B8: 46063 | C8: Nordlys A/S | D8: D-1003 | E8: 100000 | H8: =IF(OR(A8="",E8=""),"",IF(G8="",IFERROR(INDEX(Settings!$F$13:$F$27,MATCH(A8,Settings!$C$13:$C$27,0)),0),G8)) -> 0.08 | I8: =IF(H8="","",ROUND(E8*H8,2)) -> 8000 | J8: =IF(OR(A8="",B8=""),"",IF(YEAR(B8)=Settings!$C$7,MONTH(B8),"")) -> 2 | K8: =IF(AND(A8<>"",A8=Statement!$C$6,J8=Statement!$K$7),COUNTIFS(A$6:A8,Statement!$C$6,J$6:J8,Statement!$K$7),"")
A9: Anna Holm | B9: 46077 | C9: Havnens Bageri | D9: D-1004 | E9: 50000 | H9: =IF(OR(A9="",E9=""),"",IF(G9="",IFERROR(INDEX(Settings!$F$13:$F$27,MATCH(A9,Settings!$C$13:$C$27,0)),0),G9)) -> 0.08 | I9: =IF(H9="","",ROUND(E9*H9,2)) -> 4000 | J9: =IF(OR(A9="",B9=""),"",IF(YEAR(B9)=Settings!$C$7,MONTH(B9),"")) -> 2 | K9: =IF(AND(A9<>"",A9=Statement!$C$6,J9=Statement!$K$7),COUNTIFS(A$6:A9,Statement!$C$6,J$6:J9,Statement!$K$7),"")
A10: Bo Jensen | B10: 46069 | C10: Mølleparken | D10: D-1005 | E10: 140000 | H10: =IF(OR(A10="",E10=""),"",IF(G10="",IFERROR(INDEX(Settings!$F$13:$F$27,MATCH(A10,Settings!$C$13:$C$27,0)),0),G10)) -> 0.06 | I10: =IF(H10="","",ROUND(E10*H10,2)) -> 8400 | J10: =IF(OR(A10="",B10=""),"",IF(YEAR(B10)=Settings!$C$7,MONTH(B10),"")) -> 2 | K10: =IF(AND(A10<>"",A10=Statement!$C$6,J10=Statement!$K$7),COUNTIFS(A$6:A10,Statement!$C$6,J$6:J10,Statement!$K$7),"")
A11: Camilla Nørgaard | B11: 46073 | C11: Tårnby Tandklinik | D11: D-1006 | E11: 80000 | H11: =IF(OR(A11="",E11=""),"",IF(G11="",IFERROR(INDEX(Settings!$F$13:$F$27,MATCH(A11,Settings!$C$13:$C$27,0)),0),G11)) -> 0.1 | I11: =IF(H11="","",ROUND(E11*H11,2)) -> 8000 | J11: =IF(OR(A11="",B11=""),"",IF(YEAR(B11)=Settings!$C$7,MONTH(B11),"")) -> 2 | K11: =IF(AND(A11<>"",A11=Statement!$C$6,J11=Statement!$K$7),COUNTIFS(A$6:A11,Statement!$C$6,J$6:J11,Statement!$K$7),"")
A12: Anna Holm | B12: 46085 | C12: Kystvej Logistik | D12: D-1007 | E12: 120000 | F12: Tier 1 | H12: =IF(OR(A12="",E12=""),"",IF(G12="",IFERROR(INDEX(Settings!$F$13:$F$27,MATCH(A12,Settings!$C$13:$C$27,0)),0),G12)) -> 0.08 | I12: =IF(H12="","",ROUND(E12*H12,2)) -> 9600 | J12: =IF(OR(A12="",B12=""),"",IF(YEAR(B12)=Settings!$C$7,MONTH(B12),"")) -> 3 | K12: =IF(AND(A12<>"",A12=Statement!$C$6,J12=Statement!$K$7),COUNTIFS(A$6:A12,Statement!$C$6,J$6:J12,Statement!$K$7),"") -> 1
A13: Bo Jensen | B13: 46090 | C13: Lindholm El | D13: D-1008 | E13: 200000 | H13: =IF(OR(A13="",E13=""),"",IF(G13="",IFERROR(INDEX(Settings!$F$13:$F$27,MATCH(A13,Settings!$C$13:$C$27,0)),0),G13)) -> 0.06 | I13: =IF(H13="","",ROUND(E13*H13,2)) -> 12000 | J13: =IF(OR(A13="",B13=""),"",IF(YEAR(B13)=Settings!$C$7,MONTH(B13),"")) -> 3 | K13: =IF(AND(A13<>"",A13=Statement!$C$6,J13=Statement!$K$7),COUNTIFS(A$6:A13,Statement!$C$6,J$6:J13,Statement!$K$7),"")
A14: Camilla Nørgaard | B14: 46087 | C14: Vestkyst Hotel | D14: D-1009 | E14: 140000 | H14: =IF(OR(A14="",E14=""),"",IF(G14="",IFERROR(INDEX(Settings!$F$13:$F$27,MATCH(A14,Settings!$C$13:$C$27,0)),0),G14)) -> 0.1 | I14: =IF(H14="","",ROUND(E14*H14,2)) -> 14000 | J14: =IF(OR(A14="",B14=""),"",IF(YEAR(B14)=Settings!$C$7,MONTH(B14),"")) -> 3 | K14: =IF(AND(A14<>"",A14=Statement!$C$6,J14=Statement!$K$7),COUNTIFS(A$6:A14,Statement!$C$6,J$6:J14,Statement!$K$7),"")
A15: Anna Holm | B15: 46099 | C15: Bølge Media | D15: D-1010 | E15: 90000 | F15: Tier 2 | G15: 0.1 | H15: =IF(OR(A15="",E15=""),"",IF(G15="",IFERROR(INDEX(Settings!$F$13:$F$27,MATCH(A15,Settings!$C$13:$C$27,0)),0),G15)) -> 0.1 | I15: =IF(H15="","",ROUND(E15*H15,2)) -> 9000 | J15: =IF(OR(A15="",B15=""),"",IF(YEAR(B15)=Settings!$C$7,MONTH(B15),"")) -> 3 | K15: =IF(AND(A15<>"",A15=Statement!$C$6,J15=Statement!$K$7),COUNTIFS(A$6:A15,Statement!$C$6,J$6:J15,Statement!$K$7),"") -> 2
A16: Bo Jensen | B16: 46104 | C16: Ravn Revision | D16: D-1011 | E16: 150000 | H16: =IF(OR(A16="",E16=""),"",IF(G16="",IFERROR(INDEX(Settings!$F$13:$F$27,MATCH(A16,Settings!$C$13:$C$27,0)),0),G16)) -> 0.06 | I16: =IF(H16="","",ROUND(E16*H16,2)) -> 9000 | J16: =IF(OR(A16="",B16=""),"",IF(YEAR(B16)=Settings!$C$7,MONTH(B16),"")) -> 3 | K16: =IF(AND(A16<>"",A16=Statement!$C$6,J16=Statement!$K$7),COUNTIFS(A$6:A16,Statement!$C$6,J$6:J16,Statement!$K$7),"")
A17: Camilla Nørgaard | B17: 46106 | C17: Ådalen Vand | D17: D-1012 | E17: 60000 | H17: =IF(OR(A17="",E17=""),"",IF(G17="",IFERROR(INDEX(Settings!$F$13:$F$27,MATCH(A17,Settings!$C$13:$C$27,0)),0),G17)) -> 0.1 | I17: =IF(H17="","",ROUND(E17*H17,2)) -> 6000 | J17: =IF(OR(A17="",B17=""),"",IF(YEAR(B17)=Settings!$C$7,MONTH(B17),"")) -> 3 | K17: =IF(AND(A17<>"",A17=Statement!$C$6,J17=Statement!$K$7),COUNTIFS(A$6:A17,Statement!$C$6,J$6:J17,Statement!$K$7),"")
A18: Anna Holm | B18: 46108 | C18: Skovgaard & Co | D18: D-1013 | E18: 60000 | F18: Tier 2 | G18: 0.1 | H18: =IF(OR(A18="",E18=""),"",IF(G18="",IFERROR(INDEX(Settings!$F$13:$F$27,MATCH(A18,Settings!$C$13:$C$27,0)),0),G18)) -> 0.1 | I18: =IF(H18="","",ROUND(E18*H18,2)) -> 6000 | J18: =IF(OR(A18="",B18=""),"",IF(YEAR(B18)=Settings!$C$7,MONTH(B18),"")) -> 3 | K18: =IF(AND(A18<>"",A18=Statement!$C$6,J18=Statement!$K$7),COUNTIFS(A$6:A18,Statement!$C$6,J$6:J18,Statement!$K$7),"") -> 3
H19: =IF(OR(A19="",E19=""),"",IF(G19="",IFERROR(INDEX(Settings!$F$13:$F$27,MATCH(A19,Settings!$C$13:$C$27,0)),0),G19)) | I19: =IF(H19="","",ROUND(E19*H19,2)) | J19: =IF(OR(A19="",B19=""),"",IF(YEAR(B19)=Settings!$C$7,MONTH(B19),"")) | K19: =IF(AND(A19<>"",A19=Statement!$C$6,J19=Statement!$K$7),COUNTIFS(A$6:A19,Statement!$C$6,J$6:J19,Statement!$K$7),"")
H20: =IF(OR(A20="",E20=""),"",IF(G20="",IFERROR(INDEX(Settings!$F$13:$F$27,MATCH(A20,Settings!$C$13:$C$27,0)),0),G20)) | I20: =IF(H20="","",ROUND(E20*H20,2)) | J20: =IF(OR(A20="",B20=""),"",IF(YEAR(B20)=Settings!$C$7,MONTH(B20),"")) | K20: =IF(AND(A20<>"",A20=Statement!$C$6,J20=Statement!$K$7),COUNTIFS(A$6:A20,Statement!$C$6,J$6:J20,Statement!$K$7),"")
H21: =IF(OR(A21="",E21=""),"",IF(G21="",IFERROR(INDEX(Settings!$F$13:$F$27,MATCH(A21,Settings!$C$13:$C$27,0)),0),G21)) | I21: =IF(H21="","",ROUND(E21*H21,2)) | J21: =IF(OR(A21="",B21=""),"",IF(YEAR(B21)=Settings!$C$7,MONTH(B21),"")) | K21: =IF(AND(A21<>"",A21=Statement!$C$6,J21=Statement!$K$7),COUNTIFS(A$6:A21,Statement!$C$6,J$6:J21,Statement!$K$7),"")
H22: =IF(OR(A22="",E22=""),"",IF(G22="",IFERROR(INDEX(Settings!$F$13:$F$27,MATCH(A22,Settings!$C$13:$C$27,0)),0),G22)) | I22: =IF(H22="","",ROUND(E22*H22,2)) | J22: =IF(OR(A22="",B22=""),"",IF(YEAR(B22)=Settings!$C$7,MONTH(B22),"")) | K22: =IF(AND(A22<>"",A22=Statement!$C$6,J22=Statement!$K$7),COUNTIFS(A$6:A22,Statement!$C$6,J$6:J22,Statement!$K$7),"")
H23: =IF(OR(A23="",E23=""),"",IF(G23="",IFERROR(INDEX(Settings!$F$13:$F$27,MATCH(A23,Settings!$C$13:$C$27,0)),0),G23)) | I23: =IF(H23="","",ROUND(E23*H23,2)) | J23: =IF(OR(A23="",B23=""),"",IF(YEAR(B23)=Settings!$C$7,MONTH(B23),"")) | K23: =IF(AND(A23<>"",A23=Statement!$C$6,J23=Statement!$K$7),COUNTIFS(A$6:A23,Statement!$C$6,J$6:J23,Statement!$K$7),"")
H24: =IF(OR(A24="",E24=""),"",IF(G24="",IFERROR(INDEX(Settings!$F$13:$F$27,MATCH(A24,Settings!$C$13:$C$27,0)),0),G24)) | I24: =IF(H24="","",ROUND(E24*H24,2)) | J24: =IF(OR(A24="",B24=""),"",IF(YEAR(B24)=Settings!$C$7,MONTH(B24),"")) | K24: =IF(AND(A24<>"",A24=Statement!$C$6,J24=Statement!$K$7),COUNTIFS(A$6:A24,Statement!$C$6,J$6:J24,Statement!$K$7),"")
H25: =IF(OR(A25="",E25=""),"",IF(G25="",IFERROR(INDEX(Settings!$F$13:$F$27,MATCH(A25,Settings!$C$13:$C$27,0)),0),G25)) | I25: =IF(H25="","",ROUND(E25*H25,2)) | J25: =IF(OR(A25="",B25=""),"",IF(YEAR(B25)=Settings!$C$7,MONTH(B25),"")) | K25: =IF(AND(A25<>"",A25=Statement!$C$6,J25=Statement!$K$7),COUNTIFS(A$6:A25,Statement!$C$6,J$6:J25,Statement!$K$7),"")
H26: =IF(OR(A26="",E26=""),"",IF(G26="",IFERROR(INDEX(Settings!$F$13:$F$27,MATCH(A26,Settings!$C$13:$C$27,0)),0),G26)) | I26: =IF(H26="","",ROUND(E26*H26,2)) | J26: =IF(OR(A26="",B26=""),"",IF(YEAR(B26)=Settings!$C$7,MONTH(B26),"")) | K26: =IF(AND(A26<>"",A26=Statement!$C$6,J26=Statement!$K$7),COUNTIFS(A$6:A26,Statement!$C$6,J$6:J26,Statement!$K$7),"")
H27: =IF(OR(A27="",E27=""),"",IF(G27="",IFERROR(INDEX(Settings!$F$13:$F$27,MATCH(A27,Settings!$C$13:$C$27,0)),0),G27)) | I27: =IF(H27="","",ROUND(E27*H27,2)) | J27: =IF(OR(A27="",B27=""),"",IF(YEAR(B27)=Settings!$C$7,MONTH(B27),"")) | K27: =IF(AND(A27<>"",A27=Statement!$C$6,J27=Statement!$K$7),COUNTIFS(A$6:A27,Statement!$C$6,J$6:J27,Statement!$K$7),"")
H28: =IF(OR(A28="",E28=""),"",IF(G28="",IFERROR(INDEX(Settings!$F$13:$F$27,MATCH(A28,Settings!$C$13:$C$27,0)),0),G28)) | I28: =IF(H28="","",ROUND(E28*H28,2)) | J28: =IF(OR(A28="",B28=""),"",IF(YEAR(B28)=Settings!$C$7,MONTH(B28),"")) | K28: =IF(AND(A28<>"",A28=Statement!$C$6,J28=Statement!$K$7),COUNTIFS(A$6:A28,Statement!$C$6,J$6:J28,Statement!$K$7),"")
H29: =IF(OR(A29="",E29=""),"",IF(G29="",IFERROR(INDEX(Settings!$F$13:$F$27,MATCH(A29,Settings!$C$13:$C$27,0)),0),G29)) | I29: =IF(H29="","",ROUND(E29*H29,2)) | J29: =IF(OR(A29="",B29=""),"",IF(YEAR(B29)=Settings!$C$7,MONTH(B29),"")) | K29: =IF(AND(A29<>"",A29=Statement!$C$6,J29=Statement!$K$7),COUNTIFS(A$6:A29,Statement!$C$6,J$6:J29,Statement!$K$7),"")
H30: =IF(OR(A30="",E30=""),"",IF(G30="",IFERROR(INDEX(Settings!$F$13:$F$27,MATCH(A30,Settings!$C$13:$C$27,0)),0),G30)) | I30: =IF(H30="","",ROUND(E30*H30,2)) | J30: =IF(OR(A30="",B30=""),"",IF(YEAR(B30)=Settings!$C$7,MONTH(B30),"")) | K30: =IF(AND(A30<>"",A30=Statement!$C$6,J30=Statement!$K$7),COUNTIFS(A$6:A30,Statement!$C$6,J$6:J30,Statement!$K$7),"")
... H305: =IF(OR(A305="",E305=""),"",IF(G305="",IFERROR(INDEX(Settings!$F$13:$F$27,MATCH(A305,Settings!$C$13:$C$27,0)),0),G305)) | I305: =IF(H305="","",ROUND(E305*H305,2)) | J305: =IF(OR(A305="",B305=""),"",IF(YEAR(B305)=Settings!$C$7,MONTH(B305),"")) | K305: =IF(AND(A305<>"",A305=Statement!$C$6,J305=Statement!$K$7),COUNTIFS(A$6:A305,Statement!$C$6,J$6:J305,Statement!$K$7),"")

Sheet Adjustments
A2: Adjustments and clawbacks
A3: Clawback: enter the basis as a positive number and the commission is deducted. Adjustment: enter + or − on the basis.
A5: Rep | B5: Settle in month | C5: Original date | D5: Customer | E5: Deal ID | F5: Type | G5: Basis | H5: Rate (empty = default) | I5: Rate used | J5: Commission | K5: Reason | L5: Month no. | M5: Line on statement
A6: Anna Holm | B6: March | C6: 46077 | D6: Havnens Bageri | E6: D-1004 | F6: Clawback | G6: 50000 | I6: =IF(OR(A6="",G6=""),"",IF(H6="",IFERROR(INDEX(Settings!$F$13:$F$27,MATCH(A6,Settings!$C$13:$C$27,0)),0),H6)) -> 0.08 | J6: =IF(I6="","",ROUND(IF(F6="Clawback",-1,1)*G6*I6,2)) -> -4000 | K6: Customer cancelled within 90 days | L6: =IF(OR(A6="",B6=""),"",IFERROR(MATCH(B6,Settings!$N$13:$N$24,0),"")) -> 3 | M6: =IF(AND(A6<>"",A6=Statement!$C$6,L6=Statement!$K$7),COUNTIFS(A$6:A6,Statement!$C$6,L$6:L6,Statement!$K$7),"") -> 1
A7: Anna Holm | B7: March | C7: 46037 | D7: Fjordtech ApS | E7: D-1001 | F7: Adjustment | G7: 10000 | I7: =IF(OR(A7="",G7=""),"",IF(H7="",IFERROR(INDEX(Settings!$F$13:$F$27,MATCH(A7,Settings!$C$13:$C$27,0)),0),H7)) -> 0.08 | J7: =IF(I7="","",ROUND(IF(F7="Clawback",-1,1)*G7*I7,2)) -> 800 | K7: Order was increased before delivery | L7: =IF(OR(A7="",B7=""),"",IFERROR(MATCH(B7,Settings!$N$13:$N$24,0),"")) -> 3 | M7: =IF(AND(A7<>"",A7=Statement!$C$6,L7=Statement!$K$7),COUNTIFS(A$6:A7,Statement!$C$6,L$6:L7,Statement!$K$7),"") -> 2
I8: =IF(OR(A8="",G8=""),"",IF(H8="",IFERROR(INDEX(Settings!$F$13:$F$27,MATCH(A8,Settings!$C$13:$C$27,0)),0),H8)) | J8: =IF(I8="","",ROUND(IF(F8="Clawback",-1,1)*G8*I8,2)) | L8: =IF(OR(A8="",B8=""),"",IFERROR(MATCH(B8,Settings!$N$13:$N$24,0),"")) | M8: =IF(AND(A8<>"",A8=Statement!$C$6,L8=Statement!$K$7),COUNTIFS(A$6:A8,Statement!$C$6,L$6:L8,Statement!$K$7),"")
I9: =IF(OR(A9="",G9=""),"",IF(H9="",IFERROR(INDEX(Settings!$F$13:$F$27,MATCH(A9,Settings!$C$13:$C$27,0)),0),H9)) | J9: =IF(I9="","",ROUND(IF(F9="Clawback",-1,1)*G9*I9,2)) | L9: =IF(OR(A9="",B9=""),"",IFERROR(MATCH(B9,Settings!$N$13:$N$24,0),"")) | M9: =IF(AND(A9<>"",A9=Statement!$C$6,L9=Statement!$K$7),COUNTIFS(A$6:A9,Statement!$C$6,L$6:L9,Statement!$K$7),"")
I10: =IF(OR(A10="",G10=""),"",IF(H10="",IFERROR(INDEX(Settings!$F$13:$F$27,MATCH(A10,Settings!$C$13:$C$27,0)),0),H10)) | J10: =IF(I10="","",ROUND(IF(F10="Clawback",-1,1)*G10*I10,2)) | L10: =IF(OR(A10="",B10=""),"",IFERROR(MATCH(B10,Settings!$N$13:$N$24,0),"")) | M10: =IF(AND(A10<>"",A10=Statement!$C$6,L10=Statement!$K$7),COUNTIFS(A$6:A10,Statement!$C$6,L$6:L10,Statement!$K$7),"")
I11: =IF(OR(A11="",G11=""),"",IF(H11="",IFERROR(INDEX(Settings!$F$13:$F$27,MATCH(A11,Settings!$C$13:$C$27,0)),0),H11)) | J11: =IF(I11="","",ROUND(IF(F11="Clawback",-1,1)*G11*I11,2)) | L11: =IF(OR(A11="",B11=""),"",IFERROR(MATCH(B11,Settings!$N$13:$N$24,0),"")) | M11: =IF(AND(A11<>"",A11=Statement!$C$6,L11=Statement!$K$7),COUNTIFS(A$6:A11,Statement!$C$6,L$6:L11,Statement!$K$7),"")
I12: =IF(OR(A12="",G12=""),"",IF(H12="",IFERROR(INDEX(Settings!$F$13:$F$27,MATCH(A12,Settings!$C$13:$C$27,0)),0),H12)) | J12: =IF(I12="","",ROUND(IF(F12="Clawback",-1,1)*G12*I12,2)) | L12: =IF(OR(A12="",B12=""),"",IFERROR(MATCH(B12,Settings!$N$13:$N$24,0),"")) | M12: =IF(AND(A12<>"",A12=Statement!$C$6,L12=Statement!$K$7),COUNTIFS(A$6:A12,Statement!$C$6,L$6:L12,Statement!$K$7),"")
I13: =IF(OR(A13="",G13=""),"",IF(H13="",IFERROR(INDEX(Settings!$F$13:$F$27,MATCH(A13,Settings!$C$13:$C$27,0)),0),H13)) | J13: =IF(I13="","",ROUND(IF(F13="Clawback",-1,1)*G13*I13,2)) | L13: =IF(OR(A13="",B13=""),"",IFERROR(MATCH(B13,Settings!$N$13:$N$24,0),"")) | M13: =IF(AND(A13<>"",A13=Statement!$C$6,L13=Statement!$K$7),COUNTIFS(A$6:A13,Statement!$C$6,L$6:L13,Statement!$K$7),"")
I14: =IF(OR(A14="",G14=""),"",IF(H14="",IFERROR(INDEX(Settings!$F$13:$F$27,MATCH(A14,Settings!$C$13:$C$27,0)),0),H14)) | J14: =IF(I14="","",ROUND(IF(F14="Clawback",-1,1)*G14*I14,2)) | L14: =IF(OR(A14="",B14=""),"",IFERROR(MATCH(B14,Settings!$N$13:$N$24,0),"")) | M14: =IF(AND(A14<>"",A14=Statement!$C$6,L14=Statement!$K$7),COUNTIFS(A$6:A14,Statement!$C$6,L$6:L14,Statement!$K$7),"")
I15: =IF(OR(A15="",G15=""),"",IF(H15="",IFERROR(INDEX(Settings!$F$13:$F$27,MATCH(A15,Settings!$C$13:$C$27,0)),0),H15)) | J15: =IF(I15="","",ROUND(IF(F15="Clawback",-1,1)*G15*I15,2)) | L15: =IF(OR(A15="",B15=""),"",IFERROR(MATCH(B15,Settings!$N$13:$N$24,0),"")) | M15: =IF(AND(A15<>"",A15=Statement!$C$6,L15=Statement!$K$7),COUNTIFS(A$6:A15,Statement!$C$6,L$6:L15,Statement!$K$7),"")
I16: =IF(OR(A16="",G16=""),"",IF(H16="",IFERROR(INDEX(Settings!$F$13:$F$27,MATCH(A16,Settings!$C$13:$C$27,0)),0),H16)) | J16: =IF(I16="","",ROUND(IF(F16="Clawback",-1,1)*G16*I16,2)) | L16: =IF(OR(A16="",B16=""),"",IFERROR(MATCH(B16,Settings!$N$13:$N$24,0),"")) | M16: =IF(AND(A16<>"",A16=Statement!$C$6,L16=Statement!$K$7),COUNTIFS(A$6:A16,Statement!$C$6,L$6:L16,Statement!$K$7),"")
I17: =IF(OR(A17="",G17=""),"",IF(H17="",IFERROR(INDEX(Settings!$F$13:$F$27,MATCH(A17,Settings!$C$13:$C$27,0)),0),H17)) | J17: =IF(I17="","",ROUND(IF(F17="Clawback",-1,1)*G17*I17,2)) | L17: =IF(OR(A17="",B17=""),"",IFERROR(MATCH(B17,Settings!$N$13:$N$24,0),"")) | M17: =IF(AND(A17<>"",A17=Statement!$C$6,L17=Statement!$K$7),COUNTIFS(A$6:A17,Statement!$C$6,L$6:L17,Statement!$K$7),"")
I18: =IF(OR(A18="",G18=""),"",IF(H18="",IFERROR(INDEX(Settings!$F$13:$F$27,MATCH(A18,Settings!$C$13:$C$27,0)),0),H18)) | J18: =IF(I18="","",ROUND(IF(F18="Clawback",-1,1)*G18*I18,2)) | L18: =IF(OR(A18="",B18=""),"",IFERROR(MATCH(B18,Settings!$N$13:$N$24,0),"")) | M18: =IF(AND(A18<>"",A18=Statement!$C$6,L18=Statement!$K$7),COUNTIFS(A$6:A18,Statement!$C$6,L$6:L18,Statement!$K$7),"")
I19: =IF(OR(A19="",G19=""),"",IF(H19="",IFERROR(INDEX(Settings!$F$13:$F$27,MATCH(A19,Settings!$C$13:$C$27,0)),0),H19)) | J19: =IF(I19="","",ROUND(IF(F19="Clawback",-1,1)*G19*I19,2)) | L19: =IF(OR(A19="",B19=""),"",IFERROR(MATCH(B19,Settings!$N$13:$N$24,0),"")) | M19: =IF(AND(A19<>"",A19=Statement!$C$6,L19=Statement!$K$7),COUNTIFS(A$6:A19,Statement!$C$6,L$6:L19,Statement!$K$7),"")
... I105: =IF(OR(A105="",G105=""),"",IF(H105="",IFERROR(INDEX(Settings!$F$13:$F$27,MATCH(A105,Settings!$C$13:$C$27,0)),0),H105)) | J105: =IF(I105="","",ROUND(IF(F105="Clawback",-1,1)*G105*I105,2)) | L105: =IF(OR(A105="",B105=""),"",IFERROR(MATCH(B105,Settings!$N$13:$N$24,0),"")) | M105: =IF(AND(A105<>"",A105=Statement!$C$6,L105=Statement!$K$7),COUNTIFS(A$6:A105,Statement!$C$6,L$6:L105,Statement!$K$7),"")

Sheet Statement
B2: Commission statement
B3: =Settings!$C$6 -> Example ApS
B4: ="Pick a rep and a month in the lavender cells. All amounts in "&Settings!$C$9&"." -> Pick a rep and a month in the lavender cells. All amounts in DKK.
J5: Helper cells (not printed)
B6: Rep | C6: Anna Holm | E6: Employee no. | F6: =IF($K$6=0,"",IF(INDEX(Settings!$B$13:$B$27,$K$6)="","",INDEX(Settings!$B$13:$B$27,$K$6))) -> 101 | J6: Rep no. | K6: =IFERROR(MATCH($C$6,Settings!$C$13:$C$27,0),0) -> 1
B7: Month | C7: March | D7: =Settings!$C$7 -> 2026 | E7: Team | F7: =IF($K$6=0,"",IF(INDEX(Settings!$D$13:$D$27,$K$6)="","",INDEX(Settings!$D$13:$D$27,$K$6))) -> North | J7: Month no. | K7: =IFERROR(MATCH($C$7,Settings!$N$13:$N$24,0),0) -> 3
B8: Paid on | C8: 46142 | E8: Manager | F8: =IF($K$6=0,"",IF(INDEX(Settings!$E$13:$E$27,$K$6)="","",INDEX(Settings!$E$13:$E$27,$K$6))) -> Mette Lund | J8: First row in Calculation | K8: =IF(OR($K$6=0,$K$7=0),0,($K$6-1)*9+1) -> 1
B9: Default rate | C9: =IF($K$6=0,"",IF(INDEX(Settings!$F$13:$F$27,$K$6)="","",INDEX(Settings!$F$13:$F$27,$K$6))) -> 0.08 | E9: Draw | F9: =IF($K$6=0,"",IF(N(INDEX(Settings!$G$13:$G$27,$K$6))=0,"No draw",INDEX(Settings!$G$13:$G$27,$K$6))) -> 10000 | G9: =IF(OR($K$6=0,F9="No draw"),"",IF(INDEX(Settings!$J$13:$J$27,$K$6)="No","guarantee","recoverable")) -> recoverable | J9: Key | K9: =$C$7&"|"&$C$6 -> March|Anna Holm
J10: Row in Approvals | K10: =IFERROR(MATCH($K$9,Approvals!$K$6:$K$205,0),0) -> 1
B11: 1. Deals in the period
B12: Date | C12: Customer | D12: Deal ID | E12: Amount | F12: Tier | G12: Rate | H12: Commission
B13: =IF($J13=0,"",IF(INDEX(Deals!$B$6:$B$305,$J13)="","",INDEX(Deals!$B$6:$B$305,$J13))) -> 46085 | C13: =IF($J13=0,"",IF(INDEX(Deals!$C$6:$C$305,$J13)="","",INDEX(Deals!$C$6:$C$305,$J13))) -> Kystvej Logistik | D13: =IF($J13=0,"",IF(INDEX(Deals!$D$6:$D$305,$J13)="","",INDEX(Deals!$D$6:$D$305,$J13))) -> D-1007 | E13: =IF($J13=0,"",IF(INDEX(Deals!$E$6:$E$305,$J13)="","",INDEX(Deals!$E$6:$E$305,$J13))) -> 120000 | F13: =IF($J13=0,"",IF(INDEX(Deals!$F$6:$F$305,$J13)="","",INDEX(Deals!$F$6:$F$305,$J13))) -> Tier 1 | G13: =IF($J13=0,"",IF(INDEX(Deals!$H$6:$H$305,$J13)="","",INDEX(Deals!$H$6:$H$305,$J13))) -> 0.08 | H13: =IF($J13=0,"",IF(INDEX(Deals!$I$6:$I$305,$J13)="","",INDEX(Deals!$I$6:$I$305,$J13))) -> 9600 | J13: =IFERROR(MATCH(1,Deals!$K$6:$K$305,0),0) -> 7
B14: =IF($J14=0,"",IF(INDEX(Deals!$B$6:$B$305,$J14)="","",INDEX(Deals!$B$6:$B$305,$J14))) -> 46099 | C14: =IF($J14=0,"",IF(INDEX(Deals!$C$6:$C$305,$J14)="","",INDEX(Deals!$C$6:$C$305,$J14))) -> Bølge Media | D14: =IF($J14=0,"",IF(INDEX(Deals!$D$6:$D$305,$J14)="","",INDEX(Deals!$D$6:$D$305,$J14))) -> D-1010 | E14: =IF($J14=0,"",IF(INDEX(Deals!$E$6:$E$305,$J14)="","",INDEX(Deals!$E$6:$E$305,$J14))) -> 90000 | F14: =IF($J14=0,"",IF(INDEX(Deals!$F$6:$F$305,$J14)="","",INDEX(Deals!$F$6:$F$305,$J14))) -> Tier 2 | G14: =IF($J14=0,"",IF(INDEX(Deals!$H$6:$H$305,$J14)="","",INDEX(Deals!$H$6:$H$305,$J14))) -> 0.1 | H14: =IF($J14=0,"",IF(INDEX(Deals!$I$6:$I$305,$J14)="","",INDEX(Deals!$I$6:$I$305,$J14))) -> 9000 | J14: =IFERROR(MATCH(2,Deals!$K$6:$K$305,0),0) -> 10
B15: =IF($J15=0,"",IF(INDEX(Deals!$B$6:$B$305,$J15)="","",INDEX(Deals!$B$6:$B$305,$J15))) -> 46108 | C15: =IF($J15=0,"",IF(INDEX(Deals!$C$6:$C$305,$J15)="","",INDEX(Deals!$C$6:$C$305,$J15))) -> Skovgaard & Co | D15: =IF($J15=0,"",IF(INDEX(Deals!$D$6:$D$305,$J15)="","",INDEX(Deals!$D$6:$D$305,$J15))) -> D-1013 | E15: =IF($J15=0,"",IF(INDEX(Deals!$E$6:$E$305,$J15)="","",INDEX(Deals!$E$6:$E$305,$J15))) -> 60000 | F15: =IF($J15=0,"",IF(INDEX(Deals!$F$6:$F$305,$J15)="","",INDEX(Deals!$F$6:$F$305,$J15))) -> Tier 2 | G15: =IF($J15=0,"",IF(INDEX(Deals!$H$6:$H$305,$J15)="","",INDEX(Deals!$H$6:$H$305,$J15))) -> 0.1 | H15: =IF($J15=0,"",IF(INDEX(Deals!$I$6:$I$305,$J15)="","",INDEX(Deals!$I$6:$I$305,$J15))) -> 6000 | J15: =IFERROR(MATCH(3,Deals!$K$6:$K$305,0),0) -> 13
B16: =IF($J16=0,"",IF(INDEX(Deals!$B$6:$B$305,$J16)="","",INDEX(Deals!$B$6:$B$305,$J16))) | C16: =IF($J16=0,"",IF(INDEX(Deals!$C$6:$C$305,$J16)="","",INDEX(Deals!$C$6:$C$305,$J16))) | D16: =IF($J16=0,"",IF(INDEX(Deals!$D$6:$D$305,$J16)="","",INDEX(Deals!$D$6:$D$305,$J16))) | E16: =IF($J16=0,"",IF(INDEX(Deals!$E$6:$E$305,$J16)="","",INDEX(Deals!$E$6:$E$305,$J16))) | F16: =IF($J16=0,"",IF(INDEX(Deals!$F$6:$F$305,$J16)="","",INDEX(Deals!$F$6:$F$305,$J16))) | G16: =IF($J16=0,"",IF(INDEX(Deals!$H$6:$H$305,$J16)="","",INDEX(Deals!$H$6:$H$305,$J16))) | H16: =IF($J16=0,"",IF(INDEX(Deals!$I$6:$I$305,$J16)="","",INDEX(Deals!$I$6:$I$305,$J16))) | J16: =IFERROR(MATCH(4,Deals!$K$6:$K$305,0),0) -> 0
B17: =IF($J17=0,"",IF(INDEX(Deals!$B$6:$B$305,$J17)="","",INDEX(Deals!$B$6:$B$305,$J17))) | C17: =IF($J17=0,"",IF(INDEX(Deals!$C$6:$C$305,$J17)="","",INDEX(Deals!$C$6:$C$305,$J17))) | D17: =IF($J17=0,"",IF(INDEX(Deals!$D$6:$D$305,$J17)="","",INDEX(Deals!$D$6:$D$305,$J17))) | E17: =IF($J17=0,"",IF(INDEX(Deals!$E$6:$E$305,$J17)="","",INDEX(Deals!$E$6:$E$305,$J17))) | F17: =IF($J17=0,"",IF(INDEX(Deals!$F$6:$F$305,$J17)="","",INDEX(Deals!$F$6:$F$305,$J17))) | G17: =IF($J17=0,"",IF(INDEX(Deals!$H$6:$H$305,$J17)="","",INDEX(Deals!$H$6:$H$305,$J17))) | H17: =IF($J17=0,"",IF(INDEX(Deals!$I$6:$I$305,$J17)="","",INDEX(Deals!$I$6:$I$305,$J17))) | J17: =IFERROR(MATCH(5,Deals!$K$6:$K$305,0),0) -> 0
B18: =IF($J18=0,"",IF(INDEX(Deals!$B$6:$B$305,$J18)="","",INDEX(Deals!$B$6:$B$305,$J18))) | C18: =IF($J18=0,"",IF(INDEX(Deals!$C$6:$C$305,$J18)="","",INDEX(Deals!$C$6:$C$305,$J18))) | D18: =IF($J18=0,"",IF(INDEX(Deals!$D$6:$D$305,$J18)="","",INDEX(Deals!$D$6:$D$305,$J18))) | E18: =IF($J18=0,"",IF(INDEX(Deals!$E$6:$E$305,$J18)="","",INDEX(Deals!$E$6:$E$305,$J18))) | F18: =IF($J18=0,"",IF(INDEX(Deals!$F$6:$F$305,$J18)="","",INDEX(Deals!$F$6:$F$305,$J18))) | G18: =IF($J18=0,"",IF(INDEX(Deals!$H$6:$H$305,$J18)="","",INDEX(Deals!$H$6:$H$305,$J18))) | H18: =IF($J18=0,"",IF(INDEX(Deals!$I$6:$I$305,$J18)="","",INDEX(Deals!$I$6:$I$305,$J18))) | J18: =IFERROR(MATCH(6,Deals!$K$6:$K$305,0),0) -> 0
B19: =IF($J19=0,"",IF(INDEX(Deals!$B$6:$B$305,$J19)="","",INDEX(Deals!$B$6:$B$305,$J19))) | C19: =IF($J19=0,"",IF(INDEX(Deals!$C$6:$C$305,$J19)="","",INDEX(Deals!$C$6:$C$305,$J19))) | D19: =IF($J19=0,"",IF(INDEX(Deals!$D$6:$D$305,$J19)="","",INDEX(Deals!$D$6:$D$305,$J19))) | E19: =IF($J19=0,"",IF(INDEX(Deals!$E$6:$E$305,$J19)="","",INDEX(Deals!$E$6:$E$305,$J19))) | F19: =IF($J19=0,"",IF(INDEX(Deals!$F$6:$F$305,$J19)="","",INDEX(Deals!$F$6:$F$305,$J19))) | G19: =IF($J19=0,"",IF(INDEX(Deals!$H$6:$H$305,$J19)="","",INDEX(Deals!$H$6:$H$305,$J19))) | H19: =IF($J19=0,"",IF(INDEX(Deals!$I$6:$I$305,$J19)="","",INDEX(Deals!$I$6:$I$305,$J19))) | J19: =IFERROR(MATCH(7,Deals!$K$6:$K$305,0),0) -> 0
B20: =IF($J20=0,"",IF(INDEX(Deals!$B$6:$B$305,$J20)="","",INDEX(Deals!$B$6:$B$305,$J20))) | C20: =IF($J20=0,"",IF(INDEX(Deals!$C$6:$C$305,$J20)="","",INDEX(Deals!$C$6:$C$305,$J20))) | D20: =IF($J20=0,"",IF(INDEX(Deals!$D$6:$D$305,$J20)="","",INDEX(Deals!$D$6:$D$305,$J20))) | E20: =IF($J20=0,"",IF(INDEX(Deals!$E$6:$E$305,$J20)="","",INDEX(Deals!$E$6:$E$305,$J20))) | F20: =IF($J20=0,"",IF(INDEX(Deals!$F$6:$F$305,$J20)="","",INDEX(Deals!$F$6:$F$305,$J20))) | G20: =IF($J20=0,"",IF(INDEX(Deals!$H$6:$H$305,$J20)="","",INDEX(Deals!$H$6:$H$305,$J20))) | H20: =IF($J20=0,"",IF(INDEX(Deals!$I$6:$I$305,$J20)="","",INDEX(Deals!$I$6:$I$305,$J20))) | J20: =IFERROR(MATCH(8,Deals!$K$6:$K$305,0),0) -> 0
B21: =IF($J21=0,"",IF(INDEX(Deals!$B$6:$B$305,$J21)="","",INDEX(Deals!$B$6:$B$305,$J21))) | C21: =IF($J21=0,"",IF(INDEX(Deals!$C$6:$C$305,$J21)="","",INDEX(Deals!$C$6:$C$305,$J21))) | D21: =IF($J21=0,"",IF(INDEX(Deals!$D$6:$D$305,$J21)="","",INDEX(Deals!$D$6:$D$305,$J21))) | E21: =IF($J21=0,"",IF(INDEX(Deals!$E$6:$E$305,$J21)="","",INDEX(Deals!$E$6:$E$305,$J21))) | F21: =IF($J21=0,"",IF(INDEX(Deals!$F$6:$F$305,$J21)="","",INDEX(Deals!$F$6:$F$305,$J21))) | G21: =IF($J21=0,"",IF(INDEX(Deals!$H$6:$H$305,$J21)="","",INDEX(Deals!$H$6:$H$305,$J21))) | H21: =IF($J21=0,"",IF(INDEX(Deals!$I$6:$I$305,$J21)="","",INDEX(Deals!$I$6:$I$305,$J21))) | J21: =IFERROR(MATCH(9,Deals!$K$6:$K$305,0),0) -> 0
B22: =IF($J22=0,"",IF(INDEX(Deals!$B$6:$B$305,$J22)="","",INDEX(Deals!$B$6:$B$305,$J22))) | C22: =IF($J22=0,"",IF(INDEX(Deals!$C$6:$C$305,$J22)="","",INDEX(Deals!$C$6:$C$305,$J22))) | D22: =IF($J22=0,"",IF(INDEX(Deals!$D$6:$D$305,$J22)="","",INDEX(Deals!$D$6:$D$305,$J22))) | E22: =IF($J22=0,"",IF(INDEX(Deals!$E$6:$E$305,$J22)="","",INDEX(Deals!$E$6:$E$305,$J22))) | F22: =IF($J22=0,"",IF(INDEX(Deals!$F$6:$F$305,$J22)="","",INDEX(Deals!$F$6:$F$305,$J22))) | G22: =IF($J22=0,"",IF(INDEX(Deals!$H$6:$H$305,$J22)="","",INDEX(Deals!$H$6:$H$305,$J22))) | H22: =IF($J22=0,"",IF(INDEX(Deals!$I$6:$I$305,$J22)="","",INDEX(Deals!$I$6:$I$305,$J22))) | J22: =IFERROR(MATCH(10,Deals!$K$6:$K$305,0),0) -> 0
B23: =IF($J23=0,"",IF(INDEX(Deals!$B$6:$B$305,$J23)="","",INDEX(Deals!$B$6:$B$305,$J23))) | C23: =IF($J23=0,"",IF(INDEX(Deals!$C$6:$C$305,$J23)="","",INDEX(Deals!$C$6:$C$305,$J23))) | D23: =IF($J23=0,"",IF(INDEX(Deals!$D$6:$D$305,$J23)="","",INDEX(Deals!$D$6:$D$305,$J23))) | E23: =IF($J23=0,"",IF(INDEX(Deals!$E$6:$E$305,$J23)="","",INDEX(Deals!$E$6:$E$305,$J23))) | F23: =IF($J23=0,"",IF(INDEX(Deals!$F$6:$F$305,$J23)="","",INDEX(Deals!$F$6:$F$305,$J23))) | G23: =IF($J23=0,"",IF(INDEX(Deals!$H$6:$H$305,$J23)="","",INDEX(Deals!$H$6:$H$305,$J23))) | H23: =IF($J23=0,"",IF(INDEX(Deals!$I$6:$I$305,$J23)="","",INDEX(Deals!$I$6:$I$305,$J23))) | J23: =IFERROR(MATCH(11,Deals!$K$6:$K$305,0),0) -> 0
B24: =IF($J24=0,"",IF(INDEX(Deals!$B$6:$B$305,$J24)="","",INDEX(Deals!$B$6:$B$305,$J24))) | C24: =IF($J24=0,"",IF(INDEX(Deals!$C$6:$C$305,$J24)="","",INDEX(Deals!$C$6:$C$305,$J24))) | D24: =IF($J24=0,"",IF(INDEX(Deals!$D$6:$D$305,$J24)="","",INDEX(Deals!$D$6:$D$305,$J24))) | E24: =IF($J24=0,"",IF(INDEX(Deals!$E$6:$E$305,$J24)="","",INDEX(Deals!$E$6:$E$305,$J24))) | F24: =IF($J24=0,"",IF(INDEX(Deals!$F$6:$F$305,$J24)="","",INDEX(Deals!$F$6:$F$305,$J24))) | G24: =IF($J24=0,"",IF(INDEX(Deals!$H$6:$H$305,$J24)="","",INDEX(Deals!$H$6:$H$305,$J24))) | H24: =IF($J24=0,"",IF(INDEX(Deals!$I$6:$I$305,$J24)="","",INDEX(Deals!$I$6:$I$305,$J24))) | J24: =IFERROR(MATCH(12,Deals!$K$6:$K$305,0),0) -> 0
B25: =IF($J25=0,"",IF(INDEX(Deals!$B$6:$B$305,$J25)="","",INDEX(Deals!$B$6:$B$305,$J25))) | C25: =IF($J25=0,"",IF(INDEX(Deals!$C$6:$C$305,$J25)="","",INDEX(Deals!$C$6:$C$305,$J25))) | D25: =IF($J25=0,"",IF(INDEX(Deals!$D$6:$D$305,$J25)="","",INDEX(Deals!$D$6:$D$305,$J25))) | E25: =IF($J25=0,"",IF(INDEX(Deals!$E$6:$E$305,$J25)="","",INDEX(Deals!$E$6:$E$305,$J25))) | F25: =IF($J25=0,"",IF(INDEX(Deals!$F$6:$F$305,$J25)="","",INDEX(Deals!$F$6:$F$305,$J25))) | G25: =IF($J25=0,"",IF(INDEX(Deals!$H$6:$H$305,$J25)="","",INDEX(Deals!$H$6:$H$305,$J25))) | H25: =IF($J25=0,"",IF(INDEX(Deals!$I$6:$I$305,$J25)="","",INDEX(Deals!$I$6:$I$305,$J25))) | J25: =IFERROR(MATCH(13,Deals!$K$6:$K$305,0),0) -> 0
B26: =IF($J26=0,"",IF(INDEX(Deals!$B$6:$B$305,$J26)="","",INDEX(Deals!$B$6:$B$305,$J26))) | C26: =IF($J26=0,"",IF(INDEX(Deals!$C$6:$C$305,$J26)="","",INDEX(Deals!$C$6:$C$305,$J26))) | D26: =IF($J26=0,"",IF(INDEX(Deals!$D$6:$D$305,$J26)="","",INDEX(Deals!$D$6:$D$305,$J26))) | E26: =IF($J26=0,"",IF(INDEX(Deals!$E$6:$E$305,$J26)="","",INDEX(Deals!$E$6:$E$305,$J26))) | F26: =IF($J26=0,"",IF(INDEX(Deals!$F$6:$F$305,$J26)="","",INDEX(Deals!$F$6:$F$305,$J26))) | G26: =IF($J26=0,"",IF(INDEX(Deals!$H$6:$H$305,$J26)="","",INDEX(Deals!$H$6:$H$305,$J26))) | H26: =IF($J26=0,"",IF(INDEX(Deals!$I$6:$I$305,$J26)="","",INDEX(Deals!$I$6:$I$305,$J26))) | J26: =IFERROR(MATCH(14,Deals!$K$6:$K$305,0),0) -> 0
B27: =IF($J27=0,"",IF(INDEX(Deals!$B$6:$B$305,$J27)="","",INDEX(Deals!$B$6:$B$305,$J27))) | C27: =IF($J27=0,"",IF(INDEX(Deals!$C$6:$C$305,$J27)="","",INDEX(Deals!$C$6:$C$305,$J27))) | D27: =IF($J27=0,"",IF(INDEX(Deals!$D$6:$D$305,$J27)="","",INDEX(Deals!$D$6:$D$305,$J27))) | E27: =IF($J27=0,"",IF(INDEX(Deals!$E$6:$E$305,$J27)="","",INDEX(Deals!$E$6:$E$305,$J27))) | F27: =IF($J27=0,"",IF(INDEX(Deals!$F$6:$F$305,$J27)="","",INDEX(Deals!$F$6:$F$305,$J27))) | G27: =IF($J27=0,"",IF(INDEX(Deals!$H$6:$H$305,$J27)="","",INDEX(Deals!$H$6:$H$305,$J27))) | H27: =IF($J27=0,"",IF(INDEX(Deals!$I$6:$I$305,$J27)="","",INDEX(Deals!$I$6:$I$305,$J27))) | J27: =IFERROR(MATCH(15,Deals!$K$6:$K$305,0),0) -> 0
B28: =IF($J28=0,"",IF(INDEX(Deals!$B$6:$B$305,$J28)="","",INDEX(Deals!$B$6:$B$305,$J28))) | C28: =IF($J28=0,"",IF(INDEX(Deals!$C$6:$C$305,$J28)="","",INDEX(Deals!$C$6:$C$305,$J28))) | D28: =IF($J28=0,"",IF(INDEX(Deals!$D$6:$D$305,$J28)="","",INDEX(Deals!$D$6:$D$305,$J28))) | E28: =IF($J28=0,"",IF(INDEX(Deals!$E$6:$E$305,$J28)="","",INDEX(Deals!$E$6:$E$305,$J28))) | F28: =IF($J28=0,"",IF(INDEX(Deals!$F$6:$F$305,$J28)="","",INDEX(Deals!$F$6:$F$305,$J28))) | G28: =IF($J28=0,"",IF(INDEX(Deals!$H$6:$H$305,$J28)="","",INDEX(Deals!$H$6:$H$305,$J28))) | H28: =IF($J28=0,"",IF(INDEX(Deals!$I$6:$I$305,$J28)="","",INDEX(Deals!$I$6:$I$305,$J28))) | J28: =IFERROR(MATCH(16,Deals!$K$6:$K$305,0),0) -> 0
B29: =IF($J29=0,"",IF(INDEX(Deals!$B$6:$B$305,$J29)="","",INDEX(Deals!$B$6:$B$305,$J29))) | C29: =IF($J29=0,"",IF(INDEX(Deals!$C$6:$C$305,$J29)="","",INDEX(Deals!$C$6:$C$305,$J29))) | D29: =IF($J29=0,"",IF(INDEX(Deals!$D$6:$D$305,$J29)="","",INDEX(Deals!$D$6:$D$305,$J29))) | E29: =IF($J29=0,"",IF(INDEX(Deals!$E$6:$E$305,$J29)="","",INDEX(Deals!$E$6:$E$305,$J29))) | F29: =IF($J29=0,"",IF(INDEX(Deals!$F$6:$F$305,$J29)="","",INDEX(Deals!$F$6:$F$305,$J29))) | G29: =IF($J29=0,"",IF(INDEX(Deals!$H$6:$H$305,$J29)="","",INDEX(Deals!$H$6:$H$305,$J29))) | H29: =IF($J29=0,"",IF(INDEX(Deals!$I$6:$I$305,$J29)="","",INDEX(Deals!$I$6:$I$305,$J29))) | J29: =IFERROR(MATCH(17,Deals!$K$6:$K$305,0),0) -> 0
B30: =IF($J30=0,"",IF(INDEX(Deals!$B$6:$B$305,$J30)="","",INDEX(Deals!$B$6:$B$305,$J30))) | C30: =IF($J30=0,"",IF(INDEX(Deals!$C$6:$C$305,$J30)="","",INDEX(Deals!$C$6:$C$305,$J30))) | D30: =IF($J30=0,"",IF(INDEX(Deals!$D$6:$D$305,$J30)="","",INDEX(Deals!$D$6:$D$305,$J30))) | E30: =IF($J30=0,"",IF(INDEX(Deals!$E$6:$E$305,$J30)="","",INDEX(Deals!$E$6:$E$305,$J30))) | F30: =IF($J30=0,"",IF(INDEX(Deals!$F$6:$F$305,$J30)="","",INDEX(Deals!$F$6:$F$305,$J30))) | G30: =IF($J30=0,"",IF(INDEX(Deals!$H$6:$H$305,$J30)="","",INDEX(Deals!$H$6:$H$305,$J30))) | H30: =IF($J30=0,"",IF(INDEX(Deals!$I$6:$I$305,$J30)="","",INDEX(Deals!$I$6:$I$305,$J30))) | J30: =IFERROR(MATCH(18,Deals!$K$6:$K$305,0),0) -> 0
B31: =IF($J31=0,"",IF(INDEX(Deals!$B$6:$B$305,$J31)="","",INDEX(Deals!$B$6:$B$305,$J31))) | C31: =IF($J31=0,"",IF(INDEX(Deals!$C$6:$C$305,$J31)="","",INDEX(Deals!$C$6:$C$305,$J31))) | D31: =IF($J31=0,"",IF(INDEX(Deals!$D$6:$D$305,$J31)="","",INDEX(Deals!$D$6:$D$305,$J31))) | E31: =IF($J31=0,"",IF(INDEX(Deals!$E$6:$E$305,$J31)="","",INDEX(Deals!$E$6:$E$305,$J31))) | F31: =IF($J31=0,"",IF(INDEX(Deals!$F$6:$F$305,$J31)="","",INDEX(Deals!$F$6:$F$305,$J31))) | G31: =IF($J31=0,"",IF(INDEX(Deals!$H$6:$H$305,$J31)="","",INDEX(Deals!$H$6:$H$305,$J31))) | H31: =IF($J31=0,"",IF(INDEX(Deals!$I$6:$I$305,$J31)="","",INDEX(Deals!$I$6:$I$305,$J31))) | J31: =IFERROR(MATCH(19,Deals!$K$6:$K$305,0),0) -> 0
B32: =IF($J32=0,"",IF(INDEX(Deals!$B$6:$B$305,$J32)="","",INDEX(Deals!$B$6:$B$305,$J32))) | C32: =IF($J32=0,"",IF(INDEX(Deals!$C$6:$C$305,$J32)="","",INDEX(Deals!$C$6:$C$305,$J32))) | D32: =IF($J32=0,"",IF(INDEX(Deals!$D$6:$D$305,$J32)="","",INDEX(Deals!$D$6:$D$305,$J32))) | E32: =IF($J32=0,"",IF(INDEX(Deals!$E$6:$E$305,$J32)="","",INDEX(Deals!$E$6:$E$305,$J32))) | F32: =IF($J32=0,"",IF(INDEX(Deals!$F$6:$F$305,$J32)="","",INDEX(Deals!$F$6:$F$305,$J32))) | G32: =IF($J32=0,"",IF(INDEX(Deals!$H$6:$H$305,$J32)="","",INDEX(Deals!$H$6:$H$305,$J32))) | H32: =IF($J32=0,"",IF(INDEX(Deals!$I$6:$I$305,$J32)="","",INDEX(Deals!$I$6:$I$305,$J32))) | J32: =IFERROR(MATCH(20,Deals!$K$6:$K$305,0),0) -> 0
B33: =IF($J33=0,"",IF(INDEX(Deals!$B$6:$B$305,$J33)="","",INDEX(Deals!$B$6:$B$305,$J33))) | C33: =IF($J33=0,"",IF(INDEX(Deals!$C$6:$C$305,$J33)="","",INDEX(Deals!$C$6:$C$305,$J33))) | D33: =IF($J33=0,"",IF(INDEX(Deals!$D$6:$D$305,$J33)="","",INDEX(Deals!$D$6:$D$305,$J33))) | E33: =IF($J33=0,"",IF(INDEX(Deals!$E$6:$E$305,$J33)="","",INDEX(Deals!$E$6:$E$305,$J33))) | F33: =IF($J33=0,"",IF(INDEX(Deals!$F$6:$F$305,$J33)="","",INDEX(Deals!$F$6:$F$305,$J33))) | G33: =IF($J33=0,"",IF(INDEX(Deals!$H$6:$H$305,$J33)="","",INDEX(Deals!$H$6:$H$305,$J33))) | H33: =IF($J33=0,"",IF(INDEX(Deals!$I$6:$I$305,$J33)="","",INDEX(Deals!$I$6:$I$305,$J33))) | J33: =IFERROR(MATCH(21,Deals!$K$6:$K$305,0),0) -> 0
B34: =IF($J34=0,"",IF(INDEX(Deals!$B$6:$B$305,$J34)="","",INDEX(Deals!$B$6:$B$305,$J34))) | C34: =IF($J34=0,"",IF(INDEX(Deals!$C$6:$C$305,$J34)="","",INDEX(Deals!$C$6:$C$305,$J34))) | D34: =IF($J34=0,"",IF(INDEX(Deals!$D$6:$D$305,$J34)="","",INDEX(Deals!$D$6:$D$305,$J34))) | E34: =IF($J34=0,"",IF(INDEX(Deals!$E$6:$E$305,$J34)="","",INDEX(Deals!$E$6:$E$305,$J34))) | F34: =IF($J34=0,"",IF(INDEX(Deals!$F$6:$F$305,$J34)="","",INDEX(Deals!$F$6:$F$305,$J34))) | G34: =IF($J34=0,"",IF(INDEX(Deals!$H$6:$H$305,$J34)="","",INDEX(Deals!$H$6:$H$305,$J34))) | H34: =IF($J34=0,"",IF(INDEX(Deals!$I$6:$I$305,$J34)="","",INDEX(Deals!$I$6:$I$305,$J34))) | J34: =IFERROR(MATCH(22,Deals!$K$6:$K$305,0),0) -> 0
B35: =IF($J35=0,"",IF(INDEX(Deals!$B$6:$B$305,$J35)="","",INDEX(Deals!$B$6:$B$305,$J35))) | C35: =IF($J35=0,"",IF(INDEX(Deals!$C$6:$C$305,$J35)="","",INDEX(Deals!$C$6:$C$305,$J35))) | D35: =IF($J35=0,"",IF(INDEX(Deals!$D$6:$D$305,$J35)="","",INDEX(Deals!$D$6:$D$305,$J35))) | E35: =IF($J35=0,"",IF(INDEX(Deals!$E$6:$E$305,$J35)="","",INDEX(Deals!$E$6:$E$305,$J35))) | F35: =IF($J35=0,"",IF(INDEX(Deals!$F$6:$F$305,$J35)="","",INDEX(Deals!$F$6:$F$305,$J35))) | G35: =IF($J35=0,"",IF(INDEX(Deals!$H$6:$H$305,$J35)="","",INDEX(Deals!$H$6:$H$305,$J35))) | H35: =IF($J35=0,"",IF(INDEX(Deals!$I$6:$I$305,$J35)="","",INDEX(Deals!$I$6:$I$305,$J35))) | J35: =IFERROR(MATCH(23,Deals!$K$6:$K$305,0),0) -> 0
B36: =IF($J36=0,"",IF(INDEX(Deals!$B$6:$B$305,$J36)="","",INDEX(Deals!$B$6:$B$305,$J36))) | C36: =IF($J36=0,"",IF(INDEX(Deals!$C$6:$C$305,$J36)="","",INDEX(Deals!$C$6:$C$305,$J36))) | D36: =IF($J36=0,"",IF(INDEX(Deals!$D$6:$D$305,$J36)="","",INDEX(Deals!$D$6:$D$305,$J36))) | E36: =IF($J36=0,"",IF(INDEX(Deals!$E$6:$E$305,$J36)="","",INDEX(Deals!$E$6:$E$305,$J36))) | F36: =IF($J36=0,"",IF(INDEX(Deals!$F$6:$F$305,$J36)="","",INDEX(Deals!$F$6:$F$305,$J36))) | G36: =IF($J36=0,"",IF(INDEX(Deals!$H$6:$H$305,$J36)="","",INDEX(Deals!$H$6:$H$305,$J36))) | H36: =IF($J36=0,"",IF(INDEX(Deals!$I$6:$I$305,$J36)="","",INDEX(Deals!$I$6:$I$305,$J36))) | J36: =IFERROR(MATCH(24,Deals!$K$6:$K$305,0),0) -> 0
B37: =IF($J37=0,"",IF(INDEX(Deals!$B$6:$B$305,$J37)="","",INDEX(Deals!$B$6:$B$305,$J37))) | C37: =IF($J37=0,"",IF(INDEX(Deals!$C$6:$C$305,$J37)="","",INDEX(Deals!$C$6:$C$305,$J37))) | D37: =IF($J37=0,"",IF(INDEX(Deals!$D$6:$D$305,$J37)="","",INDEX(Deals!$D$6:$D$305,$J37))) | E37: =IF($J37=0,"",IF(INDEX(Deals!$E$6:$E$305,$J37)="","",INDEX(Deals!$E$6:$E$305,$J37))) | F37: =IF($J37=0,"",IF(INDEX(Deals!$F$6:$F$305,$J37)="","",INDEX(Deals!$F$6:$F$305,$J37))) | G37: =IF($J37=0,"",IF(INDEX(Deals!$H$6:$H$305,$J37)="","",INDEX(Deals!$H$6:$H$305,$J37))) | H37: =IF($J37=0,"",IF(INDEX(Deals!$I$6:$I$305,$J37)="","",INDEX(Deals!$I$6:$I$305,$J37))) | J37: =IFERROR(MATCH(25,Deals!$K$6:$K$305,0),0) -> 0
B38: A. Commission earned on deals | H38: =H57 -> 24600
B39: =IF($K$6*$K$7=0,"",COUNTIF(Deals!$K$6:$K$305,">0")&" deals in the period"&IF(COUNTIF(Deals!$K$6:$K$305,">25")>0,". Only the first 25 are listed, but all of them count in the statement below.","")) -> 3 deals in the period
B41: 2. Adjustments and clawbacks
B42: Original date | C42: Customer | D42: Deal ID | E42: Basis | F42: Type | G42: Rate | H42: Commission
...

Sheet Approvals
A2: Approvals
A3: One row per rep per month. Enter the date when each step is done. The payroll sheet counts a line as approved once finance has a date.
A5: Month | B5: Rep | C5: Rep confirmed | D5: Manager | E5: Manager approved | F5: Finance | G5: Finance approved | H5: Note | I5: Status | J5: Payable | K5: Key
A6: March | B6: Anna Holm | C6: 46114 | D6: Mette Lund | E6: 46115 | F6: Louise Winther | G6: 46118 | I6: =IF(OR(A6="",B6=""),"",IF(G6<>"","Approved",IF(E6<>"","Awaiting finance",IF(C6<>"","Awaiting manager","Awaiting rep")))) -> Approved | J6: =IF(OR(A6="",B6=""),"",IFERROR(INDEX(Calculation!$C$6:$N$140,(MATCH(B6,Settings!$C$13:$C$27,0)-1)*9+7,MATCH(A6,Settings!$N$13:$N$24,0)),"")) -> 7400 | K6: =IF(OR(A6="",B6=""),"",A6&"|"&B6) -> March|Anna Holm
A7: March | B7: Bo Jensen | C7: 46114 | D7: Mette Lund | E7: 46115 | H7: Finance is checking the Lindholm El invoice | I7: =IF(OR(A7="",B7=""),"",IF(G7<>"","Approved",IF(E7<>"","Awaiting finance",IF(C7<>"","Awaiting manager","Awaiting rep")))) -> Awaiting finance | J7: =IF(OR(A7="",B7=""),"",IFERROR(INDEX(Calculation!$C$6:$N$140,(MATCH(B7,Settings!$C$13:$C$27,0)-1)*9+7,MATCH(A7,Settings!$N$13:$N$24,0)),"")) -> 21000 | K7: =IF(OR(A7="",B7=""),"",A7&"|"&B7) -> March|Bo Jensen
A8: March | B8: Camilla Nørgaard | C8: 46113 | D8: Kasper Dahl | E8: 46114 | F8: Louise Winther | G8: 46118 | I8: =IF(OR(A8="",B8=""),"",IF(G8<>"","Approved",IF(E8<>"","Awaiting finance",IF(C8<>"","Awaiting manager","Awaiting rep")))) -> Approved | J8: =IF(OR(A8="",B8=""),"",IFERROR(INDEX(Calculation!$C$6:$N$140,(MATCH(B8,Settings!$C$13:$C$27,0)-1)*9+7,MATCH(A8,Settings!$N$13:$N$24,0)),"")) -> 5000 | K8: =IF(OR(A8="",B8=""),"",A8&"|"&B8) -> March|Camilla Nørgaard
I9: =IF(OR(A9="",B9=""),"",IF(G9<>"","Approved",IF(E9<>"","Awaiting finance",IF(C9<>"","Awaiting manager","Awaiting rep")))) | J9: =IF(OR(A9="",B9=""),"",IFERROR(INDEX(Calculation!$C$6:$N$140,(MATCH(B9,Settings!$C$13:$C$27,0)-1)*9+7,MATCH(A9,Settings!$N$13:$N$24,0)),"")) | K9: =IF(OR(A9="",B9=""),"",A9&"|"&B9)
I10: =IF(OR(A10="",B10=""),"",IF(G10<>"","Approved",IF(E10<>"","Awaiting finance",IF(C10<>"","Awaiting manager","Awaiting rep")))) | J10: =IF(OR(A10="",B10=""),"",IFERROR(INDEX(Calculation!$C$6:$N$140,(MATCH(B10,Settings!$C$13:$C$27,0)-1)*9+7,MATCH(A10,Settings!$N$13:$N$24,0)),"")) | K10: =IF(OR(A10="",B10=""),"",A10&"|"&B10)
I11: =IF(OR(A11="",B11=""),"",IF(G11<>"","Approved",IF(E11<>"","Awaiting finance",IF(C11<>"","Awaiting manager","Awaiting rep")))) | J11: =IF(OR(A11="",B11=""),"",IFERROR(INDEX(Calculation!$C$6:$N$140,(MATCH(B11,Settings!$C$13:$C$27,0)-1)*9+7,MATCH(A11,Settings!$N$13:$N$24,0)),"")) | K11: =IF(OR(A11="",B11=""),"",A11&"|"&B11)
I12: =IF(OR(A12="",B12=""),"",IF(G12<>"","Approved",IF(E12<>"","Awaiting finance",IF(C12<>"","Awaiting manager","Awaiting rep")))) | J12: =IF(OR(A12="",B12=""),"",IFERROR(INDEX(Calculation!$C$6:$N$140,(MATCH(B12,Settings!$C$13:$C$27,0)-1)*9+7,MATCH(A12,Settings!$N$13:$N$24,0)),"")) | K12: =IF(OR(A12="",B12=""),"",A12&"|"&B12)
I13: =IF(OR(A13="",B13=""),"",IF(G13<>"","Approved",IF(E13<>"","Awaiting finance",IF(C13<>"","Awaiting manager","Awaiting rep")))) | J13: =IF(OR(A13="",B13=""),"",IFERROR(INDEX(Calculation!$C$6:$N$140,(MATCH(B13,Settings!$C$13:$C$27,0)-1)*9+7,MATCH(A13,Settings!$N$13:$N$24,0)),"")) | K13: =IF(OR(A13="",B13=""),"",A13&"|"&B13)
I14: =IF(OR(A14="",B14=""),"",IF(G14<>"","Approved",IF(E14<>"","Awaiting finance",IF(C14<>"","Awaiting manager","Awaiting rep")))) | J14: =IF(OR(A14="",B14=""),"",IFERROR(INDEX(Calculation!$C$6:$N$140,(MATCH(B14,Settings!$C$13:$C$27,0)-1)*9+7,MATCH(A14,Settings!$N$13:$N$24,0)),"")) | K14: =IF(OR(A14="",B14=""),"",A14&"|"&B14)
I15: =IF(OR(A15="",B15=""),"",IF(G15<>"","Approved",IF(E15<>"","Awaiting finance",IF(C15<>"","Awaiting manager","Awaiting rep")))) | J15: =IF(OR(A15="",B15=""),"",IFERROR(INDEX(Calculation!$C$6:$N$140,(MATCH(B15,Settings!$C$13:$C$27,0)-1)*9+7,MATCH(A15,Settings!$N$13:$N$24,0)),"")) | K15: =IF(OR(A15="",B15=""),"",A15&"|"&B15)
I16: =IF(OR(A16="",B16=""),"",IF(G16<>"","Approved",IF(E16<>"","Awaiting finance",IF(C16<>"","Awaiting manager","Awaiting rep")))) | J16: =IF(OR(A16="",B16=""),"",IFERROR(INDEX(Calculation!$C$6:$N$140,(MATCH(B16,Settings!$C$13:$C$27,0)-1)*9+7,MATCH(A16,Settings!$N$13:$N$24,0)),"")) | K16: =IF(OR(A16="",B16=""),"",A16&"|"&B16)
I17: =IF(OR(A17="",B17=""),"",IF(G17<>"","Approved",IF(E17<>"","Awaiting finance",IF(C17<>"","Awaiting manager","Awaiting rep")))) | J17: =IF(OR(A17="",B17=""),"",IFERROR(INDEX(Calculation!$C$6:$N$140,(MATCH(B17,Settings!$C$13:$C$27,0)-1)*9+7,MATCH(A17,Settings!$N$13:$N$24,0)),"")) | K17: =IF(OR(A17="",B17=""),"",A17&"|"&B17)
I18: =IF(OR(A18="",B18=""),"",IF(G18<>"","Approved",IF(E18<>"","Awaiting finance",IF(C18<>"","Awaiting manager","Awaiting rep")))) | J18: =IF(OR(A18="",B18=""),"",IFERROR(INDEX(Calculation!$C$6:$N$140,(MATCH(B18,Settings!$C$13:$C$27,0)-1)*9+7,MATCH(A18,Settings!$N$13:$N$24,0)),"")) | K18: =IF(OR(A18="",B18=""),"",A18&"|"&B18)
I19: =IF(OR(A19="",B19=""),"",IF(G19<>"","Approved",IF(E19<>"","Awaiting finance",IF(C19<>"","Awaiting manager","Awaiting rep")))) | J19: =IF(OR(A19="",B19=""),"",IFERROR(INDEX(Calculation!$C$6:$N$140,(MATCH(B19,Settings!$C$13:$C$27,0)-1)*9+7,MATCH(A19,Settings!$N$13:$N$24,0)),"")) | K19: =IF(OR(A19="",B19=""),"",A19&"|"&B19)
I20: =IF(OR(A20="",B20=""),"",IF(G20<>"","Approved",IF(E20<>"","Awaiting finance",IF(C20<>"","Awaiting manager","Awaiting rep")))) | J20: =IF(OR(A20="",B20=""),"",IFERROR(INDEX(Calculation!$C$6:$N$140,(MATCH(B20,Settings!$C$13:$C$27,0)-1)*9+7,MATCH(A20,Settings!$N$13:$N$24,0)),"")) | K20: =IF(OR(A20="",B20=""),"",A20&"|"&B20)
... I205: =IF(OR(A205="",B205=""),"",IF(G205<>"","Approved",IF(E205<>"","Awaiting finance",IF(C205<>"","Awaiting manager","Awaiting rep")))) | J205: =IF(OR(A205="",B205=""),"",IFERROR(INDEX(Calculation!$C$6:$N$140,(MATCH(B205,Settings!$C$13:$C$27,0)-1)*9+7,MATCH(A205,Settings!$N$13:$N$24,0)),"")) | K205: =IF(OR(A205="",B205=""),"",A205&"|"&B205)

Sheet Payroll
B2: Payroll file
B3: One line per rep for the selected month. Enter or import into payroll once every line is approved. | I3: Month no.
B4: Payroll month | C4: March | D4: =Settings!$C$7 -> 2026 | E4: ="Amounts in "&Settings!$C$9 -> Amounts in DKK | I4: =IFERROR(MATCH($C$4,Settings!$N$13:$N$24,0),0) -> 3
B6: Employee no. | C6: Name | D6: Pay code | E6: Description | F6: Amount | G6: Approved by finance
B7: =IF(Settings!$C$13="","",Settings!$B$13) -> 101 | C7: =IF(Settings!$C$13="","",Settings!$C$13) -> Anna Holm | D7: =IF(Settings!$C$13="","",IF(Settings!$C$8="","Enter pay code",Settings!$C$8)) -> Enter pay code | E7: =IF(OR(Settings!$C$13="",$I$4=0),"","Commission "&$C$4&" "&$D$4) -> Commission March 2026 | F7: =IF(OR(Settings!$C$13="",$I$4=0),"",INDEX(Calculation!$C$6:$N$140,7,$I$4)) -> 7400 | G7: =IF(OR(Settings!$C$13="",$I$4=0),"",IF(IFERROR(INDEX(Approvals!$G$6:$G$205,MATCH($C$4&"|"&Settings!$C$13,Approvals!$K$6:$K$205,0)),"")<>"","Approved","Pending")) -> Approved
B8: =IF(Settings!$C$14="","",Settings!$B$14) -> 102 | C8: =IF(Settings!$C$14="","",Settings!$C$14) -> Bo Jensen | D8: =IF(Settings!$C$14="","",IF(Settings!$C$8="","Enter pay code",Settings!$C$8)) -> Enter pay code | E8: =IF(OR(Settings!$C$14="",$I$4=0),"","Commission "&$C$4&" "&$D$4) -> Commission March 2026 | F8: =IF(OR(Settings!$C$14="",$I$4=0),"",INDEX(Calculation!$C$6:$N$140,16,$I$4)) -> 21000 | G8: =IF(OR(Settings!$C$14="",$I$4=0),"",IF(IFERROR(INDEX(Approvals!$G$6:$G$205,MATCH($C$4&"|"&Settings!$C$14,Approvals!$K$6:$K$205,0)),"")<>"","Approved","Pending")) -> Pending
B9: =IF(Settings!$C$15="","",Settings!$B$15) -> 103 | C9: =IF(Settings!$C$15="","",Settings!$C$15) -> Camilla Nørgaard | D9: =IF(Settings!$C$15="","",IF(Settings!$C$8="","Enter pay code",Settings!$C$8)) -> Enter pay code | E9: =IF(OR(Settings!$C$15="",$I$4=0),"","Commission "&$C$4&" "&$D$4) -> Commission March 2026 | F9: =IF(OR(Settings!$C$15="",$I$4=0),"",INDEX(Calculation!$C$6:$N$140,25,$I$4)) -> 5000 | G9: =IF(OR(Settings!$C$15="",$I$4=0),"",IF(IFERROR(INDEX(Approvals!$G$6:$G$205,MATCH($C$4&"|"&Settings!$C$15,Approvals!$K$6:$K$205,0)),"")<>"","Approved","Pending")) -> Approved
B10: =IF(Settings!$C$16="","",Settings!$B$16) | C10: =IF(Settings!$C$16="","",Settings!$C$16) | D10: =IF(Settings!$C$16="","",IF(Settings!$C$8="","Enter pay code",Settings!$C$8)) | E10: =IF(OR(Settings!$C$16="",$I$4=0),"","Commission "&$C$4&" "&$D$4) | F10: =IF(OR(Settings!$C$16="",$I$4=0),"",INDEX(Calculation!$C$6:$N$140,34,$I$4)) | G10: =IF(OR(Settings!$C$16="",$I$4=0),"",IF(IFERROR(INDEX(Approvals!$G$6:$G$205,MATCH($C$4&"|"&Settings!$C$16,Approvals!$K$6:$K$205,0)),"")<>"","Approved","Pending"))
B11: =IF(Settings!$C$17="","",Settings!$B$17) | C11: =IF(Settings!$C$17="","",Settings!$C$17) | D11: =IF(Settings!$C$17="","",IF(Settings!$C$8="","Enter pay code",Settings!$C$8)) | E11: =IF(OR(Settings!$C$17="",$I$4=0),"","Commission "&$C$4&" "&$D$4) | F11: =IF(OR(Settings!$C$17="",$I$4=0),"",INDEX(Calculation!$C$6:$N$140,43,$I$4)) | G11: =IF(OR(Settings!$C$17="",$I$4=0),"",IF(IFERROR(INDEX(Approvals!$G$6:$G$205,MATCH($C$4&"|"&Settings!$C$17,Approvals!$K$6:$K$205,0)),"")<>"","Approved","Pending"))
B12: =IF(Settings!$C$18="","",Settings!$B$18) | C12: =IF(Settings!$C$18="","",Settings!$C$18) | D12: =IF(Settings!$C$18="","",IF(Settings!$C$8="","Enter pay code",Settings!$C$8)) | E12: =IF(OR(Settings!$C$18="",$I$4=0),"","Commission "&$C$4&" "&$D$4) | F12: =IF(OR(Settings!$C$18="",$I$4=0),"",INDEX(Calculation!$C$6:$N$140,52,$I$4)) | G12: =IF(OR(Settings!$C$18="",$I$4=0),"",IF(IFERROR(INDEX(Approvals!$G$6:$G$205,MATCH($C$4&"|"&Settings!$C$18,Approvals!$K$6:$K$205,0)),"")<>"","Approved","Pending"))
B13: =IF(Settings!$C$19="","",Settings!$B$19) | C13: =IF(Settings!$C$19="","",Settings!$C$19) | D13: =IF(Settings!$C$19="","",IF(Settings!$C$8="","Enter pay code",Settings!$C$8)) | E13: =IF(OR(Settings!$C$19="",$I$4=0),"","Commission "&$C$4&" "&$D$4) | F13: =IF(OR(Settings!$C$19="",$I$4=0),"",INDEX(Calculation!$C$6:$N$140,61,$I$4)) | G13: =IF(OR(Settings!$C$19="",$I$4=0),"",IF(IFERROR(INDEX(Approvals!$G$6:$G$205,MATCH($C$4&"|"&Settings!$C$19,Approvals!$K$6:$K$205,0)),"")<>"","Approved","Pending"))
B14: =IF(Settings!$C$20="","",Settings!$B$20) | C14: =IF(Settings!$C$20="","",Settings!$C$20) | D14: =IF(Settings!$C$20="","",IF(Settings!$C$8="","Enter pay code",Settings!$C$8)) | E14: =IF(OR(Settings!$C$20="",$I$4=0),"","Commission "&$C$4&" "&$D$4) | F14: =IF(OR(Settings!$C$20="",$I$4=0),"",INDEX(Calculation!$C$6:$N$140,70,$I$4)) | G14: =IF(OR(Settings!$C$20="",$I$4=0),"",IF(IFERROR(INDEX(Approvals!$G$6:$G$205,MATCH($C$4&"|"&Settings!$C$20,Approvals!$K$6:$K$205,0)),"")<>"","Approved","Pending"))
B15: =IF(Settings!$C$21="","",Settings!$B$21) | C15: =IF(Settings!$C$21="","",Settings!$C$21) | D15: =IF(Settings!$C$21="","",IF(Settings!$C$8="","Enter pay code",Settings!$C$8)) | E15: =IF(OR(Settings!$C$21="",$I$4=0),"","Commission "&$C$4&" "&$D$4) | F15: =IF(OR(Settings!$C$21="",$I$4=0),"",INDEX(Calculation!$C$6:$N$140,79,$I$4)) | G15: =IF(OR(Settings!$C$21="",$I$4=0),"",IF(IFERROR(INDEX(Approvals!$G$6:$G$205,MATCH($C$4&"|"&Settings!$C$21,Approvals!$K$6:$K$205,0)),"")<>"","Approved","Pending"))
B16: =IF(Settings!$C$22="","",Settings!$B$22) | C16: =IF(Settings!$C$22="","",Settings!$C$22) | D16: =IF(Settings!$C$22="","",IF(Settings!$C$8="","Enter pay code",Settings!$C$8)) | E16: =IF(OR(Settings!$C$22="",$I$4=0),"","Commission "&$C$4&" "&$D$4) | F16: =IF(OR(Settings!$C$22="",$I$4=0),"",INDEX(Calculation!$C$6:$N$140,88,$I$4)) | G16: =IF(OR(Settings!$C$22="",$I$4=0),"",IF(IFERROR(INDEX(Approvals!$G$6:$G$205,MATCH($C$4&"|"&Settings!$C$22,Approvals!$K$6:$K$205,0)),"")<>"","Approved","Pending"))
B17: =IF(Settings!$C$23="","",Settings!$B$23) | C17: =IF(Settings!$C$23="","",Settings!$C$23) | D17: =IF(Settings!$C$23="","",IF(Settings!$C$8="","Enter pay code",Settings!$C$8)) | E17: =IF(OR(Settings!$C$23="",$I$4=0),"","Commission "&$C$4&" "&$D$4) | F17: =IF(OR(Settings!$C$23="",$I$4=0),"",INDEX(Calculation!$C$6:$N$140,97,$I$4)) | G17: =IF(OR(Settings!$C$23="",$I$4=0),"",IF(IFERROR(INDEX(Approvals!$G$6:$G$205,MATCH($C$4&"|"&Settings!$C$23,Approvals!$K$6:$K$205,0)),"")<>"","Approved","Pending"))
B18: =IF(Settings!$C$24="","",Settings!$B$24) | C18: =IF(Settings!$C$24="","",Settings!$C$24) | D18: =IF(Settings!$C$24="","",IF(Settings!$C$8="","Enter pay code",Settings!$C$8)) | E18: =IF(OR(Settings!$C$24="",$I$4=0),"","Commission "&$C$4&" "&$D$4) | F18: =IF(OR(Settings!$C$24="",$I$4=0),"",INDEX(Calculation!$C$6:$N$140,106,$I$4)) | G18: =IF(OR(Settings!$C$24="",$I$4=0),"",IF(IFERROR(INDEX(Approvals!$G$6:$G$205,MATCH($C$4&"|"&Settings!$C$24,Approvals!$K$6:$K$205,0)),"")<>"","Approved","Pending"))
B19: =IF(Settings!$C$25="","",Settings!$B$25) | C19: =IF(Settings!$C$25="","",Settings!$C$25) | D19: =IF(Settings!$C$25="","",IF(Settings!$C$8="","Enter pay code",Settings!$C$8)) | E19: =IF(OR(Settings!$C$25="",$I$4=0),"","Commission "&$C$4&" "&$D$4) | F19: =IF(OR(Settings!$C$25="",$I$4=0),"",INDEX(Calculation!$C$6:$N$140,115,$I$4)) | G19: =IF(OR(Settings!$C$25="",$I$4=0),"",IF(IFERROR(INDEX(Approvals!$G$6:$G$205,MATCH($C$4&"|"&Settings!$C$25,Approvals!$K$6:$K$205,0)),"")<>"","Approved","Pending"))
B20: =IF(Settings!$C$26="","",Settings!$B$26) | C20: =IF(Settings!$C$26="","",Settings!$C$26) | D20: =IF(Settings!$C$26="","",IF(Settings!$C$8="","Enter pay code",Settings!$C$8)) | E20: =IF(OR(Settings!$C$26="",$I$4=0),"","Commission "&$C$4&" "&$D$4) | F20: =IF(OR(Settings!$C$26="",$I$4=0),"",INDEX(Calculation!$C$6:$N$140,124,$I$4)) | G20: =IF(OR(Settings!$C$26="",$I$4=0),"",IF(IFERROR(INDEX(Approvals!$G$6:$G$205,MATCH($C$4&"|"&Settings!$C$26,Approvals!$K$6:$K$205,0)),"")<>"","Approved","Pending"))
B21: =IF(Settings!$C$27="","",Settings!$B$27) | C21: =IF(Settings!$C$27="","",Settings!$C$27) | D21: =IF(Settings!$C$27="","",IF(Settings!$C$8="","Enter pay code",Settings!$C$8)) | E21: =IF(OR(Settings!$C$27="",$I$4=0),"","Commission "&$C$4&" "&$D$4) | F21: =IF(OR(Settings!$C$27="",$I$4=0),"",INDEX(Calculation!$C$6:$N$140,133,$I$4)) | G21: =IF(OR(Settings!$C$27="",$I$4=0),"",IF(IFERROR(INDEX(Approvals!$G$6:$G$205,MATCH($C$4&"|"&Settings!$C$27,Approvals!$K$6:$K$205,0)),"")<>"","Approved","Pending"))
B22: Total | F22: =SUM(F7:F21) -> 33400
B23: Of which approved by finance | F23: =SUMIFS(F7:F21,G7:G21,"Approved") -> 12400
B24: Awaiting approval | F24: =F22-F23 -> 21000
B26: =IF(F24>0,"Note: some amounts have not been approved by finance yet.","") -> Note: some amounts have not been approved by finance yet.
B27: The draw is not included because it is paid separately each month.
B29: prowi.io · Free template from Prowi

Sheet Calculation
A2: Calculation by rep and month
A3: Everything on this sheet is a formula. E in January is the opening balance from Settings; after that E equals H for the month before.
A5: Rep | B5: Line | C5: Jan | D5: Feb | E5: Mar | F5: Apr | G5: May | H5: Jun | I5: Jul | J5: Aug | K5: Sep | L5: Oct | M5: Nov | N5: Dec | O5: Total
A6: =IF(Settings!$C$13="","",Settings!$C$13) -> Anna Holm | B6: A. Commission on deals | C6: =IF(Settings!$C$13="",0,SUMIFS(Deals!$I$6:$I$305,Deals!$A$6:$A$305,Settings!$C$13,Deals!$J$6:$J$305,1)) -> 4000 | D6: =IF(Settings!$C$13="",0,SUMIFS(Deals!$I$6:$I$305,Deals!$A$6:$A$305,Settings!$C$13,Deals!$J$6:$J$305,2)) -> 12000 | E6: =IF(Settings!$C$13="",0,SUMIFS(Deals!$I$6:$I$305,Deals!$A$6:$A$305,Settings!$C$13,Deals!$J$6:$J$305,3)) -> 24600 | F6: =IF(Settings!$C$13="",0,SUMIFS(Deals!$I$6:$I$305,Deals!$A$6:$A$305,Settings!$C$13,Deals!$J$6:$J$305,4)) -> 0 | G6: =IF(Settings!$C$13="",0,SUMIFS(Deals!$I$6:$I$305,Deals!$A$6:$A$305,Settings!$C$13,Deals!$J$6:$J$305,5)) -> 0 | H6: =IF(Settings!$C$13="",0,SUMIFS(Deals!$I$6:$I$305,Deals!$A$6:$A$305,Settings!$C$13,Deals!$J$6:$J$305,6)) -> 0 | I6: =IF(Settings!$C$13="",0,SUMIFS(Deals!$I$6:$I$305,Deals!$A$6:$A$305,Settings!$C$13,Deals!$J$6:$J$305,7)) -> 0 | J6: =IF(Settings!$C$13="",0,SUMIFS(Deals!$I$6:$I$305,Deals!$A$6:$A$305,Settings!$C$13,Deals!$J$6:$J$305,8)) -> 0 | K6: =IF(Settings!$C$13="",0,SUMIFS(Deals!$I$6:$I$305,Deals!$A$6:$A$305,Settings!$C$13,Deals!$J$6:$J$305,9)) -> 0 | L6: =IF(Settings!$C$13="",0,SUMIFS(Deals!$I$6:$I$305,Deals!$A$6:$A$305,Settings!$C$13,Deals!$J$6:$J$305,10)) -> 0 | M6: =IF(Settings!$C$13="",0,SUMIFS(Deals!$I$6:$I$305,Deals!$A$6:$A$305,Settings!$C$13,Deals!$J$6:$J$305,11)) -> 0 | N6: =IF(Settings!$C$13="",0,SUMIFS(Deals!$I$6:$I$305,Deals!$A$6:$A$305,Settings!$C$13,Deals!$J$6:$J$305,12)) -> 0 | O6: =SUM(C6:N6) -> 40600
