Workbook

Sheet Vejledning
C2: Gratis skabelon fra Prowi
B4: Kvoteplan
B5: Fra omsætningsmål til kvote pr. sælger og måned
B7: Skabelonen fordeler virksomhedens omsætningsmål på sælgere og måneder. Den lægger en buffer oveni målet (over-assignment), tager højde for sæsonudsving, nye sælgere i opstart, territorier med forskelligt potentiale, deltid og sælgere med en fast kvote. Der er eksempeldata for 10 sælgere i fire territorier i 2026, så du kan se, hvordan den regner, før du skriver jeres egne tal ind.
B9: Trin for trin
B10: 1. Indstillinger | C10: Skriv år, omsætningsmål, buffer og planlagt målopfyldelse. Juster opstartskurven for nye sælgere og sæsonvægtene pr. måned.
B11: 2. Territorier | C11: Skriv territorierne og et potentialeindeks for hvert. 100 er et normalt territorie, 120 betyder, at en sælger der kan sælge 20 % mere.
B12: 3. Sælgere | C12: En række pr. sælger med territorie, startmåned, opstartstrin, eventuel slutmåned, kapacitet (deltid) og eventuel fast årskvote.
B13: 4. Kvoteplan | C13: Kvoten pr. sælger pr. måned, totaler pr. måned og pr. territorie. Her skal du ikke skrive noget.
B14: 5. Overblik | C14: Nøgletal, kontrol af at hele kvoten er fordelt, kvote pr. territorie og advarsler, hvis noget ikke stemmer.
B16: Farver
B17: Lavendel felt, lilla tekst | C17: Her skriver du. Alt andet er formler.
B18: Gråt felt | C18: Beregnet automatisk. Ret ikke i formlerne, medmindre du ved, hvad du gør.
B19: Lyseblåt felt | C19: Resultater og totaler.
B21: Sådan regner arket
B22: Kvote, der skal fordeles | C22: Omsætningsmål × (1 + buffer). Med 10 % buffer skal teamet i gennemsnit nå 1 ÷ 1,1 = 90,9 % af kvoten for at ramme målet.
B23: Vægt pr. sælger og måned | C23: Månedens sæsonandel × aktiv (mellem start- og slutmåned) × produktivitet i opstart × kapacitet × territoriets indeks ÷ 100.
B24: Opstart | C24: Opstartstrin er nummeret på opstartsmåneden i sælgerens startmåned: 1 for en helt ny sælger. Trinnet stiger med 1 pr. måned, og fra trin 7 er produktiviteten 100 %. Tomt felt = fuldt oplært.
B25: Fast kvote | C25: En sælger med fast årskvote beholder den, fordelt på sine egne månedsvægte. Resten af kvoten deles mellem de øvrige sælgere efter vægt.
B26: Fuld årskvote | C26: Kvote til de øvrige sælgere ÷ summen af deres vægte. Det er årskvoten for en fuldt produktiv sælger på fuld tid i et territorie med indeks 100, der er ansat hele året.
B28: Godt at vide
B29: • | C29: Alle navne og tal er eksempler. Brug jeres egne tal fra CRM og regnskab, fx salg pr. territorie de seneste 12 måneder som grundlag for indekset.
B30: • | C30: Kvoterne er ikke afrundet, så summen altid svarer til den kvote, der skal fordeles. Afrund gerne, når I skriver kvoterne i provisionsplanen.
B31: • | C31: Sælgerafgang er ikke med, fordi I ikke ved, hvem der stopper. Bufferen skal dække den.
B32: • | C32: Ingen makroer. Alle beregninger er almindelige formler, som virker i Excel, Google Sheets, Numbers og LibreOffice.
B35: prowi.io · Gratis skabelon fra Prowi

Sheet Indstillinger
B2: Indstillinger
B3: Skriv kun i de lavendel felter.
B5: Mål
B6: Virksomhed | C6: Eksempel ApS | E6: Vises i Overblik.
B7: År | C7: 2026 | E7: Året, kvoteplanen dækker.
B8: Omsætningsmål for året | C8: 30000000 | E8: Det, virksomheden skal nå. Fx nysalg eller samlet omsætning fra salgsteamet.
B9: Buffer (over-assignment) | C9: 0.1 | E9: Hvor meget mere kvote end mål der fordeles. Dækker sælgere, der ikke når målet, afgang og forsinkede ansættelser.
B10: Planlagt gennemsnitlig målopfyldelse | C10: 0.92 | E10: Den målopfyldelse, I forventer for teamet. Bruges til at tjekke, om bufferen er stor nok.
B13: Kvote, der skal fordeles | C13: =C8*(1+C9) -> 33000000 | E13: Omsætningsmål × (1 + buffer).
B14: Målopfyldelse, der skal til for at nå målet | C14: =IFERROR(1/(1+C9),0) -> 0.90909091 | E14: 1 ÷ (1 + buffer). Skal være lavere end den planlagte målopfyldelse.
B16: Opstartskurve for nye sælgere | E16: Andel af fuld kvote i hver opstartsmåned. Fra måned 7 er det 100 %.
B17: Opstartsmåned | C17: Produktivitet
B18: Måned 1 | C18: 0.25
B19: Måned 2 | C19: 0.5
B20: Måned 3 | C20: 0.75
B21: Måned 4 | C21: 1
B22: Måned 5 | C22: 1
B23: Måned 6 | C23: 1
B25: Sæsonfordeling | E25: Vægt pr. måned. Vægtene behøver ikke summe til 100; arket regner andelene ud.
B26: Måned | C26: Vægt | D26: Andel
B27: Januar | C27: 7 | D27: =IF(SUM($C$27:$C$38)=0,1/12,C27/SUM($C$27:$C$38)) -> 0.07
B28: Februar | C28: 8 | D28: =IF(SUM($C$27:$C$38)=0,1/12,C28/SUM($C$27:$C$38)) -> 0.08
B29: Marts | C29: 9 | D29: =IF(SUM($C$27:$C$38)=0,1/12,C29/SUM($C$27:$C$38)) -> 0.09
B30: April | C30: 8 | D30: =IF(SUM($C$27:$C$38)=0,1/12,C30/SUM($C$27:$C$38)) -> 0.08
B31: Maj | C31: 9 | D31: =IF(SUM($C$27:$C$38)=0,1/12,C31/SUM($C$27:$C$38)) -> 0.09
B32: Juni | C32: 9 | D32: =IF(SUM($C$27:$C$38)=0,1/12,C32/SUM($C$27:$C$38)) -> 0.09
B33: Juli | C33: 4 | D33: =IF(SUM($C$27:$C$38)=0,1/12,C33/SUM($C$27:$C$38)) -> 0.04 | E33: Eksempel: lavere i juli (ferie) og højere i årets sidste måneder.
B34: August | C34: 7 | D34: =IF(SUM($C$27:$C$38)=0,1/12,C34/SUM($C$27:$C$38)) -> 0.07
B35: September | C35: 9 | D35: =IF(SUM($C$27:$C$38)=0,1/12,C35/SUM($C$27:$C$38)) -> 0.09
B36: Oktober | C36: 9 | D36: =IF(SUM($C$27:$C$38)=0,1/12,C36/SUM($C$27:$C$38)) -> 0.09
B37: November | C37: 10 | D37: =IF(SUM($C$27:$C$38)=0,1/12,C37/SUM($C$27:$C$38)) -> 0.1
B38: December | C38: 11 | D38: =IF(SUM($C$27:$C$38)=0,1/12,C38/SUM($C$27:$C$38)) -> 0.11
B39: I alt | C39: =SUM(C27:C38) -> 100 | D39: =SUM(D27:D38) -> 1

Sheet Territorier
B2: Territorier
B3: Potentialeindeks: hvor meget en fuldt produktiv sælger kan sælge i territoriet i forhold til et normalt territorie (100).
B5: Territorie | C5: Potentiale-indeks | D5: Grundlag for indekset (valgfrit) | E5: Sælgere | F5: Kapacitet (FTE) | G5: Årskvote | H5: Andel af kvote | I5: Kvote pr. FTE
B6: Hovedstaden | C6: 120 | D6: Salg pr. sælger 2025 ift. gennemsnit | E6: =IF($B6="","",COUNTIF(Sælgere!$C$6:$C$30,$B6)) -> 3 | F6: =IF($B6="","",SUMIF(Beregning!$D$6:$D$30,$B6,Beregning!$Z$6:$Z$30)) -> 2.46 | G6: =IF($B6="","",SUMIF(Kvoteplan!$C$6:$C$30,$B6,Kvoteplan!$P$6:$P$30)) -> 10730311 | H6: =IF($B6="","",IFERROR(G6/SUM($G$6:$G$15),0)) -> 0.32516094 | I6: =IF($B6="","",IFERROR(G6/F6,0)) -> 4361915
B7: Jylland | C7: 100 | D7: Gennemsnit | E7: =IF($B7="","",COUNTIF(Sælgere!$C$6:$C$30,$B7)) -> 4 | F7: =IF($B7="","",SUMIF(Beregning!$D$6:$D$30,$B7,Beregning!$Z$6:$Z$30)) -> 3.35 | G7: =IF($B7="","",SUMIF(Kvoteplan!$C$6:$C$30,$B7,Kvoteplan!$P$6:$P$30)) -> 12304701 | H7: =IF($B7="","",IFERROR(G7/SUM($G$6:$G$15),0)) -> 0.37286973 | I7: =IF($B7="","",IFERROR(G7/F7,0)) -> 3673045.1
B8: Fyn og Sjælland | C8: 85 | D8: Salg pr. sælger 2025 ift. gennemsnit | E8: =IF($B8="","",COUNTIF(Sælgere!$C$6:$C$30,$B8)) -> 2 | F8: =IF($B8="","",SUMIF(Beregning!$D$6:$D$30,$B8,Beregning!$Z$6:$Z$30)) -> 1.7 | G8: =IF($B8="","",SUMIF(Kvoteplan!$C$6:$C$30,$B8,Kvoteplan!$P$6:$P$30)) -> 5464987.8 | H8: =IF($B8="","",IFERROR(G8/SUM($G$6:$G$15),0)) -> 0.16560569 | I8: =IF($B8="","",IFERROR(G8/F8,0)) -> 3214698.7
B9: Key accounts | C9: 100 | D9: Faste kvoter | E9: =IF($B9="","",COUNTIF(Sælgere!$C$6:$C$30,$B9)) -> 1 | F9: =IF($B9="","",SUMIF(Beregning!$D$6:$D$30,$B9,Beregning!$Z$6:$Z$30)) -> 0 | G9: =IF($B9="","",SUMIF(Kvoteplan!$C$6:$C$30,$B9,Kvoteplan!$P$6:$P$30)) -> 4500000 | H9: =IF($B9="","",IFERROR(G9/SUM($G$6:$G$15),0)) -> 0.13636364 | I9: =IF($B9="","",IFERROR(G9/F9,0)) -> 0
E10: =IF($B10="","",COUNTIF(Sælgere!$C$6:$C$30,$B10)) | F10: =IF($B10="","",SUMIF(Beregning!$D$6:$D$30,$B10,Beregning!$Z$6:$Z$30)) | G10: =IF($B10="","",SUMIF(Kvoteplan!$C$6:$C$30,$B10,Kvoteplan!$P$6:$P$30)) | H10: =IF($B10="","",IFERROR(G10/SUM($G$6:$G$15),0)) | I10: =IF($B10="","",IFERROR(G10/F10,0))
E11: =IF($B11="","",COUNTIF(Sælgere!$C$6:$C$30,$B11)) | F11: =IF($B11="","",SUMIF(Beregning!$D$6:$D$30,$B11,Beregning!$Z$6:$Z$30)) | G11: =IF($B11="","",SUMIF(Kvoteplan!$C$6:$C$30,$B11,Kvoteplan!$P$6:$P$30)) | H11: =IF($B11="","",IFERROR(G11/SUM($G$6:$G$15),0)) | I11: =IF($B11="","",IFERROR(G11/F11,0))
E12: =IF($B12="","",COUNTIF(Sælgere!$C$6:$C$30,$B12)) | F12: =IF($B12="","",SUMIF(Beregning!$D$6:$D$30,$B12,Beregning!$Z$6:$Z$30)) | G12: =IF($B12="","",SUMIF(Kvoteplan!$C$6:$C$30,$B12,Kvoteplan!$P$6:$P$30)) | H12: =IF($B12="","",IFERROR(G12/SUM($G$6:$G$15),0)) | I12: =IF($B12="","",IFERROR(G12/F12,0))
E13: =IF($B13="","",COUNTIF(Sælgere!$C$6:$C$30,$B13)) | F13: =IF($B13="","",SUMIF(Beregning!$D$6:$D$30,$B13,Beregning!$Z$6:$Z$30)) | G13: =IF($B13="","",SUMIF(Kvoteplan!$C$6:$C$30,$B13,Kvoteplan!$P$6:$P$30)) | H13: =IF($B13="","",IFERROR(G13/SUM($G$6:$G$15),0)) | I13: =IF($B13="","",IFERROR(G13/F13,0))
E14: =IF($B14="","",COUNTIF(Sælgere!$C$6:$C$30,$B14)) | F14: =IF($B14="","",SUMIF(Beregning!$D$6:$D$30,$B14,Beregning!$Z$6:$Z$30)) | G14: =IF($B14="","",SUMIF(Kvoteplan!$C$6:$C$30,$B14,Kvoteplan!$P$6:$P$30)) | H14: =IF($B14="","",IFERROR(G14/SUM($G$6:$G$15),0)) | I14: =IF($B14="","",IFERROR(G14/F14,0))
E15: =IF($B15="","",COUNTIF(Sælgere!$C$6:$C$30,$B15)) | F15: =IF($B15="","",SUMIF(Beregning!$D$6:$D$30,$B15,Beregning!$Z$6:$Z$30)) | G15: =IF($B15="","",SUMIF(Kvoteplan!$C$6:$C$30,$B15,Kvoteplan!$P$6:$P$30)) | H15: =IF($B15="","",IFERROR(G15/SUM($G$6:$G$15),0)) | I15: =IF($B15="","",IFERROR(G15/F15,0))
B16: I alt | E16: =SUM(E6:E15) -> 10 | F16: =SUM(F6:F15) -> 7.51 | G16: =SUM(G6:G15) -> 33000000 | H16: =SUM(H6:H15) -> 1
B18: Kapacitet (FTE) tæller kun sælgere uden fast kvote og er ganget med deres aktive måneder og opstart. Kvote pr. FTE er derfor kun meningsfuld for territorier uden faste kvoter.

Sheet Sælgere
B2: Sælgere
B3: En række pr. sælger. Kun navn og territorie er påkrævet. Tomme felter: startmåned 1, fuldt oplært, slutmåned 12, kapacitet 100 % og beregnet kvote.
B5: Sælger | C5: Territorie | D5: Startmåned (1-12) | E5: Opstartstrin i startmåned (tom = oplært) | F5: Slutmåned (valgfri) | G5: Kapacitet (FTE) | H5: Fast årskvote (valgfri) | I5: Årskvote | J5: Gns. pr. aktiv måned
B6: Anna Holm | C6: Hovedstaden | D6: 1 | G6: 1 | I6: =IF($B6="","",Kvoteplan!$P6) -> 4585602.9 | J6: =IF($B6="","",IFERROR(I6/COUNTIF(Beregning!$K6:$V6,">0"),0)) -> 382133.58
B7: Bo Jensen | C7: Hovedstaden | D7: 1 | G7: 1 | I7: =IF($B7="","",Kvoteplan!$P7) -> 4585602.9 | J7: =IF($B7="","",IFERROR(I7/COUNTIF(Beregning!$K7:$V7,">0"),0)) -> 382133.58
B8: Camilla Nørgaard | C8: Jylland | D8: 1 | G8: 1 | I8: =IF($B8="","",Kvoteplan!$P8) -> 3821335.8 | J8: =IF($B8="","",IFERROR(I8/COUNTIF(Beregning!$K8:$V8,">0"),0)) -> 318444.65
B9: Dennis Lund | C9: Jylland | D9: 1 | G9: 1 | I9: =IF($B9="","",Kvoteplan!$P9) -> 3821335.8 | J9: =IF($B9="","",IFERROR(I9/COUNTIF(Beregning!$K9:$V9,">0"),0)) -> 318444.65
B10: Emma Krogh | C10: Fyn og Sjælland | D10: 1 | F10: 9 | G10: 1 | I10: =IF($B10="","",Kvoteplan!$P10) -> 2273694.8 | J10: =IF($B10="","",IFERROR(I10/COUNTIF(Beregning!$K10:$V10,">0"),0)) -> 252632.76
B11: Frederik Sand | C11: Key accounts | D11: 1 | G11: 1 | H11: 4500000 | I11: =IF($B11="","",Kvoteplan!$P11) -> 4500000 | J11: =IF($B11="","",IFERROR(I11/COUNTIF(Beregning!$K11:$V11,">0"),0)) -> 375000
B12: Gitte Mølgaard | C12: Fyn og Sjælland | D12: 1 | E12: 3 | G12: 1 | I12: =IF($B12="","",Kvoteplan!$P12) -> 3191293.1 | J12: =IF($B12="","",IFERROR(I12/COUNTIF(Beregning!$K12:$V12,">0"),0)) -> 265941.09
B13: Henrik Bak | C13: Jylland | D13: 1 | G13: 0.5 | I13: =IF($B13="","",Kvoteplan!$P13) -> 1910667.9 | J13: =IF($B13="","",IFERROR(I13/COUNTIF(Beregning!$K13:$V13,">0"),0)) -> 159222.32
B14: Ny sælger 1 | C14: Jylland | D14: 3 | E14: 1 | G14: 1 | I14: =IF($B14="","",Kvoteplan!$P14) -> 2751361.8 | J14: =IF($B14="","",IFERROR(I14/COUNTIF(Beregning!$K14:$V14,">0"),0)) -> 275136.18
B15: Ny sælger 2 | C15: Hovedstaden | D15: 8 | E15: 1 | G15: 1 | I15: =IF($B15="","",Kvoteplan!$P15) -> 1559105 | J15: =IF($B15="","",IFERROR(I15/COUNTIF(Beregning!$K15:$V15,">0"),0)) -> 311821
I16: =IF($B16="","",Kvoteplan!$P16) | J16: =IF($B16="","",IFERROR(I16/COUNTIF(Beregning!$K16:$V16,">0"),0))
I17: =IF($B17="","",Kvoteplan!$P17) | J17: =IF($B17="","",IFERROR(I17/COUNTIF(Beregning!$K17:$V17,">0"),0))
I18: =IF($B18="","",Kvoteplan!$P18) | J18: =IF($B18="","",IFERROR(I18/COUNTIF(Beregning!$K18:$V18,">0"),0))
I19: =IF($B19="","",Kvoteplan!$P19) | J19: =IF($B19="","",IFERROR(I19/COUNTIF(Beregning!$K19:$V19,">0"),0))
I20: =IF($B20="","",Kvoteplan!$P20) | J20: =IF($B20="","",IFERROR(I20/COUNTIF(Beregning!$K20:$V20,">0"),0))
I21: =IF($B21="","",Kvoteplan!$P21) | J21: =IF($B21="","",IFERROR(I21/COUNTIF(Beregning!$K21:$V21,">0"),0))
I22: =IF($B22="","",Kvoteplan!$P22) | J22: =IF($B22="","",IFERROR(I22/COUNTIF(Beregning!$K22:$V22,">0"),0))
I23: =IF($B23="","",Kvoteplan!$P23) | J23: =IF($B23="","",IFERROR(I23/COUNTIF(Beregning!$K23:$V23,">0"),0))
I24: =IF($B24="","",Kvoteplan!$P24) | J24: =IF($B24="","",IFERROR(I24/COUNTIF(Beregning!$K24:$V24,">0"),0))
I25: =IF($B25="","",Kvoteplan!$P25) | J25: =IF($B25="","",IFERROR(I25/COUNTIF(Beregning!$K25:$V25,">0"),0))
I26: =IF($B26="","",Kvoteplan!$P26) | J26: =IF($B26="","",IFERROR(I26/COUNTIF(Beregning!$K26:$V26,">0"),0))
I27: =IF($B27="","",Kvoteplan!$P27) | J27: =IF($B27="","",IFERROR(I27/COUNTIF(Beregning!$K27:$V27,">0"),0))
... I30: =IF($B30="","",Kvoteplan!$P30) | J30: =IF($B30="","",IFERROR(I30/COUNTIF(Beregning!$K30:$V30,">0"),0))
B31: I alt | I31: =SUM(I6:I30) -> 33000000
B33: Opstartstrin: 1 = sælgerens første måned. En sælger, der startede i november sidste år, har trin 3 i januar.
B34: Kapacitet: 50 % for en sælger på halv tid eller en salgschef, der kun sælger halvdelen af tiden.

Sheet Beregning
B1: Beregning: vægte pr. sælger og måned
B2: Kvote til sælgere uden fast kvote | C2: =Indstillinger!$C$13-SUM($X$6:$X$30) -> 28500000 | D2: Kvote, der skal fordeles, minus faste kvoter.
B3: Fuld årskvote (indeks 100) | C3: =IFERROR(C2/SUM($Y$6:$Y$30),0) -> 3821335.8 | D3: Kvote pr. vægtenhed = årskvote for en fuldt produktiv sælger på fuld tid i et territorie med indeks 100.
J4: Sæsonandel | K4: =INDEX(Indstillinger!$D$27:$D$38,1) -> 0.07 | L4: =INDEX(Indstillinger!$D$27:$D$38,2) -> 0.08 | M4: =INDEX(Indstillinger!$D$27:$D$38,3) -> 0.09 | N4: =INDEX(Indstillinger!$D$27:$D$38,4) -> 0.08 | O4: =INDEX(Indstillinger!$D$27:$D$38,5) -> 0.09 | P4: =INDEX(Indstillinger!$D$27:$D$38,6) -> 0.09 | Q4: =INDEX(Indstillinger!$D$27:$D$38,7) -> 0.04 | R4: =INDEX(Indstillinger!$D$27:$D$38,8) -> 0.07 | S4: =INDEX(Indstillinger!$D$27:$D$38,9) -> 0.09 | T4: =INDEX(Indstillinger!$D$27:$D$38,10) -> 0.09 | U4: =INDEX(Indstillinger!$D$27:$D$38,11) -> 0.1 | V4: =INDEX(Indstillinger!$D$27:$D$38,12) -> 0.11
B5: Sælger | C5: Indeks | D5: Territorie | E5: Start | F5: Slut | G5: Kapacitet | H5: Opstartstrin | I5: Territorie ukendt | J5: Fast kvote? | K5: Jan | L5: Feb | M5: Mar | N5: Apr | O5: Maj | P5: Jun | Q5: Jul | R5: Aug | S5: Sep | T5: Okt | U5: Nov | V5: Dec | W5: Sum vægte | X5: Fast kvote | Y5: Vægte til fordeling | Z5: FTE-år
B6: =IF(Sælgere!$B$6="","",Sælgere!$B$6) -> Anna Holm | C6: =IF($B6="","",IFERROR(IF(INDEX(Territorier!$C$6:$C$15,MATCH(Sælgere!$C$6,Territorier!$B$6:$B$15,0))="",1,INDEX(Territorier!$C$6:$C$15,MATCH(Sælgere!$C$6,Territorier!$B$6:$B$15,0))/100),1)) -> 1.2 | D6: =IF($B6="","",Sælgere!$C$6&"") -> Hovedstaden | E6: =IF($B6="","",IF(N(Sælgere!$D$6)<1,1,Sælgere!$D$6)) -> 1 | F6: =IF($B6="","",IF(N(Sælgere!$F$6)<1,12,Sælgere!$F$6)) -> 12 | G6: =IF($B6="",0,IF(Sælgere!$G$6="",1,N(Sælgere!$G$6))) -> 1 | H6: =IF($B6="","",N(Sælgere!$E$6)) -> 0 | I6: =IF(AND($B6<>"",ISNA(MATCH(Sælgere!$C$6,Territorier!$B$6:$B$15,0))),1,0) -> 0 | J6: =IF(AND($B6<>"",N(Sælgere!$H$6)>0),1,0) -> 0 | K6: =IF($B6="",0,IF(OR(1<$E6,1>$F6),0,INDEX(Indstillinger!$D$27:$D$38,1)*$G6*$C6*IF($H6=0,1,IF($H6+1-$E6>6,1,INDEX(Indstillinger!$C$18:$C$23,$H6+1-$E6))))) -> 0.084 | L6: =IF($B6="",0,IF(OR(2<$E6,2>$F6),0,INDEX(Indstillinger!$D$27:$D$38,2)*$G6*$C6*IF($H6=0,1,IF($H6+2-$E6>6,1,INDEX(Indstillinger!$C$18:$C$23,$H6+2-$E6))))) -> 0.096 | M6: =IF($B6="",0,IF(OR(3<$E6,3>$F6),0,INDEX(Indstillinger!$D$27:$D$38,3)*$G6*$C6*IF($H6=0,1,IF($H6+3-$E6>6,1,INDEX(Indstillinger!$C$18:$C$23,$H6+3-$E6))))) -> 0.108 | N6: =IF($B6="",0,IF(OR(4<$E6,4>$F6),0,INDEX(Indstillinger!$D$27:$D$38,4)*$G6*$C6*IF($H6=0,1,IF($H6+4-$E6>6,1,INDEX(Indstillinger!$C$18:$C$23,$H6+4-$E6))))) -> 0.096 | O6: =IF($B6="",0,IF(OR(5<$E6,5>$F6),0,INDEX(Indstillinger!$D$27:$D$38,5)*$G6*$C6*IF($H6=0,1,IF($H6+5-$E6>6,1,INDEX(Indstillinger!$C$18:$C$23,$H6+5-$E6))))) -> 0.108 | P6: =IF($B6="",0,IF(OR(6<$E6,6>$F6),0,INDEX(Indstillinger!$D$27:$D$38,6)*$G6*$C6*IF($H6=0,1,IF($H6+6-$E6>6,1,INDEX(Indstillinger!$C$18:$C$23,$H6+6-$E6))))) -> 0.108 | Q6: =IF($B6="",0,IF(OR(7<$E6,7>$F6),0,INDEX(Indstillinger!$D$27:$D$38,7)*$G6*$C6*IF($H6=0,1,IF($H6+7-$E6>6,1,INDEX(Indstillinger!$C$18:$C$23,$H6+7-$E6))))) -> 0.048 | R6: =IF($B6="",0,IF(OR(8<$E6,8>$F6),0,INDEX(Indstillinger!$D$27:$D$38,8)*$G6*$C6*IF($H6=0,1,IF($H6+8-$E6>6,1,INDEX(Indstillinger!$C$18:$C$23,$H6+8-$E6))))) -> 0.084 | S6: =IF($B6="",0,IF(OR(9<$E6,9>$F6),0,INDEX(Indstillinger!$D$27:$D$38,9)*$G6*$C6*IF($H6=0,1,IF($H6+9-$E6>6,1,INDEX(Indstillinger!$C$18:$C$23,$H6+9-$E6))))) -> 0.108 | T6: =IF($B6="",0,IF(OR(10<$E6,10>$F6),0,INDEX(Indstillinger!$D$27:$D$38,10)*$G6*$C6*IF($H6=0,1,IF($H6+10-$E6>6,1,INDEX(Indstillinger!$C$18:$C$23,$H6+10-$E6))))) -> 0.108 | U6: =IF($B6="",0,IF(OR(11<$E6,11>$F6),0,INDEX(Indstillinger!$D$27:$D$38,11)*$G6*$C6*IF($H6=0,1,IF($H6+11-$E6>6,1,INDEX(Indstillinger!$C$18:$C$23,$H6+11-$E6))))) -> 0.12 | V6: =IF($B6="",0,IF(OR(12<$E6,12>$F6),0,INDEX(Indstillinger!$D$27:$D$38,12)*$G6*$C6*IF($H6=0,1,IF($H6+12-$E6>6,1,INDEX(Indstillinger!$C$18:$C$23,$H6+12-$E6))))) -> 0.132 | W6: =SUM(K6:V6) -> 1.2 | X6: =IF($J6=1,N(Sælgere!$H$6),0) -> 0 | Y6: =IF($J6=1,0,W6) -> 1.2 | Z6: =IF(OR($B6="",$J6=1),0,SUMPRODUCT(--(K6:V6>0),$K$4:$V$4)*$G6) -> 1
B7: =IF(Sælgere!$B$7="","",Sælgere!$B$7) -> Bo Jensen | C7: =IF($B7="","",IFERROR(IF(INDEX(Territorier!$C$6:$C$15,MATCH(Sælgere!$C$7,Territorier!$B$6:$B$15,0))="",1,INDEX(Territorier!$C$6:$C$15,MATCH(Sælgere!$C$7,Territorier!$B$6:$B$15,0))/100),1)) -> 1.2 | D7: =IF($B7="","",Sælgere!$C$7&"") -> Hovedstaden | E7: =IF($B7="","",IF(N(Sælgere!$D$7)<1,1,Sælgere!$D$7)) -> 1 | F7: =IF($B7="","",IF(N(Sælgere!$F$7)<1,12,Sælgere!$F$7)) -> 12 | G7: =IF($B7="",0,IF(Sælgere!$G$7="",1,N(Sælgere!$G$7))) -> 1 | H7: =IF($B7="","",N(Sælgere!$E$7)) -> 0 | I7: =IF(AND($B7<>"",ISNA(MATCH(Sælgere!$C$7,Territorier!$B$6:$B$15,0))),1,0) -> 0 | J7: =IF(AND($B7<>"",N(Sælgere!$H$7)>0),1,0) -> 0 | K7: =IF($B7="",0,IF(OR(1<$E7,1>$F7),0,INDEX(Indstillinger!$D$27:$D$38,1)*$G7*$C7*IF($H7=0,1,IF($H7+1-$E7>6,1,INDEX(Indstillinger!$C$18:$C$23,$H7+1-$E7))))) -> 0.084 | L7: =IF($B7="",0,IF(OR(2<$E7,2>$F7),0,INDEX(Indstillinger!$D$27:$D$38,2)*$G7*$C7*IF($H7=0,1,IF($H7+2-$E7>6,1,INDEX(Indstillinger!$C$18:$C$23,$H7+2-$E7))))) -> 0.096 | M7: =IF($B7="",0,IF(OR(3<$E7,3>$F7),0,INDEX(Indstillinger!$D$27:$D$38,3)*$G7*$C7*IF($H7=0,1,IF($H7+3-$E7>6,1,INDEX(Indstillinger!$C$18:$C$23,$H7+3-$E7))))) -> 0.108 | N7: =IF($B7="",0,IF(OR(4<$E7,4>$F7),0,INDEX(Indstillinger!$D$27:$D$38,4)*$G7*$C7*IF($H7=0,1,IF($H7+4-$E7>6,1,INDEX(Indstillinger!$C$18:$C$23,$H7+4-$E7))))) -> 0.096 | O7: =IF($B7="",0,IF(OR(5<$E7,5>$F7),0,INDEX(Indstillinger!$D$27:$D$38,5)*$G7*$C7*IF($H7=0,1,IF($H7+5-$E7>6,1,INDEX(Indstillinger!$C$18:$C$23,$H7+5-$E7))))) -> 0.108 | P7: =IF($B7="",0,IF(OR(6<$E7,6>$F7),0,INDEX(Indstillinger!$D$27:$D$38,6)*$G7*$C7*IF($H7=0,1,IF($H7+6-$E7>6,1,INDEX(Indstillinger!$C$18:$C$23,$H7+6-$E7))))) -> 0.108 | Q7: =IF($B7="",0,IF(OR(7<$E7,7>$F7),0,INDEX(Indstillinger!$D$27:$D$38,7)*$G7*$C7*IF($H7=0,1,IF($H7+7-$E7>6,1,INDEX(Indstillinger!$C$18:$C$23,$H7+7-$E7))))) -> 0.048 | R7: =IF($B7="",0,IF(OR(8<$E7,8>$F7),0,INDEX(Indstillinger!$D$27:$D$38,8)*$G7*$C7*IF($H7=0,1,IF($H7+8-$E7>6,1,INDEX(Indstillinger!$C$18:$C$23,$H7+8-$E7))))) -> 0.084 | S7: =IF($B7="",0,IF(OR(9<$E7,9>$F7),0,INDEX(Indstillinger!$D$27:$D$38,9)*$G7*$C7*IF($H7=0,1,IF($H7+9-$E7>6,1,INDEX(Indstillinger!$C$18:$C$23,$H7+9-$E7))))) -> 0.108 | T7: =IF($B7="",0,IF(OR(10<$E7,10>$F7),0,INDEX(Indstillinger!$D$27:$D$38,10)*$G7*$C7*IF($H7=0,1,IF($H7+10-$E7>6,1,INDEX(Indstillinger!$C$18:$C$23,$H7+10-$E7))))) -> 0.108 | U7: =IF($B7="",0,IF(OR(11<$E7,11>$F7),0,INDEX(Indstillinger!$D$27:$D$38,11)*$G7*$C7*IF($H7=0,1,IF($H7+11-$E7>6,1,INDEX(Indstillinger!$C$18:$C$23,$H7+11-$E7))))) -> 0.12 | V7: =IF($B7="",0,IF(OR(12<$E7,12>$F7),0,INDEX(Indstillinger!$D$27:$D$38,12)*$G7*$C7*IF($H7=0,1,IF($H7+12-$E7>6,1,INDEX(Indstillinger!$C$18:$C$23,$H7+12-$E7))))) -> 0.132 | W7: =SUM(K7:V7) -> 1.2 | X7: =IF($J7=1,N(Sælgere!$H$7),0) -> 0 | Y7: =IF($J7=1,0,W7) -> 1.2 | Z7: =IF(OR($B7="",$J7=1),0,SUMPRODUCT(--(K7:V7>0),$K$4:$V$4)*$G7) -> 1
B8: =IF(Sælgere!$B$8="","",Sælgere!$B$8) -> Camilla Nørgaard | C8: =IF($B8="","",IFERROR(IF(INDEX(Territorier!$C$6:$C$15,MATCH(Sælgere!$C$8,Territorier!$B$6:$B$15,0))="",1,INDEX(Territorier!$C$6:$C$15,MATCH(Sælgere!$C$8,Territorier!$B$6:$B$15,0))/100),1)) -> 1 | D8: =IF($B8="","",Sælgere!$C$8&"") -> Jylland | E8: =IF($B8="","",IF(N(Sælgere!$D$8)<1,1,Sælgere!$D$8)) -> 1 | F8: =IF($B8="","",IF(N(Sælgere!$F$8)<1,12,Sælgere!$F$8)) -> 12 | G8: =IF($B8="",0,IF(Sælgere!$G$8="",1,N(Sælgere!$G$8))) -> 1 | H8: =IF($B8="","",N(Sælgere!$E$8)) -> 0 | I8: =IF(AND($B8<>"",ISNA(MATCH(Sælgere!$C$8,Territorier!$B$6:$B$15,0))),1,0) -> 0 | J8: =IF(AND($B8<>"",N(Sælgere!$H$8)>0),1,0) -> 0 | K8: =IF($B8="",0,IF(OR(1<$E8,1>$F8),0,INDEX(Indstillinger!$D$27:$D$38,1)*$G8*$C8*IF($H8=0,1,IF($H8+1-$E8>6,1,INDEX(Indstillinger!$C$18:$C$23,$H8+1-$E8))))) -> 0.07 | L8: =IF($B8="",0,IF(OR(2<$E8,2>$F8),0,INDEX(Indstillinger!$D$27:$D$38,2)*$G8*$C8*IF($H8=0,1,IF($H8+2-$E8>6,1,INDEX(Indstillinger!$C$18:$C$23,$H8+2-$E8))))) -> 0.08 | M8: =IF($B8="",0,IF(OR(3<$E8,3>$F8),0,INDEX(Indstillinger!$D$27:$D$38,3)*$G8*$C8*IF($H8=0,1,IF($H8+3-$E8>6,1,INDEX(Indstillinger!$C$18:$C$23,$H8+3-$E8))))) -> 0.09 | N8: =IF($B8="",0,IF(OR(4<$E8,4>$F8),0,INDEX(Indstillinger!$D$27:$D$38,4)*$G8*$C8*IF($H8=0,1,IF($H8+4-$E8>6,1,INDEX(Indstillinger!$C$18:$C$23,$H8+4-$E8))))) -> 0.08 | O8: =IF($B8="",0,IF(OR(5<$E8,5>$F8),0,INDEX(Indstillinger!$D$27:$D$38,5)*$G8*$C8*IF($H8=0,1,IF($H8+5-$E8>6,1,INDEX(Indstillinger!$C$18:$C$23,$H8+5-$E8))))) -> 0.09 | P8: =IF($B8="",0,IF(OR(6<$E8,6>$F8),0,INDEX(Indstillinger!$D$27:$D$38,6)*$G8*$C8*IF($H8=0,1,IF($H8+6-$E8>6,1,INDEX(Indstillinger!$C$18:$C$23,$H8+6-$E8))))) -> 0.09 | Q8: =IF($B8="",0,IF(OR(7<$E8,7>$F8),0,INDEX(Indstillinger!$D$27:$D$38,7)*$G8*$C8*IF($H8=0,1,IF($H8+7-$E8>6,1,INDEX(Indstillinger!$C$18:$C$23,$H8+7-$E8))))) -> 0.04 | R8: =IF($B8="",0,IF(OR(8<$E8,8>$F8),0,INDEX(Indstillinger!$D$27:$D$38,8)*$G8*$C8*IF($H8=0,1,IF($H8+8-$E8>6,1,INDEX(Indstillinger!$C$18:$C$23,$H8+8-$E8))))) -> 0.07 | S8: =IF($B8="",0,IF(OR(9<$E8,9>$F8),0,INDEX(Indstillinger!$D$27:$D$38,9)*$G8*$C8*IF($H8=0,1,IF($H8+9-$E8>6,1,INDEX(Indstillinger!$C$18:$C$23,$H8+9-$E8))))) -> 0.09 | T8: =IF($B8="",0,IF(OR(10<$E8,10>$F8),0,INDEX(Indstillinger!$D$27:$D$38,10)*$G8*$C8*IF($H8=0,1,IF($H8+10-$E8>6,1,INDEX(Indstillinger!$C$18:$C$23,$H8+10-$E8))))) -> 0.09 | U8: =IF($B8="",0,IF(OR(11<$E8,11>$F8),0,INDEX(Indstillinger!$D$27:$D$38,11)*$G8*$C8*IF($H8=0,1,IF($H8+11-$E8>6,1,INDEX(Indstillinger!$C$18:$C$23,$H8+11-$E8))))) -> 0.1 | V8: =IF($B8="",0,IF(OR(12<$E8,12>$F8),0,INDEX(Indstillinger!$D$27:$D$38,12)*$G8*$C8*IF($H8=0,1,IF($H8+12-$E8>6,1,INDEX(Indstillinger!$C$18:$C$23,$H8+12-$E8))))) -> 0.11 | W8: =SUM(K8:V8) -> 1 | X8: =IF($J8=1,N(Sælgere!$H$8),0) -> 0 | Y8: =IF($J8=1,0,W8) -> 1 | Z8: =IF(OR($B8="",$J8=1),0,SUMPRODUCT(--(K8:V8>0),$K$4:$V$4)*$G8) -> 1
B9: =IF(Sælgere!$B$9="","",Sælgere!$B$9) -> Dennis Lund | C9: =IF($B9="","",IFERROR(IF(INDEX(Territorier!$C$6:$C$15,MATCH(Sælgere!$C$9,Territorier!$B$6:$B$15,0))="",1,INDEX(Territorier!$C$6:$C$15,MATCH(Sælgere!$C$9,Territorier!$B$6:$B$15,0))/100),1)) -> 1 | D9: =IF($B9="","",Sælgere!$C$9&"") -> Jylland | E9: =IF($B9="","",IF(N(Sælgere!$D$9)<1,1,Sælgere!$D$9)) -> 1 | F9: =IF($B9="","",IF(N(Sælgere!$F$9)<1,12,Sælgere!$F$9)) -> 12 | G9: =IF($B9="",0,IF(Sælgere!$G$9="",1,N(Sælgere!$G$9))) -> 1 | H9: =IF($B9="","",N(Sælgere!$E$9)) -> 0 | I9: =IF(AND($B9<>"",ISNA(MATCH(Sælgere!$C$9,Territorier!$B$6:$B$15,0))),1,0) -> 0 | J9: =IF(AND($B9<>"",N(Sælgere!$H$9)>0),1,0) -> 0 | K9: =IF($B9="",0,IF(OR(1<$E9,1>$F9),0,INDEX(Indstillinger!$D$27:$D$38,1)*$G9*$C9*IF($H9=0,1,IF($H9+1-$E9>6,1,INDEX(Indstillinger!$C$18:$C$23,$H9+1-$E9))))) -> 0.07 | L9: =IF($B9="",0,IF(OR(2<$E9,2>$F9),0,INDEX(Indstillinger!$D$27:$D$38,2)*$G9*$C9*IF($H9=0,1,IF($H9+2-$E9>6,1,INDEX(Indstillinger!$C$18:$C$23,$H9+2-$E9))))) -> 0.08 | M9: =IF($B9="",0,IF(OR(3<$E9,3>$F9),0,INDEX(Indstillinger!$D$27:$D$38,3)*$G9*$C9*IF($H9=0,1,IF($H9+3-$E9>6,1,INDEX(Indstillinger!$C$18:$C$23,$H9+3-$E9))))) -> 0.09 | N9: =IF($B9="",0,IF(OR(4<$E9,4>$F9),0,INDEX(Indstillinger!$D$27:$D$38,4)*$G9*$C9*IF($H9=0,1,IF($H9+4-$E9>6,1,INDEX(Indstillinger!$C$18:$C$23,$H9+4-$E9))))) -> 0.08 | O9: =IF($B9="",0,IF(OR(5<$E9,5>$F9),0,INDEX(Indstillinger!$D$27:$D$38,5)*$G9*$C9*IF($H9=0,1,IF($H9+5-$E9>6,1,INDEX(Indstillinger!$C$18:$C$23,$H9+5-$E9))))) -> 0.09 | P9: =IF($B9="",0,IF(OR(6<$E9,6>$F9),0,INDEX(Indstillinger!$D$27:$D$38,6)*$G9*$C9*IF($H9=0,1,IF($H9+6-$E9>6,1,INDEX(Indstillinger!$C$18:$C$23,$H9+6-$E9))))) -> 0.09 | Q9: =IF($B9="",0,IF(OR(7<$E9,7>$F9),0,INDEX(Indstillinger!$D$27:$D$38,7)*$G9*$C9*IF($H9=0,1,IF($H9+7-$E9>6,1,INDEX(Indstillinger!$C$18:$C$23,$H9+7-$E9))))) -> 0.04 | R9: =IF($B9="",0,IF(OR(8<$E9,8>$F9),0,INDEX(Indstillinger!$D$27:$D$38,8)*$G9*$C9*IF($H9=0,1,IF($H9+8-$E9>6,1,INDEX(Indstillinger!$C$18:$C$23,$H9+8-$E9))))) -> 0.07 | S9: =IF($B9="",0,IF(OR(9<$E9,9>$F9),0,INDEX(Indstillinger!$D$27:$D$38,9)*$G9*$C9*IF($H9=0,1,IF($H9+9-$E9>6,1,INDEX(Indstillinger!$C$18:$C$23,$H9+9-$E9))))) -> 0.09 | T9: =IF($B9="",0,IF(OR(10<$E9,10>$F9),0,INDEX(Indstillinger!$D$27:$D$38,10)*$G9*$C9*IF($H9=0,1,IF($H9+10-$E9>6,1,INDEX(Indstillinger!$C$18:$C$23,$H9+10-$E9))))) -> 0.09 | U9: =IF($B9="",0,IF(OR(11<$E9,11>$F9),0,INDEX(Indstillinger!$D$27:$D$38,11)*$G9*$C9*IF($H9=0,1,IF($H9+11-$E9>6,1,INDEX(Indstillinger!$C$18:$C$23,$H9+11-$E9))))) -> 0.1 | V9: =IF($B9="",0,IF(OR(12<$E9,12>$F9),0,INDEX(Indstillinger!$D$27:$D$38,12)*$G9*$C9*IF($H9=0,1,IF($H9+12-$E9>6,1,INDEX(Indstillinger!$C$18:$C$23,$H9+12-$E9))))) -> 0.11 | W9: =SUM(K9:V9) -> 1 | X9: =IF($J9=1,N(Sælgere!$H$9),0) -> 0 | Y9: =IF($J9=1,0,W9) -> 1 | Z9: =IF(OR($B9="",$J9=1),0,SUMPRODUCT(--(K9:V9>0),$K$4:$V$4)*$G9) -> 1
B10: =IF(Sælgere!$B$10="","",Sælgere!$B$10) -> Emma Krogh | C10: =IF($B10="","",IFERROR(IF(INDEX(Territorier!$C$6:$C$15,MATCH(Sælgere!$C$10,Territorier!$B$6:$B$15,0))="",1,INDEX(Territorier!$C$6:$C$15,MATCH(Sælgere!$C$10,Territorier!$B$6:$B$15,0))/100),1)) -> 0.85 | D10: =IF($B10="","",Sælgere!$C$10&"") -> Fyn og Sjælland | E10: =IF($B10="","",IF(N(Sælgere!$D$10)<1,1,Sælgere!$D$10)) -> 1 | F10: =IF($B10="","",IF(N(Sælgere!$F$10)<1,12,Sælgere!$F$10)) -> 9 | G10: =IF($B10="",0,IF(Sælgere!$G$10="",1,N(Sælgere!$G$10))) -> 1 | H10: =IF($B10="","",N(Sælgere!$E$10)) -> 0 | I10: =IF(AND($B10<>"",ISNA(MATCH(Sælgere!$C$10,Territorier!$B$6:$B$15,0))),1,0) -> 0 | J10: =IF(AND($B10<>"",N(Sælgere!$H$10)>0),1,0) -> 0 | K10: =IF($B10="",0,IF(OR(1<$E10,1>$F10),0,INDEX(Indstillinger!$D$27:$D$38,1)*$G10*$C10*IF($H10=0,1,IF($H10+1-$E10>6,1,INDEX(Indstillinger!$C$18:$C$23,$H10+1-$E10))))) -> 0.0595 | L10: =IF($B10="",0,IF(OR(2<$E10,2>$F10),0,INDEX(Indstillinger!$D$27:$D$38,2)*$G10*$C10*IF($H10=0,1,IF($H10+2-$E10>6,1,INDEX(Indstillinger!$C$18:$C$23,$H10+2-$E10))))) -> 0.068 | M10: =IF($B10="",0,IF(OR(3<$E10,3>$F10),0,INDEX(Indstillinger!$D$27:$D$38,3)*$G10*$C10*IF($H10=0,1,IF($H10+3-$E10>6,1,INDEX(Indstillinger!$C$18:$C$23,$H10+3-$E10))))) -> 0.0765 | N10: =IF($B10="",0,IF(OR(4<$E10,4>$F10),0,INDEX(Indstillinger!$D$27:$D$38,4)*$G10*$C10*IF($H10=0,1,IF($H10+4-$E10>6,1,INDEX(Indstillinger!$C$18:$C$23,$H10+4-$E10))))) -> 0.068 | O10: =IF($B10="",0,IF(OR(5<$E10,5>$F10),0,INDEX(Indstillinger!$D$27:$D$38,5)*$G10*$C10*IF($H10=0,1,IF($H10+5-$E10>6,1,INDEX(Indstillinger!$C$18:$C$23,$H10+5-$E10))))) -> 0.0765 | P10: =IF($B10="",0,IF(OR(6<$E10,6>$F10),0,INDEX(Indstillinger!$D$27:$D$38,6)*$G10*$C10*IF($H10=0,1,IF($H10+6-$E10>6,1,INDEX(Indstillinger!$C$18:$C$23,$H10+6-$E10))))) -> 0.0765 | Q10: =IF($B10="",0,IF(OR(7<$E10,7>$F10),0,INDEX(Indstillinger!$D$27:$D$38,7)*$G10*$C10*IF($H10=0,1,IF($H10+7-$E10>6,1,INDEX(Indstillinger!$C$18:$C$23,$H10+7-$E10))))) -> 0.034 | R10: =IF($B10="",0,IF(OR(8<$E10,8>$F10),0,INDEX(Indstillinger!$D$27:$D$38,8)*$G10*$C10*IF($H10=0,1,IF($H10+8-$E10>6,1,INDEX(Indstillinger!$C$18:$C$23,$H10+8-$E10))))) -> 0.0595 | S10: =IF($B10="",0,IF(OR(9<$E10,9>$F10),0,INDEX(Indstillinger!$D$27:$D$38,9)*$G10*$C10*IF($H10=0,1,IF($H10+9-$E10>6,1,INDEX(Indstillinger!$C$18:$C$23,$H10+9-$E10))))) -> 0.0765 | T10: =IF($B10="",0,IF(OR(10<$E10,10>$F10),0,INDEX(Indstillinger!$D$27:$D$38,10)*$G10*$C10*IF($H10=0,1,IF($H10+10-$E10>6,1,INDEX(Indstillinger!$C$18:$C$23,$H10+10-$E10))))) -> 0 | U10: =IF($B10="",0,IF(OR(11<$E10,11>$F10),0,INDEX(Indstillinger!$D$27:$D$38,11)*$G10*$C10*IF($H10=0,1,IF($H10+11-$E10>6,1,INDEX(Indstillinger!$C$18:$C$23,$H10+11-$E10))))) -> 0 | V10: =IF($B10="",0,IF(OR(12<$E10,12>$F10),0,INDEX(Indstillinger!$D$27:$D$38,12)*$G10*$C10*IF($H10=0,1,IF($H10+12-$E10>6,1,INDEX(Indstillinger!$C$18:$C$23,$H10+12-$E10))))) -> 0 | W10: =SUM(K10:V10) -> 0.595 | X10: =IF($J10=1,N(Sælgere!$H$10),0) -> 0 | Y10: =IF($J10=1,0,W10) -> 0.595 | Z10: =IF(OR($B10="",$J10=1),0,SUMPRODUCT(--(K10:V10>0),$K$4:$V$4)*$G10) -> 0.7
B11: =IF(Sælgere!$B$11="","",Sælgere!$B$11) -> Frederik Sand | C11: =IF($B11="","",IFERROR(IF(INDEX(Territorier!$C$6:$C$15,MATCH(Sælgere!$C$11,Territorier!$B$6:$B$15,0))="",1,INDEX(Territorier!$C$6:$C$15,MATCH(Sælgere!$C$11,Territorier!$B$6:$B$15,0))/100),1)) -> 1 | D11: =IF($B11="","",Sælgere!$C$11&"") -> Key accounts | E11: =IF($B11="","",IF(N(Sælgere!$D$11)<1,1,Sælgere!$D$11)) -> 1 | F11: =IF($B11="","",IF(N(Sælgere!$F$11)<1,12,Sælgere!$F$11)) -> 12 | G11: =IF($B11="",0,IF(Sælgere!$G$11="",1,N(Sælgere!$G$11))) -> 1 | H11: =IF($B11="","",N(Sælgere!$E$11)) -> 0 | I11: =IF(AND($B11<>"",ISNA(MATCH(Sælgere!$C$11,Territorier!$B$6:$B$15,0))),1,0) -> 0 | J11: =IF(AND($B11<>"",N(Sælgere!$H$11)>0),1,0) -> 1 | K11: =IF($B11="",0,IF(OR(1<$E11,1>$F11),0,INDEX(Indstillinger!$D$27:$D$38,1)*$G11*$C11*IF($H11=0,1,IF($H11+1-$E11>6,1,INDEX(Indstillinger!$C$18:$C$23,$H11+1-$E11))))) -> 0.07 | L11: =IF($B11="",0,IF(OR(2<$E11,2>$F11),0,INDEX(Indstillinger!$D$27:$D$38,2)*$G11*$C11*IF($H11=0,1,IF($H11+2-$E11>6,1,INDEX(Indstillinger!$C$18:$C$23,$H11+2-$E11))))) -> 0.08 | M11: =IF($B11="",0,IF(OR(3<$E11,3>$F11),0,INDEX(Indstillinger!$D$27:$D$38,3)*$G11*$C11*IF($H11=0,1,IF($H11+3-$E11>6,1,INDEX(Indstillinger!$C$18:$C$23,$H11+3-$E11))))) -> 0.09 | N11: =IF($B11="",0,IF(OR(4<$E11,4>$F11),0,INDEX(Indstillinger!$D$27:$D$38,4)*$G11*$C11*IF($H11=0,1,IF($H11+4-$E11>6,1,INDEX(Indstillinger!$C$18:$C$23,$H11+4-$E11))))) -> 0.08 | O11: =IF($B11="",0,IF(OR(5<$E11,5>$F11),0,INDEX(Indstillinger!$D$27:$D$38,5)*$G11*$C11*IF($H11=0,1,IF($H11+5-$E11>6,1,INDEX(Indstillinger!$C$18:$C$23,$H11+5-$E11))))) -> 0.09 | P11: =IF($B11="",0,IF(OR(6<$E11,6>$F11),0,INDEX(Indstillinger!$D$27:$D$38,6)*$G11*$C11*IF($H11=0,1,IF($H11+6-$E11>6,1,INDEX(Indstillinger!$C$18:$C$23,$H11+6-$E11))))) -> 0.09 | Q11: =IF($B11="",0,IF(OR(7<$E11,7>$F11),0,INDEX(Indstillinger!$D$27:$D$38,7)*$G11*$C11*IF($H11=0,1,IF($H11+7-$E11>6,1,INDEX(Indstillinger!$C$18:$C$23,$H11+7-$E11))))) -> 0.04 | R11: =IF($B11="",0,IF(OR(8<$E11,8>$F11),0,INDEX(Indstillinger!$D$27:$D$38,8)*$G11*$C11*IF($H11=0,1,IF($H11+8-$E11>6,1,INDEX(Indstillinger!$C$18:$C$23,$H11+8-$E11))))) -> 0.07 | S11: =IF($B11="",0,IF(OR(9<$E11,9>$F11),0,INDEX(Indstillinger!$D$27:$D$38,9)*$G11*$C11*IF($H11=0,1,IF($H11+9-$E11>6,1,INDEX(Indstillinger!$C$18:$C$23,$H11+9-$E11))))) -> 0.09 | T11: =IF($B11="",0,IF(OR(10<$E11,10>$F11),0,INDEX(Indstillinger!$D$27:$D$38,10)*$G11*$C11*IF($H11=0,1,IF($H11+10-$E11>6,1,INDEX(Indstillinger!$C$18:$C$23,$H11+10-$E11))))) -> 0.09 | U11: =IF($B11="",0,IF(OR(11<$E11,11>$F11),0,INDEX(Indstillinger!$D$27:$D$38,11)*$G11*$C11*IF($H11=0,1,IF($H11+11-$E11>6,1,INDEX(Indstillinger!$C$18:$C$23,$H11+11-$E11))))) -> 0.1 | V11: =IF($B11="",0,IF(OR(12<$E11,12>$F11),0,INDEX(Indstillinger!$D$27:$D$38,12)*$G11*$C11*IF($H11=0,1,IF($H11+12-$E11>6,1,INDEX(Indstillinger!$C$18:$C$23,$H11+12-$E11))))) -> 0.11 | W11: =SUM(K11:V11) -> 1 | X11: =IF($J11=1,N(Sælgere!$H$11),0) -> 4500000 | Y11: =IF($J11=1,0,W11) -> 0 | Z11: =IF(OR($B11="",$J11=1),0,SUMPRODUCT(--(K11:V11>0),$K$4:$V$4)*$G11) -> 0
B12: =IF(Sælgere!$B$12="","",Sælgere!$B$12) -> Gitte Mølgaard | C12: =IF($B12="","",IFERROR(IF(INDEX(Territorier!$C$6:$C$15,MATCH(Sælgere!$C$12,Territorier!$B$6:$B$15,0))="",1,INDEX(Territorier!$C$6:$C$15,MATCH(Sælgere!$C$12,Territorier!$B$6:$B$15,0))/100),1)) -> 0.85 | D12: =IF($B12="","",Sælgere!$C$12&"") -> Fyn og Sjælland | E12: =IF($B12="","",IF(N(Sælgere!$D$12)<1,1,Sælgere!$D$12)) -> 1 | F12: =IF($B12="","",IF(N(Sælgere!$F$12)<1,12,Sælgere!$F$12)) -> 12 | G12: =IF($B12="",0,IF(Sælgere!$G$12="",1,N(Sælgere!$G$12))) -> 1 | H12: =IF($B12="","",N(Sælgere!$E$12)) -> 3 | I12: =IF(AND($B12<>"",ISNA(MATCH(Sælgere!$C$12,Territorier!$B$6:$B$15,0))),1,0) -> 0 | J12: =IF(AND($B12<>"",N(Sælgere!$H$12)>0),1,0) -> 0 | K12: =IF($B12="",0,IF(OR(1<$E12,1>$F12),0,INDEX(Indstillinger!$D$27:$D$38,1)*$G12*$C12*IF($H12=0,1,IF($H12+1-$E12>6,1,INDEX(Indstillinger!$C$18:$C$23,$H12+1-$E12))))) -> 0.044625 | L12: =IF($B12="",0,IF(OR(2<$E12,2>$F12),0,INDEX(Indstillinger!$D$27:$D$38,2)*$G12*$C12*IF($H12=0,1,IF($H12+2-$E12>6,1,INDEX(Indstillinger!$C$18:$C$23,$H12+2-$E12))))) -> 0.068 | M12: =IF($B12="",0,IF(OR(3<$E12,3>$F12),0,INDEX(Indstillinger!$D$27:$D$38,3)*$G12*$C12*IF($H12=0,1,IF($H12+3-$E12>6,1,INDEX(Indstillinger!$C$18:$C$23,$H12+3-$E12))))) -> 0.0765 | N12: =IF($B12="",0,IF(OR(4<$E12,4>$F12),0,INDEX(Indstillinger!$D$27:$D$38,4)*$G12*$C12*IF($H12=0,1,IF($H12+4-$E12>6,1,INDEX(Indstillinger!$C$18:$C$23,$H12+4-$E12))))) -> 0.068 | O12: =IF($B12="",0,IF(OR(5<$E12,5>$F12),0,INDEX(Indstillinger!$D$27:$D$38,5)*$G12*$C12*IF($H12=0,1,IF($H12+5-$E12>6,1,INDEX(Indstillinger!$C$18:$C$23,$H12+5-$E12))))) -> 0.0765 | P12: =IF($B12="",0,IF(OR(6<$E12,6>$F12),0,INDEX(Indstillinger!$D$27:$D$38,6)*$G12*$C12*IF($H12=0,1,IF($H12+6-$E12>6,1,INDEX(Indstillinger!$C$18:$C$23,$H12+6-$E12))))) -> 0.0765 | Q12: =IF($B12="",0,IF(OR(7<$E12,7>$F12),0,INDEX(Indstillinger!$D$27:$D$38,7)*$G12*$C12*IF($H12=0,1,IF($H12+7-$E12>6,1,INDEX(Indstillinger!$C$18:$C$23,$H12+7-$E12))))) -> 0.034 | R12: =IF($B12="",0,IF(OR(8<$E12,8>$F12),0,INDEX(Indstillinger!$D$27:$D$38,8)*$G12*$C12*IF($H12=0,1,IF($H12+8-$E12>6,1,INDEX(Indstillinger!$C$18:$C$23,$H12+8-$E12))))) -> 0.0595 | S12: =IF($B12="",0,IF(OR(9<$E12,9>$F12),0,INDEX(Indstillinger!$D$27:$D$38,9)*$G12*$C12*IF($H12=0,1,IF($H12+9-$E12>6,1,INDEX(Indstillinger!$C$18:$C$23,$H12+9-$E12))))) -> 0.0765 | T12: =IF($B12="",0,IF(OR(10<$E12,10>$F12),0,INDEX(Indstillinger!$D$27:$D$38,10)*$G12*$C12*IF($H12=0,1,IF($H12+10-$E12>6,1,INDEX(Indstillinger!$C$18:$C$23,$H12+10-$E12))))) -> 0.0765 | U12: =IF($B12="",0,IF(OR(11<$E12,11>$F12),0,INDEX(Indstillinger!$D$27:$D$38,11)*$G12*$C12*IF($H12=0,1,IF($H12+11-$E12>6,1,INDEX(Indstillinger!$C$18:$C$23,$H12+11-$E12))))) -> 0.085 | V12: =IF($B12="",0,IF(OR(12<$E12,12>$F12),0,INDEX(Indstillinger!$D$27:$D$38,12)*$G12*$C12*IF($H12=0,1,IF($H12+12-$E12>6,1,INDEX(Indstillinger!$C$18:$C$23,$H12+12-$E12))))) -> 0.0935 | W12: =SUM(K12:V12) -> 0.835125 | X12: =IF($J12=1,N(Sælgere!$H$12),0) -> 0 | Y12: =IF($J12=1,0,W12) -> 0.835125 | Z12: =IF(OR($B12="",$J12=1),0,SUMPRODUCT(--(K12:V12>0),$K$4:$V$4)*$G12) -> 1
B13: =IF(Sælgere!$B$13="","",Sælgere!$B$13) -> Henrik Bak | C13: =IF($B13="","",IFERROR(IF(INDEX(Territorier!$C$6:$C$15,MATCH(Sælgere!$C$13,Territorier!$B$6:$B$15,0))="",1,INDEX(Territorier!$C$6:$C$15,MATCH(Sælgere!$C$13,Territorier!$B$6:$B$15,0))/100),1)) -> 1 | D13: =IF($B13="","",Sælgere!$C$13&"") -> Jylland | E13: =IF($B13="","",IF(N(Sælgere!$D$13)<1,1,Sælgere!$D$13)) -> 1 | F13: =IF($B13="","",IF(N(Sælgere!$F$13)<1,12,Sælgere!$F$13)) -> 12 | G13: =IF($B13="",0,IF(Sælgere!$G$13="",1,N(Sælgere!$G$13))) -> 0.5 | H13: =IF($B13="","",N(Sælgere!$E$13)) -> 0 | I13: =IF(AND($B13<>"",ISNA(MATCH(Sælgere!$C$13,Territorier!$B$6:$B$15,0))),1,0) -> 0 | J13: =IF(AND($B13<>"",N(Sælgere!$H$13)>0),1,0) -> 0 | K13: =IF($B13="",0,IF(OR(1<$E13,1>$F13),0,INDEX(Indstillinger!$D$27:$D$38,1)*$G13*$C13*IF($H13=0,1,IF($H13+1-$E13>6,1,INDEX(Indstillinger!$C$18:$C$23,$H13+1-$E13))))) -> 0.035 | L13: =IF($B13="",0,IF(OR(2<$E13,2>$F13),0,INDEX(Indstillinger!$D$27:$D$38,2)*$G13*$C13*IF($H13=0,1,IF($H13+2-$E13>6,1,INDEX(Indstillinger!$C$18:$C$23,$H13+2-$E13))))) -> 0.04 | M13: =IF($B13="",0,IF(OR(3<$E13,3>$F13),0,INDEX(Indstillinger!$D$27:$D$38,3)*$G13*$C13*IF($H13=0,1,IF($H13+3-$E13>6,1,INDEX(Indstillinger!$C$18:$C$23,$H13+3-$E13))))) -> 0.045 | N13: =IF($B13="",0,IF(OR(4<$E13,4>$F13),0,INDEX(Indstillinger!$D$27:$D$38,4)*$G13*$C13*IF($H13=0,1,IF($H13+4-$E13>6,1,INDEX(Indstillinger!$C$18:$C$23,$H13+4-$E13))))) -> 0.04 | O13: =IF($B13="",0,IF(OR(5<$E13,5>$F13),0,INDEX(Indstillinger!$D$27:$D$38,5)*$G13*$C13*IF($H13=0,1,IF($H13+5-$E13>6,1,INDEX(Indstillinger!$C$18:$C$23,$H13+5-$E13))))) -> 0.045 | P13: =IF($B13="",0,IF(OR(6<$E13,6>$F13),0,INDEX(Indstillinger!$D$27:$D$38,6)*$G13*$C13*IF($H13=0,1,IF($H13+6-$E13>6,1,INDEX(Indstillinger!$C$18:$C$23,$H13+6-$E13))))) -> 0.045 | Q13: =IF($B13="",0,IF(OR(7<$E13,7>$F13),0,INDEX(Indstillinger!$D$27:$D$38,7)*$G13*$C13*IF($H13=0,1,IF($H13+7-$E13>6,1,INDEX(Indstillinger!$C$18:$C$23,$H13+7-$E13))))) -> 0.02 | R13: =IF($B13="",0,IF(OR(8<$E13,8>$F13),0,INDEX(Indstillinger!$D$27:$D$38,8)*$G13*$C13*IF($H13=0,1,IF($H13+8-$E13>6,1,INDEX(Indstillinger!$C$18:$C$23,$H13+8-$E13))))) -> 0.035 | S13: =IF($B13="",0,IF(OR(9<$E13,9>$F13),0,INDEX(Indstillinger!$D$27:$D$38,9)*$G13*$C13*IF($H13=0,1,IF($H13+9-$E13>6,1,INDEX(Indstillinger!$C$18:$C$23,$H13+9-$E13))))) -> 0.045 | T13: =IF($B13="",0,IF(OR(10<$E13,10>$F13),0,INDEX(Indstillinger!$D$27:$D$38,10)*$G13*$C13*IF($H13=0,1,IF($H13+10-$E13>6,1,INDEX(Indstillinger!$C$18:$C$23,$H13+10-$E13))))) -> 0.045 | U13: =IF($B13="",0,IF(OR(11<$E13,11>$F13),0,INDEX(Indstillinger!$D$27:$D$38,11)*$G13*$C13*IF($H13=0,1,IF($H13+11-$E13>6,1,INDEX(Indstillinger!$C$18:$C$23,$H13+11-$E13))))) -> 0.05 | V13: =IF($B13="",0,IF(OR(12<$E13,12>$F13),0,INDEX(Indstillinger!$D$27:$D$38,12)*$G13*$C13*IF($H13=0,1,IF($H13+12-$E13>6,1,INDEX(Indstillinger!$C$18:$C$23,$H13+12-$E13))))) -> 0.055 | W13: =SUM(K13:V13) -> 0.5 | X13: =IF($J13=1,N(Sælgere!$H$13),0) -> 0 | Y13: =IF($J13=1,0,W13) -> 0.5 | Z13: =IF(OR($B13="",$J13=1),0,SUMPRODUCT(--(K13:V13>0),$K$4:$V$4)*$G13) -> 0.5
B14: =IF(Sælgere!$B$14="","",Sælgere!$B$14) -> Ny sælger 1 | C14: =IF($B14="","",IFERROR(IF(INDEX(Territorier!$C$6:$C$15,MATCH(Sælgere!$C$14,Territorier!$B$6:$B$15,0))="",1,INDEX(Territorier!$C$6:$C$15,MATCH(Sælgere!$C$14,Territorier!$B$6:$B$15,0))/100),1)) -> 1 | D14: =IF($B14="","",Sælgere!$C$14&"") -> Jylland | E14: =IF($B14="","",IF(N(Sælgere!$D$14)<1,1,Sælgere!$D$14)) -> 3 | F14: =IF($B14="","",IF(N(Sælgere!$F$14)<1,12,Sælgere!$F$14)) -> 12 | G14: =IF($B14="",0,IF(Sælgere!$G$14="",1,N(Sælgere!$G$14))) -> 1 | H14: =IF($B14="","",N(Sælgere!$E$14)) -> 1 | I14: =IF(AND($B14<>"",ISNA(MATCH(Sælgere!$C$14,Territorier!$B$6:$B$15,0))),1,0) -> 0 | J14: =IF(AND($B14<>"",N(Sælgere!$H$14)>0),1,0) -> 0 | K14: =IF($B14="",0,IF(OR(1<$E14,1>$F14),0,INDEX(Indstillinger!$D$27:$D$38,1)*$G14*$C14*IF($H14=0,1,IF($H14+1-$E14>6,1,INDEX(Indstillinger!$C$18:$C$23,$H14+1-$E14))))) -> 0 | L14: =IF($B14="",0,IF(OR(2<$E14,2>$F14),0,INDEX(Indstillinger!$D$27:$D$38,2)*$G14*$C14*IF($H14=0,1,IF($H14+2-$E14>6,1,INDEX(Indstillinger!$C$18:$C$23,$H14+2-$E14))))) -> 0 | M14: =IF($B14="",0,IF(OR(3<$E14,3>$F14),0,INDEX(Indstillinger!$D$27:$D$38,3)*$G14*$C14*IF($H14=0,1,IF($H14+3-$E14>6,1,INDEX(Indstillinger!$C$18:$C$23,$H14+3-$E14))))) -> 0.0225 | N14: =IF($B14="",0,IF(OR(4<$E14,4>$F14),0,INDEX(Indstillinger!$D$27:$D$38,4)*$G14*$C14*IF($H14=0,1,IF($H14+4-$E14>6,1,INDEX(Indstillinger!$C$18:$C$23,$H14+4-$E14))))) -> 0.04 | O14: =IF($B14="",0,IF(OR(5<$E14,5>$F14),0,INDEX(Indstillinger!$D$27:$D$38,5)*$G14*$C14*IF($H14=0,1,IF($H14+5-$E14>6,1,INDEX(Indstillinger!$C$18:$C$23,$H14+5-$E14))))) -> 0.0675 | P14: =IF($B14="",0,IF(OR(6<$E14,6>$F14),0,INDEX(Indstillinger!$D$27:$D$38,6)*$G14*$C14*IF($H14=0,1,IF($H14+6-$E14>6,1,INDEX(Indstillinger!$C$18:$C$23,$H14+6-$E14))))) -> 0.09 | Q14: =IF($B14="",0,IF(OR(7<$E14,7>$F14),0,INDEX(Indstillinger!$D$27:$D$38,7)*$G14*$C14*IF($H14=0,1,IF($H14+7-$E14>6,1,INDEX(Indstillinger!$C$18:$C$23,$H14+7-$E14))))) -> 0.04 | R14: =IF($B14="",0,IF(OR(8<$E14,8>$F14),0,INDEX(Indstillinger!$D$27:$D$38,8)*$G14*$C14*IF($H14=0,1,IF($H14+8-$E14>6,1,INDEX(Indstillinger!$C$18:$C$23,$H14+8-$E14))))) -> 0.07 | S14: =IF($B14="",0,IF(OR(9<$E14,9>$F14),0,INDEX(Indstillinger!$D$27:$D$38,9)*$G14*$C14*IF($H14=0,1,IF($H14+9-$E14>6,1,INDEX(Indstillinger!$C$18:$C$23,$H14+9-$E14))))) -> 0.09 | T14: =IF($B14="",0,IF(OR(10<$E14,10>$F14),0,INDEX(Indstillinger!$D$27:$D$38,10)*$G14*$C14*IF($H14=0,1,IF($H14+10-$E14>6,1,INDEX(Indstillinger!$C$18:$C$23,$H14+10-$E14))))) -> 0.09 | U14: =IF($B14="",0,IF(OR(11<$E14,11>$F14),0,INDEX(Indstillinger!$D$27:$D$38,11)*$G14*$C14*IF($H14=0,1,IF($H14+11-$E14>6,1,INDEX(Indstillinger!$C$18:$C$23,$H14+11-$E14))))) -> 0.1 | V14: =IF($B14="",0,IF(OR(12<$E14,12>$F14),0,INDEX(Indstillinger!$D$27:$D$38,12)*$G14*$C14*IF($H14=0,1,IF($H14+12-$E14>6,1,INDEX(Indstillinger!$C$18:$C$23,$H14+12-$E14))))) -> 0.11 | W14: =SUM(K14:V14) -> 0.72 | X14: =IF($J14=1,N(Sælgere!$H$14),0) -> 0 | Y14: =IF($J14=1,0,W14) -> 0.72 | Z14: =IF(OR($B14="",$J14=1),0,SUMPRODUCT(--(K14:V14>0),$K$4:$V$4)*$G14) -> 0.85
B15: =IF(Sælgere!$B$15="","",Sælgere!$B$15) -> Ny sælger 2 | C15: =IF($B15="","",IFERROR(IF(INDEX(Territorier!$C$6:$C$15,MATCH(Sælgere!$C$15,Territorier!$B$6:$B$15,0))="",1,INDEX(Territorier!$C$6:$C$15,MATCH(Sælgere!$C$15,Territorier!$B$6:$B$15,0))/100),1)) -> 1.2 | D15: =IF($B15="","",Sælgere!$C$15&"") -> Hovedstaden | E15: =IF($B15="","",IF(N(Sælgere!$D$15)<1,1,Sælgere!$D$15)) -> 8 | F15: =IF($B15="","",IF(N(Sælgere!$F$15)<1,12,Sælgere!$F$15)) -> 12 | G15: =IF($B15="",0,IF(Sælgere!$G$15="",1,N(Sælgere!$G$15))) -> 1 | H15: =IF($B15="","",N(Sælgere!$E$15)) -> 1 | I15: =IF(AND($B15<>"",ISNA(MATCH(Sælgere!$C$15,Territorier!$B$6:$B$15,0))),1,0) -> 0 | J15: =IF(AND($B15<>"",N(Sælgere!$H$15)>0),1,0) -> 0 | K15: =IF($B15="",0,IF(OR(1<$E15,1>$F15),0,INDEX(Indstillinger!$D$27:$D$38,1)*$G15*$C15*IF($H15=0,1,IF($H15+1-$E15>6,1,INDEX(Indstillinger!$C$18:$C$23,$H15+1-$E15))))) -> 0 | L15: =IF($B15="",0,IF(OR(2<$E15,2>$F15),0,INDEX(Indstillinger!$D$27:$D$38,2)*$G15*$C15*IF($H15=0,1,IF($H15+2-$E15>6,1,INDEX(Indstillinger!$C$18:$C$23,$H15+2-$E15))))) -> 0 | M15: =IF($B15="",0,IF(OR(3<$E15,3>$F15),0,INDEX(Indstillinger!$D$27:$D$38,3)*$G15*$C15*IF($H15=0,1,IF($H15+3-$E15>6,1,INDEX(Indstillinger!$C$18:$C$23,$H15+3-$E15))))) -> 0 | N15: =IF($B15="",0,IF(OR(4<$E15,4>$F15),0,INDEX(Indstillinger!$D$27:$D$38,4)*$G15*$C15*IF($H15=0,1,IF($H15+4-$E15>6,1,INDEX(Indstillinger!$C$18:$C$23,$H15+4-$E15))))) -> 0 | O15: =IF($B15="",0,IF(OR(5<$E15,5>$F15),0,INDEX(Indstillinger!$D$27:$D$38,5)*$G15*$C15*IF($H15=0,1,IF($H15+5-$E15>6,1,INDEX(Indstillinger!$C$18:$C$23,$H15+5-$E15))))) -> 0 | P15: =IF($B15="",0,IF(OR(6<$E15,6>$F15),0,INDEX(Indstillinger!$D$27:$D$38,6)*$G15*$C15*IF($H15=0,1,IF($H15+6-$E15>6,1,INDEX(Indstillinger!$C$18:$C$23,$H15+6-$E15))))) -> 0 | Q15: =IF($B15="",0,IF(OR(7<$E15,7>$F15),0,INDEX(Indstillinger!$D$27:$D$38,7)*$G15*$C15*IF($H15=0,1,IF($H15+7-$E15>6,1,INDEX(Indstillinger!$C$18:$C$23,$H15+7-$E15))))) -> 0 | R15: =IF($B15="",0,IF(OR(8<$E15,8>$F15),0,INDEX(Indstillinger!$D$27:$D$38,8)*$G15*$C15*IF($H15=0,1,IF($H15+8-$E15>6,1,INDEX(Indstillinger!$C$18:$C$23,$H15+8-$E15))))) -> 0.021 | S15: =IF($B15="",0,IF(OR(9<$E15,9>$F15),0,INDEX(Indstillinger!$D$27:$D$38,9)*$G15*$C15*IF($H15=0,1,IF($H15+9-$E15>6,1,INDEX(Indstillinger!$C$18:$C$23,$H15+9-$E15))))) -> 0.054 | T15: =IF($B15="",0,IF(OR(10<$E15,10>$F15),0,INDEX(Indstillinger!$D$27:$D$38,10)*$G15*$C15*IF($H15=0,1,IF($H15+10-$E15>6,1,INDEX(Indstillinger!$C$18:$C$23,$H15+10-$E15))))) -> 0.081 | U15: =IF($B15="",0,IF(OR(11<$E15,11>$F15),0,INDEX(Indstillinger!$D$27:$D$38,11)*$G15*$C15*IF($H15=0,1,IF($H15+11-$E15>6,1,INDEX(Indstillinger!$C$18:$C$23,$H15+11-$E15))))) -> 0.12 | V15: =IF($B15="",0,IF(OR(12<$E15,12>$F15),0,INDEX(Indstillinger!$D$27:$D$38,12)*$G15*$C15*IF($H15=0,1,IF($H15+12-$E15>6,1,INDEX(Indstillinger!$C$18:$C$23,$H15+12-$E15))))) -> 0.132 | W15: =SUM(K15:V15) -> 0.408 | X15: =IF($J15=1,N(Sælgere!$H$15),0) -> 0 | Y15: =IF($J15=1,0,W15) -> 0.408 | Z15: =IF(OR($B15="",$J15=1),0,SUMPRODUCT(--(K15:V15>0),$K$4:$V$4)*$G15) -> 0.46
B16: =IF(Sælgere!$B$16="","",Sælgere!$B$16) | C16: =IF($B16="","",IFERROR(IF(INDEX(Territorier!$C$6:$C$15,MATCH(Sælgere!$C$16,Territorier!$B$6:$B$15,0))="",1,INDEX(Territorier!$C$6:$C$15,MATCH(Sælgere!$C$16,Territorier!$B$6:$B$15,0))/100),1)) | D16: =IF($B16="","",Sælgere!$C$16&"") | E16: =IF($B16="","",IF(N(Sælgere!$D$16)<1,1,Sælgere!$D$16)) | F16: =IF($B16="","",IF(N(Sælgere!$F$16)<1,12,Sælgere!$F$16)) | G16: =IF($B16="",0,IF(Sælgere!$G$16="",1,N(Sælgere!$G$16))) -> 0 | H16: =IF($B16="","",N(Sælgere!$E$16)) | I16: =IF(AND($B16<>"",ISNA(MATCH(Sælgere!$C$16,Territorier!$B$6:$B$15,0))),1,0) -> 0 | J16: =IF(AND($B16<>"",N(Sælgere!$H$16)>0),1,0) -> 0 | K16: =IF($B16="",0,IF(OR(1<$E16,1>$F16),0,INDEX(Indstillinger!$D$27:$D$38,1)*$G16*$C16*IF($H16=0,1,IF($H16+1-$E16>6,1,INDEX(Indstillinger!$C$18:$C$23,$H16+1-$E16))))) -> 0 | L16: =IF($B16="",0,IF(OR(2<$E16,2>$F16),0,INDEX(Indstillinger!$D$27:$D$38,2)*$G16*$C16*IF($H16=0,1,IF($H16+2-$E16>6,1,INDEX(Indstillinger!$C$18:$C$23,$H16+2-$E16))))) -> 0 | M16: =IF($B16="",0,IF(OR(3<$E16,3>$F16),0,INDEX(Indstillinger!$D$27:$D$38,3)*$G16*$C16*IF($H16=0,1,IF($H16+3-$E16>6,1,INDEX(Indstillinger!$C$18:$C$23,$H16+3-$E16))))) -> 0 | N16: =IF($B16="",0,IF(OR(4<$E16,4>$F16),0,INDEX(Indstillinger!$D$27:$D$38,4)*$G16*$C16*IF($H16=0,1,IF($H16+4-$E16>6,1,INDEX(Indstillinger!$C$18:$C$23,$H16+4-$E16))))) -> 0 | O16: =IF($B16="",0,IF(OR(5<$E16,5>$F16),0,INDEX(Indstillinger!$D$27:$D$38,5)*$G16*$C16*IF($H16=0,1,IF($H16+5-$E16>6,1,INDEX(Indstillinger!$C$18:$C$23,$H16+5-$E16))))) -> 0 | P16: =IF($B16="",0,IF(OR(6<$E16,6>$F16),0,INDEX(Indstillinger!$D$27:$D$38,6)*$G16*$C16*IF($H16=0,1,IF($H16+6-$E16>6,1,INDEX(Indstillinger!$C$18:$C$23,$H16+6-$E16))))) -> 0 | Q16: =IF($B16="",0,IF(OR(7<$E16,7>$F16),0,INDEX(Indstillinger!$D$27:$D$38,7)*$G16*$C16*IF($H16=0,1,IF($H16+7-$E16>6,1,INDEX(Indstillinger!$C$18:$C$23,$H16+7-$E16))))) -> 0 | R16: =IF($B16="",0,IF(OR(8<$E16,8>$F16),0,INDEX(Indstillinger!$D$27:$D$38,8)*$G16*$C16*IF($H16=0,1,IF($H16+8-$E16>6,1,INDEX(Indstillinger!$C$18:$C$23,$H16+8-$E16))))) -> 0 | S16: =IF($B16="",0,IF(OR(9<$E16,9>$F16),0,INDEX(Indstillinger!$D$27:$D$38,9)*$G16*$C16*IF($H16=0,1,IF($H16+9-$E16>6,1,INDEX(Indstillinger!$C$18:$C$23,$H16+9-$E16))))) -> 0 | T16: =IF($B16="",0,IF(OR(10<$E16,10>$F16),0,INDEX(Indstillinger!$D$27:$D$38,10)*$G16*$C16*IF($H16=0,1,IF($H16+10-$E16>6,1,INDEX(Indstillinger!$C$18:$C$23,$H16+10-$E16))))) -> 0 | U16: =IF($B16="",0,IF(OR(11<$E16,11>$F16),0,INDEX(Indstillinger!$D$27:$D$38,11)*$G16*$C16*IF($H16=0,1,IF($H16+11-$E16>6,1,INDEX(Indstillinger!$C$18:$C$23,$H16+11-$E16))))) -> 0 | V16: =IF($B16="",0,IF(OR(12<$E16,12>$F16),0,INDEX(Indstillinger!$D$27:$D$38,12)*$G16*$C16*IF($H16=0,1,IF($H16+12-$E16>6,1,INDEX(Indstillinger!$C$18:$C$23,$H16+12-$E16))))) -> 0 | W16: =SUM(K16:V16) -> 0 | X16: =IF($J16=1,N(Sælgere!$H$16),0) -> 0 | Y16: =IF($J16=1,0,W16) -> 0 | Z16: =IF(OR($B16="",$J16=1),0,SUMPRODUCT(--(K16:V16>0),$K$4:$V$4)*$G16) -> 0
B17: =IF(Sælgere!$B$17="","",Sælgere!$B$17) | C17: =IF($B17="","",IFERROR(IF(INDEX(Territorier!$C$6:$C$15,MATCH(Sælgere!$C$17,Territorier!$B$6:$B$15,0))="",1,INDEX(Territorier!$C$6:$C$15,MATCH(Sælgere!$C$17,Territorier!$B$6:$B$15,0))/100),1)) | D17: =IF($B17="","",Sælgere!$C$17&"") | E17: =IF($B17="","",IF(N(Sælgere!$D$17)<1,1,Sælgere!$D$17)) | F17: =IF($B17="","",IF(N(Sælgere!$F$17)<1,12,Sælgere!$F$17)) | G17: =IF($B17="",0,IF(Sælgere!$G$17="",1,N(Sælgere!$G$17))) -> 0 | H17: =IF($B17="","",N(Sælgere!$E$17)) | I17: =IF(AND($B17<>"",ISNA(MATCH(Sælgere!$C$17,Territorier!$B$6:$B$15,0))),1,0) -> 0 | J17: =IF(AND($B17<>"",N(Sælgere!$H$17)>0),1,0) -> 0 | K17: =IF($B17="",0,IF(OR(1<$E17,1>$F17),0,INDEX(Indstillinger!$D$27:$D$38,1)*$G17*$C17*IF($H17=0,1,IF($H17+1-$E17>6,1,INDEX(Indstillinger!$C$18:$C$23,$H17+1-$E17))))) -> 0 | L17: =IF($B17="",0,IF(OR(2<$E17,2>$F17),0,INDEX(Indstillinger!$D$27:$D$38,2)*$G17*$C17*IF($H17=0,1,IF($H17+2-$E17>6,1,INDEX(Indstillinger!$C$18:$C$23,$H17+2-$E17))))) -> 0 | M17: =IF($B17="",0,IF(OR(3<$E17,3>$F17),0,INDEX(Indstillinger!$D$27:$D$38,3)*$G17*$C17*IF($H17=0,1,IF($H17+3-$E17>6,1,INDEX(Indstillinger!$C$18:$C$23,$H17+3-$E17))))) -> 0 | N17: =IF($B17="",0,IF(OR(4<$E17,4>$F17),0,INDEX(Indstillinger!$D$27:$D$38,4)*$G17*$C17*IF($H17=0,1,IF($H17+4-$E17>6,1,INDEX(Indstillinger!$C$18:$C$23,$H17+4-$E17))))) -> 0 | O17: =IF($B17="",0,IF(OR(5<$E17,5>$F17),0,INDEX(Indstillinger!$D$27:$D$38,5)*$G17*$C17*IF($H17=0,1,IF($H17+5-$E17>6,1,INDEX(Indstillinger!$C$18:$C$23,$H17+5-$E17))))) -> 0 | P17: =IF($B17="",0,IF(OR(6<$E17,6>$F17),0,INDEX(Indstillinger!$D$27:$D$38,6)*$G17*$C17*IF($H17=0,1,IF($H17+6-$E17>6,1,INDEX(Indstillinger!$C$18:$C$23,$H17+6-$E17))))) -> 0 | Q17: =IF($B17="",0,IF(OR(7<$E17,7>$F17),0,INDEX(Indstillinger!$D$27:$D$38,7)*$G17*$C17*IF($H17=0,1,IF($H17+7-$E17>6,1,INDEX(Indstillinger!$C$18:$C$23,$H17+7-$E17))))) -> 0 | R17: =IF($B17="",0,IF(OR(8<$E17,8>$F17),0,INDEX(Indstillinger!$D$27:$D$38,8)*$G17*$C17*IF($H17=0,1,IF($H17+8-$E17>6,1,INDEX(Indstillinger!$C$18:$C$23,$H17+8-$E17))))) -> 0 | S17: =IF($B17="",0,IF(OR(9<$E17,9>$F17),0,INDEX(Indstillinger!$D$27:$D$38,9)*$G17*$C17*IF($H17=0,1,IF($H17+9-$E17>6,1,INDEX(Indstillinger!$C$18:$C$23,$H17+9-$E17))))) -> 0 | T17: =IF($B17="",0,IF(OR(10<$E17,10>$F17),0,INDEX(Indstillinger!$D$27:$D$38,10)*$G17*$C17*IF($H17=0,1,IF($H17+10-$E17>6,1,INDEX(Indstillinger!$C$18:$C$23,$H17+10-$E17))))) -> 0 | U17: =IF($B17="",0,IF(OR(11<$E17,11>$F17),0,INDEX(Indstillinger!$D$27:$D$38,11)*$G17*$C17*IF($H17=0,1,IF($H17+11-$E17>6,1,INDEX(Indstillinger!$C$18:$C$23,$H17+11-$E17))))) -> 0 | V17: =IF($B17="",0,IF(OR(12<$E17,12>$F17),0,INDEX(Indstillinger!$D$27:$D$38,12)*$G17*$C17*IF($H17=0,1,IF($H17+12-$E17>6,1,INDEX(Indstillinger!$C$18:$C$23,$H17+12-$E17))))) -> 0 | W17: =SUM(K17:V17) -> 0 | X17: =IF($J17=1,N(Sælgere!$H$17),0) -> 0 | Y17: =IF($J17=1,0,W17) -> 0 | Z17: =IF(OR($B17="",$J17=1),0,SUMPRODUCT(--(K17:V17>0),$K$4:$V$4)*$G17) -> 0
B18: =IF(Sælgere!$B$18="","",Sælgere!$B$18) | C18: =IF($B18="","",IFERROR(IF(INDEX(Territorier!$C$6:$C$15,MATCH(Sælgere!$C$18,Territorier!$B$6:$B$15,0))="",1,INDEX(Territorier!$C$6:$C$15,MATCH(Sælgere!$C$18,Territorier!$B$6:$B$15,0))/100),1)) | D18: =IF($B18="","",Sælgere!$C$18&"") | E18: =IF($B18="","",IF(N(Sælgere!$D$18)<1,1,Sælgere!$D$18)) | F18: =IF($B18="","",IF(N(Sælgere!$F$18)<1,12,Sælgere!$F$18)) | G18: =IF($B18="",0,IF(Sælgere!$G$18="",1,N(Sælgere!$G$18))) -> 0 | H18: =IF($B18="","",N(Sælgere!$E$18)) | I18: =IF(AND($B18<>"",ISNA(MATCH(Sælgere!$C$18,Territorier!$B$6:$B$15,0))),1,0) -> 0 | J18: =IF(AND($B18<>"",N(Sælgere!$H$18)>0),1,0) -> 0 | K18: =IF($B18="",0,IF(OR(1<$E18,1>$F18),0,INDEX(Indstillinger!$D$27:$D$38,1)*$G18*$C18*IF($H18=0,1,IF($H18+1-$E18>6,1,INDEX(Indstillinger!$C$18:$C$23,$H18+1-$E18))))) -> 0 | L18: =IF($B18="",0,IF(OR(2<$E18,2>$F18),0,INDEX(Indstillinger!$D$27:$D$38,2)*$G18*$C18*IF($H18=0,1,IF($H18+2-$E18>6,1,INDEX(Indstillinger!$C$18:$C$23,$H18+2-$E18))))) -> 0 | M18: =IF($B18="",0,IF(OR(3<$E18,3>$F18),0,INDEX(Indstillinger!$D$27:$D$38,3)*$G18*$C18*IF($H18=0,1,IF($H18+3-$E18>6,1,INDEX(Indstillinger!$C$18:$C$23,$H18+3-$E18))))) -> 0 | N18: =IF($B18="",0,IF(OR(4<$E18,4>$F18),0,INDEX(Indstillinger!$D$27:$D$38,4)*$G18*$C18*IF($H18=0,1,IF($H18+4-$E18>6,1,INDEX(Indstillinger!$C$18:$C$23,$H18+4-$E18))))) -> 0 | O18: =IF($B18="",0,IF(OR(5<$E18,5>$F18),0,INDEX(Indstillinger!$D$27:$D$38,5)*$G18*$C18*IF($H18=0,1,IF($H18+5-$E18>6,1,INDEX(Indstillinger!$C$18:$C$23,$H18+5-$E18))))) -> 0 | P18: =IF($B18="",0,IF(OR(6<$E18,6>$F18),0,INDEX(Indstillinger!$D$27:$D$38,6)*$G18*$C18*IF($H18=0,1,IF($H18+6-$E18>6,1,INDEX(Indstillinger!$C$18:$C$23,$H18+6-$E18))))) -> 0 | Q18: =IF($B18="",0,IF(OR(7<$E18,7>$F18),0,INDEX(Indstillinger!$D$27:$D$38,7)*$G18*$C18*IF($H18=0,1,IF($H18+7-$E18>6,1,INDEX(Indstillinger!$C$18:$C$23,$H18+7-$E18))))) -> 0 | R18: =IF($B18="",0,IF(OR(8<$E18,8>$F18),0,INDEX(Indstillinger!$D$27:$D$38,8)*$G18*$C18*IF($H18=0,1,IF($H18+8-$E18>6,1,INDEX(Indstillinger!$C$18:$C$23,$H18+8-$E18))))) -> 0 | S18: =IF($B18="",0,IF(OR(9<$E18,9>$F18),0,INDEX(Indstillinger!$D$27:$D$38,9)*$G18*$C18*IF($H18=0,1,IF($H18+9-$E18>6,1,INDEX(Indstillinger!$C$18:$C$23,$H18+9-$E18))))) -> 0 | T18: =IF($B18="",0,IF(OR(10<$E18,10>$F18),0,INDEX(Indstillinger!$D$27:$D$38,10)*$G18*$C18*IF($H18=0,1,IF($H18+10-$E18>6,1,INDEX(Indstillinger!$C$18:$C$23,$H18+10-$E18))))) -> 0 | U18: =IF($B18="",0,IF(OR(11<$E18,11>$F18),0,INDEX(Indstillinger!$D$27:$D$38,11)*$G18*$C18*IF($H18=0,1,IF($H18+11-$E18>6,1,INDEX(Indstillinger!$C$18:$C$23,$H18+11-$E18))))) -> 0 | V18: =IF($B18="",0,IF(OR(12<$E18,12>$F18),0,INDEX(Indstillinger!$D$27:$D$38,12)*$G18*$C18*IF($H18=0,1,IF($H18+12-$E18>6,1,INDEX(Indstillinger!$C$18:$C$23,$H18+12-$E18))))) -> 0 | W18: =SUM(K18:V18) -> 0 | X18: =IF($J18=1,N(Sælgere!$H$18),0) -> 0 | Y18: =IF($J18=1,0,W18) -> 0 | Z18: =IF(OR($B18="",$J18=1),0,SUMPRODUCT(--(K18:V18>0),$K$4:$V$4)*$G18) -> 0
B19: =IF(Sælgere!$B$19="","",Sælgere!$B$19) | C19: =IF($B19="","",IFERROR(IF(INDEX(Territorier!$C$6:$C$15,MATCH(Sælgere!$C$19,Territorier!$B$6:$B$15,0))="",1,INDEX(Territorier!$C$6:$C$15,MATCH(Sælgere!$C$19,Territorier!$B$6:$B$15,0))/100),1)) | D19: =IF($B19="","",Sælgere!$C$19&"") | E19: =IF($B19="","",IF(N(Sælgere!$D$19)<1,1,Sælgere!$D$19)) | F19: =IF($B19="","",IF(N(Sælgere!$F$19)<1,12,Sælgere!$F$19)) | G19: =IF($B19="",0,IF(Sælgere!$G$19="",1,N(Sælgere!$G$19))) -> 0 | H19: =IF($B19="","",N(Sælgere!$E$19)) | I19: =IF(AND($B19<>"",ISNA(MATCH(Sælgere!$C$19,Territorier!$B$6:$B$15,0))),1,0) -> 0 | J19: =IF(AND($B19<>"",N(Sælgere!$H$19)>0),1,0) -> 0 | K19: =IF($B19="",0,IF(OR(1<$E19,1>$F19),0,INDEX(Indstillinger!$D$27:$D$38,1)*$G19*$C19*IF($H19=0,1,IF($H19+1-$E19>6,1,INDEX(Indstillinger!$C$18:$C$23,$H19+1-$E19))))) -> 0 | L19: =IF($B19="",0,IF(OR(2<$E19,2>$F19),0,INDEX(Indstillinger!$D$27:$D$38,2)*$G19*$C19*IF($H19=0,1,IF($H19+2-$E19>6,1,INDEX(Indstillinger!$C$18:$C$23,$H19+2-$E19))))) -> 0 | M19: =IF($B19="",0,IF(OR(3<$E19,3>$F19),0,INDEX(Indstillinger!$D$27:$D$38,3)*$G19*$C19*IF($H19=0,1,IF($H19+3-$E19>6,1,INDEX(Indstillinger!$C$18:$C$23,$H19+3-$E19))))) -> 0 | N19: =IF($B19="",0,IF(OR(4<$E19,4>$F19),0,INDEX(Indstillinger!$D$27:$D$38,4)*$G19*$C19*IF($H19=0,1,IF($H19+4-$E19>6,1,INDEX(Indstillinger!$C$18:$C$23,$H19+4-$E19))))) -> 0 | O19: =IF($B19="",0,IF(OR(5<$E19,5>$F19),0,INDEX(Indstillinger!$D$27:$D$38,5)*$G19*$C19*IF($H19=0,1,IF($H19+5-$E19>6,1,INDEX(Indstillinger!$C$18:$C$23,$H19+5-$E19))))) -> 0 | P19: =IF($B19="",0,IF(OR(6<$E19,6>$F19),0,INDEX(Indstillinger!$D$27:$D$38,6)*$G19*$C19*IF($H19=0,1,IF($H19+6-$E19>6,1,INDEX(Indstillinger!$C$18:$C$23,$H19+6-$E19))))) -> 0 | Q19: =IF($B19="",0,IF(OR(7<$E19,7>$F19),0,INDEX(Indstillinger!$D$27:$D$38,7)*$G19*$C19*IF($H19=0,1,IF($H19+7-$E19>6,1,INDEX(Indstillinger!$C$18:$C$23,$H19+7-$E19))))) -> 0 | R19: =IF($B19="",0,IF(OR(8<$E19,8>$F19),0,INDEX(Indstillinger!$D$27:$D$38,8)*$G19*$C19*IF($H19=0,1,IF($H19+8-$E19>6,1,INDEX(Indstillinger!$C$18:$C$23,$H19+8-$E19))))) -> 0 | S19: =IF($B19="",0,IF(OR(9<$E19,9>$F19),0,INDEX(Indstillinger!$D$27:$D$38,9)*$G19*$C19*IF($H19=0,1,IF($H19+9-$E19>6,1,INDEX(Indstillinger!$C$18:$C$23,$H19+9-$E19))))) -> 0 | T19: =IF($B19="",0,IF(OR(10<$E19,10>$F19),0,INDEX(Indstillinger!$D$27:$D$38,10)*$G19*$C19*IF($H19=0,1,IF($H19+10-$E19>6,1,INDEX(Indstillinger!$C$18:$C$23,$H19+10-$E19))))) -> 0 | U19: =IF($B19="",0,IF(OR(11<$E19,11>$F19),0,INDEX(Indstillinger!$D$27:$D$38,11)*$G19*$C19*IF($H19=0,1,IF($H19+11-$E19>6,1,INDEX(Indstillinger!$C$18:$C$23,$H19+11-$E19))))) -> 0 | V19: =IF($B19="",0,IF(OR(12<$E19,12>$F19),0,INDEX(Indstillinger!$D$27:$D$38,12)*$G19*$C19*IF($H19=0,1,IF($H19+12-$E19>6,1,INDEX(Indstillinger!$C$18:$C$23,$H19+12-$E19))))) -> 0 | W19: =SUM(K19:V19) -> 0 | X19: =IF($J19=1,N(Sælgere!$H$19),0) -> 0 | Y19: =IF($J19=1,0,W19) -> 0 | Z19: =IF(OR($B19="",$J19=1),0,SUMPRODUCT(--(K19:V19>0),$K$4:$V$4)*$G19) -> 0
B20: =IF(Sælgere!$B$20="","",Sælgere!$B$20) | C20: =IF($B20="","",IFERROR(IF(INDEX(Territorier!$C$6:$C$15,MATCH(Sælgere!$C$20,Territorier!$B$6:$B$15,0))="",1,INDEX(Territorier!$C$6:$C$15,MATCH(Sælgere!$C$20,Territorier!$B$6:$B$15,0))/100),1)) | D20: =IF($B20="","",Sælgere!$C$20&"") | E20: =IF($B20="","",IF(N(Sælgere!$D$20)<1,1,Sælgere!$D$20)) | F20: =IF($B20="","",IF(N(Sælgere!$F$20)<1,12,Sælgere!$F$20)) | G20: =IF($B20="",0,IF(Sælgere!$G$20="",1,N(Sælgere!$G$20))) -> 0 | H20: =IF($B20="","",N(Sælgere!$E$20)) | I20: =IF(AND($B20<>"",ISNA(MATCH(Sælgere!$C$20,Territorier!$B$6:$B$15,0))),1,0) -> 0 | J20: =IF(AND($B20<>"",N(Sælgere!$H$20)>0),1,0) -> 0 | K20: =IF($B20="",0,IF(OR(1<$E20,1>$F20),0,INDEX(Indstillinger!$D$27:$D$38,1)*$G20*$C20*IF($H20=0,1,IF($H20+1-$E20>6,1,INDEX(Indstillinger!$C$18:$C$23,$H20+1-$E20))))) -> 0 | L20: =IF($B20="",0,IF(OR(2<$E20,2>$F20),0,INDEX(Indstillinger!$D$27:$D$38,2)*$G20*$C20*IF($H20=0,1,IF($H20+2-$E20>6,1,INDEX(Indstillinger!$C$18:$C$23,$H20+2-$E20))))) -> 0 | M20: =IF($B20="",0,IF(OR(3<$E20,3>$F20),0,INDEX(Indstillinger!$D$27:$D$38,3)*$G20*$C20*IF($H20=0,1,IF($H20+3-$E20>6,1,INDEX(Indstillinger!$C$18:$C$23,$H20+3-$E20))))) -> 0 | N20: =IF($B20="",0,IF(OR(4<$E20,4>$F20),0,INDEX(Indstillinger!$D$27:$D$38,4)*$G20*$C20*IF($H20=0,1,IF($H20+4-$E20>6,1,INDEX(Indstillinger!$C$18:$C$23,$H20+4-$E20))))) -> 0 | O20: =IF($B20="",0,IF(OR(5<$E20,5>$F20),0,INDEX(Indstillinger!$D$27:$D$38,5)*$G20*$C20*IF($H20=0,1,IF($H20+5-$E20>6,1,INDEX(Indstillinger!$C$18:$C$23,$H20+5-$E20))))) -> 0 | P20: =IF($B20="",0,IF(OR(6<$E20,6>$F20),0,INDEX(Indstillinger!$D$27:$D$38,6)*$G20*$C20*IF($H20=0,1,IF($H20+6-$E20>6,1,INDEX(Indstillinger!$C$18:$C$23,$H20+6-$E20))))) -> 0 | Q20: =IF($B20="",0,IF(OR(7<$E20,7>$F20),0,INDEX(Indstillinger!$D$27:$D$38,7)*$G20*$C20*IF($H20=0,1,IF($H20+7-$E20>6,1,INDEX(Indstillinger!$C$18:$C$23,$H20+7-$E20))))) -> 0 | R20: =IF($B20="",0,IF(OR(8<$E20,8>$F20),0,INDEX(Indstillinger!$D$27:$D$38,8)*$G20*$C20*IF($H20=0,1,IF($H20+8-$E20>6,1,INDEX(Indstillinger!$C$18:$C$23,$H20+8-$E20))))) -> 0 | S20: =IF($B20="",0,IF(OR(9<$E20,9>$F20),0,INDEX(Indstillinger!$D$27:$D$38,9)*$G20*$C20*IF($H20=0,1,IF($H20+9-$E20>6,1,INDEX(Indstillinger!$C$18:$C$23,$H20+9-$E20))))) -> 0 | T20: =IF($B20="",0,IF(OR(10<$E20,10>$F20),0,INDEX(Indstillinger!$D$27:$D$38,10)*$G20*$C20*IF($H20=0,1,IF($H20+10-$E20>6,1,INDEX(Indstillinger!$C$18:$C$23,$H20+10-$E20))))) -> 0 | U20: =IF($B20="",0,IF(OR(11<$E20,11>$F20),0,INDEX(Indstillinger!$D$27:$D$38,11)*$G20*$C20*IF($H20=0,1,IF($H20+11-$E20>6,1,INDEX(Indstillinger!$C$18:$C$23,$H20+11-$E20))))) -> 0 | V20: =IF($B20="",0,IF(OR(12<$E20,12>$F20),0,INDEX(Indstillinger!$D$27:$D$38,12)*$G20*$C20*IF($H20=0,1,IF($H20+12-$E20>6,1,INDEX(Indstillinger!$C$18:$C$23,$H20+12-$E20))))) -> 0 | W20: =SUM(K20:V20) -> 0 | X20: =IF($J20=1,N(Sælgere!$H$20),0) -> 0 | Y20: =IF($J20=1,0,W20) -> 0 | Z20: =IF(OR($B20="",$J20=1),0,SUMPRODUCT(--(K20:V20>0),$K$4:$V$4)*$G20) -> 0
