Workbook

Sheet Instructions
C2: Free template from Prowi
B4: Sales contest
B5: Plan the contest, log results and track the leaderboard and budget
B7: The template covers a sales contest from start to finish: setup with period, metric, prizes and budget, a participant list, a log of results day by day or week by week, a leaderboard that ranks automatically, and a budget check that shows what the prizes cost and whether the contest pays for itself. The example data is a new-customer contest in March 2026 with 8 reps.
B9: Step by step
B10: 1. Setup | C10: Name, start and end date, what is measured, how ranking works, prizes, team target and budget.
B11: 2. Participants | C11: Enter the participants with team and personal target. Set 'In contest' to No for managers or anyone who cannot win.
B12: 3. Results | C12: One row per result: date, participant and value (for example 1 per new customer, or the deal amount). Set 'Counts' to No if the deal is cancelled.
B13: 4. Leaderboard | C13: Ranks automatically and shows results by week, prize and the gap to the place ahead. Share it on screen or as PDF.
B14: 5. Budget check | C14: Shows the maximum prize cost, the cost based on current standings and the extra value compared with your normal level.
B16: Colours
B17: Lavender cell, purple text | C17: This is where you type. Everything else is formulas.
B18: Grey cell | C18: Calculated automatically.
B19: Light blue cell | C19: Results and totals.
B21: How the workbook calculates
B22: What counts | C22: Only results dated from the start date to the end date where 'Counts' is not No.
B23: Ranking | C23: By result or by percent of personal target. Ranking by percent lets reps with different targets compete on equal terms.
B24: Ties | C24: Participants with the same score share the place and split the prizes for the places they occupy together. Two tied for 3rd split the prizes for 3rd and 4th.
B25: Minimum | C25: A placement prize requires at least the minimum score (in the same unit as the ranking).
B26: Threshold and team prize | C26: The threshold prize goes to everyone who reaches a given percent of their target. The team prize goes to every participant when the team's total reaches the team target.
B27: Extra value | C27: (Total result − normal level) × value per unit. Break-even is the prize cost ÷ value per unit.
B29: Good to know
B30: • | C30: All names and numbers are examples. Delete the example data in Participants and Results before you use the workbook.
B31: • | C31: Write the rules down before the contest starts: what counts, which date decides it, and what happens to cancelled deals.
B32: • | C32: Prizes from an employer are generally taxable. Check with your accountant or payroll provider how a specific prize should be handled.
B33: • | C33: No macros. Every calculation is an ordinary formula that works in Excel, Google Sheets, Numbers and LibreOffice.
B36: prowi.io · Free template from Prowi

Sheet Setup
B2: Setup
B3: Only type in the lavender cells.
B5: The contest
B6: Name | C6: New customers in March | E6: Shown at the top of the leaderboard.
B7: Start date | C7: 46083 | E7: First day that counts.
B8: End date | C8: 46108 | E8: Last day that counts.
B9: What is measured | C9: New customers (count) | E9: For example new customers, revenue, meetings or qualified pipeline.
B10: Rank by | C10: Result | E10: Result or percent of target.
B11: Minimum for a placement prize | C11: 1 | E11: Same unit as the ranking. For percent, enter for example 80%.
B12: Standings as of | C12: 46108 | E12: The date the leaderboard shows standings for.
B14: Placement prizes
B15: Place | C15: Prize
B16: 1 | C16: 8000 | E16: Up to 5 places. Enter 0 for places without a prize.
B17: 2 | C17: 8000
B18: 3 | C18: 8000
B19: 4 | C19: 0
B20: 5 | C20: 0
B21: Threshold and team prize (optional)
B22: Threshold: percent of personal target | C22: 0 | E22: 0 = no threshold prize.
B23: Threshold prize per participant | C23: 0 | E23: For everyone who reaches the threshold.
B24: Team target (total result) | C24: 14 | E24: 0 = no team prize.
B25: Team prize per participant | C25: 2000 | E25: For every participant when the team target is reached.
B27: Budget and effect
B28: Total budget | C28: 48000 | E28: The most the contest may cost.
B29: Other costs (celebration, trophy, reserve) | C29: 8000 | E29: Fixed amount on top of the prizes.
B30: Normal level without a contest | C30: 10 | E30: The result the team usually reaches in the same period (baseline).
B31: Value per unit | C31: 60000 | E31: For example gross margin per new customer in year one. Use your own numbers.

Sheet Participants
A2: Participants
A3: Enter participants in columns A-E. Column G onwards are formulas.
A5: Name | B5: Team | C5: Personal target | D5: In contest | E5: Employee no. | G5: Result | H5: % of target | I5: Score | J5: Place | K5: Unique place | L5: Tied on place | M5: Placement prize | N5: Threshold prize | O5: Team prize | P5: Total prize | Q5: Week 1 | R5: Week 2 | S5: Week 3 | T5: Week 4 | U5: Week 5 | V5: Week 6 | W5: Week 7 | X5: Week 8 | Y5: Gap to place ahead
A6: Anna Holm | B6: North | C6: 2 | D6: Yes | G6: =IF(A6="","",SUMIFS(Results!$C$6:$C$505,Results!$B$6:$B$505,A6,Results!$F$6:$F$505,1)) -> 4 | H6: =IF(OR(A6="",N(C6)=0),"",G6/C6) -> 2 | I6: =IF(OR(A6="",D6="No"),"",IF(Setup!$C$10="Percent of target",N(H6),G6)) -> 4 | J6: =IF(I6="","",COUNTIF($I$6:$I$25,">"&I6)+1) -> 1 | K6: =IF(I6="","",J6+COUNTIF($I$6:I6,I6)-1) -> 1 | L6: =IF(I6="","",COUNTIF($I$6:$I$25,I6)) -> 1 | M6: =IF(I6="",0,IF(OR(I6<=0,I6<Setup!$C$11),0,SUMPRODUCT((Setup!$B$16:$B$20>=J6)*(Setup!$B$16:$B$20<=J6+L6-1)*Setup!$C$16:$C$20)/L6)) -> 8000 | N6: =IF(OR(I6="",N(Setup!$C$22)=0,H6=""),0,IF(H6>=Setup!$C$22,N(Setup!$C$23),0)) -> 0 | O6: =IF(OR(I6="",N(Setup!$C$24)=0),0,IF(SUMIFS($G$6:$G$25,$D$6:$D$25,"<>No")>=Setup!$C$24,N(Setup!$C$25),0)) -> 2000 | P6: =IF(A6="","",M6+N6+O6) -> 10000 | Q6: =IF(A6="","",SUMIFS(Results!$C$6:$C$505,Results!$B$6:$B$505,A6,Results!$G$6:$G$505,1)) -> 1 | R6: =IF(A6="","",SUMIFS(Results!$C$6:$C$505,Results!$B$6:$B$505,A6,Results!$G$6:$G$505,2)) -> 1 | S6: =IF(A6="","",SUMIFS(Results!$C$6:$C$505,Results!$B$6:$B$505,A6,Results!$G$6:$G$505,3)) -> 1 | T6: =IF(A6="","",SUMIFS(Results!$C$6:$C$505,Results!$B$6:$B$505,A6,Results!$G$6:$G$505,4)) -> 1 | U6: =IF(A6="","",SUMIFS(Results!$C$6:$C$505,Results!$B$6:$B$505,A6,Results!$G$6:$G$505,5)) -> 0 | V6: =IF(A6="","",SUMIFS(Results!$C$6:$C$505,Results!$B$6:$B$505,A6,Results!$G$6:$G$505,6)) -> 0 | W6: =IF(A6="","",SUMIFS(Results!$C$6:$C$505,Results!$B$6:$B$505,A6,Results!$G$6:$G$505,7)) -> 0 | X6: =IF(A6="","",SUMIFS(Results!$C$6:$C$505,Results!$B$6:$B$505,A6,Results!$G$6:$G$505,8)) -> 0 | Y6: =IF(I6="","",IF(J6=1,"",SMALL($I$6:$I$25,COUNTIF($I$6:$I$25,"<="&I6)+1)-I6))
A7: Bo Jensen | B7: North | C7: 2 | D7: Yes | G7: =IF(A7="","",SUMIFS(Results!$C$6:$C$505,Results!$B$6:$B$505,A7,Results!$F$6:$F$505,1)) -> 3 | H7: =IF(OR(A7="",N(C7)=0),"",G7/C7) -> 1.5 | I7: =IF(OR(A7="",D7="No"),"",IF(Setup!$C$10="Percent of target",N(H7),G7)) -> 3 | J7: =IF(I7="","",COUNTIF($I$6:$I$25,">"&I7)+1) -> 2 | K7: =IF(I7="","",J7+COUNTIF($I$6:I7,I7)-1) -> 2 | L7: =IF(I7="","",COUNTIF($I$6:$I$25,I7)) -> 1 | M7: =IF(I7="",0,IF(OR(I7<=0,I7<Setup!$C$11),0,SUMPRODUCT((Setup!$B$16:$B$20>=J7)*(Setup!$B$16:$B$20<=J7+L7-1)*Setup!$C$16:$C$20)/L7)) -> 8000 | N7: =IF(OR(I7="",N(Setup!$C$22)=0,H7=""),0,IF(H7>=Setup!$C$22,N(Setup!$C$23),0)) -> 0 | O7: =IF(OR(I7="",N(Setup!$C$24)=0),0,IF(SUMIFS($G$6:$G$25,$D$6:$D$25,"<>No")>=Setup!$C$24,N(Setup!$C$25),0)) -> 2000 | P7: =IF(A7="","",M7+N7+O7) -> 10000 | Q7: =IF(A7="","",SUMIFS(Results!$C$6:$C$505,Results!$B$6:$B$505,A7,Results!$G$6:$G$505,1)) -> 1 | R7: =IF(A7="","",SUMIFS(Results!$C$6:$C$505,Results!$B$6:$B$505,A7,Results!$G$6:$G$505,2)) -> 0 | S7: =IF(A7="","",SUMIFS(Results!$C$6:$C$505,Results!$B$6:$B$505,A7,Results!$G$6:$G$505,3)) -> 1 | T7: =IF(A7="","",SUMIFS(Results!$C$6:$C$505,Results!$B$6:$B$505,A7,Results!$G$6:$G$505,4)) -> 1 | U7: =IF(A7="","",SUMIFS(Results!$C$6:$C$505,Results!$B$6:$B$505,A7,Results!$G$6:$G$505,5)) -> 0 | V7: =IF(A7="","",SUMIFS(Results!$C$6:$C$505,Results!$B$6:$B$505,A7,Results!$G$6:$G$505,6)) -> 0 | W7: =IF(A7="","",SUMIFS(Results!$C$6:$C$505,Results!$B$6:$B$505,A7,Results!$G$6:$G$505,7)) -> 0 | X7: =IF(A7="","",SUMIFS(Results!$C$6:$C$505,Results!$B$6:$B$505,A7,Results!$G$6:$G$505,8)) -> 0 | Y7: =IF(I7="","",IF(J7=1,"",SMALL($I$6:$I$25,COUNTIF($I$6:$I$25,"<="&I7)+1)-I7)) -> 1
A8: Camilla Nørgaard | B8: South | C8: 2 | D8: Yes | G8: =IF(A8="","",SUMIFS(Results!$C$6:$C$505,Results!$B$6:$B$505,A8,Results!$F$6:$F$505,1)) -> 2 | H8: =IF(OR(A8="",N(C8)=0),"",G8/C8) -> 1 | I8: =IF(OR(A8="",D8="No"),"",IF(Setup!$C$10="Percent of target",N(H8),G8)) -> 2 | J8: =IF(I8="","",COUNTIF($I$6:$I$25,">"&I8)+1) -> 3 | K8: =IF(I8="","",J8+COUNTIF($I$6:I8,I8)-1) -> 3 | L8: =IF(I8="","",COUNTIF($I$6:$I$25,I8)) -> 2 | M8: =IF(I8="",0,IF(OR(I8<=0,I8<Setup!$C$11),0,SUMPRODUCT((Setup!$B$16:$B$20>=J8)*(Setup!$B$16:$B$20<=J8+L8-1)*Setup!$C$16:$C$20)/L8)) -> 4000 | N8: =IF(OR(I8="",N(Setup!$C$22)=0,H8=""),0,IF(H8>=Setup!$C$22,N(Setup!$C$23),0)) -> 0 | O8: =IF(OR(I8="",N(Setup!$C$24)=0),0,IF(SUMIFS($G$6:$G$25,$D$6:$D$25,"<>No")>=Setup!$C$24,N(Setup!$C$25),0)) -> 2000 | P8: =IF(A8="","",M8+N8+O8) -> 6000 | Q8: =IF(A8="","",SUMIFS(Results!$C$6:$C$505,Results!$B$6:$B$505,A8,Results!$G$6:$G$505,1)) -> 0 | R8: =IF(A8="","",SUMIFS(Results!$C$6:$C$505,Results!$B$6:$B$505,A8,Results!$G$6:$G$505,2)) -> 1 | S8: =IF(A8="","",SUMIFS(Results!$C$6:$C$505,Results!$B$6:$B$505,A8,Results!$G$6:$G$505,3)) -> 0 | T8: =IF(A8="","",SUMIFS(Results!$C$6:$C$505,Results!$B$6:$B$505,A8,Results!$G$6:$G$505,4)) -> 1 | U8: =IF(A8="","",SUMIFS(Results!$C$6:$C$505,Results!$B$6:$B$505,A8,Results!$G$6:$G$505,5)) -> 0 | V8: =IF(A8="","",SUMIFS(Results!$C$6:$C$505,Results!$B$6:$B$505,A8,Results!$G$6:$G$505,6)) -> 0 | W8: =IF(A8="","",SUMIFS(Results!$C$6:$C$505,Results!$B$6:$B$505,A8,Results!$G$6:$G$505,7)) -> 0 | X8: =IF(A8="","",SUMIFS(Results!$C$6:$C$505,Results!$B$6:$B$505,A8,Results!$G$6:$G$505,8)) -> 0 | Y8: =IF(I8="","",IF(J8=1,"",SMALL($I$6:$I$25,COUNTIF($I$6:$I$25,"<="&I8)+1)-I8)) -> 1
A9: David Lund | B9: South | C9: 2 | D9: Yes | G9: =IF(A9="","",SUMIFS(Results!$C$6:$C$505,Results!$B$6:$B$505,A9,Results!$F$6:$F$505,1)) -> 2 | H9: =IF(OR(A9="",N(C9)=0),"",G9/C9) -> 1 | I9: =IF(OR(A9="",D9="No"),"",IF(Setup!$C$10="Percent of target",N(H9),G9)) -> 2 | J9: =IF(I9="","",COUNTIF($I$6:$I$25,">"&I9)+1) -> 3 | K9: =IF(I9="","",J9+COUNTIF($I$6:I9,I9)-1) -> 4 | L9: =IF(I9="","",COUNTIF($I$6:$I$25,I9)) -> 2 | M9: =IF(I9="",0,IF(OR(I9<=0,I9<Setup!$C$11),0,SUMPRODUCT((Setup!$B$16:$B$20>=J9)*(Setup!$B$16:$B$20<=J9+L9-1)*Setup!$C$16:$C$20)/L9)) -> 4000 | N9: =IF(OR(I9="",N(Setup!$C$22)=0,H9=""),0,IF(H9>=Setup!$C$22,N(Setup!$C$23),0)) -> 0 | O9: =IF(OR(I9="",N(Setup!$C$24)=0),0,IF(SUMIFS($G$6:$G$25,$D$6:$D$25,"<>No")>=Setup!$C$24,N(Setup!$C$25),0)) -> 2000 | P9: =IF(A9="","",M9+N9+O9) -> 6000 | Q9: =IF(A9="","",SUMIFS(Results!$C$6:$C$505,Results!$B$6:$B$505,A9,Results!$G$6:$G$505,1)) -> 1 | R9: =IF(A9="","",SUMIFS(Results!$C$6:$C$505,Results!$B$6:$B$505,A9,Results!$G$6:$G$505,2)) -> 0 | S9: =IF(A9="","",SUMIFS(Results!$C$6:$C$505,Results!$B$6:$B$505,A9,Results!$G$6:$G$505,3)) -> 1 | T9: =IF(A9="","",SUMIFS(Results!$C$6:$C$505,Results!$B$6:$B$505,A9,Results!$G$6:$G$505,4)) -> 0 | U9: =IF(A9="","",SUMIFS(Results!$C$6:$C$505,Results!$B$6:$B$505,A9,Results!$G$6:$G$505,5)) -> 0 | V9: =IF(A9="","",SUMIFS(Results!$C$6:$C$505,Results!$B$6:$B$505,A9,Results!$G$6:$G$505,6)) -> 0 | W9: =IF(A9="","",SUMIFS(Results!$C$6:$C$505,Results!$B$6:$B$505,A9,Results!$G$6:$G$505,7)) -> 0 | X9: =IF(A9="","",SUMIFS(Results!$C$6:$C$505,Results!$B$6:$B$505,A9,Results!$G$6:$G$505,8)) -> 0 | Y9: =IF(I9="","",IF(J9=1,"",SMALL($I$6:$I$25,COUNTIF($I$6:$I$25,"<="&I9)+1)-I9)) -> 1
A10: Emma Krogh | B10: North | C10: 2 | D10: Yes | G10: =IF(A10="","",SUMIFS(Results!$C$6:$C$505,Results!$B$6:$B$505,A10,Results!$F$6:$F$505,1)) -> 1 | H10: =IF(OR(A10="",N(C10)=0),"",G10/C10) -> 0.5 | I10: =IF(OR(A10="",D10="No"),"",IF(Setup!$C$10="Percent of target",N(H10),G10)) -> 1 | J10: =IF(I10="","",COUNTIF($I$6:$I$25,">"&I10)+1) -> 5 | K10: =IF(I10="","",J10+COUNTIF($I$6:I10,I10)-1) -> 5 | L10: =IF(I10="","",COUNTIF($I$6:$I$25,I10)) -> 4 | M10: =IF(I10="",0,IF(OR(I10<=0,I10<Setup!$C$11),0,SUMPRODUCT((Setup!$B$16:$B$20>=J10)*(Setup!$B$16:$B$20<=J10+L10-1)*Setup!$C$16:$C$20)/L10)) -> 0 | N10: =IF(OR(I10="",N(Setup!$C$22)=0,H10=""),0,IF(H10>=Setup!$C$22,N(Setup!$C$23),0)) -> 0 | O10: =IF(OR(I10="",N(Setup!$C$24)=0),0,IF(SUMIFS($G$6:$G$25,$D$6:$D$25,"<>No")>=Setup!$C$24,N(Setup!$C$25),0)) -> 2000 | P10: =IF(A10="","",M10+N10+O10) -> 2000 | Q10: =IF(A10="","",SUMIFS(Results!$C$6:$C$505,Results!$B$6:$B$505,A10,Results!$G$6:$G$505,1)) -> 0 | R10: =IF(A10="","",SUMIFS(Results!$C$6:$C$505,Results!$B$6:$B$505,A10,Results!$G$6:$G$505,2)) -> 1 | S10: =IF(A10="","",SUMIFS(Results!$C$6:$C$505,Results!$B$6:$B$505,A10,Results!$G$6:$G$505,3)) -> 0 | T10: =IF(A10="","",SUMIFS(Results!$C$6:$C$505,Results!$B$6:$B$505,A10,Results!$G$6:$G$505,4)) -> 0 | U10: =IF(A10="","",SUMIFS(Results!$C$6:$C$505,Results!$B$6:$B$505,A10,Results!$G$6:$G$505,5)) -> 0 | V10: =IF(A10="","",SUMIFS(Results!$C$6:$C$505,Results!$B$6:$B$505,A10,Results!$G$6:$G$505,6)) -> 0 | W10: =IF(A10="","",SUMIFS(Results!$C$6:$C$505,Results!$B$6:$B$505,A10,Results!$G$6:$G$505,7)) -> 0 | X10: =IF(A10="","",SUMIFS(Results!$C$6:$C$505,Results!$B$6:$B$505,A10,Results!$G$6:$G$505,8)) -> 0 | Y10: =IF(I10="","",IF(J10=1,"",SMALL($I$6:$I$25,COUNTIF($I$6:$I$25,"<="&I10)+1)-I10)) -> 1
A11: Frederik Bach | B11: South | C11: 2 | D11: Yes | G11: =IF(A11="","",SUMIFS(Results!$C$6:$C$505,Results!$B$6:$B$505,A11,Results!$F$6:$F$505,1)) -> 1 | H11: =IF(OR(A11="",N(C11)=0),"",G11/C11) -> 0.5 | I11: =IF(OR(A11="",D11="No"),"",IF(Setup!$C$10="Percent of target",N(H11),G11)) -> 1 | J11: =IF(I11="","",COUNTIF($I$6:$I$25,">"&I11)+1) -> 5 | K11: =IF(I11="","",J11+COUNTIF($I$6:I11,I11)-1) -> 6 | L11: =IF(I11="","",COUNTIF($I$6:$I$25,I11)) -> 4 | M11: =IF(I11="",0,IF(OR(I11<=0,I11<Setup!$C$11),0,SUMPRODUCT((Setup!$B$16:$B$20>=J11)*(Setup!$B$16:$B$20<=J11+L11-1)*Setup!$C$16:$C$20)/L11)) -> 0 | N11: =IF(OR(I11="",N(Setup!$C$22)=0,H11=""),0,IF(H11>=Setup!$C$22,N(Setup!$C$23),0)) -> 0 | O11: =IF(OR(I11="",N(Setup!$C$24)=0),0,IF(SUMIFS($G$6:$G$25,$D$6:$D$25,"<>No")>=Setup!$C$24,N(Setup!$C$25),0)) -> 2000 | P11: =IF(A11="","",M11+N11+O11) -> 2000 | Q11: =IF(A11="","",SUMIFS(Results!$C$6:$C$505,Results!$B$6:$B$505,A11,Results!$G$6:$G$505,1)) -> 0 | R11: =IF(A11="","",SUMIFS(Results!$C$6:$C$505,Results!$B$6:$B$505,A11,Results!$G$6:$G$505,2)) -> 0 | S11: =IF(A11="","",SUMIFS(Results!$C$6:$C$505,Results!$B$6:$B$505,A11,Results!$G$6:$G$505,3)) -> 1 | T11: =IF(A11="","",SUMIFS(Results!$C$6:$C$505,Results!$B$6:$B$505,A11,Results!$G$6:$G$505,4)) -> 0 | U11: =IF(A11="","",SUMIFS(Results!$C$6:$C$505,Results!$B$6:$B$505,A11,Results!$G$6:$G$505,5)) -> 0 | V11: =IF(A11="","",SUMIFS(Results!$C$6:$C$505,Results!$B$6:$B$505,A11,Results!$G$6:$G$505,6)) -> 0 | W11: =IF(A11="","",SUMIFS(Results!$C$6:$C$505,Results!$B$6:$B$505,A11,Results!$G$6:$G$505,7)) -> 0 | X11: =IF(A11="","",SUMIFS(Results!$C$6:$C$505,Results!$B$6:$B$505,A11,Results!$G$6:$G$505,8)) -> 0 | Y11: =IF(I11="","",IF(J11=1,"",SMALL($I$6:$I$25,COUNTIF($I$6:$I$25,"<="&I11)+1)-I11)) -> 1
A12: Gitte Sørensen | B12: North | C12: 2 | D12: Yes | G12: =IF(A12="","",SUMIFS(Results!$C$6:$C$505,Results!$B$6:$B$505,A12,Results!$F$6:$F$505,1)) -> 1 | H12: =IF(OR(A12="",N(C12)=0),"",G12/C12) -> 0.5 | I12: =IF(OR(A12="",D12="No"),"",IF(Setup!$C$10="Percent of target",N(H12),G12)) -> 1 | J12: =IF(I12="","",COUNTIF($I$6:$I$25,">"&I12)+1) -> 5 | K12: =IF(I12="","",J12+COUNTIF($I$6:I12,I12)-1) -> 7 | L12: =IF(I12="","",COUNTIF($I$6:$I$25,I12)) -> 4 | M12: =IF(I12="",0,IF(OR(I12<=0,I12<Setup!$C$11),0,SUMPRODUCT((Setup!$B$16:$B$20>=J12)*(Setup!$B$16:$B$20<=J12+L12-1)*Setup!$C$16:$C$20)/L12)) -> 0 | N12: =IF(OR(I12="",N(Setup!$C$22)=0,H12=""),0,IF(H12>=Setup!$C$22,N(Setup!$C$23),0)) -> 0 | O12: =IF(OR(I12="",N(Setup!$C$24)=0),0,IF(SUMIFS($G$6:$G$25,$D$6:$D$25,"<>No")>=Setup!$C$24,N(Setup!$C$25),0)) -> 2000 | P12: =IF(A12="","",M12+N12+O12) -> 2000 | Q12: =IF(A12="","",SUMIFS(Results!$C$6:$C$505,Results!$B$6:$B$505,A12,Results!$G$6:$G$505,1)) -> 0 | R12: =IF(A12="","",SUMIFS(Results!$C$6:$C$505,Results!$B$6:$B$505,A12,Results!$G$6:$G$505,2)) -> 0 | S12: =IF(A12="","",SUMIFS(Results!$C$6:$C$505,Results!$B$6:$B$505,A12,Results!$G$6:$G$505,3)) -> 0 | T12: =IF(A12="","",SUMIFS(Results!$C$6:$C$505,Results!$B$6:$B$505,A12,Results!$G$6:$G$505,4)) -> 1 | U12: =IF(A12="","",SUMIFS(Results!$C$6:$C$505,Results!$B$6:$B$505,A12,Results!$G$6:$G$505,5)) -> 0 | V12: =IF(A12="","",SUMIFS(Results!$C$6:$C$505,Results!$B$6:$B$505,A12,Results!$G$6:$G$505,6)) -> 0 | W12: =IF(A12="","",SUMIFS(Results!$C$6:$C$505,Results!$B$6:$B$505,A12,Results!$G$6:$G$505,7)) -> 0 | X12: =IF(A12="","",SUMIFS(Results!$C$6:$C$505,Results!$B$6:$B$505,A12,Results!$G$6:$G$505,8)) -> 0 | Y12: =IF(I12="","",IF(J12=1,"",SMALL($I$6:$I$25,COUNTIF($I$6:$I$25,"<="&I12)+1)-I12)) -> 1
A13: Hassan Ali | B13: South | C13: 2 | D13: Yes | G13: =IF(A13="","",SUMIFS(Results!$C$6:$C$505,Results!$B$6:$B$505,A13,Results!$F$6:$F$505,1)) -> 1 | H13: =IF(OR(A13="",N(C13)=0),"",G13/C13) -> 0.5 | I13: =IF(OR(A13="",D13="No"),"",IF(Setup!$C$10="Percent of target",N(H13),G13)) -> 1 | J13: =IF(I13="","",COUNTIF($I$6:$I$25,">"&I13)+1) -> 5 | K13: =IF(I13="","",J13+COUNTIF($I$6:I13,I13)-1) -> 8 | L13: =IF(I13="","",COUNTIF($I$6:$I$25,I13)) -> 4 | M13: =IF(I13="",0,IF(OR(I13<=0,I13<Setup!$C$11),0,SUMPRODUCT((Setup!$B$16:$B$20>=J13)*(Setup!$B$16:$B$20<=J13+L13-1)*Setup!$C$16:$C$20)/L13)) -> 0 | N13: =IF(OR(I13="",N(Setup!$C$22)=0,H13=""),0,IF(H13>=Setup!$C$22,N(Setup!$C$23),0)) -> 0 | O13: =IF(OR(I13="",N(Setup!$C$24)=0),0,IF(SUMIFS($G$6:$G$25,$D$6:$D$25,"<>No")>=Setup!$C$24,N(Setup!$C$25),0)) -> 2000 | P13: =IF(A13="","",M13+N13+O13) -> 2000 | Q13: =IF(A13="","",SUMIFS(Results!$C$6:$C$505,Results!$B$6:$B$505,A13,Results!$G$6:$G$505,1)) -> 0 | R13: =IF(A13="","",SUMIFS(Results!$C$6:$C$505,Results!$B$6:$B$505,A13,Results!$G$6:$G$505,2)) -> 0 | S13: =IF(A13="","",SUMIFS(Results!$C$6:$C$505,Results!$B$6:$B$505,A13,Results!$G$6:$G$505,3)) -> 0 | T13: =IF(A13="","",SUMIFS(Results!$C$6:$C$505,Results!$B$6:$B$505,A13,Results!$G$6:$G$505,4)) -> 1 | U13: =IF(A13="","",SUMIFS(Results!$C$6:$C$505,Results!$B$6:$B$505,A13,Results!$G$6:$G$505,5)) -> 0 | V13: =IF(A13="","",SUMIFS(Results!$C$6:$C$505,Results!$B$6:$B$505,A13,Results!$G$6:$G$505,6)) -> 0 | W13: =IF(A13="","",SUMIFS(Results!$C$6:$C$505,Results!$B$6:$B$505,A13,Results!$G$6:$G$505,7)) -> 0 | X13: =IF(A13="","",SUMIFS(Results!$C$6:$C$505,Results!$B$6:$B$505,A13,Results!$G$6:$G$505,8)) -> 0 | Y13: =IF(I13="","",IF(J13=1,"",SMALL($I$6:$I$25,COUNTIF($I$6:$I$25,"<="&I13)+1)-I13)) -> 1
A14: Mette Lund | B14: Manager | D14: No | G14: =IF(A14="","",SUMIFS(Results!$C$6:$C$505,Results!$B$6:$B$505,A14,Results!$F$6:$F$505,1)) -> 0 | H14: =IF(OR(A14="",N(C14)=0),"",G14/C14) | I14: =IF(OR(A14="",D14="No"),"",IF(Setup!$C$10="Percent of target",N(H14),G14)) | J14: =IF(I14="","",COUNTIF($I$6:$I$25,">"&I14)+1) | K14: =IF(I14="","",J14+COUNTIF($I$6:I14,I14)-1) | L14: =IF(I14="","",COUNTIF($I$6:$I$25,I14)) | M14: =IF(I14="",0,IF(OR(I14<=0,I14<Setup!$C$11),0,SUMPRODUCT((Setup!$B$16:$B$20>=J14)*(Setup!$B$16:$B$20<=J14+L14-1)*Setup!$C$16:$C$20)/L14)) -> 0 | N14: =IF(OR(I14="",N(Setup!$C$22)=0,H14=""),0,IF(H14>=Setup!$C$22,N(Setup!$C$23),0)) -> 0 | O14: =IF(OR(I14="",N(Setup!$C$24)=0),0,IF(SUMIFS($G$6:$G$25,$D$6:$D$25,"<>No")>=Setup!$C$24,N(Setup!$C$25),0)) -> 0 | P14: =IF(A14="","",M14+N14+O14) -> 0 | Q14: =IF(A14="","",SUMIFS(Results!$C$6:$C$505,Results!$B$6:$B$505,A14,Results!$G$6:$G$505,1)) -> 0 | R14: =IF(A14="","",SUMIFS(Results!$C$6:$C$505,Results!$B$6:$B$505,A14,Results!$G$6:$G$505,2)) -> 0 | S14: =IF(A14="","",SUMIFS(Results!$C$6:$C$505,Results!$B$6:$B$505,A14,Results!$G$6:$G$505,3)) -> 0 | T14: =IF(A14="","",SUMIFS(Results!$C$6:$C$505,Results!$B$6:$B$505,A14,Results!$G$6:$G$505,4)) -> 0 | U14: =IF(A14="","",SUMIFS(Results!$C$6:$C$505,Results!$B$6:$B$505,A14,Results!$G$6:$G$505,5)) -> 0 | V14: =IF(A14="","",SUMIFS(Results!$C$6:$C$505,Results!$B$6:$B$505,A14,Results!$G$6:$G$505,6)) -> 0 | W14: =IF(A14="","",SUMIFS(Results!$C$6:$C$505,Results!$B$6:$B$505,A14,Results!$G$6:$G$505,7)) -> 0 | X14: =IF(A14="","",SUMIFS(Results!$C$6:$C$505,Results!$B$6:$B$505,A14,Results!$G$6:$G$505,8)) -> 0 | Y14: =IF(I14="","",IF(J14=1,"",SMALL($I$6:$I$25,COUNTIF($I$6:$I$25,"<="&I14)+1)-I14))
G15: =IF(A15="","",SUMIFS(Results!$C$6:$C$505,Results!$B$6:$B$505,A15,Results!$F$6:$F$505,1)) | H15: =IF(OR(A15="",N(C15)=0),"",G15/C15) | I15: =IF(OR(A15="",D15="No"),"",IF(Setup!$C$10="Percent of target",N(H15),G15)) | J15: =IF(I15="","",COUNTIF($I$6:$I$25,">"&I15)+1) | K15: =IF(I15="","",J15+COUNTIF($I$6:I15,I15)-1) | L15: =IF(I15="","",COUNTIF($I$6:$I$25,I15)) | M15: =IF(I15="",0,IF(OR(I15<=0,I15<Setup!$C$11),0,SUMPRODUCT((Setup!$B$16:$B$20>=J15)*(Setup!$B$16:$B$20<=J15+L15-1)*Setup!$C$16:$C$20)/L15)) -> 0 | N15: =IF(OR(I15="",N(Setup!$C$22)=0,H15=""),0,IF(H15>=Setup!$C$22,N(Setup!$C$23),0)) -> 0 | O15: =IF(OR(I15="",N(Setup!$C$24)=0),0,IF(SUMIFS($G$6:$G$25,$D$6:$D$25,"<>No")>=Setup!$C$24,N(Setup!$C$25),0)) -> 0 | P15: =IF(A15="","",M15+N15+O15) | Q15: =IF(A15="","",SUMIFS(Results!$C$6:$C$505,Results!$B$6:$B$505,A15,Results!$G$6:$G$505,1)) | R15: =IF(A15="","",SUMIFS(Results!$C$6:$C$505,Results!$B$6:$B$505,A15,Results!$G$6:$G$505,2)) | S15: =IF(A15="","",SUMIFS(Results!$C$6:$C$505,Results!$B$6:$B$505,A15,Results!$G$6:$G$505,3)) | T15: =IF(A15="","",SUMIFS(Results!$C$6:$C$505,Results!$B$6:$B$505,A15,Results!$G$6:$G$505,4)) | U15: =IF(A15="","",SUMIFS(Results!$C$6:$C$505,Results!$B$6:$B$505,A15,Results!$G$6:$G$505,5)) | V15: =IF(A15="","",SUMIFS(Results!$C$6:$C$505,Results!$B$6:$B$505,A15,Results!$G$6:$G$505,6)) | W15: =IF(A15="","",SUMIFS(Results!$C$6:$C$505,Results!$B$6:$B$505,A15,Results!$G$6:$G$505,7)) | X15: =IF(A15="","",SUMIFS(Results!$C$6:$C$505,Results!$B$6:$B$505,A15,Results!$G$6:$G$505,8)) | Y15: =IF(I15="","",IF(J15=1,"",SMALL($I$6:$I$25,COUNTIF($I$6:$I$25,"<="&I15)+1)-I15))
G16: =IF(A16="","",SUMIFS(Results!$C$6:$C$505,Results!$B$6:$B$505,A16,Results!$F$6:$F$505,1)) | H16: =IF(OR(A16="",N(C16)=0),"",G16/C16) | I16: =IF(OR(A16="",D16="No"),"",IF(Setup!$C$10="Percent of target",N(H16),G16)) | J16: =IF(I16="","",COUNTIF($I$6:$I$25,">"&I16)+1) | K16: =IF(I16="","",J16+COUNTIF($I$6:I16,I16)-1) | L16: =IF(I16="","",COUNTIF($I$6:$I$25,I16)) | M16: =IF(I16="",0,IF(OR(I16<=0,I16<Setup!$C$11),0,SUMPRODUCT((Setup!$B$16:$B$20>=J16)*(Setup!$B$16:$B$20<=J16+L16-1)*Setup!$C$16:$C$20)/L16)) -> 0 | N16: =IF(OR(I16="",N(Setup!$C$22)=0,H16=""),0,IF(H16>=Setup!$C$22,N(Setup!$C$23),0)) -> 0 | O16: =IF(OR(I16="",N(Setup!$C$24)=0),0,IF(SUMIFS($G$6:$G$25,$D$6:$D$25,"<>No")>=Setup!$C$24,N(Setup!$C$25),0)) -> 0 | P16: =IF(A16="","",M16+N16+O16) | Q16: =IF(A16="","",SUMIFS(Results!$C$6:$C$505,Results!$B$6:$B$505,A16,Results!$G$6:$G$505,1)) | R16: =IF(A16="","",SUMIFS(Results!$C$6:$C$505,Results!$B$6:$B$505,A16,Results!$G$6:$G$505,2)) | S16: =IF(A16="","",SUMIFS(Results!$C$6:$C$505,Results!$B$6:$B$505,A16,Results!$G$6:$G$505,3)) | T16: =IF(A16="","",SUMIFS(Results!$C$6:$C$505,Results!$B$6:$B$505,A16,Results!$G$6:$G$505,4)) | U16: =IF(A16="","",SUMIFS(Results!$C$6:$C$505,Results!$B$6:$B$505,A16,Results!$G$6:$G$505,5)) | V16: =IF(A16="","",SUMIFS(Results!$C$6:$C$505,Results!$B$6:$B$505,A16,Results!$G$6:$G$505,6)) | W16: =IF(A16="","",SUMIFS(Results!$C$6:$C$505,Results!$B$6:$B$505,A16,Results!$G$6:$G$505,7)) | X16: =IF(A16="","",SUMIFS(Results!$C$6:$C$505,Results!$B$6:$B$505,A16,Results!$G$6:$G$505,8)) | Y16: =IF(I16="","",IF(J16=1,"",SMALL($I$6:$I$25,COUNTIF($I$6:$I$25,"<="&I16)+1)-I16))
G17: =IF(A17="","",SUMIFS(Results!$C$6:$C$505,Results!$B$6:$B$505,A17,Results!$F$6:$F$505,1)) | H17: =IF(OR(A17="",N(C17)=0),"",G17/C17) | I17: =IF(OR(A17="",D17="No"),"",IF(Setup!$C$10="Percent of target",N(H17),G17)) | J17: =IF(I17="","",COUNTIF($I$6:$I$25,">"&I17)+1) | K17: =IF(I17="","",J17+COUNTIF($I$6:I17,I17)-1) | L17: =IF(I17="","",COUNTIF($I$6:$I$25,I17)) | M17: =IF(I17="",0,IF(OR(I17<=0,I17<Setup!$C$11),0,SUMPRODUCT((Setup!$B$16:$B$20>=J17)*(Setup!$B$16:$B$20<=J17+L17-1)*Setup!$C$16:$C$20)/L17)) -> 0 | N17: =IF(OR(I17="",N(Setup!$C$22)=0,H17=""),0,IF(H17>=Setup!$C$22,N(Setup!$C$23),0)) -> 0 | O17: =IF(OR(I17="",N(Setup!$C$24)=0),0,IF(SUMIFS($G$6:$G$25,$D$6:$D$25,"<>No")>=Setup!$C$24,N(Setup!$C$25),0)) -> 0 | P17: =IF(A17="","",M17+N17+O17) | Q17: =IF(A17="","",SUMIFS(Results!$C$6:$C$505,Results!$B$6:$B$505,A17,Results!$G$6:$G$505,1)) | R17: =IF(A17="","",SUMIFS(Results!$C$6:$C$505,Results!$B$6:$B$505,A17,Results!$G$6:$G$505,2)) | S17: =IF(A17="","",SUMIFS(Results!$C$6:$C$505,Results!$B$6:$B$505,A17,Results!$G$6:$G$505,3)) | T17: =IF(A17="","",SUMIFS(Results!$C$6:$C$505,Results!$B$6:$B$505,A17,Results!$G$6:$G$505,4)) | U17: =IF(A17="","",SUMIFS(Results!$C$6:$C$505,Results!$B$6:$B$505,A17,Results!$G$6:$G$505,5)) | V17: =IF(A17="","",SUMIFS(Results!$C$6:$C$505,Results!$B$6:$B$505,A17,Results!$G$6:$G$505,6)) | W17: =IF(A17="","",SUMIFS(Results!$C$6:$C$505,Results!$B$6:$B$505,A17,Results!$G$6:$G$505,7)) | X17: =IF(A17="","",SUMIFS(Results!$C$6:$C$505,Results!$B$6:$B$505,A17,Results!$G$6:$G$505,8)) | Y17: =IF(I17="","",IF(J17=1,"",SMALL($I$6:$I$25,COUNTIF($I$6:$I$25,"<="&I17)+1)-I17))
G18: =IF(A18="","",SUMIFS(Results!$C$6:$C$505,Results!$B$6:$B$505,A18,Results!$F$6:$F$505,1)) | H18: =IF(OR(A18="",N(C18)=0),"",G18/C18) | I18: =IF(OR(A18="",D18="No"),"",IF(Setup!$C$10="Percent of target",N(H18),G18)) | J18: =IF(I18="","",COUNTIF($I$6:$I$25,">"&I18)+1) | K18: =IF(I18="","",J18+COUNTIF($I$6:I18,I18)-1) | L18: =IF(I18="","",COUNTIF($I$6:$I$25,I18)) | M18: =IF(I18="",0,IF(OR(I18<=0,I18<Setup!$C$11),0,SUMPRODUCT((Setup!$B$16:$B$20>=J18)*(Setup!$B$16:$B$20<=J18+L18-1)*Setup!$C$16:$C$20)/L18)) -> 0 | N18: =IF(OR(I18="",N(Setup!$C$22)=0,H18=""),0,IF(H18>=Setup!$C$22,N(Setup!$C$23),0)) -> 0 | O18: =IF(OR(I18="",N(Setup!$C$24)=0),0,IF(SUMIFS($G$6:$G$25,$D$6:$D$25,"<>No")>=Setup!$C$24,N(Setup!$C$25),0)) -> 0 | P18: =IF(A18="","",M18+N18+O18) | Q18: =IF(A18="","",SUMIFS(Results!$C$6:$C$505,Results!$B$6:$B$505,A18,Results!$G$6:$G$505,1)) | R18: =IF(A18="","",SUMIFS(Results!$C$6:$C$505,Results!$B$6:$B$505,A18,Results!$G$6:$G$505,2)) | S18: =IF(A18="","",SUMIFS(Results!$C$6:$C$505,Results!$B$6:$B$505,A18,Results!$G$6:$G$505,3)) | T18: =IF(A18="","",SUMIFS(Results!$C$6:$C$505,Results!$B$6:$B$505,A18,Results!$G$6:$G$505,4)) | U18: =IF(A18="","",SUMIFS(Results!$C$6:$C$505,Results!$B$6:$B$505,A18,Results!$G$6:$G$505,5)) | V18: =IF(A18="","",SUMIFS(Results!$C$6:$C$505,Results!$B$6:$B$505,A18,Results!$G$6:$G$505,6)) | W18: =IF(A18="","",SUMIFS(Results!$C$6:$C$505,Results!$B$6:$B$505,A18,Results!$G$6:$G$505,7)) | X18: =IF(A18="","",SUMIFS(Results!$C$6:$C$505,Results!$B$6:$B$505,A18,Results!$G$6:$G$505,8)) | Y18: =IF(I18="","",IF(J18=1,"",SMALL($I$6:$I$25,COUNTIF($I$6:$I$25,"<="&I18)+1)-I18))
G19: =IF(A19="","",SUMIFS(Results!$C$6:$C$505,Results!$B$6:$B$505,A19,Results!$F$6:$F$505,1)) | H19: =IF(OR(A19="",N(C19)=0),"",G19/C19) | I19: =IF(OR(A19="",D19="No"),"",IF(Setup!$C$10="Percent of target",N(H19),G19)) | J19: =IF(I19="","",COUNTIF($I$6:$I$25,">"&I19)+1) | K19: =IF(I19="","",J19+COUNTIF($I$6:I19,I19)-1) | L19: =IF(I19="","",COUNTIF($I$6:$I$25,I19)) | M19: =IF(I19="",0,IF(OR(I19<=0,I19<Setup!$C$11),0,SUMPRODUCT((Setup!$B$16:$B$20>=J19)*(Setup!$B$16:$B$20<=J19+L19-1)*Setup!$C$16:$C$20)/L19)) -> 0 | N19: =IF(OR(I19="",N(Setup!$C$22)=0,H19=""),0,IF(H19>=Setup!$C$22,N(Setup!$C$23),0)) -> 0 | O19: =IF(OR(I19="",N(Setup!$C$24)=0),0,IF(SUMIFS($G$6:$G$25,$D$6:$D$25,"<>No")>=Setup!$C$24,N(Setup!$C$25),0)) -> 0 | P19: =IF(A19="","",M19+N19+O19) | Q19: =IF(A19="","",SUMIFS(Results!$C$6:$C$505,Results!$B$6:$B$505,A19,Results!$G$6:$G$505,1)) | R19: =IF(A19="","",SUMIFS(Results!$C$6:$C$505,Results!$B$6:$B$505,A19,Results!$G$6:$G$505,2)) | S19: =IF(A19="","",SUMIFS(Results!$C$6:$C$505,Results!$B$6:$B$505,A19,Results!$G$6:$G$505,3)) | T19: =IF(A19="","",SUMIFS(Results!$C$6:$C$505,Results!$B$6:$B$505,A19,Results!$G$6:$G$505,4)) | U19: =IF(A19="","",SUMIFS(Results!$C$6:$C$505,Results!$B$6:$B$505,A19,Results!$G$6:$G$505,5)) | V19: =IF(A19="","",SUMIFS(Results!$C$6:$C$505,Results!$B$6:$B$505,A19,Results!$G$6:$G$505,6)) | W19: =IF(A19="","",SUMIFS(Results!$C$6:$C$505,Results!$B$6:$B$505,A19,Results!$G$6:$G$505,7)) | X19: =IF(A19="","",SUMIFS(Results!$C$6:$C$505,Results!$B$6:$B$505,A19,Results!$G$6:$G$505,8)) | Y19: =IF(I19="","",IF(J19=1,"",SMALL($I$6:$I$25,COUNTIF($I$6:$I$25,"<="&I19)+1)-I19))
G20: =IF(A20="","",SUMIFS(Results!$C$6:$C$505,Results!$B$6:$B$505,A20,Results!$F$6:$F$505,1)) | H20: =IF(OR(A20="",N(C20)=0),"",G20/C20) | I20: =IF(OR(A20="",D20="No"),"",IF(Setup!$C$10="Percent of target",N(H20),G20)) | J20: =IF(I20="","",COUNTIF($I$6:$I$25,">"&I20)+1) | K20: =IF(I20="","",J20+COUNTIF($I$6:I20,I20)-1) | L20: =IF(I20="","",COUNTIF($I$6:$I$25,I20)) | M20: =IF(I20="",0,IF(OR(I20<=0,I20<Setup!$C$11),0,SUMPRODUCT((Setup!$B$16:$B$20>=J20)*(Setup!$B$16:$B$20<=J20+L20-1)*Setup!$C$16:$C$20)/L20)) -> 0 | N20: =IF(OR(I20="",N(Setup!$C$22)=0,H20=""),0,IF(H20>=Setup!$C$22,N(Setup!$C$23),0)) -> 0 | O20: =IF(OR(I20="",N(Setup!$C$24)=0),0,IF(SUMIFS($G$6:$G$25,$D$6:$D$25,"<>No")>=Setup!$C$24,N(Setup!$C$25),0)) -> 0 | P20: =IF(A20="","",M20+N20+O20) | Q20: =IF(A20="","",SUMIFS(Results!$C$6:$C$505,Results!$B$6:$B$505,A20,Results!$G$6:$G$505,1)) | R20: =IF(A20="","",SUMIFS(Results!$C$6:$C$505,Results!$B$6:$B$505,A20,Results!$G$6:$G$505,2)) | S20: =IF(A20="","",SUMIFS(Results!$C$6:$C$505,Results!$B$6:$B$505,A20,Results!$G$6:$G$505,3)) | T20: =IF(A20="","",SUMIFS(Results!$C$6:$C$505,Results!$B$6:$B$505,A20,Results!$G$6:$G$505,4)) | U20: =IF(A20="","",SUMIFS(Results!$C$6:$C$505,Results!$B$6:$B$505,A20,Results!$G$6:$G$505,5)) | V20: =IF(A20="","",SUMIFS(Results!$C$6:$C$505,Results!$B$6:$B$505,A20,Results!$G$6:$G$505,6)) | W20: =IF(A20="","",SUMIFS(Results!$C$6:$C$505,Results!$B$6:$B$505,A20,Results!$G$6:$G$505,7)) | X20: =IF(A20="","",SUMIFS(Results!$C$6:$C$505,Results!$B$6:$B$505,A20,Results!$G$6:$G$505,8)) | Y20: =IF(I20="","",IF(J20=1,"",SMALL($I$6:$I$25,COUNTIF($I$6:$I$25,"<="&I20)+1)-I20))
G21: =IF(A21="","",SUMIFS(Results!$C$6:$C$505,Results!$B$6:$B$505,A21,Results!$F$6:$F$505,1)) | H21: =IF(OR(A21="",N(C21)=0),"",G21/C21) | I21: =IF(OR(A21="",D21="No"),"",IF(Setup!$C$10="Percent of target",N(H21),G21)) | J21: =IF(I21="","",COUNTIF($I$6:$I$25,">"&I21)+1) | K21: =IF(I21="","",J21+COUNTIF($I$6:I21,I21)-1) | L21: =IF(I21="","",COUNTIF($I$6:$I$25,I21)) | M21: =IF(I21="",0,IF(OR(I21<=0,I21<Setup!$C$11),0,SUMPRODUCT((Setup!$B$16:$B$20>=J21)*(Setup!$B$16:$B$20<=J21+L21-1)*Setup!$C$16:$C$20)/L21)) -> 0 | N21: =IF(OR(I21="",N(Setup!$C$22)=0,H21=""),0,IF(H21>=Setup!$C$22,N(Setup!$C$23),0)) -> 0 | O21: =IF(OR(I21="",N(Setup!$C$24)=0),0,IF(SUMIFS($G$6:$G$25,$D$6:$D$25,"<>No")>=Setup!$C$24,N(Setup!$C$25),0)) -> 0 | P21: =IF(A21="","",M21+N21+O21) | Q21: =IF(A21="","",SUMIFS(Results!$C$6:$C$505,Results!$B$6:$B$505,A21,Results!$G$6:$G$505,1)) | R21: =IF(A21="","",SUMIFS(Results!$C$6:$C$505,Results!$B$6:$B$505,A21,Results!$G$6:$G$505,2)) | S21: =IF(A21="","",SUMIFS(Results!$C$6:$C$505,Results!$B$6:$B$505,A21,Results!$G$6:$G$505,3)) | T21: =IF(A21="","",SUMIFS(Results!$C$6:$C$505,Results!$B$6:$B$505,A21,Results!$G$6:$G$505,4)) | U21: =IF(A21="","",SUMIFS(Results!$C$6:$C$505,Results!$B$6:$B$505,A21,Results!$G$6:$G$505,5)) | V21: =IF(A21="","",SUMIFS(Results!$C$6:$C$505,Results!$B$6:$B$505,A21,Results!$G$6:$G$505,6)) | W21: =IF(A21="","",SUMIFS(Results!$C$6:$C$505,Results!$B$6:$B$505,A21,Results!$G$6:$G$505,7)) | X21: =IF(A21="","",SUMIFS(Results!$C$6:$C$505,Results!$B$6:$B$505,A21,Results!$G$6:$G$505,8)) | Y21: =IF(I21="","",IF(J21=1,"",SMALL($I$6:$I$25,COUNTIF($I$6:$I$25,"<="&I21)+1)-I21))
G22: =IF(A22="","",SUMIFS(Results!$C$6:$C$505,Results!$B$6:$B$505,A22,Results!$F$6:$F$505,1)) | H22: =IF(OR(A22="",N(C22)=0),"",G22/C22) | I22: =IF(OR(A22="",D22="No"),"",IF(Setup!$C$10="Percent of target",N(H22),G22)) | J22: =IF(I22="","",COUNTIF($I$6:$I$25,">"&I22)+1) | K22: =IF(I22="","",J22+COUNTIF($I$6:I22,I22)-1) | L22: =IF(I22="","",COUNTIF($I$6:$I$25,I22)) | M22: =IF(I22="",0,IF(OR(I22<=0,I22<Setup!$C$11),0,SUMPRODUCT((Setup!$B$16:$B$20>=J22)*(Setup!$B$16:$B$20<=J22+L22-1)*Setup!$C$16:$C$20)/L22)) -> 0 | N22: =IF(OR(I22="",N(Setup!$C$22)=0,H22=""),0,IF(H22>=Setup!$C$22,N(Setup!$C$23),0)) -> 0 | O22: =IF(OR(I22="",N(Setup!$C$24)=0),0,IF(SUMIFS($G$6:$G$25,$D$6:$D$25,"<>No")>=Setup!$C$24,N(Setup!$C$25),0)) -> 0 | P22: =IF(A22="","",M22+N22+O22) | Q22: =IF(A22="","",SUMIFS(Results!$C$6:$C$505,Results!$B$6:$B$505,A22,Results!$G$6:$G$505,1)) | R22: =IF(A22="","",SUMIFS(Results!$C$6:$C$505,Results!$B$6:$B$505,A22,Results!$G$6:$G$505,2)) | S22: =IF(A22="","",SUMIFS(Results!$C$6:$C$505,Results!$B$6:$B$505,A22,Results!$G$6:$G$505,3)) | T22: =IF(A22="","",SUMIFS(Results!$C$6:$C$505,Results!$B$6:$B$505,A22,Results!$G$6:$G$505,4)) | U22: =IF(A22="","",SUMIFS(Results!$C$6:$C$505,Results!$B$6:$B$505,A22,Results!$G$6:$G$505,5)) | V22: =IF(A22="","",SUMIFS(Results!$C$6:$C$505,Results!$B$6:$B$505,A22,Results!$G$6:$G$505,6)) | W22: =IF(A22="","",SUMIFS(Results!$C$6:$C$505,Results!$B$6:$B$505,A22,Results!$G$6:$G$505,7)) | X22: =IF(A22="","",SUMIFS(Results!$C$6:$C$505,Results!$B$6:$B$505,A22,Results!$G$6:$G$505,8)) | Y22: =IF(I22="","",IF(J22=1,"",SMALL($I$6:$I$25,COUNTIF($I$6:$I$25,"<="&I22)+1)-I22))
G23: =IF(A23="","",SUMIFS(Results!$C$6:$C$505,Results!$B$6:$B$505,A23,Results!$F$6:$F$505,1)) | H23: =IF(OR(A23="",N(C23)=0),"",G23/C23) | I23: =IF(OR(A23="",D23="No"),"",IF(Setup!$C$10="Percent of target",N(H23),G23)) | J23: =IF(I23="","",COUNTIF($I$6:$I$25,">"&I23)+1) | K23: =IF(I23="","",J23+COUNTIF($I$6:I23,I23)-1) | L23: =IF(I23="","",COUNTIF($I$6:$I$25,I23)) | M23: =IF(I23="",0,IF(OR(I23<=0,I23<Setup!$C$11),0,SUMPRODUCT((Setup!$B$16:$B$20>=J23)*(Setup!$B$16:$B$20<=J23+L23-1)*Setup!$C$16:$C$20)/L23)) -> 0 | N23: =IF(OR(I23="",N(Setup!$C$22)=0,H23=""),0,IF(H23>=Setup!$C$22,N(Setup!$C$23),0)) -> 0 | O23: =IF(OR(I23="",N(Setup!$C$24)=0),0,IF(SUMIFS($G$6:$G$25,$D$6:$D$25,"<>No")>=Setup!$C$24,N(Setup!$C$25),0)) -> 0 | P23: =IF(A23="","",M23+N23+O23) | Q23: =IF(A23="","",SUMIFS(Results!$C$6:$C$505,Results!$B$6:$B$505,A23,Results!$G$6:$G$505,1)) | R23: =IF(A23="","",SUMIFS(Results!$C$6:$C$505,Results!$B$6:$B$505,A23,Results!$G$6:$G$505,2)) | S23: =IF(A23="","",SUMIFS(Results!$C$6:$C$505,Results!$B$6:$B$505,A23,Results!$G$6:$G$505,3)) | T23: =IF(A23="","",SUMIFS(Results!$C$6:$C$505,Results!$B$6:$B$505,A23,Results!$G$6:$G$505,4)) | U23: =IF(A23="","",SUMIFS(Results!$C$6:$C$505,Results!$B$6:$B$505,A23,Results!$G$6:$G$505,5)) | V23: =IF(A23="","",SUMIFS(Results!$C$6:$C$505,Results!$B$6:$B$505,A23,Results!$G$6:$G$505,6)) | W23: =IF(A23="","",SUMIFS(Results!$C$6:$C$505,Results!$B$6:$B$505,A23,Results!$G$6:$G$505,7)) | X23: =IF(A23="","",SUMIFS(Results!$C$6:$C$505,Results!$B$6:$B$505,A23,Results!$G$6:$G$505,8)) | Y23: =IF(I23="","",IF(J23=1,"",SMALL($I$6:$I$25,COUNTIF($I$6:$I$25,"<="&I23)+1)-I23))
G24: =IF(A24="","",SUMIFS(Results!$C$6:$C$505,Results!$B$6:$B$505,A24,Results!$F$6:$F$505,1)) | H24: =IF(OR(A24="",N(C24)=0),"",G24/C24) | I24: =IF(OR(A24="",D24="No"),"",IF(Setup!$C$10="Percent of target",N(H24),G24)) | J24: =IF(I24="","",COUNTIF($I$6:$I$25,">"&I24)+1) | K24: =IF(I24="","",J24+COUNTIF($I$6:I24,I24)-1) | L24: =IF(I24="","",COUNTIF($I$6:$I$25,I24)) | M24: =IF(I24="",0,IF(OR(I24<=0,I24<Setup!$C$11),0,SUMPRODUCT((Setup!$B$16:$B$20>=J24)*(Setup!$B$16:$B$20<=J24+L24-1)*Setup!$C$16:$C$20)/L24)) -> 0 | N24: =IF(OR(I24="",N(Setup!$C$22)=0,H24=""),0,IF(H24>=Setup!$C$22,N(Setup!$C$23),0)) -> 0 | O24: =IF(OR(I24="",N(Setup!$C$24)=0),0,IF(SUMIFS($G$6:$G$25,$D$6:$D$25,"<>No")>=Setup!$C$24,N(Setup!$C$25),0)) -> 0 | P24: =IF(A24="","",M24+N24+O24) | Q24: =IF(A24="","",SUMIFS(Results!$C$6:$C$505,Results!$B$6:$B$505,A24,Results!$G$6:$G$505,1)) | R24: =IF(A24="","",SUMIFS(Results!$C$6:$C$505,Results!$B$6:$B$505,A24,Results!$G$6:$G$505,2)) | S24: =IF(A24="","",SUMIFS(Results!$C$6:$C$505,Results!$B$6:$B$505,A24,Results!$G$6:$G$505,3)) | T24: =IF(A24="","",SUMIFS(Results!$C$6:$C$505,Results!$B$6:$B$505,A24,Results!$G$6:$G$505,4)) | U24: =IF(A24="","",SUMIFS(Results!$C$6:$C$505,Results!$B$6:$B$505,A24,Results!$G$6:$G$505,5)) | V24: =IF(A24="","",SUMIFS(Results!$C$6:$C$505,Results!$B$6:$B$505,A24,Results!$G$6:$G$505,6)) | W24: =IF(A24="","",SUMIFS(Results!$C$6:$C$505,Results!$B$6:$B$505,A24,Results!$G$6:$G$505,7)) | X24: =IF(A24="","",SUMIFS(Results!$C$6:$C$505,Results!$B$6:$B$505,A24,Results!$G$6:$G$505,8)) | Y24: =IF(I24="","",IF(J24=1,"",SMALL($I$6:$I$25,COUNTIF($I$6:$I$25,"<="&I24)+1)-I24))
G25: =IF(A25="","",SUMIFS(Results!$C$6:$C$505,Results!$B$6:$B$505,A25,Results!$F$6:$F$505,1)) | H25: =IF(OR(A25="",N(C25)=0),"",G25/C25) | I25: =IF(OR(A25="",D25="No"),"",IF(Setup!$C$10="Percent of target",N(H25),G25)) | J25: =IF(I25="","",COUNTIF($I$6:$I$25,">"&I25)+1) | K25: =IF(I25="","",J25+COUNTIF($I$6:I25,I25)-1) | L25: =IF(I25="","",COUNTIF($I$6:$I$25,I25)) | M25: =IF(I25="",0,IF(OR(I25<=0,I25<Setup!$C$11),0,SUMPRODUCT((Setup!$B$16:$B$20>=J25)*(Setup!$B$16:$B$20<=J25+L25-1)*Setup!$C$16:$C$20)/L25)) -> 0 | N25: =IF(OR(I25="",N(Setup!$C$22)=0,H25=""),0,IF(H25>=Setup!$C$22,N(Setup!$C$23),0)) -> 0 | O25: =IF(OR(I25="",N(Setup!$C$24)=0),0,IF(SUMIFS($G$6:$G$25,$D$6:$D$25,"<>No")>=Setup!$C$24,N(Setup!$C$25),0)) -> 0 | P25: =IF(A25="","",M25+N25+O25) | Q25: =IF(A25="","",SUMIFS(Results!$C$6:$C$505,Results!$B$6:$B$505,A25,Results!$G$6:$G$505,1)) | R25: =IF(A25="","",SUMIFS(Results!$C$6:$C$505,Results!$B$6:$B$505,A25,Results!$G$6:$G$505,2)) | S25: =IF(A25="","",SUMIFS(Results!$C$6:$C$505,Results!$B$6:$B$505,A25,Results!$G$6:$G$505,3)) | T25: =IF(A25="","",SUMIFS(Results!$C$6:$C$505,Results!$B$6:$B$505,A25,Results!$G$6:$G$505,4)) | U25: =IF(A25="","",SUMIFS(Results!$C$6:$C$505,Results!$B$6:$B$505,A25,Results!$G$6:$G$505,5)) | V25: =IF(A25="","",SUMIFS(Results!$C$6:$C$505,Results!$B$6:$B$505,A25,Results!$G$6:$G$505,6)) | W25: =IF(A25="","",SUMIFS(Results!$C$6:$C$505,Results!$B$6:$B$505,A25,Results!$G$6:$G$505,7)) | X25: =IF(A25="","",SUMIFS(Results!$C$6:$C$505,Results!$B$6:$B$505,A25,Results!$G$6:$G$505,8)) | Y25: =IF(I25="","",IF(J25=1,"",SMALL($I$6:$I$25,COUNTIF($I$6:$I$25,"<="&I25)+1)-I25))
A26: Total | G26: =SUMIFS($G$6:$G$25,$D$6:$D$25,"<>No") -> 15 | M26: =SUM(M6:M25) -> 24000 | N26: =SUM(N6:N25) -> 0 | O26: =SUM(O6:O25) -> 16000 | P26: =SUM(P6:P25) -> 40000 | Q26: =SUMIFS(Q6:Q25,$D$6:$D$25,"<>No") -> 3 | R26: =SUMIFS(R6:R25,$D$6:$D$25,"<>No") -> 3 | S26: =SUMIFS(S6:S25,$D$6:$D$25,"<>No") -> 4 | T26: =SUMIFS(T6:T25,$D$6:$D$25,"<>No") -> 5 | U26: =SUMIFS(U6:U25,$D$6:$D$25,"<>No") -> 0 | V26: =SUMIFS(V6:V25,$D$6:$D$25,"<>No") -> 0 | W26: =SUMIFS(W6:W25,$D$6:$D$25,"<>No") -> 0 | X26: =SUMIFS(X6:X25,$D$6:$D$25,"<>No") -> 0
A28: In contest = No: the person's results are shown, but they are not ranked and cannot win. 'Total' counts only participants in the contest.

Sheet Results
A2: Results
A3: One row per result, daily or weekly as suits you. Columns F and G are formulas.
A5: Date | B5: Participant | C5: Value | D5: Counts | E5: Deal ID / note | F5: In period | G5: Week no. | I5: Counts: empty = yes. Enter No if the deal is cancelled or breaks the rules.
A6: 46084 | B6: Anna Holm | C6: 1 | E6: D-2001 | F6: =IF(OR(A6="",B6="",C6=""),"",IF(AND(A6>=Setup!$C$7,A6<=Setup!$C$8,D6<>"No"),1,0)) -> 1 | G6: =IF(F6=1,INT((A6-Setup!$C$7)/7)+1,"") -> 1
A7: 46085 | B7: David Lund | C7: 1 | E7: D-2002 | F7: =IF(OR(A7="",B7="",C7=""),"",IF(AND(A7>=Setup!$C$7,A7<=Setup!$C$8,D7<>"No"),1,0)) -> 1 | G7: =IF(F7=1,INT((A7-Setup!$C$7)/7)+1,"") -> 1
A8: 46086 | B8: Bo Jensen | C8: 1 | E8: D-2003 | F8: =IF(OR(A8="",B8="",C8=""),"",IF(AND(A8>=Setup!$C$7,A8<=Setup!$C$8,D8<>"No"),1,0)) -> 1 | G8: =IF(F8=1,INT((A8-Setup!$C$7)/7)+1,"") -> 1
A9: 46091 | B9: Camilla Nørgaard | C9: 1 | E9: D-2004 | F9: =IF(OR(A9="",B9="",C9=""),"",IF(AND(A9>=Setup!$C$7,A9<=Setup!$C$8,D9<>"No"),1,0)) -> 1 | G9: =IF(F9=1,INT((A9-Setup!$C$7)/7)+1,"") -> 2
A10: 46092 | B10: Anna Holm | C10: 1 | E10: D-2005 | F10: =IF(OR(A10="",B10="",C10=""),"",IF(AND(A10>=Setup!$C$7,A10<=Setup!$C$8,D10<>"No"),1,0)) -> 1 | G10: =IF(F10=1,INT((A10-Setup!$C$7)/7)+1,"") -> 2
A11: 46093 | B11: Emma Krogh | C11: 1 | E11: D-2006 | F11: =IF(OR(A11="",B11="",C11=""),"",IF(AND(A11>=Setup!$C$7,A11<=Setup!$C$8,D11<>"No"),1,0)) -> 1 | G11: =IF(F11=1,INT((A11-Setup!$C$7)/7)+1,"") -> 2
A12: 46094 | B12: Emma Krogh | C12: 1 | D12: No | E12: D-2007, cancelled within 14 days | F12: =IF(OR(A12="",B12="",C12=""),"",IF(AND(A12>=Setup!$C$7,A12<=Setup!$C$8,D12<>"No"),1,0)) -> 0 | G12: =IF(F12=1,INT((A12-Setup!$C$7)/7)+1,"")
A13: 46098 | B13: Anna Holm | C13: 1 | E13: D-2008 | F13: =IF(OR(A13="",B13="",C13=""),"",IF(AND(A13>=Setup!$C$7,A13<=Setup!$C$8,D13<>"No"),1,0)) -> 1 | G13: =IF(F13=1,INT((A13-Setup!$C$7)/7)+1,"") -> 3
A14: 46099 | B14: Bo Jensen | C14: 1 | E14: D-2009 | F14: =IF(OR(A14="",B14="",C14=""),"",IF(AND(A14>=Setup!$C$7,A14<=Setup!$C$8,D14<>"No"),1,0)) -> 1 | G14: =IF(F14=1,INT((A14-Setup!$C$7)/7)+1,"") -> 3
A15: 46100 | B15: David Lund | C15: 1 | E15: D-2010 | F15: =IF(OR(A15="",B15="",C15=""),"",IF(AND(A15>=Setup!$C$7,A15<=Setup!$C$8,D15<>"No"),1,0)) -> 1 | G15: =IF(F15=1,INT((A15-Setup!$C$7)/7)+1,"") -> 3
A16: 46101 | B16: Frederik Bach | C16: 1 | E16: D-2011 | F16: =IF(OR(A16="",B16="",C16=""),"",IF(AND(A16>=Setup!$C$7,A16<=Setup!$C$8,D16<>"No"),1,0)) -> 1 | G16: =IF(F16=1,INT((A16-Setup!$C$7)/7)+1,"") -> 3
A17: 46104 | B17: Gitte Sørensen | C17: 1 | E17: D-2012 | F17: =IF(OR(A17="",B17="",C17=""),"",IF(AND(A17>=Setup!$C$7,A17<=Setup!$C$8,D17<>"No"),1,0)) -> 1 | G17: =IF(F17=1,INT((A17-Setup!$C$7)/7)+1,"") -> 4
A18: 46105 | B18: Bo Jensen | C18: 1 | E18: D-2013 | F18: =IF(OR(A18="",B18="",C18=""),"",IF(AND(A18>=Setup!$C$7,A18<=Setup!$C$8,D18<>"No"),1,0)) -> 1 | G18: =IF(F18=1,INT((A18-Setup!$C$7)/7)+1,"") -> 4
A19: 46106 | B19: Camilla Nørgaard | C19: 1 | E19: D-2014 | F19: =IF(OR(A19="",B19="",C19=""),"",IF(AND(A19>=Setup!$C$7,A19<=Setup!$C$8,D19<>"No"),1,0)) -> 1 | G19: =IF(F19=1,INT((A19-Setup!$C$7)/7)+1,"") -> 4
A20: 46107 | B20: Anna Holm | C20: 1 | E20: D-2015 | F20: =IF(OR(A20="",B20="",C20=""),"",IF(AND(A20>=Setup!$C$7,A20<=Setup!$C$8,D20<>"No"),1,0)) -> 1 | G20: =IF(F20=1,INT((A20-Setup!$C$7)/7)+1,"") -> 4
A21: 46108 | B21: Hassan Ali | C21: 1 | E21: D-2016 | F21: =IF(OR(A21="",B21="",C21=""),"",IF(AND(A21>=Setup!$C$7,A21<=Setup!$C$8,D21<>"No"),1,0)) -> 1 | G21: =IF(F21=1,INT((A21-Setup!$C$7)/7)+1,"") -> 4
F22: =IF(OR(A22="",B22="",C22=""),"",IF(AND(A22>=Setup!$C$7,A22<=Setup!$C$8,D22<>"No"),1,0)) | G22: =IF(F22=1,INT((A22-Setup!$C$7)/7)+1,"")
F23: =IF(OR(A23="",B23="",C23=""),"",IF(AND(A23>=Setup!$C$7,A23<=Setup!$C$8,D23<>"No"),1,0)) | G23: =IF(F23=1,INT((A23-Setup!$C$7)/7)+1,"")
F24: =IF(OR(A24="",B24="",C24=""),"",IF(AND(A24>=Setup!$C$7,A24<=Setup!$C$8,D24<>"No"),1,0)) | G24: =IF(F24=1,INT((A24-Setup!$C$7)/7)+1,"")
F25: =IF(OR(A25="",B25="",C25=""),"",IF(AND(A25>=Setup!$C$7,A25<=Setup!$C$8,D25<>"No"),1,0)) | G25: =IF(F25=1,INT((A25-Setup!$C$7)/7)+1,"")
F26: =IF(OR(A26="",B26="",C26=""),"",IF(AND(A26>=Setup!$C$7,A26<=Setup!$C$8,D26<>"No"),1,0)) | G26: =IF(F26=1,INT((A26-Setup!$C$7)/7)+1,"")
F27: =IF(OR(A27="",B27="",C27=""),"",IF(AND(A27>=Setup!$C$7,A27<=Setup!$C$8,D27<>"No"),1,0)) | G27: =IF(F27=1,INT((A27-Setup!$C$7)/7)+1,"")
F28: =IF(OR(A28="",B28="",C28=""),"",IF(AND(A28>=Setup!$C$7,A28<=Setup!$C$8,D28<>"No"),1,0)) | G28: =IF(F28=1,INT((A28-Setup!$C$7)/7)+1,"")
F29: =IF(OR(A29="",B29="",C29=""),"",IF(AND(A29>=Setup!$C$7,A29<=Setup!$C$8,D29<>"No"),1,0)) | G29: =IF(F29=1,INT((A29-Setup!$C$7)/7)+1,"")
F30: =IF(OR(A30="",B30="",C30=""),"",IF(AND(A30>=Setup!$C$7,A30<=Setup!$C$8,D30<>"No"),1,0)) | G30: =IF(F30=1,INT((A30-Setup!$C$7)/7)+1,"")
F31: =IF(OR(A31="",B31="",C31=""),"",IF(AND(A31>=Setup!$C$7,A31<=Setup!$C$8,D31<>"No"),1,0)) | G31: =IF(F31=1,INT((A31-Setup!$C$7)/7)+1,"")
F32: =IF(OR(A32="",B32="",C32=""),"",IF(AND(A32>=Setup!$C$7,A32<=Setup!$C$8,D32<>"No"),1,0)) | G32: =IF(F32=1,INT((A32-Setup!$C$7)/7)+1,"")
F33: =IF(OR(A33="",B33="",C33=""),"",IF(AND(A33>=Setup!$C$7,A33<=Setup!$C$8,D33<>"No"),1,0)) | G33: =IF(F33=1,INT((A33-Setup!$C$7)/7)+1,"")
... F505: =IF(OR(A505="",B505="",C505=""),"",IF(AND(A505>=Setup!$C$7,A505<=Setup!$C$8,D505<>"No"),1,0)) | G505: =IF(F505=1,INT((A505-Setup!$C$7)/7)+1,"")

Sheet Leaderboard
B2: =Setup!$C$6 -> New customers in March
B3: ="Leaderboard · "&Setup!$C$9 -> Leaderboard · New customers (count)
B5: Period | D5: =Setup!$C$7 -> 46083 | E5: =Setup!$C$8 -> 46108 | H5: Cost on current standings | O5: ='Budget check'!$C$16 -> 48000
B6: Standings as of | D6: =Setup!$C$12 -> 46108 | H6: Budget | O6: =Setup!$C$28 -> 48000
B7: Days left | D7: =MAX(0,Setup!$C$8-Setup!$C$12) -> 0
B8: Team result / team target | D8: =Participants!$G$26 -> 15 | E8: =IF(N(Setup!$C$24)=0,"",Setup!$C$24) -> 14 | F8: =IF(N(Setup!$C$24)=0,"",D8/Setup!$C$24) -> 1.0714286 | H8: =IF(N(Setup!$C$24)=0,"",IF(D8>=Setup!$C$24,"Team target reached","Needs "&(Setup!$C$24-D8)&" more for the team target")) -> Team target reached
B10: Place | C10: Name | D10: Team | E10: Result | F10: % of target | G10: =IF(1>(INT((Setup!$C$8-Setup!$C$7)/7)+1),"","Wk 1") -> Wk 1 | H10: =IF(2>(INT((Setup!$C$8-Setup!$C$7)/7)+1),"","Wk 2") -> Wk 2 | I10: =IF(3>(INT((Setup!$C$8-Setup!$C$7)/7)+1),"","Wk 3") -> Wk 3 | J10: =IF(4>(INT((Setup!$C$8-Setup!$C$7)/7)+1),"","Wk 4") -> Wk 4 | K10: =IF(5>(INT((Setup!$C$8-Setup!$C$7)/7)+1),"","Wk 5") | L10: =IF(6>(INT((Setup!$C$8-Setup!$C$7)/7)+1),"","Wk 6") | M10: =IF(7>(INT((Setup!$C$8-Setup!$C$7)/7)+1),"","Wk 7") | N10: =IF(8>(INT((Setup!$C$8-Setup!$C$7)/7)+1),"","Wk 8") | O10: Prize | P10: Gap to place ahead | R10: Row
B11: =IF($R11=0,"",IF(INDEX(Participants!$J$6:$J$25,$R11)="","",INDEX(Participants!$J$6:$J$25,$R11))) -> 1 | C11: =IF($R11=0,"",IF(INDEX(Participants!$A$6:$A$25,$R11)="","",INDEX(Participants!$A$6:$A$25,$R11))) -> Anna Holm | D11: =IF($R11=0,"",IF(INDEX(Participants!$B$6:$B$25,$R11)="","",INDEX(Participants!$B$6:$B$25,$R11))) -> North | E11: =IF($R11=0,"",IF(INDEX(Participants!$G$6:$G$25,$R11)="","",INDEX(Participants!$G$6:$G$25,$R11))) -> 4 | F11: =IF($R11=0,"",IF(INDEX(Participants!$H$6:$H$25,$R11)="","",INDEX(Participants!$H$6:$H$25,$R11))) -> 2 | G11: =IF(1>(INT((Setup!$C$8-Setup!$C$7)/7)+1),"",IF($R11=0,"",INDEX(Participants!$Q$6:$Q$25,$R11))) -> 1 | H11: =IF(2>(INT((Setup!$C$8-Setup!$C$7)/7)+1),"",IF($R11=0,"",INDEX(Participants!$R$6:$R$25,$R11))) -> 1 | I11: =IF(3>(INT((Setup!$C$8-Setup!$C$7)/7)+1),"",IF($R11=0,"",INDEX(Participants!$S$6:$S$25,$R11))) -> 1 | J11: =IF(4>(INT((Setup!$C$8-Setup!$C$7)/7)+1),"",IF($R11=0,"",INDEX(Participants!$T$6:$T$25,$R11))) -> 1 | K11: =IF(5>(INT((Setup!$C$8-Setup!$C$7)/7)+1),"",IF($R11=0,"",INDEX(Participants!$U$6:$U$25,$R11))) | L11: =IF(6>(INT((Setup!$C$8-Setup!$C$7)/7)+1),"",IF($R11=0,"",INDEX(Participants!$V$6:$V$25,$R11))) | M11: =IF(7>(INT((Setup!$C$8-Setup!$C$7)/7)+1),"",IF($R11=0,"",INDEX(Participants!$W$6:$W$25,$R11))) | N11: =IF(8>(INT((Setup!$C$8-Setup!$C$7)/7)+1),"",IF($R11=0,"",INDEX(Participants!$X$6:$X$25,$R11))) | O11: =IF($R11=0,"",IF(INDEX(Participants!$P$6:$P$25,$R11)="","",INDEX(Participants!$P$6:$P$25,$R11))) -> 10000 | P11: =IF($R11=0,"",IF(INDEX(Participants!$Y$6:$Y$25,$R11)="","",INDEX(Participants!$Y$6:$Y$25,$R11))) | R11: =IFERROR(MATCH(1,Participants!$K$6:$K$25,0),0) -> 1
B12: =IF($R12=0,"",IF(INDEX(Participants!$J$6:$J$25,$R12)="","",INDEX(Participants!$J$6:$J$25,$R12))) -> 2 | C12: =IF($R12=0,"",IF(INDEX(Participants!$A$6:$A$25,$R12)="","",INDEX(Participants!$A$6:$A$25,$R12))) -> Bo Jensen | D12: =IF($R12=0,"",IF(INDEX(Participants!$B$6:$B$25,$R12)="","",INDEX(Participants!$B$6:$B$25,$R12))) -> North | E12: =IF($R12=0,"",IF(INDEX(Participants!$G$6:$G$25,$R12)="","",INDEX(Participants!$G$6:$G$25,$R12))) -> 3 | F12: =IF($R12=0,"",IF(INDEX(Participants!$H$6:$H$25,$R12)="","",INDEX(Participants!$H$6:$H$25,$R12))) -> 1.5 | G12: =IF(1>(INT((Setup!$C$8-Setup!$C$7)/7)+1),"",IF($R12=0,"",INDEX(Participants!$Q$6:$Q$25,$R12))) -> 1 | H12: =IF(2>(INT((Setup!$C$8-Setup!$C$7)/7)+1),"",IF($R12=0,"",INDEX(Participants!$R$6:$R$25,$R12))) -> 0 | I12: =IF(3>(INT((Setup!$C$8-Setup!$C$7)/7)+1),"",IF($R12=0,"",INDEX(Participants!$S$6:$S$25,$R12))) -> 1 | J12: =IF(4>(INT((Setup!$C$8-Setup!$C$7)/7)+1),"",IF($R12=0,"",INDEX(Participants!$T$6:$T$25,$R12))) -> 1 | K12: =IF(5>(INT((Setup!$C$8-Setup!$C$7)/7)+1),"",IF($R12=0,"",INDEX(Participants!$U$6:$U$25,$R12))) | L12: =IF(6>(INT((Setup!$C$8-Setup!$C$7)/7)+1),"",IF($R12=0,"",INDEX(Participants!$V$6:$V$25,$R12))) | M12: =IF(7>(INT((Setup!$C$8-Setup!$C$7)/7)+1),"",IF($R12=0,"",INDEX(Participants!$W$6:$W$25,$R12))) | N12: =IF(8>(INT((Setup!$C$8-Setup!$C$7)/7)+1),"",IF($R12=0,"",INDEX(Participants!$X$6:$X$25,$R12))) | O12: =IF($R12=0,"",IF(INDEX(Participants!$P$6:$P$25,$R12)="","",INDEX(Participants!$P$6:$P$25,$R12))) -> 10000 | P12: =IF($R12=0,"",IF(INDEX(Participants!$Y$6:$Y$25,$R12)="","",INDEX(Participants!$Y$6:$Y$25,$R12))) -> 1 | R12: =IFERROR(MATCH(2,Participants!$K$6:$K$25,0),0) -> 2
B13: =IF($R13=0,"",IF(INDEX(Participants!$J$6:$J$25,$R13)="","",INDEX(Participants!$J$6:$J$25,$R13))) -> 3 | C13: =IF($R13=0,"",IF(INDEX(Participants!$A$6:$A$25,$R13)="","",INDEX(Participants!$A$6:$A$25,$R13))) -> Camilla Nørgaard | D13: =IF($R13=0,"",IF(INDEX(Participants!$B$6:$B$25,$R13)="","",INDEX(Participants!$B$6:$B$25,$R13))) -> South | E13: =IF($R13=0,"",IF(INDEX(Participants!$G$6:$G$25,$R13)="","",INDEX(Participants!$G$6:$G$25,$R13))) -> 2 | F13: =IF($R13=0,"",IF(INDEX(Participants!$H$6:$H$25,$R13)="","",INDEX(Participants!$H$6:$H$25,$R13))) -> 1 | G13: =IF(1>(INT((Setup!$C$8-Setup!$C$7)/7)+1),"",IF($R13=0,"",INDEX(Participants!$Q$6:$Q$25,$R13))) -> 0 | H13: =IF(2>(INT((Setup!$C$8-Setup!$C$7)/7)+1),"",IF($R13=0,"",INDEX(Participants!$R$6:$R$25,$R13))) -> 1 | I13: =IF(3>(INT((Setup!$C$8-Setup!$C$7)/7)+1),"",IF($R13=0,"",INDEX(Participants!$S$6:$S$25,$R13))) -> 0 | J13: =IF(4>(INT((Setup!$C$8-Setup!$C$7)/7)+1),"",IF($R13=0,"",INDEX(Participants!$T$6:$T$25,$R13))) -> 1 | K13: =IF(5>(INT((Setup!$C$8-Setup!$C$7)/7)+1),"",IF($R13=0,"",INDEX(Participants!$U$6:$U$25,$R13))) | L13: =IF(6>(INT((Setup!$C$8-Setup!$C$7)/7)+1),"",IF($R13=0,"",INDEX(Participants!$V$6:$V$25,$R13))) | M13: =IF(7>(INT((Setup!$C$8-Setup!$C$7)/7)+1),"",IF($R13=0,"",INDEX(Participants!$W$6:$W$25,$R13))) | N13: =IF(8>(INT((Setup!$C$8-Setup!$C$7)/7)+1),"",IF($R13=0,"",INDEX(Participants!$X$6:$X$25,$R13))) | O13: =IF($R13=0,"",IF(INDEX(Participants!$P$6:$P$25,$R13)="","",INDEX(Participants!$P$6:$P$25,$R13))) -> 6000 | P13: =IF($R13=0,"",IF(INDEX(Participants!$Y$6:$Y$25,$R13)="","",INDEX(Participants!$Y$6:$Y$25,$R13))) -> 1 | R13: =IFERROR(MATCH(3,Participants!$K$6:$K$25,0),0) -> 3
B14: =IF($R14=0,"",IF(INDEX(Participants!$J$6:$J$25,$R14)="","",INDEX(Participants!$J$6:$J$25,$R14))) -> 3 | C14: =IF($R14=0,"",IF(INDEX(Participants!$A$6:$A$25,$R14)="","",INDEX(Participants!$A$6:$A$25,$R14))) -> David Lund | D14: =IF($R14=0,"",IF(INDEX(Participants!$B$6:$B$25,$R14)="","",INDEX(Participants!$B$6:$B$25,$R14))) -> South | E14: =IF($R14=0,"",IF(INDEX(Participants!$G$6:$G$25,$R14)="","",INDEX(Participants!$G$6:$G$25,$R14))) -> 2 | F14: =IF($R14=0,"",IF(INDEX(Participants!$H$6:$H$25,$R14)="","",INDEX(Participants!$H$6:$H$25,$R14))) -> 1 | G14: =IF(1>(INT((Setup!$C$8-Setup!$C$7)/7)+1),"",IF($R14=0,"",INDEX(Participants!$Q$6:$Q$25,$R14))) -> 1 | H14: =IF(2>(INT((Setup!$C$8-Setup!$C$7)/7)+1),"",IF($R14=0,"",INDEX(Participants!$R$6:$R$25,$R14))) -> 0 | I14: =IF(3>(INT((Setup!$C$8-Setup!$C$7)/7)+1),"",IF($R14=0,"",INDEX(Participants!$S$6:$S$25,$R14))) -> 1 | J14: =IF(4>(INT((Setup!$C$8-Setup!$C$7)/7)+1),"",IF($R14=0,"",INDEX(Participants!$T$6:$T$25,$R14))) -> 0 | K14: =IF(5>(INT((Setup!$C$8-Setup!$C$7)/7)+1),"",IF($R14=0,"",INDEX(Participants!$U$6:$U$25,$R14))) | L14: =IF(6>(INT((Setup!$C$8-Setup!$C$7)/7)+1),"",IF($R14=0,"",INDEX(Participants!$V$6:$V$25,$R14))) | M14: =IF(7>(INT((Setup!$C$8-Setup!$C$7)/7)+1),"",IF($R14=0,"",INDEX(Participants!$W$6:$W$25,$R14))) | N14: =IF(8>(INT((Setup!$C$8-Setup!$C$7)/7)+1),"",IF($R14=0,"",INDEX(Participants!$X$6:$X$25,$R14))) | O14: =IF($R14=0,"",IF(INDEX(Participants!$P$6:$P$25,$R14)="","",INDEX(Participants!$P$6:$P$25,$R14))) -> 6000 | P14: =IF($R14=0,"",IF(INDEX(Participants!$Y$6:$Y$25,$R14)="","",INDEX(Participants!$Y$6:$Y$25,$R14))) -> 1 | R14: =IFERROR(MATCH(4,Participants!$K$6:$K$25,0),0) -> 4
B15: =IF($R15=0,"",IF(INDEX(Participants!$J$6:$J$25,$R15)="","",INDEX(Participants!$J$6:$J$25,$R15))) -> 5 | C15: =IF($R15=0,"",IF(INDEX(Participants!$A$6:$A$25,$R15)="","",INDEX(Participants!$A$6:$A$25,$R15))) -> Emma Krogh | D15: =IF($R15=0,"",IF(INDEX(Participants!$B$6:$B$25,$R15)="","",INDEX(Participants!$B$6:$B$25,$R15))) -> North | E15: =IF($R15=0,"",IF(INDEX(Participants!$G$6:$G$25,$R15)="","",INDEX(Participants!$G$6:$G$25,$R15))) -> 1 | F15: =IF($R15=0,"",IF(INDEX(Participants!$H$6:$H$25,$R15)="","",INDEX(Participants!$H$6:$H$25,$R15))) -> 0.5 | G15: =IF(1>(INT((Setup!$C$8-Setup!$C$7)/7)+1),"",IF($R15=0,"",INDEX(Participants!$Q$6:$Q$25,$R15))) -> 0 | H15: =IF(2>(INT((Setup!$C$8-Setup!$C$7)/7)+1),"",IF($R15=0,"",INDEX(Participants!$R$6:$R$25,$R15))) -> 1 | I15: =IF(3>(INT((Setup!$C$8-Setup!$C$7)/7)+1),"",IF($R15=0,"",INDEX(Participants!$S$6:$S$25,$R15))) -> 0 | J15: =IF(4>(INT((Setup!$C$8-Setup!$C$7)/7)+1),"",IF($R15=0,"",INDEX(Participants!$T$6:$T$25,$R15))) -> 0 | K15: =IF(5>(INT((Setup!$C$8-Setup!$C$7)/7)+1),"",IF($R15=0,"",INDEX(Participants!$U$6:$U$25,$R15))) | L15: =IF(6>(INT((Setup!$C$8-Setup!$C$7)/7)+1),"",IF($R15=0,"",INDEX(Participants!$V$6:$V$25,$R15))) | M15: =IF(7>(INT((Setup!$C$8-Setup!$C$7)/7)+1),"",IF($R15=0,"",INDEX(Participants!$W$6:$W$25,$R15))) | N15: =IF(8>(INT((Setup!$C$8-Setup!$C$7)/7)+1),"",IF($R15=0,"",INDEX(Participants!$X$6:$X$25,$R15))) | O15: =IF($R15=0,"",IF(INDEX(Participants!$P$6:$P$25,$R15)="","",INDEX(Participants!$P$6:$P$25,$R15))) -> 2000 | P15: =IF($R15=0,"",IF(INDEX(Participants!$Y$6:$Y$25,$R15)="","",INDEX(Participants!$Y$6:$Y$25,$R15))) -> 1 | R15: =IFERROR(MATCH(5,Participants!$K$6:$K$25,0),0) -> 5
B16: =IF($R16=0,"",IF(INDEX(Participants!$J$6:$J$25,$R16)="","",INDEX(Participants!$J$6:$J$25,$R16))) -> 5 | C16: =IF($R16=0,"",IF(INDEX(Participants!$A$6:$A$25,$R16)="","",INDEX(Participants!$A$6:$A$25,$R16))) -> Frederik Bach | D16: =IF($R16=0,"",IF(INDEX(Participants!$B$6:$B$25,$R16)="","",INDEX(Participants!$B$6:$B$25,$R16))) -> South | E16: =IF($R16=0,"",IF(INDEX(Participants!$G$6:$G$25,$R16)="","",INDEX(Participants!$G$6:$G$25,$R16))) -> 1 | F16: =IF($R16=0,"",IF(INDEX(Participants!$H$6:$H$25,$R16)="","",INDEX(Participants!$H$6:$H$25,$R16))) -> 0.5 | G16: =IF(1>(INT((Setup!$C$8-Setup!$C$7)/7)+1),"",IF($R16=0,"",INDEX(Participants!$Q$6:$Q$25,$R16))) -> 0 | H16: =IF(2>(INT((Setup!$C$8-Setup!$C$7)/7)+1),"",IF($R16=0,"",INDEX(Participants!$R$6:$R$25,$R16))) -> 0 | I16: =IF(3>(INT((Setup!$C$8-Setup!$C$7)/7)+1),"",IF($R16=0,"",INDEX(Participants!$S$6:$S$25,$R16))) -> 1 | J16: =IF(4>(INT((Setup!$C$8-Setup!$C$7)/7)+1),"",IF($R16=0,"",INDEX(Participants!$T$6:$T$25,$R16))) -> 0 | K16: =IF(5>(INT((Setup!$C$8-Setup!$C$7)/7)+1),"",IF($R16=0,"",INDEX(Participants!$U$6:$U$25,$R16))) | L16: =IF(6>(INT((Setup!$C$8-Setup!$C$7)/7)+1),"",IF($R16=0,"",INDEX(Participants!$V$6:$V$25,$R16))) | M16: =IF(7>(INT((Setup!$C$8-Setup!$C$7)/7)+1),"",IF($R16=0,"",INDEX(Participants!$W$6:$W$25,$R16))) | N16: =IF(8>(INT((Setup!$C$8-Setup!$C$7)/7)+1),"",IF($R16=0,"",INDEX(Participants!$X$6:$X$25,$R16))) | O16: =IF($R16=0,"",IF(INDEX(Participants!$P$6:$P$25,$R16)="","",INDEX(Participants!$P$6:$P$25,$R16))) -> 2000 | P16: =IF($R16=0,"",IF(INDEX(Participants!$Y$6:$Y$25,$R16)="","",INDEX(Participants!$Y$6:$Y$25,$R16))) -> 1 | R16: =IFERROR(MATCH(6,Participants!$K$6:$K$25,0),0) -> 6
B17: =IF($R17=0,"",IF(INDEX(Participants!$J$6:$J$25,$R17)="","",INDEX(Participants!$J$6:$J$25,$R17))) -> 5 | C17: =IF($R17=0,"",IF(INDEX(Participants!$A$6:$A$25,$R17)="","",INDEX(Participants!$A$6:$A$25,$R17))) -> Gitte Sørensen | D17: =IF($R17=0,"",IF(INDEX(Participants!$B$6:$B$25,$R17)="","",INDEX(Participants!$B$6:$B$25,$R17))) -> North | E17: =IF($R17=0,"",IF(INDEX(Participants!$G$6:$G$25,$R17)="","",INDEX(Participants!$G$6:$G$25,$R17))) -> 1 | F17: =IF($R17=0,"",IF(INDEX(Participants!$H$6:$H$25,$R17)="","",INDEX(Participants!$H$6:$H$25,$R17))) -> 0.5 | G17: =IF(1>(INT((Setup!$C$8-Setup!$C$7)/7)+1),"",IF($R17=0,"",INDEX(Participants!$Q$6:$Q$25,$R17))) -> 0 | H17: =IF(2>(INT((Setup!$C$8-Setup!$C$7)/7)+1),"",IF($R17=0,"",INDEX(Participants!$R$6:$R$25,$R17))) -> 0 | I17: =IF(3>(INT((Setup!$C$8-Setup!$C$7)/7)+1),"",IF($R17=0,"",INDEX(Participants!$S$6:$S$25,$R17))) -> 0 | J17: =IF(4>(INT((Setup!$C$8-Setup!$C$7)/7)+1),"",IF($R17=0,"",INDEX(Participants!$T$6:$T$25,$R17))) -> 1 | K17: =IF(5>(INT((Setup!$C$8-Setup!$C$7)/7)+1),"",IF($R17=0,"",INDEX(Participants!$U$6:$U$25,$R17))) | L17: =IF(6>(INT((Setup!$C$8-Setup!$C$7)/7)+1),"",IF($R17=0,"",INDEX(Participants!$V$6:$V$25,$R17))) | M17: =IF(7>(INT((Setup!$C$8-Setup!$C$7)/7)+1),"",IF($R17=0,"",INDEX(Participants!$W$6:$W$25,$R17))) | N17: =IF(8>(INT((Setup!$C$8-Setup!$C$7)/7)+1),"",IF($R17=0,"",INDEX(Participants!$X$6:$X$25,$R17))) | O17: =IF($R17=0,"",IF(INDEX(Participants!$P$6:$P$25,$R17)="","",INDEX(Participants!$P$6:$P$25,$R17))) -> 2000 | P17: =IF($R17=0,"",IF(INDEX(Participants!$Y$6:$Y$25,$R17)="","",INDEX(Participants!$Y$6:$Y$25,$R17))) -> 1 | R17: =IFERROR(MATCH(7,Participants!$K$6:$K$25,0),0) -> 7
B18: =IF($R18=0,"",IF(INDEX(Participants!$J$6:$J$25,$R18)="","",INDEX(Participants!$J$6:$J$25,$R18))) -> 5 | C18: =IF($R18=0,"",IF(INDEX(Participants!$A$6:$A$25,$R18)="","",INDEX(Participants!$A$6:$A$25,$R18))) -> Hassan Ali | D18: =IF($R18=0,"",IF(INDEX(Participants!$B$6:$B$25,$R18)="","",INDEX(Participants!$B$6:$B$25,$R18))) -> South | E18: =IF($R18=0,"",IF(INDEX(Participants!$G$6:$G$25,$R18)="","",INDEX(Participants!$G$6:$G$25,$R18))) -> 1 | F18: =IF($R18=0,"",IF(INDEX(Participants!$H$6:$H$25,$R18)="","",INDEX(Participants!$H$6:$H$25,$R18))) -> 0.5 | G18: =IF(1>(INT((Setup!$C$8-Setup!$C$7)/7)+1),"",IF($R18=0,"",INDEX(Participants!$Q$6:$Q$25,$R18))) -> 0 | H18: =IF(2>(INT((Setup!$C$8-Setup!$C$7)/7)+1),"",IF($R18=0,"",INDEX(Participants!$R$6:$R$25,$R18))) -> 0 | I18: =IF(3>(INT((Setup!$C$8-Setup!$C$7)/7)+1),"",IF($R18=0,"",INDEX(Participants!$S$6:$S$25,$R18))) -> 0 | J18: =IF(4>(INT((Setup!$C$8-Setup!$C$7)/7)+1),"",IF($R18=0,"",INDEX(Participants!$T$6:$T$25,$R18))) -> 1 | K18: =IF(5>(INT((Setup!$C$8-Setup!$C$7)/7)+1),"",IF($R18=0,"",INDEX(Participants!$U$6:$U$25,$R18))) | L18: =IF(6>(INT((Setup!$C$8-Setup!$C$7)/7)+1),"",IF($R18=0,"",INDEX(Participants!$V$6:$V$25,$R18))) | M18: =IF(7>(INT((Setup!$C$8-Setup!$C$7)/7)+1),"",IF($R18=0,"",INDEX(Participants!$W$6:$W$25,$R18))) | N18: =IF(8>(INT((Setup!$C$8-Setup!$C$7)/7)+1),"",IF($R18=0,"",INDEX(Participants!$X$6:$X$25,$R18))) | O18: =IF($R18=0,"",IF(INDEX(Participants!$P$6:$P$25,$R18)="","",INDEX(Participants!$P$6:$P$25,$R18))) -> 2000 | P18: =IF($R18=0,"",IF(INDEX(Participants!$Y$6:$Y$25,$R18)="","",INDEX(Participants!$Y$6:$Y$25,$R18))) -> 1 | R18: =IFERROR(MATCH(8,Participants!$K$6:$K$25,0),0) -> 8
