Workbook

Sheet Instructions
C2: Free template from Prowi
B4: Sales budget
B5: From revenue goal to reps, quotas and commission cost
B7: The workbook works backwards from your revenue goal: how much pipeline and how many deals you need, how many reps you need, how quotas are split per rep and month, and what sales pay costs at 80, 100 and 120% attainment. It contains example data for 10 reps, so you can see how it works. Amounts are plain numbers in your currency; the example uses DKK.
B9: Step by step
B10: 1. Assumptions | C10: Enter revenue goal, deal size, win rate, sales cycle, quota, ramp period, rep attrition, pay and seasonality. These are the only numbers the workbook uses, apart from the rep list.
B11: 2. Capacity | C11: Shows the pipeline, deals and opportunities you need, and how many reps you need once ramp and attrition are included. You do not type anything here.
B12: 3. Quota allocation | C12: Enter the reps (up to 20) with start month and whether they are new. The sheet spreads the annual quota over the months by seasonality and reduces it during ramp.
B13: 4. OTE and commission | C13: Shows OTE, pay mix and commission rate (variable pay ÷ quota), and commission per rep at 80, 100 and 120% attainment. The attainment levels can be changed.
B14: 5. Summary | C14: Brings the budget together: reps, quota, pipeline, sales pay cost and cost as a % of revenue (cost of sales) for the three scenarios and per month.
B16: Colours
B17: Lavender cell, purple text | C17: This is where you type. Everything else is formulas.
B18: Grey cell | C18: Calculated automatically. Leave the formulas alone unless you know what you are changing.
B19: Light blue cell | C19: Results and totals.
B21: How the workbook calculates
B22: Deals and pipeline | C22: Deals = revenue goal ÷ deal size. Opportunities = deals ÷ win rate. Pipeline needed = revenue goal ÷ win rate, and pipeline coverage = pipeline ÷ goal.
B23: Capacity per rep | C23: Annual quota × planned attainment. Fully productive reps (FTE) = revenue goal ÷ capacity per rep.
B24: Ramp and attrition | C24: A new rep loses ramp months × (1 − ramp productivity) ÷ 12 of a year's capacity. A rep who leaves costs the hiring time plus a new ramp. Reps needed = (FTE − reps at start × loss per new rep) ÷ (1 − attrition × loss per leaver − loss per new rep). New reps are assumed to start at the beginning of the year.
B25: Quota per month | C25: Annual quota × the month's share of the seasonality. Before the start month the quota is 0, and during ramp it is multiplied by ramp productivity. Attrition is not in the quota plan, because you do not know who will leave.
B26: Commission rate | C26: Variable pay at 100% ÷ the rep's annual quota. Above 100% the rate is multiplied by the accelerator factor. Set the factor to 1 if you do not use an accelerator.
B27: Cost of sales | C27: Base salary + commission + other pay costs ÷ revenue in the scenario. Revenue = total quota × attainment.
B28: Pipeline per month | C28: Pipeline to create in a month = the quota one sales cycle later ÷ win rate. For the last months, this year's seasonality is used as an estimate for next year.
B30: Good to know
B31: • | C31: All numbers in the workbook are examples. Use your own numbers from your CRM and accounts, for example win rate and deal size for the last 12 months.
B32: • | C32: The budget is a model, not a guarantee. Use it to test what happens if the win rate drops or a hire is delayed.
B33: • | C33: Pay excludes holiday pay, pension and other costs unless you include them in 'Other pay costs'.
B34: • | C34: No macros. Every calculation is an ordinary formula that works in Excel, Google Sheets, Numbers and LibreOffice.
B37: prowi.io · Free template from Prowi

Sheet Assumptions
B2: Assumptions
B3: Only type in the lavender cells. Every other sheet calculates from the numbers here and the rep list in Quota allocation.
B5: Goal and sales process
B6: Year | C6: 2026 | E6: The budget year.
B7: Revenue goal, new business | C7: 24000000 | E7: The revenue the reps must close in the year.
B8: Average deal size | C8: 150000 | E8: Average value of a won deal. Use your own numbers from the CRM.
B9: Win rate | C9: 0.25 | E9: Share of qualified opportunities that are won.
B10: Sales cycle (months) | C10: 3 | E10: Time from qualified opportunity to signature.
B12: Reps
B13: Reps at the start of the year | C13: 7 | E13: Fully ramped reps employed on 1 January.
B14: Annual quota per fully productive rep | C14: 3000000 | E14: Default quota. Can be changed per rep in Quota allocation.
B15: Planned average attainment | C15: 0.9 | E15: The attainment you budget with. Rarely 100% for the whole team.
B16: Ramp period (months) | C16: 4 | E16: Months before a new rep is fully productive.
B17: Productivity during ramp | C17: 0.5 | E17: Average share of full quota during ramp.
B18: Annual rep attrition | C18: 0.15 | E18: Share of reps expected to leave during the year.
B19: Hiring time after a leaver (months) | C19: 2 | E19: Months a position is empty before a new rep starts.
B21: Pay and commission (standard plan)
B22: Base salary per month | C22: 42000 | E22: Fixed pay per rep.
B23: Variable pay at 100%, per year | C23: 216000 | E23: Commission at exactly 100% of annual quota.
B24: Accelerator above 100% (factor) | C24: 1.5 | E24: Rate above quota = commission rate × factor. Enter 1 if you do not use an accelerator.
B25: Other pay costs (% of pay) | C25: 0.1 | E25: Example. For instance pension, ATP, insurance and holiday pay. Use your own numbers.
B27: Seasonality | E27: Weight per month. The weights do not need to add up to 100; the sheet works out the shares.
B28: Month | C28: Weight | D28: Share
B29: January | C29: 7 | D29: =IF(SUM($C$29:$C$40)=0,1/12,C29/SUM($C$29:$C$40)) -> 0.07
B30: February | C30: 8 | D30: =IF(SUM($C$29:$C$40)=0,1/12,C30/SUM($C$29:$C$40)) -> 0.08
B31: March | C31: 9 | D31: =IF(SUM($C$29:$C$40)=0,1/12,C31/SUM($C$29:$C$40)) -> 0.09
B32: April | C32: 8 | D32: =IF(SUM($C$29:$C$40)=0,1/12,C32/SUM($C$29:$C$40)) -> 0.08
B33: May | C33: 9 | D33: =IF(SUM($C$29:$C$40)=0,1/12,C33/SUM($C$29:$C$40)) -> 0.09 | E33: Example: lower in July (summer holiday) and higher in the last months of the year.
B34: June | C34: 9 | D34: =IF(SUM($C$29:$C$40)=0,1/12,C34/SUM($C$29:$C$40)) -> 0.09
B35: July | C35: 4 | D35: =IF(SUM($C$29:$C$40)=0,1/12,C35/SUM($C$29:$C$40)) -> 0.04
B36: August | C36: 7 | D36: =IF(SUM($C$29:$C$40)=0,1/12,C36/SUM($C$29:$C$40)) -> 0.07
B37: September | C37: 9 | D37: =IF(SUM($C$29:$C$40)=0,1/12,C37/SUM($C$29:$C$40)) -> 0.09
B38: October | C38: 9 | D38: =IF(SUM($C$29:$C$40)=0,1/12,C38/SUM($C$29:$C$40)) -> 0.09
B39: November | C39: 10 | D39: =IF(SUM($C$29:$C$40)=0,1/12,C39/SUM($C$29:$C$40)) -> 0.1
B40: December | C40: 11 | D40: =IF(SUM($C$29:$C$40)=0,1/12,C40/SUM($C$29:$C$40)) -> 0.11
B41: Total | C41: =SUM(C29:C40) -> 100 | D41: =SUM(D29:D40) -> 1

Sheet Capacity
B2: Capacity: pipeline and number of reps
B3: Everything on this sheet is formulas. Change the assumptions in Assumptions.
B4: Pipeline and activity
B5: Revenue goal | C5: =Assumptions!$C$7 -> 24000000 | E5: From Assumptions.
B6: Deals to win | C6: =IFERROR(C5/Assumptions!$C$8,0) -> 160 | E6: Revenue goal ÷ average deal size.
B7: Qualified opportunities in the year | C7: =IFERROR(C6/Assumptions!$C$9,0) -> 640 | E7: Deals ÷ win rate.
B8: Pipeline needed | C8: =IFERROR(C5/Assumptions!$C$9,0) -> 96000000 | E8: Revenue goal ÷ win rate.
B9: Pipeline coverage | C9: =IFERROR(C8/C5,0) -> 4 | E9: Pipeline ÷ revenue goal. Equals 1 ÷ win rate.
B10: Opportunities per month (average) | C10: =C7/12 -> 53.333333 | E10: See the split per month in Summary.
B11: Pipeline is created about this many months before close | C11: =Assumptions!$C$10 -> 3 | E11: The sales cycle from Assumptions.
B13: Rep capacity
B14: Capacity per fully productive rep | C14: =Assumptions!$C$14*Assumptions!$C$15 -> 2700000 | E14: Annual quota × planned attainment.
B15: Fully productive reps (FTE) needed | C15: =IFERROR(C5/C14,0) -> 8.8888889 | E15: Revenue goal ÷ capacity per rep.
B16: Loss per new rep (share of a year's capacity) | C16: =Assumptions!$C$16*(1-Assumptions!$C$17)/12 -> 0.16666667 | E16: Ramp months × (1 − ramp productivity) ÷ 12.
B17: Loss per rep who leaves (share of a year) | C17: =(Assumptions!$C$19+Assumptions!$C$16*(1-Assumptions!$C$17))/12 -> 0.33333333 | E17: (Hiring time + ramp loss in months) ÷ 12.
B18: Reps needed (calculated) | C18: =IFERROR(IF((C15-Assumptions!$C$13*C16)/(1-Assumptions!$C$18*C17-C16)>Assumptions!$C$13,(C15-Assumptions!$C$13*C16)/(1-Assumptions!$C$18*C17-C16),C15/(1-Assumptions!$C$18*C17)),0) -> 9.858156 | E18: Including losses from ramp and attrition. New reps are assumed to start at the beginning of the year.
B19: Reps needed (rounded up) | C19: =ROUNDUP(C18,0) -> 10 | E19: The number of positions the budget needs on average over the year.
B20: Reps at the start of the year | C20: =Assumptions!$C$13 -> 7 | E20: From Assumptions.
B21: New reps for growth | C21: =MAX(0,C19-C20) -> 3 | E21: Should start early in the year.
B22: Expected leavers in the year | C22: =C19*Assumptions!$C$18 -> 1.5 | E22: Number of reps × annual attrition. Each leaver needs a replacement hire.
B23: Total hires in the year | C23: =C21+C22 -> 4.5 | E23: New reps + replacement hires.
B25: Comparison with the quota plan
B26: Reps in Quota allocation | C26: =COUNTA('Quota allocation'!$B$7:$B$26) -> 10 | E26: Number of names on the rep list.
B27: Difference: reps in plan − reps needed | C27: =C26-C19 -> 0 | E27: Negative number: the plan has too few reps.

Sheet Quota allocation
B2: Quota allocation per rep and month
B3: Enter the reps in the lavender columns B-E. Quota is spread by seasonality and reduced during ramp for new reps.
B4: Individual annual quota is optional. Empty = the default quota from Assumptions. Start month 1 = January.
B6: Rep | C6: Start month (1-12) | D6: New rep with ramp? | E6: Individual annual quota (optional) | F6: Annual quota, applied | G6: Jan | H6: Feb | I6: Mar | J6: Apr | K6: May | L6: Jun | M6: Jul | N6: Aug | O6: Sep | P6: Oct | Q6: Nov | R6: Dec | S6: Quota for the year
B7: Anna Holm | C7: 1 | D7: No | F7: =IF($B7="","",IF(N($E7)>0,$E7,Assumptions!$C$14)) -> 3000000 | G7: =IF($B7="","",$F7*INDEX(Assumptions!$D$29:$D$40,1)*IF(1<IF(N($C7)<1,1,$C7),0,IF(AND($D7="Yes",1<IF(N($C7)<1,1,$C7)+Assumptions!$C$16),Assumptions!$C$17,1))) -> 210000 | H7: =IF($B7="","",$F7*INDEX(Assumptions!$D$29:$D$40,2)*IF(2<IF(N($C7)<1,1,$C7),0,IF(AND($D7="Yes",2<IF(N($C7)<1,1,$C7)+Assumptions!$C$16),Assumptions!$C$17,1))) -> 240000 | I7: =IF($B7="","",$F7*INDEX(Assumptions!$D$29:$D$40,3)*IF(3<IF(N($C7)<1,1,$C7),0,IF(AND($D7="Yes",3<IF(N($C7)<1,1,$C7)+Assumptions!$C$16),Assumptions!$C$17,1))) -> 270000 | J7: =IF($B7="","",$F7*INDEX(Assumptions!$D$29:$D$40,4)*IF(4<IF(N($C7)<1,1,$C7),0,IF(AND($D7="Yes",4<IF(N($C7)<1,1,$C7)+Assumptions!$C$16),Assumptions!$C$17,1))) -> 240000 | K7: =IF($B7="","",$F7*INDEX(Assumptions!$D$29:$D$40,5)*IF(5<IF(N($C7)<1,1,$C7),0,IF(AND($D7="Yes",5<IF(N($C7)<1,1,$C7)+Assumptions!$C$16),Assumptions!$C$17,1))) -> 270000 | L7: =IF($B7="","",$F7*INDEX(Assumptions!$D$29:$D$40,6)*IF(6<IF(N($C7)<1,1,$C7),0,IF(AND($D7="Yes",6<IF(N($C7)<1,1,$C7)+Assumptions!$C$16),Assumptions!$C$17,1))) -> 270000 | M7: =IF($B7="","",$F7*INDEX(Assumptions!$D$29:$D$40,7)*IF(7<IF(N($C7)<1,1,$C7),0,IF(AND($D7="Yes",7<IF(N($C7)<1,1,$C7)+Assumptions!$C$16),Assumptions!$C$17,1))) -> 120000 | N7: =IF($B7="","",$F7*INDEX(Assumptions!$D$29:$D$40,8)*IF(8<IF(N($C7)<1,1,$C7),0,IF(AND($D7="Yes",8<IF(N($C7)<1,1,$C7)+Assumptions!$C$16),Assumptions!$C$17,1))) -> 210000 | O7: =IF($B7="","",$F7*INDEX(Assumptions!$D$29:$D$40,9)*IF(9<IF(N($C7)<1,1,$C7),0,IF(AND($D7="Yes",9<IF(N($C7)<1,1,$C7)+Assumptions!$C$16),Assumptions!$C$17,1))) -> 270000 | P7: =IF($B7="","",$F7*INDEX(Assumptions!$D$29:$D$40,10)*IF(10<IF(N($C7)<1,1,$C7),0,IF(AND($D7="Yes",10<IF(N($C7)<1,1,$C7)+Assumptions!$C$16),Assumptions!$C$17,1))) -> 270000 | Q7: =IF($B7="","",$F7*INDEX(Assumptions!$D$29:$D$40,11)*IF(11<IF(N($C7)<1,1,$C7),0,IF(AND($D7="Yes",11<IF(N($C7)<1,1,$C7)+Assumptions!$C$16),Assumptions!$C$17,1))) -> 300000 | R7: =IF($B7="","",$F7*INDEX(Assumptions!$D$29:$D$40,12)*IF(12<IF(N($C7)<1,1,$C7),0,IF(AND($D7="Yes",12<IF(N($C7)<1,1,$C7)+Assumptions!$C$16),Assumptions!$C$17,1))) -> 330000 | S7: =IF($B7="","",SUM(G7:R7)) -> 3000000
B8: Bo Jensen | C8: 1 | D8: No | F8: =IF($B8="","",IF(N($E8)>0,$E8,Assumptions!$C$14)) -> 3000000 | G8: =IF($B8="","",$F8*INDEX(Assumptions!$D$29:$D$40,1)*IF(1<IF(N($C8)<1,1,$C8),0,IF(AND($D8="Yes",1<IF(N($C8)<1,1,$C8)+Assumptions!$C$16),Assumptions!$C$17,1))) -> 210000 | H8: =IF($B8="","",$F8*INDEX(Assumptions!$D$29:$D$40,2)*IF(2<IF(N($C8)<1,1,$C8),0,IF(AND($D8="Yes",2<IF(N($C8)<1,1,$C8)+Assumptions!$C$16),Assumptions!$C$17,1))) -> 240000 | I8: =IF($B8="","",$F8*INDEX(Assumptions!$D$29:$D$40,3)*IF(3<IF(N($C8)<1,1,$C8),0,IF(AND($D8="Yes",3<IF(N($C8)<1,1,$C8)+Assumptions!$C$16),Assumptions!$C$17,1))) -> 270000 | J8: =IF($B8="","",$F8*INDEX(Assumptions!$D$29:$D$40,4)*IF(4<IF(N($C8)<1,1,$C8),0,IF(AND($D8="Yes",4<IF(N($C8)<1,1,$C8)+Assumptions!$C$16),Assumptions!$C$17,1))) -> 240000 | K8: =IF($B8="","",$F8*INDEX(Assumptions!$D$29:$D$40,5)*IF(5<IF(N($C8)<1,1,$C8),0,IF(AND($D8="Yes",5<IF(N($C8)<1,1,$C8)+Assumptions!$C$16),Assumptions!$C$17,1))) -> 270000 | L8: =IF($B8="","",$F8*INDEX(Assumptions!$D$29:$D$40,6)*IF(6<IF(N($C8)<1,1,$C8),0,IF(AND($D8="Yes",6<IF(N($C8)<1,1,$C8)+Assumptions!$C$16),Assumptions!$C$17,1))) -> 270000 | M8: =IF($B8="","",$F8*INDEX(Assumptions!$D$29:$D$40,7)*IF(7<IF(N($C8)<1,1,$C8),0,IF(AND($D8="Yes",7<IF(N($C8)<1,1,$C8)+Assumptions!$C$16),Assumptions!$C$17,1))) -> 120000 | N8: =IF($B8="","",$F8*INDEX(Assumptions!$D$29:$D$40,8)*IF(8<IF(N($C8)<1,1,$C8),0,IF(AND($D8="Yes",8<IF(N($C8)<1,1,$C8)+Assumptions!$C$16),Assumptions!$C$17,1))) -> 210000 | O8: =IF($B8="","",$F8*INDEX(Assumptions!$D$29:$D$40,9)*IF(9<IF(N($C8)<1,1,$C8),0,IF(AND($D8="Yes",9<IF(N($C8)<1,1,$C8)+Assumptions!$C$16),Assumptions!$C$17,1))) -> 270000 | P8: =IF($B8="","",$F8*INDEX(Assumptions!$D$29:$D$40,10)*IF(10<IF(N($C8)<1,1,$C8),0,IF(AND($D8="Yes",10<IF(N($C8)<1,1,$C8)+Assumptions!$C$16),Assumptions!$C$17,1))) -> 270000 | Q8: =IF($B8="","",$F8*INDEX(Assumptions!$D$29:$D$40,11)*IF(11<IF(N($C8)<1,1,$C8),0,IF(AND($D8="Yes",11<IF(N($C8)<1,1,$C8)+Assumptions!$C$16),Assumptions!$C$17,1))) -> 300000 | R8: =IF($B8="","",$F8*INDEX(Assumptions!$D$29:$D$40,12)*IF(12<IF(N($C8)<1,1,$C8),0,IF(AND($D8="Yes",12<IF(N($C8)<1,1,$C8)+Assumptions!$C$16),Assumptions!$C$17,1))) -> 330000 | S8: =IF($B8="","",SUM(G8:R8)) -> 3000000
B9: Camilla Nørgaard | C9: 1 | D9: No | F9: =IF($B9="","",IF(N($E9)>0,$E9,Assumptions!$C$14)) -> 3000000 | G9: =IF($B9="","",$F9*INDEX(Assumptions!$D$29:$D$40,1)*IF(1<IF(N($C9)<1,1,$C9),0,IF(AND($D9="Yes",1<IF(N($C9)<1,1,$C9)+Assumptions!$C$16),Assumptions!$C$17,1))) -> 210000 | H9: =IF($B9="","",$F9*INDEX(Assumptions!$D$29:$D$40,2)*IF(2<IF(N($C9)<1,1,$C9),0,IF(AND($D9="Yes",2<IF(N($C9)<1,1,$C9)+Assumptions!$C$16),Assumptions!$C$17,1))) -> 240000 | I9: =IF($B9="","",$F9*INDEX(Assumptions!$D$29:$D$40,3)*IF(3<IF(N($C9)<1,1,$C9),0,IF(AND($D9="Yes",3<IF(N($C9)<1,1,$C9)+Assumptions!$C$16),Assumptions!$C$17,1))) -> 270000 | J9: =IF($B9="","",$F9*INDEX(Assumptions!$D$29:$D$40,4)*IF(4<IF(N($C9)<1,1,$C9),0,IF(AND($D9="Yes",4<IF(N($C9)<1,1,$C9)+Assumptions!$C$16),Assumptions!$C$17,1))) -> 240000 | K9: =IF($B9="","",$F9*INDEX(Assumptions!$D$29:$D$40,5)*IF(5<IF(N($C9)<1,1,$C9),0,IF(AND($D9="Yes",5<IF(N($C9)<1,1,$C9)+Assumptions!$C$16),Assumptions!$C$17,1))) -> 270000 | L9: =IF($B9="","",$F9*INDEX(Assumptions!$D$29:$D$40,6)*IF(6<IF(N($C9)<1,1,$C9),0,IF(AND($D9="Yes",6<IF(N($C9)<1,1,$C9)+Assumptions!$C$16),Assumptions!$C$17,1))) -> 270000 | M9: =IF($B9="","",$F9*INDEX(Assumptions!$D$29:$D$40,7)*IF(7<IF(N($C9)<1,1,$C9),0,IF(AND($D9="Yes",7<IF(N($C9)<1,1,$C9)+Assumptions!$C$16),Assumptions!$C$17,1))) -> 120000 | N9: =IF($B9="","",$F9*INDEX(Assumptions!$D$29:$D$40,8)*IF(8<IF(N($C9)<1,1,$C9),0,IF(AND($D9="Yes",8<IF(N($C9)<1,1,$C9)+Assumptions!$C$16),Assumptions!$C$17,1))) -> 210000 | O9: =IF($B9="","",$F9*INDEX(Assumptions!$D$29:$D$40,9)*IF(9<IF(N($C9)<1,1,$C9),0,IF(AND($D9="Yes",9<IF(N($C9)<1,1,$C9)+Assumptions!$C$16),Assumptions!$C$17,1))) -> 270000 | P9: =IF($B9="","",$F9*INDEX(Assumptions!$D$29:$D$40,10)*IF(10<IF(N($C9)<1,1,$C9),0,IF(AND($D9="Yes",10<IF(N($C9)<1,1,$C9)+Assumptions!$C$16),Assumptions!$C$17,1))) -> 270000 | Q9: =IF($B9="","",$F9*INDEX(Assumptions!$D$29:$D$40,11)*IF(11<IF(N($C9)<1,1,$C9),0,IF(AND($D9="Yes",11<IF(N($C9)<1,1,$C9)+Assumptions!$C$16),Assumptions!$C$17,1))) -> 300000 | R9: =IF($B9="","",$F9*INDEX(Assumptions!$D$29:$D$40,12)*IF(12<IF(N($C9)<1,1,$C9),0,IF(AND($D9="Yes",12<IF(N($C9)<1,1,$C9)+Assumptions!$C$16),Assumptions!$C$17,1))) -> 330000 | S9: =IF($B9="","",SUM(G9:R9)) -> 3000000
B10: Dennis Lund | C10: 1 | D10: No | F10: =IF($B10="","",IF(N($E10)>0,$E10,Assumptions!$C$14)) -> 3000000 | G10: =IF($B10="","",$F10*INDEX(Assumptions!$D$29:$D$40,1)*IF(1<IF(N($C10)<1,1,$C10),0,IF(AND($D10="Yes",1<IF(N($C10)<1,1,$C10)+Assumptions!$C$16),Assumptions!$C$17,1))) -> 210000 | H10: =IF($B10="","",$F10*INDEX(Assumptions!$D$29:$D$40,2)*IF(2<IF(N($C10)<1,1,$C10),0,IF(AND($D10="Yes",2<IF(N($C10)<1,1,$C10)+Assumptions!$C$16),Assumptions!$C$17,1))) -> 240000 | I10: =IF($B10="","",$F10*INDEX(Assumptions!$D$29:$D$40,3)*IF(3<IF(N($C10)<1,1,$C10),0,IF(AND($D10="Yes",3<IF(N($C10)<1,1,$C10)+Assumptions!$C$16),Assumptions!$C$17,1))) -> 270000 | J10: =IF($B10="","",$F10*INDEX(Assumptions!$D$29:$D$40,4)*IF(4<IF(N($C10)<1,1,$C10),0,IF(AND($D10="Yes",4<IF(N($C10)<1,1,$C10)+Assumptions!$C$16),Assumptions!$C$17,1))) -> 240000 | K10: =IF($B10="","",$F10*INDEX(Assumptions!$D$29:$D$40,5)*IF(5<IF(N($C10)<1,1,$C10),0,IF(AND($D10="Yes",5<IF(N($C10)<1,1,$C10)+Assumptions!$C$16),Assumptions!$C$17,1))) -> 270000 | L10: =IF($B10="","",$F10*INDEX(Assumptions!$D$29:$D$40,6)*IF(6<IF(N($C10)<1,1,$C10),0,IF(AND($D10="Yes",6<IF(N($C10)<1,1,$C10)+Assumptions!$C$16),Assumptions!$C$17,1))) -> 270000 | M10: =IF($B10="","",$F10*INDEX(Assumptions!$D$29:$D$40,7)*IF(7<IF(N($C10)<1,1,$C10),0,IF(AND($D10="Yes",7<IF(N($C10)<1,1,$C10)+Assumptions!$C$16),Assumptions!$C$17,1))) -> 120000 | N10: =IF($B10="","",$F10*INDEX(Assumptions!$D$29:$D$40,8)*IF(8<IF(N($C10)<1,1,$C10),0,IF(AND($D10="Yes",8<IF(N($C10)<1,1,$C10)+Assumptions!$C$16),Assumptions!$C$17,1))) -> 210000 | O10: =IF($B10="","",$F10*INDEX(Assumptions!$D$29:$D$40,9)*IF(9<IF(N($C10)<1,1,$C10),0,IF(AND($D10="Yes",9<IF(N($C10)<1,1,$C10)+Assumptions!$C$16),Assumptions!$C$17,1))) -> 270000 | P10: =IF($B10="","",$F10*INDEX(Assumptions!$D$29:$D$40,10)*IF(10<IF(N($C10)<1,1,$C10),0,IF(AND($D10="Yes",10<IF(N($C10)<1,1,$C10)+Assumptions!$C$16),Assumptions!$C$17,1))) -> 270000 | Q10: =IF($B10="","",$F10*INDEX(Assumptions!$D$29:$D$40,11)*IF(11<IF(N($C10)<1,1,$C10),0,IF(AND($D10="Yes",11<IF(N($C10)<1,1,$C10)+Assumptions!$C$16),Assumptions!$C$17,1))) -> 300000 | R10: =IF($B10="","",$F10*INDEX(Assumptions!$D$29:$D$40,12)*IF(12<IF(N($C10)<1,1,$C10),0,IF(AND($D10="Yes",12<IF(N($C10)<1,1,$C10)+Assumptions!$C$16),Assumptions!$C$17,1))) -> 330000 | S10: =IF($B10="","",SUM(G10:R10)) -> 3000000
B11: Emma Krogh | C11: 1 | D11: No | F11: =IF($B11="","",IF(N($E11)>0,$E11,Assumptions!$C$14)) -> 3000000 | G11: =IF($B11="","",$F11*INDEX(Assumptions!$D$29:$D$40,1)*IF(1<IF(N($C11)<1,1,$C11),0,IF(AND($D11="Yes",1<IF(N($C11)<1,1,$C11)+Assumptions!$C$16),Assumptions!$C$17,1))) -> 210000 | H11: =IF($B11="","",$F11*INDEX(Assumptions!$D$29:$D$40,2)*IF(2<IF(N($C11)<1,1,$C11),0,IF(AND($D11="Yes",2<IF(N($C11)<1,1,$C11)+Assumptions!$C$16),Assumptions!$C$17,1))) -> 240000 | I11: =IF($B11="","",$F11*INDEX(Assumptions!$D$29:$D$40,3)*IF(3<IF(N($C11)<1,1,$C11),0,IF(AND($D11="Yes",3<IF(N($C11)<1,1,$C11)+Assumptions!$C$16),Assumptions!$C$17,1))) -> 270000 | J11: =IF($B11="","",$F11*INDEX(Assumptions!$D$29:$D$40,4)*IF(4<IF(N($C11)<1,1,$C11),0,IF(AND($D11="Yes",4<IF(N($C11)<1,1,$C11)+Assumptions!$C$16),Assumptions!$C$17,1))) -> 240000 | K11: =IF($B11="","",$F11*INDEX(Assumptions!$D$29:$D$40,5)*IF(5<IF(N($C11)<1,1,$C11),0,IF(AND($D11="Yes",5<IF(N($C11)<1,1,$C11)+Assumptions!$C$16),Assumptions!$C$17,1))) -> 270000 | L11: =IF($B11="","",$F11*INDEX(Assumptions!$D$29:$D$40,6)*IF(6<IF(N($C11)<1,1,$C11),0,IF(AND($D11="Yes",6<IF(N($C11)<1,1,$C11)+Assumptions!$C$16),Assumptions!$C$17,1))) -> 270000 | M11: =IF($B11="","",$F11*INDEX(Assumptions!$D$29:$D$40,7)*IF(7<IF(N($C11)<1,1,$C11),0,IF(AND($D11="Yes",7<IF(N($C11)<1,1,$C11)+Assumptions!$C$16),Assumptions!$C$17,1))) -> 120000 | N11: =IF($B11="","",$F11*INDEX(Assumptions!$D$29:$D$40,8)*IF(8<IF(N($C11)<1,1,$C11),0,IF(AND($D11="Yes",8<IF(N($C11)<1,1,$C11)+Assumptions!$C$16),Assumptions!$C$17,1))) -> 210000 | O11: =IF($B11="","",$F11*INDEX(Assumptions!$D$29:$D$40,9)*IF(9<IF(N($C11)<1,1,$C11),0,IF(AND($D11="Yes",9<IF(N($C11)<1,1,$C11)+Assumptions!$C$16),Assumptions!$C$17,1))) -> 270000 | P11: =IF($B11="","",$F11*INDEX(Assumptions!$D$29:$D$40,10)*IF(10<IF(N($C11)<1,1,$C11),0,IF(AND($D11="Yes",10<IF(N($C11)<1,1,$C11)+Assumptions!$C$16),Assumptions!$C$17,1))) -> 270000 | Q11: =IF($B11="","",$F11*INDEX(Assumptions!$D$29:$D$40,11)*IF(11<IF(N($C11)<1,1,$C11),0,IF(AND($D11="Yes",11<IF(N($C11)<1,1,$C11)+Assumptions!$C$16),Assumptions!$C$17,1))) -> 300000 | R11: =IF($B11="","",$F11*INDEX(Assumptions!$D$29:$D$40,12)*IF(12<IF(N($C11)<1,1,$C11),0,IF(AND($D11="Yes",12<IF(N($C11)<1,1,$C11)+Assumptions!$C$16),Assumptions!$C$17,1))) -> 330000 | S11: =IF($B11="","",SUM(G11:R11)) -> 3000000
B12: Frederik Sand | C12: 1 | D12: No | F12: =IF($B12="","",IF(N($E12)>0,$E12,Assumptions!$C$14)) -> 3000000 | G12: =IF($B12="","",$F12*INDEX(Assumptions!$D$29:$D$40,1)*IF(1<IF(N($C12)<1,1,$C12),0,IF(AND($D12="Yes",1<IF(N($C12)<1,1,$C12)+Assumptions!$C$16),Assumptions!$C$17,1))) -> 210000 | H12: =IF($B12="","",$F12*INDEX(Assumptions!$D$29:$D$40,2)*IF(2<IF(N($C12)<1,1,$C12),0,IF(AND($D12="Yes",2<IF(N($C12)<1,1,$C12)+Assumptions!$C$16),Assumptions!$C$17,1))) -> 240000 | I12: =IF($B12="","",$F12*INDEX(Assumptions!$D$29:$D$40,3)*IF(3<IF(N($C12)<1,1,$C12),0,IF(AND($D12="Yes",3<IF(N($C12)<1,1,$C12)+Assumptions!$C$16),Assumptions!$C$17,1))) -> 270000 | J12: =IF($B12="","",$F12*INDEX(Assumptions!$D$29:$D$40,4)*IF(4<IF(N($C12)<1,1,$C12),0,IF(AND($D12="Yes",4<IF(N($C12)<1,1,$C12)+Assumptions!$C$16),Assumptions!$C$17,1))) -> 240000 | K12: =IF($B12="","",$F12*INDEX(Assumptions!$D$29:$D$40,5)*IF(5<IF(N($C12)<1,1,$C12),0,IF(AND($D12="Yes",5<IF(N($C12)<1,1,$C12)+Assumptions!$C$16),Assumptions!$C$17,1))) -> 270000 | L12: =IF($B12="","",$F12*INDEX(Assumptions!$D$29:$D$40,6)*IF(6<IF(N($C12)<1,1,$C12),0,IF(AND($D12="Yes",6<IF(N($C12)<1,1,$C12)+Assumptions!$C$16),Assumptions!$C$17,1))) -> 270000 | M12: =IF($B12="","",$F12*INDEX(Assumptions!$D$29:$D$40,7)*IF(7<IF(N($C12)<1,1,$C12),0,IF(AND($D12="Yes",7<IF(N($C12)<1,1,$C12)+Assumptions!$C$16),Assumptions!$C$17,1))) -> 120000 | N12: =IF($B12="","",$F12*INDEX(Assumptions!$D$29:$D$40,8)*IF(8<IF(N($C12)<1,1,$C12),0,IF(AND($D12="Yes",8<IF(N($C12)<1,1,$C12)+Assumptions!$C$16),Assumptions!$C$17,1))) -> 210000 | O12: =IF($B12="","",$F12*INDEX(Assumptions!$D$29:$D$40,9)*IF(9<IF(N($C12)<1,1,$C12),0,IF(AND($D12="Yes",9<IF(N($C12)<1,1,$C12)+Assumptions!$C$16),Assumptions!$C$17,1))) -> 270000 | P12: =IF($B12="","",$F12*INDEX(Assumptions!$D$29:$D$40,10)*IF(10<IF(N($C12)<1,1,$C12),0,IF(AND($D12="Yes",10<IF(N($C12)<1,1,$C12)+Assumptions!$C$16),Assumptions!$C$17,1))) -> 270000 | Q12: =IF($B12="","",$F12*INDEX(Assumptions!$D$29:$D$40,11)*IF(11<IF(N($C12)<1,1,$C12),0,IF(AND($D12="Yes",11<IF(N($C12)<1,1,$C12)+Assumptions!$C$16),Assumptions!$C$17,1))) -> 300000 | R12: =IF($B12="","",$F12*INDEX(Assumptions!$D$29:$D$40,12)*IF(12<IF(N($C12)<1,1,$C12),0,IF(AND($D12="Yes",12<IF(N($C12)<1,1,$C12)+Assumptions!$C$16),Assumptions!$C$17,1))) -> 330000 | S12: =IF($B12="","",SUM(G12:R12)) -> 3000000
B13: Gitte Mølgaard | C13: 1 | D13: No | F13: =IF($B13="","",IF(N($E13)>0,$E13,Assumptions!$C$14)) -> 3000000 | G13: =IF($B13="","",$F13*INDEX(Assumptions!$D$29:$D$40,1)*IF(1<IF(N($C13)<1,1,$C13),0,IF(AND($D13="Yes",1<IF(N($C13)<1,1,$C13)+Assumptions!$C$16),Assumptions!$C$17,1))) -> 210000 | H13: =IF($B13="","",$F13*INDEX(Assumptions!$D$29:$D$40,2)*IF(2<IF(N($C13)<1,1,$C13),0,IF(AND($D13="Yes",2<IF(N($C13)<1,1,$C13)+Assumptions!$C$16),Assumptions!$C$17,1))) -> 240000 | I13: =IF($B13="","",$F13*INDEX(Assumptions!$D$29:$D$40,3)*IF(3<IF(N($C13)<1,1,$C13),0,IF(AND($D13="Yes",3<IF(N($C13)<1,1,$C13)+Assumptions!$C$16),Assumptions!$C$17,1))) -> 270000 | J13: =IF($B13="","",$F13*INDEX(Assumptions!$D$29:$D$40,4)*IF(4<IF(N($C13)<1,1,$C13),0,IF(AND($D13="Yes",4<IF(N($C13)<1,1,$C13)+Assumptions!$C$16),Assumptions!$C$17,1))) -> 240000 | K13: =IF($B13="","",$F13*INDEX(Assumptions!$D$29:$D$40,5)*IF(5<IF(N($C13)<1,1,$C13),0,IF(AND($D13="Yes",5<IF(N($C13)<1,1,$C13)+Assumptions!$C$16),Assumptions!$C$17,1))) -> 270000 | L13: =IF($B13="","",$F13*INDEX(Assumptions!$D$29:$D$40,6)*IF(6<IF(N($C13)<1,1,$C13),0,IF(AND($D13="Yes",6<IF(N($C13)<1,1,$C13)+Assumptions!$C$16),Assumptions!$C$17,1))) -> 270000 | M13: =IF($B13="","",$F13*INDEX(Assumptions!$D$29:$D$40,7)*IF(7<IF(N($C13)<1,1,$C13),0,IF(AND($D13="Yes",7<IF(N($C13)<1,1,$C13)+Assumptions!$C$16),Assumptions!$C$17,1))) -> 120000 | N13: =IF($B13="","",$F13*INDEX(Assumptions!$D$29:$D$40,8)*IF(8<IF(N($C13)<1,1,$C13),0,IF(AND($D13="Yes",8<IF(N($C13)<1,1,$C13)+Assumptions!$C$16),Assumptions!$C$17,1))) -> 210000 | O13: =IF($B13="","",$F13*INDEX(Assumptions!$D$29:$D$40,9)*IF(9<IF(N($C13)<1,1,$C13),0,IF(AND($D13="Yes",9<IF(N($C13)<1,1,$C13)+Assumptions!$C$16),Assumptions!$C$17,1))) -> 270000 | P13: =IF($B13="","",$F13*INDEX(Assumptions!$D$29:$D$40,10)*IF(10<IF(N($C13)<1,1,$C13),0,IF(AND($D13="Yes",10<IF(N($C13)<1,1,$C13)+Assumptions!$C$16),Assumptions!$C$17,1))) -> 270000 | Q13: =IF($B13="","",$F13*INDEX(Assumptions!$D$29:$D$40,11)*IF(11<IF(N($C13)<1,1,$C13),0,IF(AND($D13="Yes",11<IF(N($C13)<1,1,$C13)+Assumptions!$C$16),Assumptions!$C$17,1))) -> 300000 | R13: =IF($B13="","",$F13*INDEX(Assumptions!$D$29:$D$40,12)*IF(12<IF(N($C13)<1,1,$C13),0,IF(AND($D13="Yes",12<IF(N($C13)<1,1,$C13)+Assumptions!$C$16),Assumptions!$C$17,1))) -> 330000 | S13: =IF($B13="","",SUM(G13:R13)) -> 3000000
B14: New rep 1 | C14: 1 | D14: Yes | F14: =IF($B14="","",IF(N($E14)>0,$E14,Assumptions!$C$14)) -> 3000000 | G14: =IF($B14="","",$F14*INDEX(Assumptions!$D$29:$D$40,1)*IF(1<IF(N($C14)<1,1,$C14),0,IF(AND($D14="Yes",1<IF(N($C14)<1,1,$C14)+Assumptions!$C$16),Assumptions!$C$17,1))) -> 105000 | H14: =IF($B14="","",$F14*INDEX(Assumptions!$D$29:$D$40,2)*IF(2<IF(N($C14)<1,1,$C14),0,IF(AND($D14="Yes",2<IF(N($C14)<1,1,$C14)+Assumptions!$C$16),Assumptions!$C$17,1))) -> 120000 | I14: =IF($B14="","",$F14*INDEX(Assumptions!$D$29:$D$40,3)*IF(3<IF(N($C14)<1,1,$C14),0,IF(AND($D14="Yes",3<IF(N($C14)<1,1,$C14)+Assumptions!$C$16),Assumptions!$C$17,1))) -> 135000 | J14: =IF($B14="","",$F14*INDEX(Assumptions!$D$29:$D$40,4)*IF(4<IF(N($C14)<1,1,$C14),0,IF(AND($D14="Yes",4<IF(N($C14)<1,1,$C14)+Assumptions!$C$16),Assumptions!$C$17,1))) -> 120000 | K14: =IF($B14="","",$F14*INDEX(Assumptions!$D$29:$D$40,5)*IF(5<IF(N($C14)<1,1,$C14),0,IF(AND($D14="Yes",5<IF(N($C14)<1,1,$C14)+Assumptions!$C$16),Assumptions!$C$17,1))) -> 270000 | L14: =IF($B14="","",$F14*INDEX(Assumptions!$D$29:$D$40,6)*IF(6<IF(N($C14)<1,1,$C14),0,IF(AND($D14="Yes",6<IF(N($C14)<1,1,$C14)+Assumptions!$C$16),Assumptions!$C$17,1))) -> 270000 | M14: =IF($B14="","",$F14*INDEX(Assumptions!$D$29:$D$40,7)*IF(7<IF(N($C14)<1,1,$C14),0,IF(AND($D14="Yes",7<IF(N($C14)<1,1,$C14)+Assumptions!$C$16),Assumptions!$C$17,1))) -> 120000 | N14: =IF($B14="","",$F14*INDEX(Assumptions!$D$29:$D$40,8)*IF(8<IF(N($C14)<1,1,$C14),0,IF(AND($D14="Yes",8<IF(N($C14)<1,1,$C14)+Assumptions!$C$16),Assumptions!$C$17,1))) -> 210000 | O14: =IF($B14="","",$F14*INDEX(Assumptions!$D$29:$D$40,9)*IF(9<IF(N($C14)<1,1,$C14),0,IF(AND($D14="Yes",9<IF(N($C14)<1,1,$C14)+Assumptions!$C$16),Assumptions!$C$17,1))) -> 270000 | P14: =IF($B14="","",$F14*INDEX(Assumptions!$D$29:$D$40,10)*IF(10<IF(N($C14)<1,1,$C14),0,IF(AND($D14="Yes",10<IF(N($C14)<1,1,$C14)+Assumptions!$C$16),Assumptions!$C$17,1))) -> 270000 | Q14: =IF($B14="","",$F14*INDEX(Assumptions!$D$29:$D$40,11)*IF(11<IF(N($C14)<1,1,$C14),0,IF(AND($D14="Yes",11<IF(N($C14)<1,1,$C14)+Assumptions!$C$16),Assumptions!$C$17,1))) -> 300000 | R14: =IF($B14="","",$F14*INDEX(Assumptions!$D$29:$D$40,12)*IF(12<IF(N($C14)<1,1,$C14),0,IF(AND($D14="Yes",12<IF(N($C14)<1,1,$C14)+Assumptions!$C$16),Assumptions!$C$17,1))) -> 330000 | S14: =IF($B14="","",SUM(G14:R14)) -> 2520000
B15: New rep 2 | C15: 2 | D15: Yes | F15: =IF($B15="","",IF(N($E15)>0,$E15,Assumptions!$C$14)) -> 3000000 | G15: =IF($B15="","",$F15*INDEX(Assumptions!$D$29:$D$40,1)*IF(1<IF(N($C15)<1,1,$C15),0,IF(AND($D15="Yes",1<IF(N($C15)<1,1,$C15)+Assumptions!$C$16),Assumptions!$C$17,1))) -> 0 | H15: =IF($B15="","",$F15*INDEX(Assumptions!$D$29:$D$40,2)*IF(2<IF(N($C15)<1,1,$C15),0,IF(AND($D15="Yes",2<IF(N($C15)<1,1,$C15)+Assumptions!$C$16),Assumptions!$C$17,1))) -> 120000 | I15: =IF($B15="","",$F15*INDEX(Assumptions!$D$29:$D$40,3)*IF(3<IF(N($C15)<1,1,$C15),0,IF(AND($D15="Yes",3<IF(N($C15)<1,1,$C15)+Assumptions!$C$16),Assumptions!$C$17,1))) -> 135000 | J15: =IF($B15="","",$F15*INDEX(Assumptions!$D$29:$D$40,4)*IF(4<IF(N($C15)<1,1,$C15),0,IF(AND($D15="Yes",4<IF(N($C15)<1,1,$C15)+Assumptions!$C$16),Assumptions!$C$17,1))) -> 120000 | K15: =IF($B15="","",$F15*INDEX(Assumptions!$D$29:$D$40,5)*IF(5<IF(N($C15)<1,1,$C15),0,IF(AND($D15="Yes",5<IF(N($C15)<1,1,$C15)+Assumptions!$C$16),Assumptions!$C$17,1))) -> 135000 | L15: =IF($B15="","",$F15*INDEX(Assumptions!$D$29:$D$40,6)*IF(6<IF(N($C15)<1,1,$C15),0,IF(AND($D15="Yes",6<IF(N($C15)<1,1,$C15)+Assumptions!$C$16),Assumptions!$C$17,1))) -> 270000 | M15: =IF($B15="","",$F15*INDEX(Assumptions!$D$29:$D$40,7)*IF(7<IF(N($C15)<1,1,$C15),0,IF(AND($D15="Yes",7<IF(N($C15)<1,1,$C15)+Assumptions!$C$16),Assumptions!$C$17,1))) -> 120000 | N15: =IF($B15="","",$F15*INDEX(Assumptions!$D$29:$D$40,8)*IF(8<IF(N($C15)<1,1,$C15),0,IF(AND($D15="Yes",8<IF(N($C15)<1,1,$C15)+Assumptions!$C$16),Assumptions!$C$17,1))) -> 210000 | O15: =IF($B15="","",$F15*INDEX(Assumptions!$D$29:$D$40,9)*IF(9<IF(N($C15)<1,1,$C15),0,IF(AND($D15="Yes",9<IF(N($C15)<1,1,$C15)+Assumptions!$C$16),Assumptions!$C$17,1))) -> 270000 | P15: =IF($B15="","",$F15*INDEX(Assumptions!$D$29:$D$40,10)*IF(10<IF(N($C15)<1,1,$C15),0,IF(AND($D15="Yes",10<IF(N($C15)<1,1,$C15)+Assumptions!$C$16),Assumptions!$C$17,1))) -> 270000 | Q15: =IF($B15="","",$F15*INDEX(Assumptions!$D$29:$D$40,11)*IF(11<IF(N($C15)<1,1,$C15),0,IF(AND($D15="Yes",11<IF(N($C15)<1,1,$C15)+Assumptions!$C$16),Assumptions!$C$17,1))) -> 300000 | R15: =IF($B15="","",$F15*INDEX(Assumptions!$D$29:$D$40,12)*IF(12<IF(N($C15)<1,1,$C15),0,IF(AND($D15="Yes",12<IF(N($C15)<1,1,$C15)+Assumptions!$C$16),Assumptions!$C$17,1))) -> 330000 | S15: =IF($B15="","",SUM(G15:R15)) -> 2280000
B16: New rep 3 | C16: 4 | D16: Yes | F16: =IF($B16="","",IF(N($E16)>0,$E16,Assumptions!$C$14)) -> 3000000 | G16: =IF($B16="","",$F16*INDEX(Assumptions!$D$29:$D$40,1)*IF(1<IF(N($C16)<1,1,$C16),0,IF(AND($D16="Yes",1<IF(N($C16)<1,1,$C16)+Assumptions!$C$16),Assumptions!$C$17,1))) -> 0 | H16: =IF($B16="","",$F16*INDEX(Assumptions!$D$29:$D$40,2)*IF(2<IF(N($C16)<1,1,$C16),0,IF(AND($D16="Yes",2<IF(N($C16)<1,1,$C16)+Assumptions!$C$16),Assumptions!$C$17,1))) -> 0 | I16: =IF($B16="","",$F16*INDEX(Assumptions!$D$29:$D$40,3)*IF(3<IF(N($C16)<1,1,$C16),0,IF(AND($D16="Yes",3<IF(N($C16)<1,1,$C16)+Assumptions!$C$16),Assumptions!$C$17,1))) -> 0 | J16: =IF($B16="","",$F16*INDEX(Assumptions!$D$29:$D$40,4)*IF(4<IF(N($C16)<1,1,$C16),0,IF(AND($D16="Yes",4<IF(N($C16)<1,1,$C16)+Assumptions!$C$16),Assumptions!$C$17,1))) -> 120000 | K16: =IF($B16="","",$F16*INDEX(Assumptions!$D$29:$D$40,5)*IF(5<IF(N($C16)<1,1,$C16),0,IF(AND($D16="Yes",5<IF(N($C16)<1,1,$C16)+Assumptions!$C$16),Assumptions!$C$17,1))) -> 135000 | L16: =IF($B16="","",$F16*INDEX(Assumptions!$D$29:$D$40,6)*IF(6<IF(N($C16)<1,1,$C16),0,IF(AND($D16="Yes",6<IF(N($C16)<1,1,$C16)+Assumptions!$C$16),Assumptions!$C$17,1))) -> 135000 | M16: =IF($B16="","",$F16*INDEX(Assumptions!$D$29:$D$40,7)*IF(7<IF(N($C16)<1,1,$C16),0,IF(AND($D16="Yes",7<IF(N($C16)<1,1,$C16)+Assumptions!$C$16),Assumptions!$C$17,1))) -> 60000 | N16: =IF($B16="","",$F16*INDEX(Assumptions!$D$29:$D$40,8)*IF(8<IF(N($C16)<1,1,$C16),0,IF(AND($D16="Yes",8<IF(N($C16)<1,1,$C16)+Assumptions!$C$16),Assumptions!$C$17,1))) -> 210000 | O16: =IF($B16="","",$F16*INDEX(Assumptions!$D$29:$D$40,9)*IF(9<IF(N($C16)<1,1,$C16),0,IF(AND($D16="Yes",9<IF(N($C16)<1,1,$C16)+Assumptions!$C$16),Assumptions!$C$17,1))) -> 270000 | P16: =IF($B16="","",$F16*INDEX(Assumptions!$D$29:$D$40,10)*IF(10<IF(N($C16)<1,1,$C16),0,IF(AND($D16="Yes",10<IF(N($C16)<1,1,$C16)+Assumptions!$C$16),Assumptions!$C$17,1))) -> 270000 | Q16: =IF($B16="","",$F16*INDEX(Assumptions!$D$29:$D$40,11)*IF(11<IF(N($C16)<1,1,$C16),0,IF(AND($D16="Yes",11<IF(N($C16)<1,1,$C16)+Assumptions!$C$16),Assumptions!$C$17,1))) -> 300000 | R16: =IF($B16="","",$F16*INDEX(Assumptions!$D$29:$D$40,12)*IF(12<IF(N($C16)<1,1,$C16),0,IF(AND($D16="Yes",12<IF(N($C16)<1,1,$C16)+Assumptions!$C$16),Assumptions!$C$17,1))) -> 330000 | S16: =IF($B16="","",SUM(G16:R16)) -> 1830000
F17: =IF($B17="","",IF(N($E17)>0,$E17,Assumptions!$C$14)) | G17: =IF($B17="","",$F17*INDEX(Assumptions!$D$29:$D$40,1)*IF(1<IF(N($C17)<1,1,$C17),0,IF(AND($D17="Yes",1<IF(N($C17)<1,1,$C17)+Assumptions!$C$16),Assumptions!$C$17,1))) | H17: =IF($B17="","",$F17*INDEX(Assumptions!$D$29:$D$40,2)*IF(2<IF(N($C17)<1,1,$C17),0,IF(AND($D17="Yes",2<IF(N($C17)<1,1,$C17)+Assumptions!$C$16),Assumptions!$C$17,1))) | I17: =IF($B17="","",$F17*INDEX(Assumptions!$D$29:$D$40,3)*IF(3<IF(N($C17)<1,1,$C17),0,IF(AND($D17="Yes",3<IF(N($C17)<1,1,$C17)+Assumptions!$C$16),Assumptions!$C$17,1))) | J17: =IF($B17="","",$F17*INDEX(Assumptions!$D$29:$D$40,4)*IF(4<IF(N($C17)<1,1,$C17),0,IF(AND($D17="Yes",4<IF(N($C17)<1,1,$C17)+Assumptions!$C$16),Assumptions!$C$17,1))) | K17: =IF($B17="","",$F17*INDEX(Assumptions!$D$29:$D$40,5)*IF(5<IF(N($C17)<1,1,$C17),0,IF(AND($D17="Yes",5<IF(N($C17)<1,1,$C17)+Assumptions!$C$16),Assumptions!$C$17,1))) | L17: =IF($B17="","",$F17*INDEX(Assumptions!$D$29:$D$40,6)*IF(6<IF(N($C17)<1,1,$C17),0,IF(AND($D17="Yes",6<IF(N($C17)<1,1,$C17)+Assumptions!$C$16),Assumptions!$C$17,1))) | M17: =IF($B17="","",$F17*INDEX(Assumptions!$D$29:$D$40,7)*IF(7<IF(N($C17)<1,1,$C17),0,IF(AND($D17="Yes",7<IF(N($C17)<1,1,$C17)+Assumptions!$C$16),Assumptions!$C$17,1))) | N17: =IF($B17="","",$F17*INDEX(Assumptions!$D$29:$D$40,8)*IF(8<IF(N($C17)<1,1,$C17),0,IF(AND($D17="Yes",8<IF(N($C17)<1,1,$C17)+Assumptions!$C$16),Assumptions!$C$17,1))) | O17: =IF($B17="","",$F17*INDEX(Assumptions!$D$29:$D$40,9)*IF(9<IF(N($C17)<1,1,$C17),0,IF(AND($D17="Yes",9<IF(N($C17)<1,1,$C17)+Assumptions!$C$16),Assumptions!$C$17,1))) | P17: =IF($B17="","",$F17*INDEX(Assumptions!$D$29:$D$40,10)*IF(10<IF(N($C17)<1,1,$C17),0,IF(AND($D17="Yes",10<IF(N($C17)<1,1,$C17)+Assumptions!$C$16),Assumptions!$C$17,1))) | Q17: =IF($B17="","",$F17*INDEX(Assumptions!$D$29:$D$40,11)*IF(11<IF(N($C17)<1,1,$C17),0,IF(AND($D17="Yes",11<IF(N($C17)<1,1,$C17)+Assumptions!$C$16),Assumptions!$C$17,1))) | R17: =IF($B17="","",$F17*INDEX(Assumptions!$D$29:$D$40,12)*IF(12<IF(N($C17)<1,1,$C17),0,IF(AND($D17="Yes",12<IF(N($C17)<1,1,$C17)+Assumptions!$C$16),Assumptions!$C$17,1))) | S17: =IF($B17="","",SUM(G17:R17))
F18: =IF($B18="","",IF(N($E18)>0,$E18,Assumptions!$C$14)) | G18: =IF($B18="","",$F18*INDEX(Assumptions!$D$29:$D$40,1)*IF(1<IF(N($C18)<1,1,$C18),0,IF(AND($D18="Yes",1<IF(N($C18)<1,1,$C18)+Assumptions!$C$16),Assumptions!$C$17,1))) | H18: =IF($B18="","",$F18*INDEX(Assumptions!$D$29:$D$40,2)*IF(2<IF(N($C18)<1,1,$C18),0,IF(AND($D18="Yes",2<IF(N($C18)<1,1,$C18)+Assumptions!$C$16),Assumptions!$C$17,1))) | I18: =IF($B18="","",$F18*INDEX(Assumptions!$D$29:$D$40,3)*IF(3<IF(N($C18)<1,1,$C18),0,IF(AND($D18="Yes",3<IF(N($C18)<1,1,$C18)+Assumptions!$C$16),Assumptions!$C$17,1))) | J18: =IF($B18="","",$F18*INDEX(Assumptions!$D$29:$D$40,4)*IF(4<IF(N($C18)<1,1,$C18),0,IF(AND($D18="Yes",4<IF(N($C18)<1,1,$C18)+Assumptions!$C$16),Assumptions!$C$17,1))) | K18: =IF($B18="","",$F18*INDEX(Assumptions!$D$29:$D$40,5)*IF(5<IF(N($C18)<1,1,$C18),0,IF(AND($D18="Yes",5<IF(N($C18)<1,1,$C18)+Assumptions!$C$16),Assumptions!$C$17,1))) | L18: =IF($B18="","",$F18*INDEX(Assumptions!$D$29:$D$40,6)*IF(6<IF(N($C18)<1,1,$C18),0,IF(AND($D18="Yes",6<IF(N($C18)<1,1,$C18)+Assumptions!$C$16),Assumptions!$C$17,1))) | M18: =IF($B18="","",$F18*INDEX(Assumptions!$D$29:$D$40,7)*IF(7<IF(N($C18)<1,1,$C18),0,IF(AND($D18="Yes",7<IF(N($C18)<1,1,$C18)+Assumptions!$C$16),Assumptions!$C$17,1))) | N18: =IF($B18="","",$F18*INDEX(Assumptions!$D$29:$D$40,8)*IF(8<IF(N($C18)<1,1,$C18),0,IF(AND($D18="Yes",8<IF(N($C18)<1,1,$C18)+Assumptions!$C$16),Assumptions!$C$17,1))) | O18: =IF($B18="","",$F18*INDEX(Assumptions!$D$29:$D$40,9)*IF(9<IF(N($C18)<1,1,$C18),0,IF(AND($D18="Yes",9<IF(N($C18)<1,1,$C18)+Assumptions!$C$16),Assumptions!$C$17,1))) | P18: =IF($B18="","",$F18*INDEX(Assumptions!$D$29:$D$40,10)*IF(10<IF(N($C18)<1,1,$C18),0,IF(AND($D18="Yes",10<IF(N($C18)<1,1,$C18)+Assumptions!$C$16),Assumptions!$C$17,1))) | Q18: =IF($B18="","",$F18*INDEX(Assumptions!$D$29:$D$40,11)*IF(11<IF(N($C18)<1,1,$C18),0,IF(AND($D18="Yes",11<IF(N($C18)<1,1,$C18)+Assumptions!$C$16),Assumptions!$C$17,1))) | R18: =IF($B18="","",$F18*INDEX(Assumptions!$D$29:$D$40,12)*IF(12<IF(N($C18)<1,1,$C18),0,IF(AND($D18="Yes",12<IF(N($C18)<1,1,$C18)+Assumptions!$C$16),Assumptions!$C$17,1))) | S18: =IF($B18="","",SUM(G18:R18))
F19: =IF($B19="","",IF(N($E19)>0,$E19,Assumptions!$C$14)) | G19: =IF($B19="","",$F19*INDEX(Assumptions!$D$29:$D$40,1)*IF(1<IF(N($C19)<1,1,$C19),0,IF(AND($D19="Yes",1<IF(N($C19)<1,1,$C19)+Assumptions!$C$16),Assumptions!$C$17,1))) | H19: =IF($B19="","",$F19*INDEX(Assumptions!$D$29:$D$40,2)*IF(2<IF(N($C19)<1,1,$C19),0,IF(AND($D19="Yes",2<IF(N($C19)<1,1,$C19)+Assumptions!$C$16),Assumptions!$C$17,1))) | I19: =IF($B19="","",$F19*INDEX(Assumptions!$D$29:$D$40,3)*IF(3<IF(N($C19)<1,1,$C19),0,IF(AND($D19="Yes",3<IF(N($C19)<1,1,$C19)+Assumptions!$C$16),Assumptions!$C$17,1))) | J19: =IF($B19="","",$F19*INDEX(Assumptions!$D$29:$D$40,4)*IF(4<IF(N($C19)<1,1,$C19),0,IF(AND($D19="Yes",4<IF(N($C19)<1,1,$C19)+Assumptions!$C$16),Assumptions!$C$17,1))) | K19: =IF($B19="","",$F19*INDEX(Assumptions!$D$29:$D$40,5)*IF(5<IF(N($C19)<1,1,$C19),0,IF(AND($D19="Yes",5<IF(N($C19)<1,1,$C19)+Assumptions!$C$16),Assumptions!$C$17,1))) | L19: =IF($B19="","",$F19*INDEX(Assumptions!$D$29:$D$40,6)*IF(6<IF(N($C19)<1,1,$C19),0,IF(AND($D19="Yes",6<IF(N($C19)<1,1,$C19)+Assumptions!$C$16),Assumptions!$C$17,1))) | M19: =IF($B19="","",$F19*INDEX(Assumptions!$D$29:$D$40,7)*IF(7<IF(N($C19)<1,1,$C19),0,IF(AND($D19="Yes",7<IF(N($C19)<1,1,$C19)+Assumptions!$C$16),Assumptions!$C$17,1))) | N19: =IF($B19="","",$F19*INDEX(Assumptions!$D$29:$D$40,8)*IF(8<IF(N($C19)<1,1,$C19),0,IF(AND($D19="Yes",8<IF(N($C19)<1,1,$C19)+Assumptions!$C$16),Assumptions!$C$17,1))) | O19: =IF($B19="","",$F19*INDEX(Assumptions!$D$29:$D$40,9)*IF(9<IF(N($C19)<1,1,$C19),0,IF(AND($D19="Yes",9<IF(N($C19)<1,1,$C19)+Assumptions!$C$16),Assumptions!$C$17,1))) | P19: =IF($B19="","",$F19*INDEX(Assumptions!$D$29:$D$40,10)*IF(10<IF(N($C19)<1,1,$C19),0,IF(AND($D19="Yes",10<IF(N($C19)<1,1,$C19)+Assumptions!$C$16),Assumptions!$C$17,1))) | Q19: =IF($B19="","",$F19*INDEX(Assumptions!$D$29:$D$40,11)*IF(11<IF(N($C19)<1,1,$C19),0,IF(AND($D19="Yes",11<IF(N($C19)<1,1,$C19)+Assumptions!$C$16),Assumptions!$C$17,1))) | R19: =IF($B19="","",$F19*INDEX(Assumptions!$D$29:$D$40,12)*IF(12<IF(N($C19)<1,1,$C19),0,IF(AND($D19="Yes",12<IF(N($C19)<1,1,$C19)+Assumptions!$C$16),Assumptions!$C$17,1))) | S19: =IF($B19="","",SUM(G19:R19))
F20: =IF($B20="","",IF(N($E20)>0,$E20,Assumptions!$C$14)) | G20: =IF($B20="","",$F20*INDEX(Assumptions!$D$29:$D$40,1)*IF(1<IF(N($C20)<1,1,$C20),0,IF(AND($D20="Yes",1<IF(N($C20)<1,1,$C20)+Assumptions!$C$16),Assumptions!$C$17,1))) | H20: =IF($B20="","",$F20*INDEX(Assumptions!$D$29:$D$40,2)*IF(2<IF(N($C20)<1,1,$C20),0,IF(AND($D20="Yes",2<IF(N($C20)<1,1,$C20)+Assumptions!$C$16),Assumptions!$C$17,1))) | I20: =IF($B20="","",$F20*INDEX(Assumptions!$D$29:$D$40,3)*IF(3<IF(N($C20)<1,1,$C20),0,IF(AND($D20="Yes",3<IF(N($C20)<1,1,$C20)+Assumptions!$C$16),Assumptions!$C$17,1))) | J20: =IF($B20="","",$F20*INDEX(Assumptions!$D$29:$D$40,4)*IF(4<IF(N($C20)<1,1,$C20),0,IF(AND($D20="Yes",4<IF(N($C20)<1,1,$C20)+Assumptions!$C$16),Assumptions!$C$17,1))) | K20: =IF($B20="","",$F20*INDEX(Assumptions!$D$29:$D$40,5)*IF(5<IF(N($C20)<1,1,$C20),0,IF(AND($D20="Yes",5<IF(N($C20)<1,1,$C20)+Assumptions!$C$16),Assumptions!$C$17,1))) | L20: =IF($B20="","",$F20*INDEX(Assumptions!$D$29:$D$40,6)*IF(6<IF(N($C20)<1,1,$C20),0,IF(AND($D20="Yes",6<IF(N($C20)<1,1,$C20)+Assumptions!$C$16),Assumptions!$C$17,1))) | M20: =IF($B20="","",$F20*INDEX(Assumptions!$D$29:$D$40,7)*IF(7<IF(N($C20)<1,1,$C20),0,IF(AND($D20="Yes",7<IF(N($C20)<1,1,$C20)+Assumptions!$C$16),Assumptions!$C$17,1))) | N20: =IF($B20="","",$F20*INDEX(Assumptions!$D$29:$D$40,8)*IF(8<IF(N($C20)<1,1,$C20),0,IF(AND($D20="Yes",8<IF(N($C20)<1,1,$C20)+Assumptions!$C$16),Assumptions!$C$17,1))) | O20: =IF($B20="","",$F20*INDEX(Assumptions!$D$29:$D$40,9)*IF(9<IF(N($C20)<1,1,$C20),0,IF(AND($D20="Yes",9<IF(N($C20)<1,1,$C20)+Assumptions!$C$16),Assumptions!$C$17,1))) | P20: =IF($B20="","",$F20*INDEX(Assumptions!$D$29:$D$40,10)*IF(10<IF(N($C20)<1,1,$C20),0,IF(AND($D20="Yes",10<IF(N($C20)<1,1,$C20)+Assumptions!$C$16),Assumptions!$C$17,1))) | Q20: =IF($B20="","",$F20*INDEX(Assumptions!$D$29:$D$40,11)*IF(11<IF(N($C20)<1,1,$C20),0,IF(AND($D20="Yes",11<IF(N($C20)<1,1,$C20)+Assumptions!$C$16),Assumptions!$C$17,1))) | R20: =IF($B20="","",$F20*INDEX(Assumptions!$D$29:$D$40,12)*IF(12<IF(N($C20)<1,1,$C20),0,IF(AND($D20="Yes",12<IF(N($C20)<1,1,$C20)+Assumptions!$C$16),Assumptions!$C$17,1))) | S20: =IF($B20="","",SUM(G20:R20))
F21: =IF($B21="","",IF(N($E21)>0,$E21,Assumptions!$C$14)) | G21: =IF($B21="","",$F21*INDEX(Assumptions!$D$29:$D$40,1)*IF(1<IF(N($C21)<1,1,$C21),0,IF(AND($D21="Yes",1<IF(N($C21)<1,1,$C21)+Assumptions!$C$16),Assumptions!$C$17,1))) | H21: =IF($B21="","",$F21*INDEX(Assumptions!$D$29:$D$40,2)*IF(2<IF(N($C21)<1,1,$C21),0,IF(AND($D21="Yes",2<IF(N($C21)<1,1,$C21)+Assumptions!$C$16),Assumptions!$C$17,1))) | I21: =IF($B21="","",$F21*INDEX(Assumptions!$D$29:$D$40,3)*IF(3<IF(N($C21)<1,1,$C21),0,IF(AND($D21="Yes",3<IF(N($C21)<1,1,$C21)+Assumptions!$C$16),Assumptions!$C$17,1))) | J21: =IF($B21="","",$F21*INDEX(Assumptions!$D$29:$D$40,4)*IF(4<IF(N($C21)<1,1,$C21),0,IF(AND($D21="Yes",4<IF(N($C21)<1,1,$C21)+Assumptions!$C$16),Assumptions!$C$17,1))) | K21: =IF($B21="","",$F21*INDEX(Assumptions!$D$29:$D$40,5)*IF(5<IF(N($C21)<1,1,$C21),0,IF(AND($D21="Yes",5<IF(N($C21)<1,1,$C21)+Assumptions!$C$16),Assumptions!$C$17,1))) | L21: =IF($B21="","",$F21*INDEX(Assumptions!$D$29:$D$40,6)*IF(6<IF(N($C21)<1,1,$C21),0,IF(AND($D21="Yes",6<IF(N($C21)<1,1,$C21)+Assumptions!$C$16),Assumptions!$C$17,1))) | M21: =IF($B21="","",$F21*INDEX(Assumptions!$D$29:$D$40,7)*IF(7<IF(N($C21)<1,1,$C21),0,IF(AND($D21="Yes",7<IF(N($C21)<1,1,$C21)+Assumptions!$C$16),Assumptions!$C$17,1))) | N21: =IF($B21="","",$F21*INDEX(Assumptions!$D$29:$D$40,8)*IF(8<IF(N($C21)<1,1,$C21),0,IF(AND($D21="Yes",8<IF(N($C21)<1,1,$C21)+Assumptions!$C$16),Assumptions!$C$17,1))) | O21: =IF($B21="","",$F21*INDEX(Assumptions!$D$29:$D$40,9)*IF(9<IF(N($C21)<1,1,$C21),0,IF(AND($D21="Yes",9<IF(N($C21)<1,1,$C21)+Assumptions!$C$16),Assumptions!$C$17,1))) | P21: =IF($B21="","",$F21*INDEX(Assumptions!$D$29:$D$40,10)*IF(10<IF(N($C21)<1,1,$C21),0,IF(AND($D21="Yes",10<IF(N($C21)<1,1,$C21)+Assumptions!$C$16),Assumptions!$C$17,1))) | Q21: =IF($B21="","",$F21*INDEX(Assumptions!$D$29:$D$40,11)*IF(11<IF(N($C21)<1,1,$C21),0,IF(AND($D21="Yes",11<IF(N($C21)<1,1,$C21)+Assumptions!$C$16),Assumptions!$C$17,1))) | R21: =IF($B21="","",$F21*INDEX(Assumptions!$D$29:$D$40,12)*IF(12<IF(N($C21)<1,1,$C21),0,IF(AND($D21="Yes",12<IF(N($C21)<1,1,$C21)+Assumptions!$C$16),Assumptions!$C$17,1))) | S21: =IF($B21="","",SUM(G21:R21))
F22: =IF($B22="","",IF(N($E22)>0,$E22,Assumptions!$C$14)) | G22: =IF($B22="","",$F22*INDEX(Assumptions!$D$29:$D$40,1)*IF(1<IF(N($C22)<1,1,$C22),0,IF(AND($D22="Yes",1<IF(N($C22)<1,1,$C22)+Assumptions!$C$16),Assumptions!$C$17,1))) | H22: =IF($B22="","",$F22*INDEX(Assumptions!$D$29:$D$40,2)*IF(2<IF(N($C22)<1,1,$C22),0,IF(AND($D22="Yes",2<IF(N($C22)<1,1,$C22)+Assumptions!$C$16),Assumptions!$C$17,1))) | I22: =IF($B22="","",$F22*INDEX(Assumptions!$D$29:$D$40,3)*IF(3<IF(N($C22)<1,1,$C22),0,IF(AND($D22="Yes",3<IF(N($C22)<1,1,$C22)+Assumptions!$C$16),Assumptions!$C$17,1))) | J22: =IF($B22="","",$F22*INDEX(Assumptions!$D$29:$D$40,4)*IF(4<IF(N($C22)<1,1,$C22),0,IF(AND($D22="Yes",4<IF(N($C22)<1,1,$C22)+Assumptions!$C$16),Assumptions!$C$17,1))) | K22: =IF($B22="","",$F22*INDEX(Assumptions!$D$29:$D$40,5)*IF(5<IF(N($C22)<1,1,$C22),0,IF(AND($D22="Yes",5<IF(N($C22)<1,1,$C22)+Assumptions!$C$16),Assumptions!$C$17,1))) | L22: =IF($B22="","",$F22*INDEX(Assumptions!$D$29:$D$40,6)*IF(6<IF(N($C22)<1,1,$C22),0,IF(AND($D22="Yes",6<IF(N($C22)<1,1,$C22)+Assumptions!$C$16),Assumptions!$C$17,1))) | M22: =IF($B22="","",$F22*INDEX(Assumptions!$D$29:$D$40,7)*IF(7<IF(N($C22)<1,1,$C22),0,IF(AND($D22="Yes",7<IF(N($C22)<1,1,$C22)+Assumptions!$C$16),Assumptions!$C$17,1))) | N22: =IF($B22="","",$F22*INDEX(Assumptions!$D$29:$D$40,8)*IF(8<IF(N($C22)<1,1,$C22),0,IF(AND($D22="Yes",8<IF(N($C22)<1,1,$C22)+Assumptions!$C$16),Assumptions!$C$17,1))) | O22: =IF($B22="","",$F22*INDEX(Assumptions!$D$29:$D$40,9)*IF(9<IF(N($C22)<1,1,$C22),0,IF(AND($D22="Yes",9<IF(N($C22)<1,1,$C22)+Assumptions!$C$16),Assumptions!$C$17,1))) | P22: =IF($B22="","",$F22*INDEX(Assumptions!$D$29:$D$40,10)*IF(10<IF(N($C22)<1,1,$C22),0,IF(AND($D22="Yes",10<IF(N($C22)<1,1,$C22)+Assumptions!$C$16),Assumptions!$C$17,1))) | Q22: =IF($B22="","",$F22*INDEX(Assumptions!$D$29:$D$40,11)*IF(11<IF(N($C22)<1,1,$C22),0,IF(AND($D22="Yes",11<IF(N($C22)<1,1,$C22)+Assumptions!$C$16),Assumptions!$C$17,1))) | R22: =IF($B22="","",$F22*INDEX(Assumptions!$D$29:$D$40,12)*IF(12<IF(N($C22)<1,1,$C22),0,IF(AND($D22="Yes",12<IF(N($C22)<1,1,$C22)+Assumptions!$C$16),Assumptions!$C$17,1))) | S22: =IF($B22="","",SUM(G22:R22))
F23: =IF($B23="","",IF(N($E23)>0,$E23,Assumptions!$C$14)) | G23: =IF($B23="","",$F23*INDEX(Assumptions!$D$29:$D$40,1)*IF(1<IF(N($C23)<1,1,$C23),0,IF(AND($D23="Yes",1<IF(N($C23)<1,1,$C23)+Assumptions!$C$16),Assumptions!$C$17,1))) | H23: =IF($B23="","",$F23*INDEX(Assumptions!$D$29:$D$40,2)*IF(2<IF(N($C23)<1,1,$C23),0,IF(AND($D23="Yes",2<IF(N($C23)<1,1,$C23)+Assumptions!$C$16),Assumptions!$C$17,1))) | I23: =IF($B23="","",$F23*INDEX(Assumptions!$D$29:$D$40,3)*IF(3<IF(N($C23)<1,1,$C23),0,IF(AND($D23="Yes",3<IF(N($C23)<1,1,$C23)+Assumptions!$C$16),Assumptions!$C$17,1))) | J23: =IF($B23="","",$F23*INDEX(Assumptions!$D$29:$D$40,4)*IF(4<IF(N($C23)<1,1,$C23),0,IF(AND($D23="Yes",4<IF(N($C23)<1,1,$C23)+Assumptions!$C$16),Assumptions!$C$17,1))) | K23: =IF($B23="","",$F23*INDEX(Assumptions!$D$29:$D$40,5)*IF(5<IF(N($C23)<1,1,$C23),0,IF(AND($D23="Yes",5<IF(N($C23)<1,1,$C23)+Assumptions!$C$16),Assumptions!$C$17,1))) | L23: =IF($B23="","",$F23*INDEX(Assumptions!$D$29:$D$40,6)*IF(6<IF(N($C23)<1,1,$C23),0,IF(AND($D23="Yes",6<IF(N($C23)<1,1,$C23)+Assumptions!$C$16),Assumptions!$C$17,1))) | M23: =IF($B23="","",$F23*INDEX(Assumptions!$D$29:$D$40,7)*IF(7<IF(N($C23)<1,1,$C23),0,IF(AND($D23="Yes",7<IF(N($C23)<1,1,$C23)+Assumptions!$C$16),Assumptions!$C$17,1))) | N23: =IF($B23="","",$F23*INDEX(Assumptions!$D$29:$D$40,8)*IF(8<IF(N($C23)<1,1,$C23),0,IF(AND($D23="Yes",8<IF(N($C23)<1,1,$C23)+Assumptions!$C$16),Assumptions!$C$17,1))) | O23: =IF($B23="","",$F23*INDEX(Assumptions!$D$29:$D$40,9)*IF(9<IF(N($C23)<1,1,$C23),0,IF(AND($D23="Yes",9<IF(N($C23)<1,1,$C23)+Assumptions!$C$16),Assumptions!$C$17,1))) | P23: =IF($B23="","",$F23*INDEX(Assumptions!$D$29:$D$40,10)*IF(10<IF(N($C23)<1,1,$C23),0,IF(AND($D23="Yes",10<IF(N($C23)<1,1,$C23)+Assumptions!$C$16),Assumptions!$C$17,1))) | Q23: =IF($B23="","",$F23*INDEX(Assumptions!$D$29:$D$40,11)*IF(11<IF(N($C23)<1,1,$C23),0,IF(AND($D23="Yes",11<IF(N($C23)<1,1,$C23)+Assumptions!$C$16),Assumptions!$C$17,1))) | R23: =IF($B23="","",$F23*INDEX(Assumptions!$D$29:$D$40,12)*IF(12<IF(N($C23)<1,1,$C23),0,IF(AND($D23="Yes",12<IF(N($C23)<1,1,$C23)+Assumptions!$C$16),Assumptions!$C$17,1))) | S23: =IF($B23="","",SUM(G23:R23))
F24: =IF($B24="","",IF(N($E24)>0,$E24,Assumptions!$C$14)) | G24: =IF($B24="","",$F24*INDEX(Assumptions!$D$29:$D$40,1)*IF(1<IF(N($C24)<1,1,$C24),0,IF(AND($D24="Yes",1<IF(N($C24)<1,1,$C24)+Assumptions!$C$16),Assumptions!$C$17,1))) | H24: =IF($B24="","",$F24*INDEX(Assumptions!$D$29:$D$40,2)*IF(2<IF(N($C24)<1,1,$C24),0,IF(AND($D24="Yes",2<IF(N($C24)<1,1,$C24)+Assumptions!$C$16),Assumptions!$C$17,1))) | I24: =IF($B24="","",$F24*INDEX(Assumptions!$D$29:$D$40,3)*IF(3<IF(N($C24)<1,1,$C24),0,IF(AND($D24="Yes",3<IF(N($C24)<1,1,$C24)+Assumptions!$C$16),Assumptions!$C$17,1))) | J24: =IF($B24="","",$F24*INDEX(Assumptions!$D$29:$D$40,4)*IF(4<IF(N($C24)<1,1,$C24),0,IF(AND($D24="Yes",4<IF(N($C24)<1,1,$C24)+Assumptions!$C$16),Assumptions!$C$17,1))) | K24: =IF($B24="","",$F24*INDEX(Assumptions!$D$29:$D$40,5)*IF(5<IF(N($C24)<1,1,$C24),0,IF(AND($D24="Yes",5<IF(N($C24)<1,1,$C24)+Assumptions!$C$16),Assumptions!$C$17,1))) | L24: =IF($B24="","",$F24*INDEX(Assumptions!$D$29:$D$40,6)*IF(6<IF(N($C24)<1,1,$C24),0,IF(AND($D24="Yes",6<IF(N($C24)<1,1,$C24)+Assumptions!$C$16),Assumptions!$C$17,1))) | M24: =IF($B24="","",$F24*INDEX(Assumptions!$D$29:$D$40,7)*IF(7<IF(N($C24)<1,1,$C24),0,IF(AND($D24="Yes",7<IF(N($C24)<1,1,$C24)+Assumptions!$C$16),Assumptions!$C$17,1))) | N24: =IF($B24="","",$F24*INDEX(Assumptions!$D$29:$D$40,8)*IF(8<IF(N($C24)<1,1,$C24),0,IF(AND($D24="Yes",8<IF(N($C24)<1,1,$C24)+Assumptions!$C$16),Assumptions!$C$17,1))) | O24: =IF($B24="","",$F24*INDEX(Assumptions!$D$29:$D$40,9)*IF(9<IF(N($C24)<1,1,$C24),0,IF(AND($D24="Yes",9<IF(N($C24)<1,1,$C24)+Assumptions!$C$16),Assumptions!$C$17,1))) | P24: =IF($B24="","",$F24*INDEX(Assumptions!$D$29:$D$40,10)*IF(10<IF(N($C24)<1,1,$C24),0,IF(AND($D24="Yes",10<IF(N($C24)<1,1,$C24)+Assumptions!$C$16),Assumptions!$C$17,1))) | Q24: =IF($B24="","",$F24*INDEX(Assumptions!$D$29:$D$40,11)*IF(11<IF(N($C24)<1,1,$C24),0,IF(AND($D24="Yes",11<IF(N($C24)<1,1,$C24)+Assumptions!$C$16),Assumptions!$C$17,1))) | R24: =IF($B24="","",$F24*INDEX(Assumptions!$D$29:$D$40,12)*IF(12<IF(N($C24)<1,1,$C24),0,IF(AND($D24="Yes",12<IF(N($C24)<1,1,$C24)+Assumptions!$C$16),Assumptions!$C$17,1))) | S24: =IF($B24="","",SUM(G24:R24))
F25: =IF($B25="","",IF(N($E25)>0,$E25,Assumptions!$C$14)) | G25: =IF($B25="","",$F25*INDEX(Assumptions!$D$29:$D$40,1)*IF(1<IF(N($C25)<1,1,$C25),0,IF(AND($D25="Yes",1<IF(N($C25)<1,1,$C25)+Assumptions!$C$16),Assumptions!$C$17,1))) | H25: =IF($B25="","",$F25*INDEX(Assumptions!$D$29:$D$40,2)*IF(2<IF(N($C25)<1,1,$C25),0,IF(AND($D25="Yes",2<IF(N($C25)<1,1,$C25)+Assumptions!$C$16),Assumptions!$C$17,1))) | I25: =IF($B25="","",$F25*INDEX(Assumptions!$D$29:$D$40,3)*IF(3<IF(N($C25)<1,1,$C25),0,IF(AND($D25="Yes",3<IF(N($C25)<1,1,$C25)+Assumptions!$C$16),Assumptions!$C$17,1))) | J25: =IF($B25="","",$F25*INDEX(Assumptions!$D$29:$D$40,4)*IF(4<IF(N($C25)<1,1,$C25),0,IF(AND($D25="Yes",4<IF(N($C25)<1,1,$C25)+Assumptions!$C$16),Assumptions!$C$17,1))) | K25: =IF($B25="","",$F25*INDEX(Assumptions!$D$29:$D$40,5)*IF(5<IF(N($C25)<1,1,$C25),0,IF(AND($D25="Yes",5<IF(N($C25)<1,1,$C25)+Assumptions!$C$16),Assumptions!$C$17,1))) | L25: =IF($B25="","",$F25*INDEX(Assumptions!$D$29:$D$40,6)*IF(6<IF(N($C25)<1,1,$C25),0,IF(AND($D25="Yes",6<IF(N($C25)<1,1,$C25)+Assumptions!$C$16),Assumptions!$C$17,1))) | M25: =IF($B25="","",$F25*INDEX(Assumptions!$D$29:$D$40,7)*IF(7<IF(N($C25)<1,1,$C25),0,IF(AND($D25="Yes",7<IF(N($C25)<1,1,$C25)+Assumptions!$C$16),Assumptions!$C$17,1))) | N25: =IF($B25="","",$F25*INDEX(Assumptions!$D$29:$D$40,8)*IF(8<IF(N($C25)<1,1,$C25),0,IF(AND($D25="Yes",8<IF(N($C25)<1,1,$C25)+Assumptions!$C$16),Assumptions!$C$17,1))) | O25: =IF($B25="","",$F25*INDEX(Assumptions!$D$29:$D$40,9)*IF(9<IF(N($C25)<1,1,$C25),0,IF(AND($D25="Yes",9<IF(N($C25)<1,1,$C25)+Assumptions!$C$16),Assumptions!$C$17,1))) | P25: =IF($B25="","",$F25*INDEX(Assumptions!$D$29:$D$40,10)*IF(10<IF(N($C25)<1,1,$C25),0,IF(AND($D25="Yes",10<IF(N($C25)<1,1,$C25)+Assumptions!$C$16),Assumptions!$C$17,1))) | Q25: =IF($B25="","",$F25*INDEX(Assumptions!$D$29:$D$40,11)*IF(11<IF(N($C25)<1,1,$C25),0,IF(AND($D25="Yes",11<IF(N($C25)<1,1,$C25)+Assumptions!$C$16),Assumptions!$C$17,1))) | R25: =IF($B25="","",$F25*INDEX(Assumptions!$D$29:$D$40,12)*IF(12<IF(N($C25)<1,1,$C25),0,IF(AND($D25="Yes",12<IF(N($C25)<1,1,$C25)+Assumptions!$C$16),Assumptions!$C$17,1))) | S25: =IF($B25="","",SUM(G25:R25))
F26: =IF($B26="","",IF(N($E26)>0,$E26,Assumptions!$C$14)) | G26: =IF($B26="","",$F26*INDEX(Assumptions!$D$29:$D$40,1)*IF(1<IF(N($C26)<1,1,$C26),0,IF(AND($D26="Yes",1<IF(N($C26)<1,1,$C26)+Assumptions!$C$16),Assumptions!$C$17,1))) | H26: =IF($B26="","",$F26*INDEX(Assumptions!$D$29:$D$40,2)*IF(2<IF(N($C26)<1,1,$C26),0,IF(AND($D26="Yes",2<IF(N($C26)<1,1,$C26)+Assumptions!$C$16),Assumptions!$C$17,1))) | I26: =IF($B26="","",$F26*INDEX(Assumptions!$D$29:$D$40,3)*IF(3<IF(N($C26)<1,1,$C26),0,IF(AND($D26="Yes",3<IF(N($C26)<1,1,$C26)+Assumptions!$C$16),Assumptions!$C$17,1))) | J26: =IF($B26="","",$F26*INDEX(Assumptions!$D$29:$D$40,4)*IF(4<IF(N($C26)<1,1,$C26),0,IF(AND($D26="Yes",4<IF(N($C26)<1,1,$C26)+Assumptions!$C$16),Assumptions!$C$17,1))) | K26: =IF($B26="","",$F26*INDEX(Assumptions!$D$29:$D$40,5)*IF(5<IF(N($C26)<1,1,$C26),0,IF(AND($D26="Yes",5<IF(N($C26)<1,1,$C26)+Assumptions!$C$16),Assumptions!$C$17,1))) | L26: =IF($B26="","",$F26*INDEX(Assumptions!$D$29:$D$40,6)*IF(6<IF(N($C26)<1,1,$C26),0,IF(AND($D26="Yes",6<IF(N($C26)<1,1,$C26)+Assumptions!$C$16),Assumptions!$C$17,1))) | M26: =IF($B26="","",$F26*INDEX(Assumptions!$D$29:$D$40,7)*IF(7<IF(N($C26)<1,1,$C26),0,IF(AND($D26="Yes",7<IF(N($C26)<1,1,$C26)+Assumptions!$C$16),Assumptions!$C$17,1))) | N26: =IF($B26="","",$F26*INDEX(Assumptions!$D$29:$D$40,8)*IF(8<IF(N($C26)<1,1,$C26),0,IF(AND($D26="Yes",8<IF(N($C26)<1,1,$C26)+Assumptions!$C$16),Assumptions!$C$17,1))) | O26: =IF($B26="","",$F26*INDEX(Assumptions!$D$29:$D$40,9)*IF(9<IF(N($C26)<1,1,$C26),0,IF(AND($D26="Yes",9<IF(N($C26)<1,1,$C26)+Assumptions!$C$16),Assumptions!$C$17,1))) | P26: =IF($B26="","",$F26*INDEX(Assumptions!$D$29:$D$40,10)*IF(10<IF(N($C26)<1,1,$C26),0,IF(AND($D26="Yes",10<IF(N($C26)<1,1,$C26)+Assumptions!$C$16),Assumptions!$C$17,1))) | Q26: =IF($B26="","",$F26*INDEX(Assumptions!$D$29:$D$40,11)*IF(11<IF(N($C26)<1,1,$C26),0,IF(AND($D26="Yes",11<IF(N($C26)<1,1,$C26)+Assumptions!$C$16),Assumptions!$C$17,1))) | R26: =IF($B26="","",$F26*INDEX(Assumptions!$D$29:$D$40,12)*IF(12<IF(N($C26)<1,1,$C26),0,IF(AND($D26="Yes",12<IF(N($C26)<1,1,$C26)+Assumptions!$C$16),Assumptions!$C$17,1))) | S26: =IF($B26="","",SUM(G26:R26))
B27: Total quota | G27: =SUM(G7:G26) -> 1575000 | H27: =SUM(H7:H26) -> 1920000 | I27: =SUM(I7:I26) -> 2160000 | J27: =SUM(J7:J26) -> 2040000 | K27: =SUM(K7:K26) -> 2430000 | L27: =SUM(L7:L26) -> 2565000 | M27: =SUM(M7:M26) -> 1140000 | N27: =SUM(N7:N26) -> 2100000 | ... S27: =SUM(S7:S26) -> 27630000
B28: Revenue goal spread by seasonality | G28: =Assumptions!$C$7*INDEX(Assumptions!$D$29:$D$40,1) -> 1680000 | H28: =Assumptions!$C$7*INDEX(Assumptions!$D$29:$D$40,2) -> 1920000 | I28: =Assumptions!$C$7*INDEX(Assumptions!$D$29:$D$40,3) -> 2160000 | J28: =Assumptions!$C$7*INDEX(Assumptions!$D$29:$D$40,4) -> 1920000 | K28: =Assumptions!$C$7*INDEX(Assumptions!$D$29:$D$40,5) -> 2160000 | L28: =Assumptions!$C$7*INDEX(Assumptions!$D$29:$D$40,6) -> 2160000 | M28: =Assumptions!$C$7*INDEX(Assumptions!$D$29:$D$40,7) -> 960000 | N28: =Assumptions!$C$7*INDEX(Assumptions!$D$29:$D$40,8) -> 1680000 | O28: =Assumptions!$C$7*INDEX(Assumptions!$D$29:$D$40,9) -> 2160000 | P28: =Assumptions!$C$7*INDEX(Assumptions!$D$29:$D$40,10) -> 2160000 | Q28: =Assumptions!$C$7*INDEX(Assumptions!$D$29:$D$40,11) -> 2400000 | R28: =Assumptions!$C$7*INDEX(Assumptions!$D$29:$D$40,12) -> 2640000 | S28: =SUM(G28:R28) -> 24000000
B29: Quota as % of revenue goal | G29: =IFERROR(G27/G28,0) -> 0.9375 | H29: =IFERROR(H27/H28,0) -> 1 | I29: =IFERROR(I27/I28,0) -> 1 | J29: =IFERROR(J27/J28,0) -> 1.0625 | K29: =IFERROR(K27/K28,0) -> 1.125 | L29: =IFERROR(L27/L28,0) -> 1.1875 | M29: =IFERROR(M27/M28,0) -> 1.1875 | N29: =IFERROR(N27/N28,0) -> 1.25 | ... S29: =IFERROR(S27/S28,0) -> 1.15125
B31: Quota above 100% of the revenue goal is a buffer against attrition, delayed hires and reps who miss target.

Sheet OTE and commission
B2: OTE and commission
B3: The standard plan from Assumptions. The attainment levels in row 15 can be changed.
B4: Standard plan per fully productive rep
B5: Base salary per year | C5: =Assumptions!$C$22*12 -> 504000
B6: Variable pay at 100% | C6: =Assumptions!$C$23 -> 216000
B7: OTE, on-target earnings | C7: =C5+C6 -> 720000 | D7: OTE = base salary + variable pay at 100%.
B8: Pay mix, fixed share | C8: =IFERROR(C5/C7,0) -> 0.7
B9: Pay mix, variable share | C9: =IFERROR(C6/C7,0) -> 0.3
B10: Commission rate (variable ÷ quota) | C10: =IFERROR(C6/Assumptions!$C$14,0) -> 0.072 | D10: Rate = variable pay at 100% ÷ annual quota.
B11: Rate above 100% (with accelerator) | C11: =C10*Assumptions!$C$24 -> 0.108
B13: Commission for a fully productive rep
C14: Scenario 1 | D14: Scenario 2 | E14: Scenario 3
B15: Attainment | C15: 0.8 | D15: 1 | E15: 1.2
B16: Sales | C16: =Assumptions!$C$14*C15 -> 2400000 | D16: =Assumptions!$C$14*D15 -> 3000000 | E16: =Assumptions!$C$14*E15 -> 3600000
B17: Commission | C17: =Assumptions!$C$14*MIN(C15,1)*$C$10+Assumptions!$C$14*MAX(0,C15-1)*$C$11 -> 172800 | D17: =Assumptions!$C$14*MIN(D15,1)*$C$10+Assumptions!$C$14*MAX(0,D15-1)*$C$11 -> 216000 | E17: =Assumptions!$C$14*MIN(E15,1)*$C$10+Assumptions!$C$14*MAX(0,E15-1)*$C$11 -> 280800
B18: Total pay | C18: =$C$5+C17 -> 676800 | D18: =$C$5+D17 -> 720000 | E18: =$C$5+E17 -> 784800
B19: Commission as % of sales | C19: =IFERROR(C17/C16,0) -> 0.072 | D19: =IFERROR(D17/D16,0) -> 0.072 | E19: =IFERROR(E17/E16,0) -> 0.078
B21: Commission per rep in the budget year
B22: Quota from Quota allocation. Reps in ramp have a lower quota and therefore earn less commission at the same attainment.
B23: Rep | C23: Months employed | D23: Quota for the year | E23: Commission rate | F23: Base salary for the year | G23: Commission at scenario 1 | H23: Commission at scenario 2 | I23: Commission at scenario 3
B24: =IF('Quota allocation'!$B$7="","",'Quota allocation'!$B$7) -> Anna Holm | C24: =IF($B24="","",13-IF(N('Quota allocation'!$C$7)<1,1,'Quota allocation'!$C$7)) -> 12 | D24: =IF($B24="","",'Quota allocation'!$S$7) -> 3000000 | E24: =IF($B24="","",IFERROR($C$6/'Quota allocation'!$F$7,0)) -> 0.072 | F24: =IF($B24="","",Assumptions!$C$22*$C24) -> 504000 | G24: =IF($B24="","",$D24*MIN(C$15,1)*$E24+$D24*MAX(0,C$15-1)*$E24*Assumptions!$C$24) -> 172800 | H24: =IF($B24="","",$D24*MIN(D$15,1)*$E24+$D24*MAX(0,D$15-1)*$E24*Assumptions!$C$24) -> 216000 | I24: =IF($B24="","",$D24*MIN(E$15,1)*$E24+$D24*MAX(0,E$15-1)*$E24*Assumptions!$C$24) -> 280800
B25: =IF('Quota allocation'!$B$8="","",'Quota allocation'!$B$8) -> Bo Jensen | C25: =IF($B25="","",13-IF(N('Quota allocation'!$C$8)<1,1,'Quota allocation'!$C$8)) -> 12 | D25: =IF($B25="","",'Quota allocation'!$S$8) -> 3000000 | E25: =IF($B25="","",IFERROR($C$6/'Quota allocation'!$F$8,0)) -> 0.072 | F25: =IF($B25="","",Assumptions!$C$22*$C25) -> 504000 | G25: =IF($B25="","",$D25*MIN(C$15,1)*$E25+$D25*MAX(0,C$15-1)*$E25*Assumptions!$C$24) -> 172800 | H25: =IF($B25="","",$D25*MIN(D$15,1)*$E25+$D25*MAX(0,D$15-1)*$E25*Assumptions!$C$24) -> 216000 | I25: =IF($B25="","",$D25*MIN(E$15,1)*$E25+$D25*MAX(0,E$15-1)*$E25*Assumptions!$C$24) -> 280800
